Workbook

Sheet comments
A1: 999 | B1: This is the 'threshold' for the difference between the TOTALS and the sum of their parts
B2: formulae are written in BLUE
B3: All Text and figures are formatted to 'ARIEL' - font size 10 (Headers are BOLD and font size 14)
B4: Titles and headings should be in BOLD
B6: Due to the amalgamation of tables 1.1 and 1.2 all subsequent tables have been renumbered
B7: i.e. Table 1.3 became 1.2, Table 1.4 became 1.3 etc.

Sheet T12.1 - T12.3a
A2: Table 12.1 Trips per person per year by main mode
A4: Scottish residents: average per head of population *
C6: 1995 | E6: 1998 | G6: 2002 | I6: 2004 | K6: 2005 | M6: 2006
C7: / 1997 | E7: / 2000 | G7: / 2003 | I7: / 2005 | K7: / 2006 | M7: / 2007
A9: Walk (1) | C9: 300.63025 | E9: 302.38334 | G9: 289.25548 | I9: 242.13133 | K9: 248.36098
A10: Bicycle | C10: 8.6983851 | E10: 13.634431 | G10: 9.1875457 | I10: 10.304629 | K10: 8.2680609
A11: Driver of car, van or lorry | C11: 388.20494 | E11: 432.73755 | G11: 395.47993 | I11: 406.56784 | K11: 407.74083
A12: Passenger in car, van or lorry | C12: 229.82106 | E12: 219.43389 | G12: 214.15986 | I12: 229.44826 | K12: 225.32205
A13: Motorcycle / moped | C13: 1.3336041 | E13: 1.203069 | G13: 2.3798107 | I13: 0.77829025 | K13: #DIV/0!
A14: Other private transport | C14: 11.103423 | E14: 10.201899 | G14: 10.104487 | I14: 9.1877285 | K14: #DIV/0!
A15: Other private transport (eg motorcycle, private hire bus) | C15: 12.437027 | E15: 11.404968 | G15: 12.484298 | I15: 9.9660188 | K15: 11.035503
A16: Local bus | C16: 86.264589 | E16: 82.778034 | G16: 82.984144 | I16: 81.165354 | K16: 80.097205
A17: Non-local bus | C17: 1.8842372 | E17: 3.0208179 | G17: 0.57930659 | I17: 0.44633675 | K17: 15.457035
A18: Surface Rail | C18: 9.3519143 | E18: 14.570385 | G18: 11.885574 | I18: 15.947234 | K18: 15.457035
A19: Taxi / minicab | C19: 12.592509 | E19: 19.365835 | G19: 15.846041 | I19: 15.863262 | K19: 15.677132
A20: Other public transport | C20: 4.5122588 | E20: 2.1913418 | G20: 3.140612 | I20: 1.6815548 | K20: 0
A21: Other public transport (eg air, ferry, non-local bus) | C21: 6.396496 | E21: 5.2121596 | G21: 3.7199186 | I21: 2.1278915 | K21: 2.4426083
A22: All modes | C22: 1054.3972 | E22: 1101.5206 | G22: 1035.0028 | I22: 1013.5218 | K22: 1014.4014
C23: =IF(ABS(C22-(SUM(C9:C21)-C13-C14-C17-C20))>comments!$A$1,'T12.1 - T12.3a'!C22-(SUM(C9:C21)-C13-C14-C17-C20)," ") | E23: =IF(ABS(E22-(SUM(E9:E21)-E13-E14-E17-E20))>comments!$A$1,'T12.1 - T12.3a'!E22-(SUM(E9:E21)-E13-E14-E17-E20)," ") | G23: =IF(ABS(G22-(SUM(G9:G21)-G13-G14-G17-G20))>comments!$A$1,'T12.1 - T12.3a'!G22-(SUM(G9:G21)-G13-G14-G17-G20)," ") | I23: =IF(ABS(I22-(SUM(I9:I21)-I13-I14-I17-I20))>comments!$A$1,'T12.1 - T12.3a'!I22-(SUM(I9:I21)-I13-I14-I17-I20)," ")
A25: Sample size (number of people) | C25: 2024 | E25: 1926 | G25: 3396 | I25: 3766 | K25: 3723
A27: * Some of the results are based upon a small number of trips in the sample, and so may be subject to large percentage sampling errors.
A28: As a result, there may be some apparently large, and potentially misleading, percentage changes between periods.
A29: As mentioned in the text, NTS results for Scotland should be regarded as broad indicators rather than precise measures.
A30: The figures for 1995/97 onwards are based on weighted data, so are not directly comparable with earlier results (which are based on
A31: unweighted data) which can be found in the previous edition or in the "Travel by Scottish residents" bulletin.
A32: (1) Short walks are believed to be under-recorded in 2002/03 compared with earlier years.
A35: Table 12.2 Average distance travelled per person per year by main mode
A37: Scottish residents: average per head of population *
C39: 1995 | E39: 1998 | G39: 2002 | I39: 2004 | K39: 2005 | M39: 2006
C40: / 1997 | E40: / 2000 | G40: / 2003 | I40: / 2005 | K40: / 2006 | M40: / 2007
M41: miles
A42: Walk (1) | C42: 182.7773 | E42: 185.79268 | G42: 199.23 | I42: 169.2292 | K42: 190.9626
A43: Bicycle | C43: 25.536002 | E43: 30.095233 | G43: 27.598551 | I43: 24.827444 | K43: 22.822146
A44: Driver of car, van or lorry | C44: 3316.4356 | E44: 3737.7596 | G44: 3275.2022 | I44: 3548.6476 | K44: 3595.3512
A45: Passenger in car, van or lorry | C45: 1998.7991 | E45: 2000.6704 | G45: 2058.1865 | I45: 2071.6572 | K45: 2079.9246
A46: Motorcycle / moped | C46: 18.866136 | E46: 12.999113 | G46: 20.230333 | I46: 16.582167 | K46: 170.67517
A47: Other private transport | C47: 141.14759 | E47: 179.36652 | G47: 162.73221 | I47: 155.12225 | K47: 407.20551
A48: Other private transport (eg motorcycle, private hire bus) | C48: 160.01373 | E48: 192.36563 | G48: 182.96254 | I48: 171.70442 | K48: 170.67517
A49: Local bus | C49: 434.78147 | E49: 447.29347 | G49: 379.5538 | I49: 440.95692 | K49: 407.20551
A50: Non-local bus | C50: 94.870975 | E50: 117.03001 | G50: 54.650708 | I50: 35.433252 | K50: 433.33542
...

Sheet T12.4 - T12.6a
A2: Table 12.4 Trips per person per year by purpose
A4: Scottish residents: average per head of population *
F6: 1995 | H6: 1998 | J6: 2002 | L6: 2004 | N6: 2005 | P6: 2006
F7: / 1997 | H7: / 2000 | J7: / 2003 | L7: / 2005 | N7: / 2006 | P7: / 2007
A9: Commuting | F9: 177.20956 | H9: 177.55942 | J9: 173.89741 | L9: 169.71569 | N9: 158.76595
A10: Business | F10: 38.661624 | H10: 33.032604 | J10: 28.35457 | L10: 34.703061 | N10: 36.469452
A11: Education | F11: 72.090211 | H11: 70.769954 | J11: 81.888918 | L11: 64.321967 | N11: 61.329295
A12: Escort education | F12: 35.819973 | H12: 25.605178 | J12: 31.121441 | L12: 29.452022 | N12: 27.699403
A13: Shopping | F13: 231.78873 | H13: 249.50404 | J13: 207.48162 | L13: 206.55421 | N13: 216.42857
A14: Other escort | F14: 88.923454 | H14: 80.864849 | J14: 98.467998 | L14: 104.17833 | N14: 100.47477
A15: Other personal business | F15: 101.6631 | H15: 114.92832 | J15: 106.6635 | L15: 102.07162 | N15: 106.52062
A16: Visting friends at home | F16: 139.1461 | H16: 136.42082 | J16: 119.25933 | L16: 118.09662 | N16: 118.52942
A17: Visiting friends elsewhere | F17: 36.945509 | H17: 41.742234 | J17: 43.826389 | L17: 36.056444 | N17: 36.647205
A18: Sport / entertainment | F18: 60.702117 | H18: 78.106677 | J18: 71.775605 | L18: 73.718037 | N18: 65.489584
A19: Holiday / day trip | F19: 21.652168 | H19: 27.662436 | J19: 28.746605 | L19: 30.807524 | N19: 34.932815
A20: Other (including "just walk") | F20: 49.794627 | H20: 65.324332 | J20: 43.519565 | L20: 43.846155 | N20: 51.114179
A21: All purposes | F21: 1054.3969 | H21: 1101.5209 | J21: 1035.003 | L21: 1013.5217 | N21: 1014.4016
F22: =IF(ABS(F21-SUM(F9:F20))>comments!$A$1,'T12.4 - T12.6a'!F21-SUM(F9:F20)," ") | H22: =IF(ABS(H21-SUM(H9:H20))>comments!$A$1,'T12.4 - T12.6a'!H21-SUM(H9:H20)," ") | J22: =IF(ABS(J21-SUM(J9:J20))>comments!$A$1,'T12.4 - T12.6a'!J21-SUM(J9:J20)," ") | L22: =IF(ABS(L21-SUM(L9:L20))>comments!$A$1,'T12.4 - T12.6a'!L21-SUM(L9:L20)," ") | N22: =IF(ABS(N21-SUM(N9:N20))>comments!$A$1,'T12.4 - T12.6a'!N21-SUM(N9:N20)," ") | O22: =IF(ABS(O21-SUM(O9:O20))>comments!$A$1,'T12.4 - T12.6a'!O21-SUM(O9:O20)," ") | P22: =IF(ABS(P21-SUM(P9:P20))>comments!$A$1,'T12.4 - T12.6a'!P21-SUM(P9:P20)," ")
A24: Sample size (number of people) | F24: 2024 | H24: 1926 | J24: 3396 | L24: 3766 | N24: 3723
A26: * See footnotes for table 12.1
A28: Table 12.5 Average distance travelled per person per year by purpose
A30: Scottish residents: average per head of population *
F32: 1995 | H32: 1998 | J32: 2002 | L32: 2004 | N32: 2005 | P32: 2006
F33: / 1997 | H33: / 2000 | J33: / 2003 | L33: / 2005 | N33: / 2006 | P33: / 2007
N34: miles
A35: Commuting | F35: 1400.5298 | H35: 1469.5448 | J35: 1322.775 | L35: 1368.5121 | N35: 1305.9154
A36: Business | F36: 683.21327 | H36: 738.41193 | J36: 656.19628 | L36: 819.91174 | N36: 815.59541
A37: Education | F37: 177.69947 | H37: 230.33105 | J37: 208.31287 | L37: 219.26833 | N37: 223.29978
A38: Escort education | F38: 73.490255 | H38: 62.937518 | J38: 54.601684 | L38: 63.583257 | N38: 57.32216
A39: Shopping | F39: 978.49162 | H39: 1132.3436 | J39: 981.57785 | L39: 1011.1709 | N39: 1033.0671
A40: Other escort | F40: 504.93829 | H40: 471.80424 | J40: 516.18966 | L40: 587.37246 | N40: 555.57107
A41: Other personal business | F41: 472.0952 | H41: 598.18525 | J41: 501.20879 | L41: 506.28433 | N41: 537.06229
A42: Visting friends at home | F42: 1135.2696 | H42: 1039.0146 | J42: 1029.9342 | L42: 1139.8493 | N42: 1092.2214
A43: Visiting friends elsewhere | F43: 188.49183 | H43: 221.50091 | J43: 228.68535 | L43: 217.30071 | N43: 237.65143
A44: Sport / entertainment | F44: 428.61893 | H44: 624.09613 | J44: 515.88041 | L44: 496.15056 | N44: 446.55136
A45: Holiday / day trip | F45: 802.71004 | H45: 884.59075 | J45: 874.57813 | L45: 855.53234 | N45: 1023.2394
A46: Other (including "just walk") | F46: 50.836279 | H46: 76.97738 | J46: 42.864852 | L46: 47.372352 | N46: 48.427445
A47: All purposes | F47: 6896.3845 | H47: 7549.7383 | J47: 6932.8055 | L47: 7332.3082 | N47: 7375.9242
F48: =IF(ABS(F47-SUM(F35:F46))>comments!$A$1,'T12.4 - T12.6a'!F47-SUM(F35:F46)," ") | H48: =IF(ABS(H47-SUM(H35:H46))>comments!$A$1,'T12.4 - T12.6a'!H47-SUM(H35:H46)," ") | J48: =IF(ABS(J47-SUM(J35:J46))>comments!$A$1,'T12.4 - T12.6a'!J47-SUM(J35:J46)," ") | L48: =IF(ABS(L47-SUM(L35:L46))>comments!$A$1,'T12.4 - T12.6a'!L47-SUM(L35:L46)," ") | N48: =IF(ABS(N47-SUM(N35:N46))>comments!$A$1,'T12.4 - T12.6a'!N47-SUM(N35:N46)," ") | O48: =IF(ABS(O47-SUM(O35:O46))>comments!$A$1,'T12.4 - T12.6a'!O47-SUM(O35:O46)," ") | P48: =IF(ABS(P47-SUM(P35:P46))>comments!$A$1,'T12.4 - T12.6a'!P47-SUM(P35:P46)," ")
A49: * See footnotes for table 12.1
...

Sheet T12.7-T12.9a
A2: Table 12.7 Hours travelled per person per year by purpose
A4: Scottish residents: average per head of population *
E6: 1995 | G6: 1998 | I6: 2002 | K6: 2004 | M6: 2005 | O6: 2006
E7: / 1997 | G7: / 2000 | I7: / 2003 | K7: / 2005 | M7: / 2006 | O7: / 2007
A9: Commuting | E9: 68.296466 | G9: 71.154636 | I9: 64.699944 | K9: 64.643117 | M9: 65.521389
A10: Business | E10: 20.654876 | G10: 19.845108 | I10: 15.858137 | K10: 21.928857 | M10: 23.585537
A11: Education | E11: 21.077428 | G11: 22.420638 | I11: 23.413117 | K11: 19.054895 | M11: 20.058268
A12: Escort education | E12: 6.9327867 | G12: 4.9525059 | I12: 5.486801 | K12: 5.1192568 | M12: 5.2544084
A13: Shopping | E13: 68.030176 | G13: 69.473513 | I13: 57.452517 | K13: 55.959075 | M13: 63.314558
A14: Other escort | E14: 23.690713 | G14: 21.219685 | I14: 25.926467 | K14: 26.580001 | M14: 27.46403
A15: Other personal business | E15: 28.11601 | G15: 34.060748 | I15: 28.906548 | K15: 28.046878 | M15: 31.815167
A16: Visting friends at home | E16: 52.150528 | G16: 49.084784 | I16: 44.387223 | K16: 43.147218 | M16: 45.60764
A17: Visiting friends elsewhere | E17: 11.037129 | G17: 12.927571 | I17: 13.450651 | K17: 10.991992 | M17: 12.719276
A18: Sport / entertainment | E18: 21.559486 | G18: 28.295412 | I18: 24.06488 | K18: 23.398358 | M18: 22.127121
A19: Holiday / day trip | E19: 25.410234 | G19: 29.051699 | I19: 26.017724 | K19: 24.608352 | M19: 29.743865
A20: Other (including "just walk") | E20: 20.228169 | G20: 23.496248 | I20: 16.122545 | K20: 15.590822 | M20: 18.140937
... A23: Sample size (number of people) | E23: 2024 | G23: 1926 | I23: 3396 | K23: 3766 | M23: 3723
A25: * See footnotes for table 12.1
A27: Table 12.8 Average duration of travel per trip by purpose
A29: Scottish residents: average per head of population *
E31: 1995 | G31: 1998 | I31: 2002 | K31: 2004 | M31: 2005 | O31: 2006
E32: / 1997 | G32: / 2000 | I32: / 2003 | K32: / 2005 | M32: / 2006 | O32: / 2007
M33: minutes
A34: Commuting | E34: 23.123967 | G34: 24.044223 | I34: 22.323488 | K34: 22.853438 | M34: 24.761501
A35: Business | E35: 32.05485 | G35: 36.046402 | I35: 33.556785 | K35: 37.913989 | M35: 38.803221
A36: Education | E36: 17.542543 | G36: 19.008607 | I36: 17.154788 | K36: 17.774545 | M36: 19.623511
A37: Escort education | E37: 11.612717 | G37: 11.605088 | I37: 10.578175 | K37: 10.429009 | M37: 11.381635
A38: Shopping | E38: 17.610048 | G38: 16.706787 | I38: 16.614248 | K38: 16.255028 | M38: 17.552551
A39: Other escort | E39: 15.985015 | G39: 15.744555 | I39: 15.797904 | K39: 15.308367 | M39: 16.400553
A40: Other personal business | E40: 16.593637 | G40: 17.781909 | I40: 16.260416 | K40: 16.486588 | M40: 17.920569
A41: Visting friends at home | E41: 22.487383 | G41: 21.588252 | I41: 22.331447 | K41: 21.921314 | M41: 23.086744
A42: Visiting friends elsewhere | E42: 17.924444 | G42: 18.582001 | I42: 18.414455 | K42: 18.291307 | M42: 20.824414
A43: Sport / entertainment | E43: 21.310116 | G43: 21.735974 | I43: 20.116762 | K43: 19.044206 | M43: 20.272343
A44: Holiday / day trip | E44: 70.413921 | G44: 63.013319 | I44: 54.304272 | K44: 47.926639 | M44: 51.087548
A45: Other (including "just walk") | E45: 24.373918 | G45: 21.581161 | I45: 22.227995 | K45: 21.334809 | M45: 21.294604
A46: All purposes | E46: 20.894445 | G46: 21.024524 | I46: 20.045539 | K46: 20.072713 | M46: 21.609915
A48: * See footnotes for table 12.1
A50: Table 12.9 Trips per person per year by main mode and cars available to the household
A52: Scottish residents: 2007 (average per head of population *)
J54: Number of cars available to the household
...

Sheet Table 11.1-11.10
A1: Table 11.1 Trips per person per year by main mode
A3: Note: This table has been removed as data are no longer available for Scotland.
A5: Table 11.2 Average distance travelled per person per year by main mode
A7: Note: This table has been removed as data are no longer available for Scotland.
A9: Table 11.3 Average length of trip by main mode
A11: Note: This table has been removed as data are no longer available for Scotland.
A13: Table 11.4 Trips per person per year by purpose
A14: Note: This table has been removed as data are no longer available for Scotland.
A16: Table 11.5 Average distance travelled per person per year by purpose
A17: Note: This table has been removed as data are no longer available for Scotland.
A19: Table 11.6 Average length of trip by purpose
A20: Note: This table has been removed as data are no longer available for Scotland.
... A31: Table 11.10 Frequency of driving* for people aged 17+: 2013
C33: Per Week | E33: Per Month
H35: Holds | I35: Total | J35: Doesn't
B36: Every | C36: At least | D36: Once or | E36: At least | F36: At least | G36: Less | H36: full | I36: with | J36: have | K36: Sample
B37: day | C37: 3 times | D37: twice | E37: 2 or 3 | F37: once | G37: than | H37: licence, | I37: a full | J37: a full | K37: size
E38: times | G38: once | H38: never | I38: driving | J38: driving | K38: (=100%)
H39: drives | I39: licence | J39: licence
F41: row percentages
A42: All people aged 17+ in 2013: | B42: 42 | C42: 13 | D42: 6 | E42: 1 | F42: 0 | G42: 2 | H42: 4 | I42: 68 | J42: 32 | K42: 9838
A43: by gender:
A44: Male | B44: 49 | C44: 14 | D44: 6 | E44: 1 | F44: 0 | G44: 1 | H44: 4 | I44: 76 | J44: 24 | K44: 4405
A45: Female | B45: 36 | C45: 13 | D45: 5 | E45: 1 | F45: 1 | G45: 2 | H45: 5 | I45: 61 | J45: 39 | K45: 5433
A46: by age:
A47: 17-19 | B47: 17 | C47: 2 | D47: ** | E47: ** | F47: 0 | G47: 2 | H47: ** | I47: 26 | J47: 74 | K47: 211
A48: 20-29 | B48: 34 | C48: 8 | D48: 3 | E48: 1 | F48: 1 | G48: 2 | H48: 6 | I48: 56 | J48: 44 | K48: 1201
A49: 30-39 | B49: 51 | C49: 11 | D49: 6 | E49: 0 | F49: 0 | G49: 2 | H49: 4 | I49: 74 | J49: 26 | K49: 1337
A50: 40-49 | B50: 57 | C50: 13 | D50: 5 | E50: 1 | F50: 0 | G50: 1 | H50: 3 | I50: 80 | J50: 20 | K50: 1632
A51: 50-59 | B51: 52 | C51: 13 | D51: 7 | E51: 1 | F51: ** | G51: 1 | H51: 4 | I51: 80 | J51: 20 | K51: 1754
A52: 60-69 | B52: 39 | C52: 20 | D52: 7 | E52: 1 | F52: 1 | G52: 1 | H52: 5 | I52: 74 | J52: 26 | K52: 1703
A53: 70-79 | B53: 22 | C53: 21 | D53: 8 | E53: 1 | F53: 1 | G53: 3 | H53: 5 | I53: 60 | J53: 40 | K53: 1286
A54: 80+ | B54: 13 | C54: 12 | D54: 7 | E54: 1 | F54: ** | G54: 1 | H54: 7 | I54: 41 | J54: 59 | K54: 714
A55: by current situation:
A56: Self employed | B56: 67 | C56: 16 | D56: 7 | E56: 1 | F56: ** | G56: 1 | H56: 2 | I56: 93 | J56: 7 | K56: 602
A57: Employed full time | B57: 62 | C57: 11 | D57: 5 | E57: 1 | F57: 0 | G57: 1 | H57: 3 | I57: 84 | J57: 16 | K57: 3249
A58: Employed part time | B58: 45 | C58: 13 | D58: 3 | E58: 1 | F58: ** | G58: 1 | H58: 4 | I58: 67 | J58: 33 | K58: 993
A59: Looking after the home or family | B59: 32 | C59: 13 | D59: 4 | E59: 1 | F59: 0 | G59: 1 | H59: 3 | I59: 55 | J59: 45 | K59: 538
A60: Permanently retired from work | B60: 24 | C60: 20 | D60: 8 | E60: 1 | F60: 1 | G60: 2 | H60: 5 | I60: 62 | J60: 38 | K60: 3128
A61: Unemployed and seeking work | B61: 11 | C61: 6 | D61: 3 | E61: ** | F61: ** | G61: 2 | H61: 9 | I61: 32 | J61: 68 | K61: 475
...

Sheet T11.11
A1: Table 11.11 Frequency of Walking in the previous seven days 1 (people aged 16+): 2012 2
B2: As means of transport | G2: Sample | H2: Just for pleasure | M2: Sample
G3: size | H3: or to keep fit 2 | M3: size
G4: (=100%) | M4: (=100%)
B5: none | C5: 1-2 days | D5: 3-5 days | E5: 6-7 days | F5: 1 + | H5: none | I5: 1-2 days | J5: 3-5 days | K5: 6-7 days | L5: 1 +
F6: days | L6: days
L7: row percentages
A9: All people in 2012: | B9: 34 | C9: 20 | D9: 23 | E9: 23 | F9: 66 | G9: 9841 | H9: 45 | I9: 19 | J9: 17 | K9: 19 | L9: 55 | M9: 9805
A10: by gender:
A11: Male | B11: 34 | C11: 19 | D11: 23 | E11: 24 | F11: 66 | G11: 4383 | H11: 44 | I11: 20 | J11: 16 | K11: 20 | L11: 56 | M11: 4369
A12: Female | B12: 35 | C12: 20 | D12: 24 | E12: 21 | F12: 65 | G12: 5458 | H12: 46 | I12: 18 | J12: 17 | K12: 19 | L12: 54 | M12: 5436
A13: by age:
A14: 16-19 | B14: 18 | C14: 19 | D14: 34 | E14: 29 | F14: 82 | G14: 272 | H14: 39 | I14: 21 | J14: 22 | K14: 19 | L14: 61 | M14: 272
A15: 20-29 | B15: 22 | C15: 18 | D15: 28 | E15: 31 | F15: 78 | G15: 1148 | H15: 43 | I15: 21 | J15: 19 | K15: 18 | L15: 57 | M15: 1137
A16: 30-39 | B16: 29 | C16: 20 | D16: 24 | E16: 27 | F16: 71 | G16: 1458 | H16: 39 | I16: 22 | J16: 18 | K16: 21 | L16: 61 | M16: 1448
A17: 40-49 | B17: 35 | C17: 24 | D17: 21 | E17: 20 | F17: 65 | G17: 1617 | H17: 41 | I17: 21 | J17: 17 | K17: 21 | L17: 59 | M17: 1612
A18: 50-59 | B18: 36 | C18: 21 | D18: 23 | E18: 20 | F18: 64 | G18: 1629 | H18: 43 | I18: 19 | J18: 16 | K18: 22 | L18: 57 | M18: 1630
A19: 60-69 | B19: 39 | C19: 19 | D19: 21 | E19: 20 | F19: 61 | G19: 1745 | H19: 47 | I19: 16 | J19: 16 | K19: 20 | L19: 53 | M19: 1740
A20: 70-79 | B20: 46 | C20: 19 | D20: 19 | E20: 15 | F20: 54 | G20: 1257 | H20: 57 | I20: 15 | J20: 12 | K20: 16 | L20: 43 | M20: 1252
A21: 80+ | B21: 65 | C21: 11 | D21: 13 | E21: 12 | F21: 35 | G21: 715 | H21: 76 | I21: 9 | J21: 7 | K21: 8 | L21: 24 | M21: 714
A22: by current situation:
A23: Self employed | B23: 38 | C23: 19 | D23: 21 | E23: 22 | F23: 62 | G23: 579 | H23: 36 | I23: 23 | J23: 17 | K23: 24 | L23: 64 | M23: 579
A24: Employed full time | B24: 32 | C24: 23 | D24: 23 | E24: 22 | F24: 68 | G24: 3115 | H24: 41 | I24: 23 | J24: 18 | K24: 18 | L24: 59 | M24: 3099
A25: Employed part time | B25: 29 | C25: 20 | D25: 28 | E25: 23 | F25: 71 | G25: 1009 | H25: 40 | I25: 19 | J25: 19 | K25: 21 | L25: 60 | M25: 1007
A26: Looking after the home/family | B26: 20 | C26: 22 | D26: 24 | E26: 33 | F26: 80 | G26: 475 | H26: 35 | I26: 15 | J26: 18 | K26: 32 | L26: 65 | M26: 472
A27: Permanently retired from work | B27: 46 | C27: 18 | D27: 19 | E27: 17 | F27: 54 | G27: 3188 | H27: 56 | I27: 14 | J27: 13 | K27: 17 | L27: 44 | M27: 3179
A28: Unemployed/seeking work | B28: 23 | C28: 16 | D28: 28 | E28: 33 | F28: 77 | G28: 486 | H28: 38 | I28: 15 | J28: 22 | K28: 25 | L28: 62 | M28: 482
A29: In further/higher education | B29: 14 | C29: 11 | D29: 37 | E29: 38 | F29: 86 | G29: 312 | H29: 36 | I29: 22 | J29: 24 | K29: 18 | L29: 64 | M29: 312
A30: Permanently sick or disabled | B30: 62 | C30: 12 | D30: 15 | E30: 11 | F30: 38 | G30: 504 | H30: 71 | I30: 6 | J30: 10 | K30: 13 | L30: 29 | M30: 503
A31: by annual net household income:
A32: up to £10,000 p.a. | B32: 32 | C32: 15 | D32: 23 | E32: 30 | F32: 68 | G32: 1399 | H32: 49 | I32: 13 | J32: 14 | K32: 24 | L32: 51 | M32: 1391
A33: over £10,000 - £15,000 | B33: 35 | C33: 18 | D33: 22 | E33: 25 | F33: 65 | G33: 1863 | H33: 51 | I33: 15 | J33: 15 | K33: 19 | L33: 49 | M33: 1865
A34: over £15,000 - £20,000 | B34: 38 | C34: 18 | D34: 21 | E34: 23 | F34: 62 | G34: 1525 | H34: 49 | I34: 18 | J34: 15 | K34: 18 | L34: 51 | M34: 1522
A35: over £20,000 - £25,000 | B35: 36 | C35: 20 | D35: 22 | E35: 22 | F35: 64 | G35: 1260 | H35: 46 | I35: 18 | J35: 16 | K35: 20 | L35: 54 | M35: 1259
A36: over £25,000 - £30,000 | B36: 34 | C36: 20 | D36: 25 | E36: 21 | F36: 66 | G36: 901 | H36: 45 | I36: 20 | J36: 16 | K36: 19 | L36: 55 | M36: 891
A37: over £30,000 - £40,000 | B37: 34 | C37: 22 | D37: 24 | E37: 20 | F37: 66 | G37: 1181 | H37: 40 | I37: 23 | J37: 18 | K37: 19 | L37: 60 | M37: 1181
A38: over £40,000 p.a. | B38: 32 | C38: 25 | D38: 25 | E38: 19 | F38: 68 | G38: 1375 | H38: 37 | I38: 24 | J38: 20 | K38: 19 | L38: 63 | M38: 1368
A39: by Scottish Index of Multiple Deprivation:
A40: 1 (20 % most deprived) | B40: 32 | C40: 19 | D40: 24 | E40: 25 | F40: 68 | G40: 1869 | H40: 50 | I40: 17 | J40: 17 | K40: 17 | L40: 50 | M40: 1854 | P40: hjhjkk
A41: 2 | B41: 34 | C41: 19 | D41: 23 | E41: 23 | F41: 66 | G41: 2060 | H41: 48 | I41: 17 | J41: 15 | K41: 21 | L41: 52 | M41: 2056
...

Sheet T11.12-T11.13
A1: Table 11.12 Frequency of Driving1,2 for people aged 17+
C2: 1999 | D2: 2000 | E2: 2001 | F2: 2002 | G2: 2003 | H2: 2004 | I2: 2005 | J2: 2006 | K2: 2007 | L2: 2008 | M2: 2009 | N2: 2010 | O2: 2011 | P2: 2012 | Q2: 2013
Q3: column percentages
A4: Every Day | C4: 44.2 | D4: 44.7 | E4: 45.8 | F4: 45.5 | G4: 43.3 | H4: 41.4 | I4: 41.8 | J4: 40.9 | K4: 45.2 | L4: 44.9 | M4: 43.4 | N4: 41.4 | O4: 40.7 | P4: 42 | Q4: 41.9
A6: Per Week:
A7: At least 3 times | C7: 7.6 | D7: 7.9 | E7: 8 | F7: 8 | G7: 10.2 | H7: 11.2 | I7: 11.2 | J7: 11.6 | K7: 10 | L7: 10.4 | M7: 11.9 | N7: 12.8 | O7: 13.3 | P7: 13.1 | Q7: 13.3
A8: Once or twice | C8: 4.5 | D8: 4.2 | E8: 3.9 | F8: 4.2 | G8: 5.5 | H8: 5.7 | I8: 5.8 | J8: 6.7 | K8: 5.1 | L8: 5.6 | M8: 5.6 | N8: 6 | O8: 6.2 | P8: 6 | Q8: 5.6
A9: Per Month:
A10: At least 2 or 3 times | C10: 1 | D10: 0.9 | E10: 1 | F10: 0.9 | G10: 0.7 | H10: 0.8 | I10: 0.8 | J10: 1 | K10: 0.9 | L10: 1 | M10: 0.9 | N10: 0.9 | O10: 0.9 | P10: 0.8 | Q10: 1
A11: At least once | C11: 0.5 | D11: 0.5 | E11: 0.6 | F11: 0.4 | G11: 0.4 | H11: 0.6 | I11: 0.5 | J11: 0.5 | K11: 0.6 | L11: 0.4 | M11: 0.4 | N11: 0.4 | O11: 0.4 | P11: 0.3 | Q11: 0.5
A12: Less than once | C12: 1.7 | D12: 1.8 | E12: 1.9 | F12: 2.1 | G12: 1.7 | H12: 1.6 | I12: 1.4 | J12: 1.4 | K12: 1.7 | L12: 1.3 | M12: 1.6 | N12: 1.8 | O12: 1.7 | P12: 1.7 | Q12: 1.6
A14: Holds full driving licence, never drives | C14: 4 | D14: 4 | E14: 3.5 | F14: 3.5 | G14: 4.1 | H14: 4.5 | I14: 4.1 | J14: 4.4 | K14: 3.5 | L14: 4 | M14: 4.2 | N14: 4.3 | O14: 4.1 | P14: 4.5 | Q14: 4.5
A16: Total with a full driving licence | C16: =100-C18 -> 63.5 | D16: =100-D18 -> 64 | E16: =100-E18 -> 64.7 | F16: =100-F18 -> 64.6 | G16: =100-G18 -> 65.8 | H16: =100-H18 -> 65.8 | I16: =100-I18 -> 65.6 | J16: =100-J18 -> 66.4 | ... Q16: =100-Q18 -> 68.4
A18: Doesn't have a full driving licence | C18: 36.5 | D18: 36 | E18: 35.3 | F18: 35.4 | G18: 34.2 | H18: 34.2 | I18: 34.4 | J18: 33.6 | K18: 33 | L18: 32.4 | M18: 32 | N18: 32.4 | O18: 32.7 | P18: 31.7 | Q18: 31.6
A20: Sample size (=100%) | C20: 13660 | D20: 14440 | E20: 14527 | F20: 13936 | G20: 13850 | H20: 14660 | I20: 13968 | J20: 14075 | K20: 12152 | L20: 12263 | M20: 12447 | N20: 12361 | O20: 12801 | P20: 9828 | Q20: 9838
A22: Source: Scottish Household Survey
A23: 1 For holders of full licences.
A24: 2 From April 2003, the questionnaire changed such that information on possession of driving licences and frequency of driving was no longer collected from
A25: the head of the household, or his / her spouse/partner, about all adults in the household, but instead from one randomly chosen adult member of the
A26: household about him or herself.
A28: Table 11.13 Frequency of Walking in the previous seven days1 2 (people aged 16+)
C29: 1999 | D29: 2000 | E29: 2001 | G29: 2002 | H29: 2003 | I29: 2004 | J29: 2005 | K29: 2006 | L29: 2007 | M29: 2008 | N29: 2009 | O29: 2010 | P29: 2011 | Q29: 2012
Q30: column percentages
A31: As means of transport
A32: None | C32: 47.6 | D32: 46.4 | E32: 44.9 | G32: 45.1 | H32: 45.6 | I32: 45.8 | J32: 46 | K32: 46 | L32: 48 | M32: 47.5 | N32: 41 | O32: 38 | P32: 36.9 | Q32: 34
A33: 1-2 days | C33: 18.7 | D33: 18.3 | E33: 19.1 | G33: 18.3 | H33: 17.5 | I33: 16.8 | J33: 15.3 | K33: 15.8 | L33: 17.9 | M33: 17.2 | N33: 17.5 | O33: 18.9 | P33: 19.1 | Q33: 20
A34: 3-5 days | C34: 18.2 | D34: 20.5 | E34: 21.6 | G34: 22.1 | H34: 21.9 | I34: 21.3 | J34: 22 | K34: 21.3 | L34: 19.8 | M34: 21.7 | N34: 22.4 | O34: 24.3 | P34: 24.4 | Q34: 23
A35: 6-7 days | C35: 15.4 | D35: 14.7 | E35: 14.5 | G35: 14.6 | H35: 15 | I35: 16 | J35: 16.7 | K35: 17 | L35: 14.3 | M35: 13.6 | N35: 19.1 | O35: 18.8 | P35: 19.6 | Q35: 23
A36: 1+ days | C36: =100-C32 -> 52.4 | D36: =100-D32 -> 53.6 | E36: =100-E32 -> 55.1 | G36: =100-G32 -> 54.9 | H36: =100-H32 -> 54.4 | I36: =100-I32 -> 54.2 | J36: =100-J32 -> 54 | K36: =100-K32 -> 54 | L36: =100-L32 -> 52 | M36: =100-M32 -> 52.5 | N36: =100-N32 -> 59 | ... Q36: =100-Q32 -> 66
A37: Sample size (=100%) | G37: 13984 | H37: 13927 | I37: 14715 | J37: 6992 | K37: 7111 | L37: 6116 | M37: 6197 | N37: 6137 | O37: 6178 | P37: 6381 | Q37: 9841
A39: Just for pleasure or to keep fit 2
A40: None | C40: 60.3 | D40: 58.6 | E40: 57.1 | G40: 59.3 | H40: 56.1 | I40: 56.1 | J40: 53.9 | K40: 53.3 | L40: 53.1 | M40: 54.9 | N40: 51.6 | O40: 48.7 | P40: 46 | Q40: 45
A41: 1-2 days | C41: 15.9 | D41: 16.9 | E41: 18.2 | G41: 18 | H41: 17.8 | I41: 16.4 | J41: 16.9 | K41: 16.5 | L41: 17.6 | M41: 18.4 | N41: 19.1 | O41: 17.7 | P41: 18.9 | Q41: 19
A42: 3-5 days | C42: 10.5 | D42: 11.7 | E42: 12.1 | G42: 10.7 | H42: 12.4 | I42: 13.3 | J42: 14.2 | K42: 13.7 | L42: 13.7 | M42: 13 | N42: 13.1 | O42: 16.5 | P42: 16.7 | Q42: 17
A43: 6-7 days | C43: 13.2 | D43: 12.8 | E43: 12.6 | G43: 12.1 | H43: 13.7 | I43: 14.2 | J43: 15.1 | K43: 16.4 | L43: 15.5 | M43: 13.7 | N43: 16.1 | O43: 17.2 | P43: 18.5 | Q43: 19
A44: 1+ days | C44: =100-C40 -> 39.7 | D44: =100-D40 -> 41.4 | E44: =100-E40 -> 42.9 | G44: =100-G40 -> 40.7 | H44: =100-H40 -> 43.9 | I44: =100-I40 -> 43.9 | J44: =100-J40 -> 46.1 | K44: =100-K40 -> 46.7 | L44: =100-L40 -> 46.9 | M44: =100-M40 -> 45.1 | N44: =100-N40 -> 48.4 | ... Q44: =100-Q40 -> 55
A46: Sample size (=100%) | C46: 13757 | D46: 14516 | E46: 14643 | G46: 14041 | H46: 13925 | I46: 14713 | J46: 6993 | K46: 7111 | L46: 6121 | M46: 6209 | N46: 6119 | O46: 6136 | P46: 6372 | Q46: 9805
A48: Source: Scottish Household Survey
A49: 1. The number of days in the previous seven days on which the person made a trip of more than a quarter of a mile by foot for the specified purpose.
A50: 2. Question now asked in survey every other year. 2012 is the most recent data available.
...

Sheet T11.14-T11.17
A1: Table 11.14 Usual means of travel to usual place of work (in Autumn)
C2: 2000 | D2: 2001 | E2: 2002 | F2: 2003 | G2: 2004 | H2: 2005 | I2: 2006 | J2: 2007 | K2: 2008 | L2: 2009 | M2: 2010 | N2: 2011 | O2: 2012 | P2: 2013
P3: percentage
A4: Car,van,minibus,works van | C4: 67.2 | D4: 69 | E4: 69.6 | F4: 70.013997 | G4: 69 | H4: 67.802761 | I4: 69 | J4: 69 | K4: 68.8 | L4: 69.5 | M4: 71.2 | N4: 68 | O4: 68 | P4: 68
A5: Bicycle | C5: 1.8 | D5: 2 | E5: 1.71 | F5: 1.391109 | G5: 1 | H5: 1.8727915 | I5: 1 | J5: 1.8163701 | K5: 1.9 | L5: 1.5 | M5: 1.6 | N5: 2 | O5: 2 | P5: 2
A6: Bus,coach.private bus | C6: 12.6 | D6: 12 | E6: 11.35 | F6: 11.477822 | G6: 12 | H6: 11.986742 | I6: 12 | J6: 11.519449 | K6: 12.6 | L6: 10.7 | M6: 10.2 | N6: 12 | O6: 11 | P6: 11
A7: Rail (inc Underground) | C7: 3.6 | D7: 4 | E7: 3.34 | F7: 3.5422079 | G7: 3 | H7: 3.7772539 | I7: 5 | J7: 4.1090769 | K7: 3.5 | L7: 3.6 | M7: 3.8 | N7: 4 | O7: 4 | P7: 5
A8: Walk | C8: 13.4 | D8: 12 | E8: 12.51 | F8: 12.058832 | G8: 12 | H8: 12.654096 | I8: 12 | J8: 11.050838 | K8: 11.1 | L8: 12.114203 | M8: 11.5 | N8: 12 | O8: 12 | P8: 13
A9: Other (inc taxi) | C9: 1.4 | D9: 2 | E9: 1.49 | F9: 1.5160325 | G9: 3 | H9: 1.9063553 | I9: 1 | J9: 1.6183218 | K9: 2.1 | L9: 2.6 | M9: 1.7 | N9: 2 | O9: 2 | P9: 2
A10: All | C10: 100 | D10: 100 | E10: 100 | F10: 100 | G10: 100 | H10: 100 | I10: 100 | J10: 100 | K10: 100 | L10: 100 | M10: 100 | N10: 100 | O10: 100 | P10: 100
A11: Source: Transport Statistics Great Britain
A13: Table 11.15(a) Usual time taken to travel to usual place of work (in Autumn)
C14: 1996 | D14: 1997 | F14: 1998 | G14: 1999 | H14: 2000 | I14: 2001 | J14: 2002 | K14: 2003 | L14: 2004 | M14: 2005
M15: minutes
A16: Car,van,minibus,works van | C16: 21.885618 | D16: 22.023187 | F16: 21.811141 | G16: 22.22 | H16: 22.78 | I16: 20 | J16: 23 | K16: 20.009707 | L16: 22 | M16: 21
A17: Bicycle | C17: 14.220463 | D17: 14.227601 | F17: 14.947838 | G17: 15.33 | H17: 17.82 | I17: 15 | J17: 14 | K17: 16.135704 | L17: 15 | M17: 16
A18: Bus,coach.private bus | C18: 30.909023 | D18: 33.003612 | F18: 31.823399 | G18: 31.53 | H18: 32.09 | I18: 33 | J18: 34 | K18: 32.738495 | L18: 32 | M18: 32
A19: Rail (inc Underground) | C19: 57.64136 | D19: 41.771988 | F19: 55.077975 | G19: 53.292577 | H19: 51.98 | I19: 47 | J19: 46 | K19: 47.906168 | L19: 46 | M19: 49
A20: Walk | C20: 10.599927 | D20: 12.047324 | F20: 12.375157 | G20: 11.69 | H20: 11.98 | I20: 11 | J20: 12 | K20: 11.702521 | L20: 12 | M20: 13
A21: Other (inc taxi) | C21: 33.961582 | D21: 32.987736 | F21: 44.920248 | G21: 33.267132 | H21: 46.6 | I21: 42 | J21: 46 | K21: 24.55 | L21: 36 | M21: 40
A22: All | C22: 22.240523 | D22: 22.659841 | F22: 22.862528 | G22: 23.07 | H22: 23.83 | I22: 22 | J22: 24 | K22: 21.473591 | L22: 23 | M22: 22
A24: Note: This table is no longer being updated. Henceforth, information about average times taken to travel to work will be given in Table 11.15 (b),
A25: which is on the basis that is used to produce such figures for DfT's "Regional Transport Statistics".
A27: Table 11.15(b) Usual time taken to travel to usual place of work (in Autumn) 1,2
B28: 2000 | D28: 2001 | E28: 2002 | F28: 2003 | G28: 2004 | H28: 2005 | I28: 2006 | J28: 2007 | K28: 2008 | L28: 2009 1 | M28: 2010 1 | N28: 2011 1 | O28: 2012 1 | P28: 2013 1
P29: minutes
A30: Car | B30: .. | D30: .. | E30: 23 | F30: 23 | G30: 24 | H30: 23 | I30: 23 | J30: 23.977322 | K30: 24.341143 | L30: 24.104782 | M30: 24.688766 | N30: 23 | O30: 24 | P30: 25
A31: Motorcycle | B31: .. | D31: .. | E31: * | F31: 17 | G31: 16 | H31: 19 | I31: * | J31: 23.626276 | K31: * | L31: 18.98669 | M31: * | N31: * | O31: * | P31: *
A32: Bicycle | B32: .. | D32: .. | E32: 14 | F32: 16 | G32: 15 | H32: 17 | I32: 21 | J32: 18.634174 | K32: 17.828401 | L32: 15.363224 | M32: 19.70647 | N32: 20 | O32: 18 | P32: 22
A33: Bus/coach | B33: .. | D33: .. | E33: 34 | F33: 33 | G33: 33 | H33: 33 | I33: 35 | J33: 32.746595 | K33: 36.138308 | L33: 34.798889 | M33: 36.371534 | N33: 35 | O33: 39 | P33: 37
A34: Rail | B34: .. | D34: .. | E34: 46 | F34: 50 | G34: 52 | H34: 49 | I34: 50 | J34: 48.855581 | K34: 56.918911 | L34: 52.664806 | M34: 52.807462 | N34: 51 | O34: 59 | P34: 56
A35: Walk | B35: .. | D35: .. | E35: 12 | F35: 12 | G35: 13 | H35: 13 | I35: 13 | J35: 12.393947 | K35: 12.329584 | L35: 13.665875 | M35: 13.507867 | N35: 13 | O35: 15 | P35: 14
A36: Other | B36: .. | D36: .. | E36: 53 | F36: 39 | G36: 62 | H36: 61 | I36: 70.125607 | J36: 64.297866 | K36: 75.278838 | L36: 95 | M36: 73 | N36: 47 3 | O36: 89 | P36: 77
A37: All | B37: .. | D37: .. | E37: 24 | F37: 24 | G37: 25 | H37: 24 | I37: 24.836265 | J37: 25.154771 | K37: 26.187521 | L37: 25.61485 | M37: 26.171684 | N37: 25 | O37: 26 | P37: 27
A38: Source: Transport Statistics Great Britain
A39: * Sample size for this cell is too small for reliable estimates.
A40: Source: Oct-Dec, Office for National Statistics (ONS) Labour Force Survey.
A41: Notes: Some of the figures shown in table 11.15 (b) differ slightly from those in 11.15 (a) due to differing methodology used to extract.
A42: Results are weighted using population estimates to ensure they are representative of the population at large.
A43: 1. Data are for males and females in employment aged 16-99.
...

Sheet Figs11.3-11.4
A2: Figure 11.3: Travel to work a) 2003 and b) 2013
U4: 2003 | V4: 2013
T5: Driver | U5: 59.8 | V5: 60.6
T6: Passenger | U6: 8.7 | V6: 5.6
T7: Bus | U7: 11.6 | V7: 11.3
T8: Walking | U8: 12.6 | V8: 12.9
T9: Rail, including underground | U9: 2.9 | V9: 4
T10: Other | U10: 2.6 | V10: 3.1
T11: Bicycle | U11: 1.8 | V11: 2.5
A38: Figure 11.4: Driver experience of congestion and bus passenger experience of delays 2003-2013
A84: Note: The Scottish Household Survey Travel Diary asks car drivers whether their journey was delayed by congestion.
A85: Those making bus journeys are asked whether their journey was delayed and there is a separate question asking the reason.
A86: The data on reason for delay is included in the SHS Travel Diary publication.

Sheet T11.18
A1: Table 11.18 Employed1 adults (16+) not working from home - usual method of travel to work: 2013
K3: Sample
B4: Walking | D4: Car or van | F4: Bicycle | G4: Bus | H4: Rail 2 | I4: Other 3 | K4: size
C5: Driver | D5: Pass. | E5: All | K5: (=100%)
I6: row percentages
A8: All people aged 16+ in 2013: | B8: 12.9 | C8: 60.6 | D8: 5.6 | E8: 66.2 | F8: 2.5 | G8: 11.3 | H8: 4 | I8: 3.1 | K8: 4157
A9: By gender:
A10: Male | B10: 9.9 | C10: 64.3 | D10: 3.8 | E10: 68.1 | F10: 3.4 | G10: 9 | H10: 4.6 | I10: 5 | K10: 1974
A11: Female | B11: 15.9 | C11: 56.8 | D11: 7.4 | E11: 64.2 | F11: 1.6 | G11: 13.6 | H11: 3.4 | I11: 1.3 | K11: 2183
A12: by age:
A13: 16 - 20 | B13: 19.2 | C13: 35.7 | D13: 22.1 | E13: 57.8 | F13: ** | G13: 16.7 | H13: ** | I13: ** | K13: 146
A14: 20 - 29 | B14: 16.8 | C14: 53.1 | D14: 5.8 | E14: 58.9 | F14: 1.7 | G14: 15.5 | H14: 5 | I14: 2.2 | K14: 612
A15: 30 - 39 | B15: 11.7 | C15: 60.9 | D15: 3.8 | E15: 64.7 | F15: 3.5 | G15: 11.8 | H15: 5 | I15: 3.3 | K15: 923
A16: 40 - 49 | B16: 11.7 | C16: 66.9 | D16: 3.7 | E16: 70.6 | F16: 3 | G16: 8 | H16: 3.1 | I16: 3.7 | K16: 1056
A17: 50 - 59 | B17: 11.3 | C17: 64.4 | D17: 4.3 | E17: 68.7 | F17: 2.7 | G17: 10.1 | H17: 3.6 | I17: 3.7 | K17: 1038
A18: 60 and over | B18: 11.7 | C18: 62.4 | D18: 8.2 | E18: 70.6 | F18: ** | G18: 11.3 | H18: 2.8 | I18: 3.4 | K18: 382
A19: by current situation:
A20: Self employed | B20: 10.6 | C20: 62.3 | D20: 6.4 | E20: 68.7 | F20: 4.1 | G20: 5.2 | H20: 5 | I20: 6.3 | K20: 206
A21: Employed full time | B21: 10.6 | C21: 64.1 | D21: 5.5 | E21: 69.6 | F21: 2.6 | G21: 9.9 | H21: 4 | I21: 3.4 | K21: 3038
A22: Employed part time | B22: 21.7 | C22: 47.6 | D22: 5.5 | E22: 53.1 | F22: 2 | G22: 17.6 | H22: 3.8 | I22: 1.7 | K22: 913
A23: by annual net household income:
A24: up to £10,000 p.a. | B24: 29 | C24: 37.5 | D24: 7.9 | E24: 45.4 | F24: ** | G24: 19 | H24: 3.3 | I24: ** | K24: 134
A25: over £10,000 - £15,000 | B25: 21.2 | C25: 42 | D25: 7.9 | E25: 49.9 | F25: 3.3 | G25: 21 | H25: 2 | I25: 2.6 | K25: 445
A26: over £15,000 - £20,000 | B26: 21.6 | C26: 48.8 | D26: 6.7 | E26: 55.5 | F26: 1.4 | G26: 15.5 | H26: 4 | I26: 2 | K26: 509
A27: over £20,000 - £25,000 | B27: 17 | C27: 53.4 | D27: 9.3 | E27: 62.7 | F27: 3.1 | G27: 12.8 | H27: 2.6 | I27: 1.8 | K27: 539
A28: over £25,000 - £30,000 | B28: 12.6 | C28: 58.8 | D28: 7 | E28: 65.8 | F28: 1.9 | G28: 13.8 | H28: 3.1 | I28: 2.7 | K28: 528
A29: over £30,000 - £40,000 | B29: 10.5 | C29: 66.6 | D29: 5 | E29: 71.6 | F29: 2.2 | G29: 9.8 | H29: 3.4 | I29: 2.3 | K29: 836
A30: over £40,000 p.a. | B30: 7 | C30: 70.1 | D30: 2.9 | E30: 73 | F30: 3 | G30: 6.3 | H30: 5.9 | I30: 4.8 | K30: 1149
A31: by Scottish Index of Multiple Deprivation:
A32: 1 (20 % most deprived) | B32: 18.3 | C32: 46.5 | D32: 8.3 | E32: 54.8 | F32: 1.3 | G32: 18.8 | H32: 3.8 | I32: 3 | K32: 644
A33: 2 | B33: 13.3 | C33: 57.8 | D33: 6.6 | E33: 64.4 | F33: 2.1 | G33: 15.1 | H33: 2.8 | I33: 2.2 | K33: 826
A34: 3 | B34: 12.9 | C34: 61.7 | D34: 6.4 | E34: 68.1 | F34: 1.9 | G34: 9.2 | H34: 2.7 | I34: 5.1 | K34: 944
A35: 4 | B35: 10 | C35: 67.8 | D35: 4.7 | E35: 72.5 | F35: 2.4 | G35: 7.8 | H35: 4.6 | I35: 2.7 | K35: 960
A36: 5 (20% least deprived) | B36: 11.3 | C36: 65.4 | D36: 2.6 | E36: 68 | F36: 4.5 | G36: 7.7 | H36: 6 | I36: 2.5 | K36: 783
A37: by urban/rural classification:
A38: Large urban areas | B38: 15.3 | C38: 51.2 | D38: 5.7 | E38: 56.9 | F38: 3.4 | G38: 16.6 | H38: 5.2 | I38: 2.6 | K38: 1387
A39: Other urban | B39: 11.8 | C39: 63.3 | D39: 4.8 | E39: 68.1 | F39: 1.5 | G39: 10.8 | H39: 4.2 | I39: 3.6 | K39: 1257
A40: Small accessible towns | B40: 10.2 | C40: 67.3 | D40: 6.5 | E40: 73.8 | F40: 3.3 | G40: 7.9 | H40: 3.1 | I40: 1.7 | K40: 374
A41: Small remote towns | B41: 29.2 | C41: 55.9 | D41: 4.6 | E41: 60.5 | F41: 2.6 | G41: 2.4 | H41: ** | I41: 4.5 | K41: 287
A42: Accessible rural | B42: 4.9 | C42: 73.9 | D42: 7.4 | E42: 81.3 | F42: 2.1 | G42: 4.5 | H42: 3 | I42: 4.1 | K42: 425
...

Sheet T11.19-T11.20
A1: Table 11.19 Usual main method of travel to school1: 2013
J2: Sample
B3: Walking | C3: Car or | D3: Bicycle | F3: Bus | H3: Rail3 | I3: Other4 | J3: size
C4: Van | E4: School2 | F4: Service | G4: All | J4: (=100%)
H5: row percentages
A7: All children in full-time education, 2007 | B7: 51.7 | C7: 24.4 | D7: 1.2 | E7: 14.5 | F7: 5.4 | G7: =E7+F7 -> 19.9 | H7: 0.6 | I7: 2.2 | J7: 1975
A8: By gender:
A9: Male | B9: 51.6 | C9: 24.3 | D9: 1.9 | E9: 14.2 | F9: 5.6 | G9: =E9+F9 -> 19.8 | H9: 0.3 | I9: 2.2 | J9: 1072
A10: Female | B10: 51.8 | C10: 24.4 | D10: ** | E10: 15 | F10: 5.1 | G10: =E10+F10 -> 20.1 | H10: 1 | I10: 2.2 | J10: 903
A11: by age:
A12: age 4-5 | B12: 51.9 | C12: 35.6 | D12: ** | E12: 8.2 | F12: ** | G12: 8 | H12: 0 | I12: ** | J12: 172
A13: age 6-7 | B13: 60.7 | C13: 28.5 | D13: ** | E13: 7.2 | F13: 1.9 | G13: =E13+F13 -> 9.1 | H13: 0 | I13: 1.4 | J13: 345
A14: age 8-9 | B14: 59.7 | C14: 28.3 | D14: 2.3 | E14: 5.1 | F14: 1.9 | G14: =E14+F14 -> 7 | H14: 0 | I14: 2.6 | J14: 324
A15: age 10-11 | B15: 54.7 | C15: 29 | D15: 2.4 | E15: 8.7 | F15: 2.5 | G15: =E15+F15 -> 11.2 | H15: 0 | I15: 2.7 | J15: 292
A16: All 4-11 | B16: 57.6 | C16: 29.5 | D16: 1.5 | E16: 7.2 | F16: 1.8 | G16: =E16+F16 -> 9 | H16: 0 | I16: 2.4 | J16: 1133
A17: age 12-13 | B17: 46 | C17: 18.3 | D17: ** | E17: 25.4 | F17: 8 | G17: =E17+F17 -> 33.4 | H17: ** | I17: ** | J17: 286
A18: age 14-15 | B18: 39.9 | C18: 16.7 | D18: ** | E18: 27 | F18: 11.4 | G18: =E18+F18 -> 38.4 | H18: 1.8 | I18: 2.9 | J18: 344
A19: age 16-18 | B19: 47.2 | C19: 18.4 | D19: ** | E19: 17.2 | F19: 11.2 | G19: =E19+F19 -> 28.4 | H19: ** | I19: ** | J19: 212
A20: All 12 - 18 | B20: 43.9 | C20: 17.7 | D20: 0.8 | E20: 24.2 | F20: 10.1 | G20: =E20+F20 -> 34.3 | H20: 1.5 | I20: 1.9 | J20: 842
A21: by annual net household income:
A22: up to £15,000 p.a. | B22: 60.9 | C22: 11.4 | D22: ** | E22: 13.4 | F22: 11 | G22: =E22+F22 -> 24.4 | H22: ** | I22: 1.9 | J22: 222
A23: over £15,000 - £20,000 | B23: 62.6 | C23: 16.4 | D23: ** | E23: 9.8 | F23: 6.1 | G23: =E23+F23 -> 15.9 | H23: ** | I23: 2.7 | J23: 292
A24: over £20,000 - £25,000 | B24: 51 | C24: 24.5 | D24: 2.2 | E24: 14.3 | F24: 6.4 | G24: =E24+F24 -> 20.7 | H24: ** | I24: ** | J24: 252
A25: over £25,000 - £30,000 | B25: 53.8 | C25: 23.9 | D25: ** | E25: 12.9 | F25: 4.5 | G25: =E25+F25 -> 17.4 | H25: 0 | I25: 4.1 | J25: 242
A26: over £30,000 - £40,000 | B26: 48.1 | C26: 25.1 | D26: 1.7 | E26: 18.9 | F26: 4.5 | G26: =E26+F26 -> 23.4 | H26: ** | I26: ** | J26: 358
A27: over £40,000 p.a. | B27: 44.6 | C27: 32.5 | D27: 1.3 | E27: 15.4 | F27: 3.5 | G27: =E27+F27 -> 18.9 | H27: ** | I27: 2.2 | J27: 596
A28: by Scottish Index of Multiple Deprivation:
A29: 1 (20 % most deprived) | B29: 60.8 | C29: 13.5 | D29: ** | E29: 10.6 | F29: 9.9 | G29: =E29+F29 -> 20.5 | H29: ** | I29: 2.9 | J29: 406
A30: 2 | B30: 58 | C30: 21 | D30: 1 | E30: 11.6 | F30: 6.5 | G30: =E30+F30 -> 18.1 | H30: ** | I30: ** | J30: 334
A31: 3 | B31: 47.7 | C31: 26 | D31: ** | E31: 18.4 | F31: 4.5 | G31: =E31+F31 -> 22.9 | H31: ** | I31: 2.7 | J31: 427
A32: 4 | B32: 40.2 | C32: 31 | D32: 1.9 | E32: 21 | F32: 2.6 | G32: =E32+F32 -> 23.6 | H32: ** | I32: 2.6 | J32: 428
A33: 5 (20% least deprived) | B33: 52.6 | C33: 30.2 | D33: 1.9 | E33: 10.4 | F33: 3.5 | G33: =E33+F33 -> 13.9 | H33: ** | I33: ** | J33: 380
A34: by urban/rural classification:
A35: Large urban areas | B35: 54.7 | C35: 26.1 | D35: 1.2 | E35: 5.8 | F35: 8.2 | G35: =E35+F35 -> 14 | H35: 1.1 | I35: 2.8 | J35: 608
A36: Other urban | B36: 59.2 | C36: 22.3 | D36: 0.8 | E36: 12.2 | F36: 4.1 | G36: =E36+F36 -> 16.3 | H36: ** | I36: 1 | J36: 664
A37: Small accessible towns and small remote towns | B37: 63.3 | C37: 16.6 | D37: ** | E37: 15.2 | F37: 3.2 | G37: =E37+F37 -> 18.4 | H37: ** | I37: ** | J37: 270
A38: Accessible rural | B38: 24.6 | C38: 32.1 | D38: 1.4 | E38: 32.6 | F38: 3.6 | G38: =E38+F38 -> 36.2 | H38: ** | I38: 5.1 | J38: 229
A39: Remote rural | B39: 30.5 | C39: 24.4 | D39: 3.7 | E39: 35 | F39: 4.4 | G39: =E39+F39 -> 39.4 | H39: 0 | I39: 1.9 | J39: 204
A40: by number of cars:
A41: None | B41: 73.6 | C41: 1.4 | D41: ** | E41: 9.2 | F41: 9.7 | G41: =E41+F41 -> 18.9 | H41: ** | I41: 3.5 | J41: 349
...

Sheet T11.21-T11.23a
A1: Table 11.21 Employed 1 adults (16+) - place of work
C2: 1999 | D2: 2000 | E2: 2001 | F2: 2002 | G2: 2003 | H2: 2004 | I2: 2005 | J2: 2006 | K2: 2007 | L2: 2008 | M2: 2009 | N2: 2010 | O2: 2011 | P2: 2012 | Q2: 2013
Q3: column percentages
A4: Works from home | C4: 7.3 | D4: 7.9 | E4: 8.7 | F4: 9.3 | G4: 9.1 | H4: 9 | I4: 11.1 | J4: 10.7 | K4: 11.2 | L4: 10 | M4: 11.4 | N4: 10.1 | O4: 10.6 | P4: 13.2 | Q4: 13.3
A6: Does not work from home | C6: 92.7 | D6: 92.1 | E6: 91.3 | F6: 90.7 | G6: 90.9 | H6: 91 | I6: 88.9 | J6: 89.3 | K6: 88.8 | L6: 90 | M6: 88.6 | N6: 89.9 | O6: 89.4 | P6: 86.8 | Q6: 86.7
A8: All employed adults | C8: 100 | D8: 100 | E8: 100 | F8: 100 | G8: 100 | H8: 100 | I8: 100 | J8: 100 | K8: 100 | L8: 100 | M8: 100 | N8: 100 | O8: 100 | P8: 100 | Q8: 100
A10: Sample size (100%) | C10: 6534 | D10: 6818 | E10: 6922 | F10: 6597 | G10: 6681 | H10: 7058 | I10: 6841 | J10: 6845 | K10: 5888 | L10: 6092 | M10: 6103 | N10: 5862 | O10: 6189 | P10: 4734 | Q10: 4848
A12: Source: Scottish Household Survey
A13: 1. Those whose current situation was described as self-employed, employed full-time or employed part-time.
A15: Table 11.22 Employed 1 adults (16+) not working from home - usual method of travel to work
C16: 1999 | D16: 2000 | E16: 2001 | F16: 2002 | G16: 2003 | H16: 2004 | I16: 2005 | J16: 2006 | K16: 2007 | L16: 2008 | M16: 2009 | N16: 2010 | O16: 2011 | P16: 2012 | Q16: 2013
Q17: column percentages
A18: Walking | C18: 13.674 | D18: 13.658 | E18: 13.103 | F18: 13.15 | G18: 12.646 | H18: 12.651 | I18: 12.735 | J18: 13.83 | K18: 11.857 | L18: 12.504 | M18: 12.322 | N18: 13.4 | O18: 12.907 | P18: 13.603 | Q18: 12.9
A20: Car or van
A21: Driver | C21: 54.598 | D21: 56.519 | E21: 57.93 | F21: 56.622 | G21: 59.819 | H21: 58.894 | I21: 59.844 | J21: 59.783 | K21: 61.324 | L21: 59.891 | M21: 60.655 | N21: 61 | O21: 59.096 | P21: 61.362 | Q21: 60.6
A22: Passenger | C22: 11.819 | D22: 10.498 | E22: 10.445 | F22: 11.029 | G22: 8.686 | H22: 8.076 | I22: 7.538 | J22: 7.011 | K22: 6.651 | L22: 6.142 | M22: 6.385 | N22: 6.3 | O22: 7.505 | P22: 5.981 | Q22: 5.6
A23: All | C23: 66.4 | D23: 67 | E23: 68.4 | F23: 67.7 | G23: 68.5 | H23: 67 | I23: 67.4 | J23: 66.8 | K23: 68 | L23: 66 | M23: 67 | N23: 67.3 | O23: 66.601 | P23: 67.343 | Q23: 66.2
A25: Bicycle | C25: 1.737 | D25: 1.718 | E25: 1.716 | F25: 1.567 | G25: 1.775 | H25: 1.866 | I25: 1.648 | J25: 2.031 | K25: 1.658 | L25: 2.332 | M25: 2.383 | N25: 2.3 | O25: 1.953 | P25: 2.043 | Q25: 2.5
A27: Bus | C27: 12.1 | D27: 12.486 | E27: 12.153 | F27: 12.233 | G27: 11.597 | H27: 12.675 | I27: 12.101 | J27: 11.762 | K27: 12.666 | L27: 12.138 | M27: 12.129 | N27: 10.8 | O27: 11.979 | P27: 10.08 | Q27: 11.3
A29: Rail 2 | C29: 3.041 | D29: 2.293 | E29: 2.265 | F29: 3.064 | G29: 2.881 | H29: 3.521 | I29: 3.869 | J29: 3.576 | K29: 3.52 | L29: 4.265 | M29: 3.875 | N29: 3.6 | O29: 3.949 | P29: 4.348 | Q29: 4
A31: Other 3 | C31: 3.03 | D31: 2.828 | E31: 2.389 | F31: 2.336 | G31: 2.596 | H31: 2.317 | I31: 2.267 | J31: 2.005 | K31: 2.324 | L31: 2.729 | M31: 2.252 | N31: 2.7 | O31: 2.61 | P31: 2.583 | Q31: 3.1
A33: Sample size (100%) | C33: 6020 | D33: 6253 | E33: 6276 | F33: 5973 | G33: 6033 | H33: 6359 | I33: 6044 | J33: 6068 | K33: 5176 | L33: 5437 | M33: 5371 | N33: 5221 | O33: 5508 | P33: 4103 | Q33: 4157
A35: Source: Scottish Household Survey
A36: 1. The main method of transport is recorded if the journey involves more than one method.
A37: 2. Including the Glasgow Underground.
A38: 3. e.g. motorcycle, lorry, taxi, ferry, etc.
A40: Table 11.23 Usual main method of travel to school 1
C41: 1999 | D41: 2000 | E41: 2001 | F41: 2002 | G41: 2003 | H41: 2004 | I41: 2005 | J41: 2006 | K41: 2007 | L41: 2008 | M41: 2009 | N41: 2010 | O41: 2011 | P41: 2012 | Q41: 2013
Q42: column percentages
A43: Walking | C43: 53.89 | D43: 53.82 | E43: 51.86 | F43: 55.54 | G43: 52.4 | H43: 51.15 | I43: 52.52 | J43: 51.13 | K43: 52.81 | L43: 48.82 | M43: 49.97 | N43: 49.7 | O43: 50.6 | P43: 51.4 | Q43: 51.7
A45: Car or van | C45: 18.28 | D45: 19.72 | E45: 20.83 | F45: 18.95 | G45: 21.7 | H45: 21.62 | I45: 20.96 | J45: 21.72 | K45: 21.89 | L45: 23.61 | M45: 24.44 | N45: 23 | O45: 23.4 | P45: 24.1 | Q45: 24.4
A47: Bicycle | C47: 0.73 | D47: 0.64 | E47: 0.58 | F47: 0.67 | G47: 1.15 | H47: 0.98 | I47: 0.59 | J47: 0.87 | K47: 0.76 | L47: 1.47 | M47: 1.02 | N47: 1.4 | O47: 1.4 | P47: 0.8 | Q47: 1.2
A49: Bus
A50: School 2 | C50: 17.38 | D50: 16.9 | E50: 17.73 | F50: 15.05 | G50: 16.9 | H50: 16.85 | I50: 16.5 | J50: 17.04 | K50: 14.84 | L50: 16.53 | M50: 16.05 | N50: 16.1 | O50: 15.1 | P50: 14.9 | Q50: 14.5
A51: Service | C51: 7.37 | D51: 6.58 | E51: 6.77 | F51: 7.31 | G51: 5.51 | H51: 6.71 | I51: 7.06 | J51: 6.69 | K51: 7.1 | L51: 7.33 | M51: 5.94 | N51: 7.8 | O51: 6.6 | P51: 6.2 | Q51: 5.4
A52: All | C52: 24.76 | D52: 23.48 | E52: 24.27 | F52: 22.36 | G52: 22.19 | H52: 23.2 | I52: 23.32 | J52: 23.41 | K52: 21.91 | L52: 23.85 | M52: 21.99 | N52: 23.9 | O52: 21.7 | P52: 21.1 | Q52: 19.9
A54: Rail 3 | C54: 0.68 | D54: 0.63 | E54: 0.54 | F54: 0.35 | G54: 0.53 | H54: 0.86 | I54: 0.73 | J54: 1.23 | K54: 0.9 | L54: 0.73 | M54: 0.74 | N54: 0.3 | O54: 0.7 | P54: 0.4 | Q54: 0.6
A56: Other 4 | C56: 1.66 | D56: 1.72 | E56: 1.68 | F56: 2.13 | G56: 1.81 | H56: 1.83 | I56: 1.62 | J56: 1.33 | K56: 1.7 | L56: 1.52 | M56: 1.84 | N56: 1.7 | O56: 2.2 | P56: 2.2 | Q56: 2.2
A58: Sample size (100%) | C58: 2636 | D58: 3475 | E58: 3463 | F58: 3295 | G58: 3250 | H58: 3347 | I58: 3272 | J58: 3240 | K58: 2517 | L58: 2750 | M58: 2881 | N58: 2676 | O58: 2715 | P58: 1923 | Q58: 1975
A60: Source: Scottish Household Survey
...

Sheet T11.24-T11.25
A1: Table 11.24 Scottish residents' visits abroad by means of leaving the UK and purpose of visit, 2013
E4: Purpose of visit
E5: Visiting | G5: Miscellaneous
B6: Package | C6: Other | E6: Friends or | G6: and other
A7: Means of leaving the UK | B7: Holiday | C7: Holiday | D7: Business | E7: Relatives | G7: Purposes | I7: Total
I9: thousands
A10: Air
A11: Edinburgh | B11: 250.50342 | C11: 485.26577 | D11: 104.86858 | E11: 301.87128 | G11: 23.615656 | I11: =SUM(B11:G11) -> 1166.1247
A12: Glasgow | B12: 487.26549 | C12: 262.98946 | D12: 45.60577 | E12: 162.84795 | G12: 12.860011 | I12: =SUM(B12:G12) -> 971.56869
A13: Prestwick | B13: 78.152865 | C13: 219.42236 | D13: 6.5779886 | E13: 74.099811 | G13: 3.8233704 | I13: =SUM(B13:G13) -> 382.07639
A14: Aberdeen | B14: 31.43302 | C14: 43.047494 | D14: 53.577758 | E14: 47.731249 | G14: 2.9460147 | I14: =SUM(B14:G14) -> 178.73554
A15: Total Edinburgh, Glasgow, Prestwick & Aberdeen | B15: =SUM(B11:B14) -> 847.3548 | C15: =SUM(C11:C14) -> 1010.7251 | D15: =SUM(D11:D14) -> 210.6301 | E15: =SUM(E11:E14) -> 586.55029 | G15: =SUM(G11:G14) -> 43.245052 | I15: =SUM(I11:I14) -> 2698.5053
A17: Heathrow | B17: 8.4986815 | C17: 28.936648 | D17: 22.828412 | E17: 11.637018 | G17: 2.046527 | I17: =SUM(B17:G17) -> 73.947287
A18: Gatwick | B18: 41.072671 | C18: 61.6954 | D18: 4.8696454 | E18: 22.616307 | G18: 3.4629243 | I18: =SUM(B18:G18) -> 133.71695
A19: Stanstead | C19: 8.432051 | D19: 7.1790158 | E19: 7.4275601 | G19: 1.3029546 | I19: =SUM(B19:G19) -> 24.341582
A20: Manchester | B20: 101.78385 | C20: 38.665269 | D20: 4.0000461 | E20: 12.45622 | G20: 4.2872638 | I20: =SUM(B20:G20) -> 161.19265
A21: Newcastle | B21: 38.836902 | C21: 37.482524 | D21: 0.58719167 | E21: 2.3096478 | G21: 0.58719167 | I21: =SUM(B21:G21) -> 79.803457
A22: Birmingham | B22: 2.4734859 | C22: 7.3163216 | D22: 2.1386303 | E22: 7.4474197 | G22: .. | I22: =SUM(B22:G22) -> 19.375857
A24: Other UK Airports | B24: 34.371651 | C24: 78.693786 | D24: 51.816931 | E24: 37.29919 | G24: 5.504136 | I24: =SUM(B24:G24) -> 207.68569
A26: Total Air | B26: =SUM(B17:B24)+B15 -> 1074.392 | C26: =SUM(C17:C24)+C15 -> 1271.9471 | D26: =SUM(D17:D24)+D15 -> 304.04997 | E26: =SUM(E17:E24)+E15 -> 687.74366 | G26: =SUM(G17:G24)+G15 -> 60.43605 | I26: =SUM(I17:I24)+I15 -> 3398.5688
A28: Channel Tunnel | B28: 5.5406356 | C28: 34.833131 | D28: 7.7382937 | E28: 10.235326 | G28: 1.1448828 | I28: =SUM(B28:G28) -> 59.492269
A30: Sea
A31: English Channel Ports | B31: 28.027663 | C31: 47.086265 | D31: 11.501056 | E31: 11.561517 | G31: 6.8191923 | I31: =SUM(B31:G31) -> 104.99569
A32: English East Coast Ports | B32: 14.862029 | C32: 8.0088606 | D32: 1.0383625 | E32: 1.2422778 | G32: 0.49253467 | I32: =SUM(B32:G32) -> 25.644064
A33: Other UK Ports 2 | B33: 0.19475902 | C33: 1.5686505 | D33: 0.99009308 | E33: 0.085578035 | G33: .. | I33: =SUM(B33:G33) -> 2.8390807
A34: Total Sea | B34: =SUM(B31:B33) -> 43.084451 | C34: =SUM(C31:C33) -> 56.663776 | D34: =SUM(D31:D33) -> 13.529512 | E34: =SUM(E31:E33) -> 12.889373 | G34: =SUM(G31:G33) -> 7.3117269 | I34: =SUM(B34:G34) -> 133.47884
A36: Total All Means of Leaving the UK | B36: =B26+B28+B34 -> 1123.0171 | C36: =C26+C28+C34 -> 1363.444 | D36: =D26+D28+D34 -> 325.31777 | E36: =E26+E28+E34 -> 710.86836 | G36: =G26+G28+G34 -> 68.892659 | I36: =I26+I28+I34 -> 3591.5399
A38: Source: Office for National Statistics
A40: Table 11.25 Scottish residents' visits abroad by means of leaving the UK 1 and area visited, 2013
E42: Area Visited
I43: Rest of
B44: EU | C44: Other | D44: Canada | E44: Australia & | I44: the
A45: Means of leaving the UK | C45: Europe | D45: & USA | E45: New Zealand | G45: Asia | I45: World | J45: Total
J47: thousands
A48: Air
A49: Edinburgh | B49: 1026.8504 | C49: 22.576798 | D49: 60.843573 | E49: .. | G49: 21.531579 | I49: 34.322395 | J49: =SUM(B49:I49) -> 1166.1247
A50: Glasgow | B50: 658.93321 | C50: 4.904153 | D50: 76.255391 | E50: 32.530924 | G50: 66.29629 | I50: 132.64872 | J50: =SUM(B50:I50) -> 971.56869
A51: Prestwick | B51: 376.05914 | C51: 6.017249 | D51: .. | E51: .. | G51: .. | I51: .. | J51: =SUM(B51:I51) -> 382.07639
A52: Aberdeen | B52: 128.57692 | C52: 3.1786637 | D52: 7.9518886 | E52: .. | G52: 6.6675042 | I52: 32.360555 | J52: =SUM(B52:I52) -> 178.73554
A53: Total Edinburgh, Glasgow, Prestwick & Aberdeen | B53: =SUM(B49:B52) -> 2190.4196 | C53: =SUM(C49:C52) -> 36.676863 | D53: =SUM(D49:D52) -> 145.05085 | E53: =SUM(E49:E52) -> 32.530924 | G53: =SUM(G49:G52) -> 94.495373 | I53: =SUM(I49:I52) -> 199.33167 | J53: =SUM(J49:J52) -> 2698.5053
...

Sheet T11.26
A1: Table 11.26 Scottish residents' visits abroad, by means of leaving the UK1, purpose of visit, and area visited
D3: 1995 | E3: 1996 | F3: 1997 | G3: 1998 | H3: 1999 | I3: 2000 | J3: 2001 | K3: 2002 | L3: 2003 | M3: 2004 | N3: 2005 | O3: 2006 | P3: 2007 | Q3: 2008 | R3: 2009 | S3: 2010 | T3: 2011 | U3: 2012 | V3: 2013
V5: thousands
A7: All visits abroad by Scots | D7: =SUM(D10,D23,D24) -> 2535 | E7: =SUM(E10,E23,E24) -> 2469 | F7: =SUM(F10,F23,F24) -> 2781 | G7: =SUM(G10,G23,G24) -> 2776 | H7: =SUM(H10,H23,H24) -> 3058 | I7: =SUM(I10,I23,I24) -> 3506 | J7: =SUM(J10,J23,J24) -> 3714 | K7: =SUM(K10,K23,K24) -> 3804 | ... V7: =SUM(V10,V23,V24) -> 3591.5399
A9: by means of leaving the UK
B10: Air | C10: Total | D10: =SUM(D15:D22) -> 2132 | E10: =SUM(E15:E22) -> 2123 | F10: =SUM(F15:F22) -> 2350 | G10: =SUM(G15:G22) -> 2381 | H10: =SUM(H15:H22) -> 2666 | I10: =SUM(I15:I22) -> 3110 | J10: =SUM(J15:J22) -> 3327 | K10: =SUM(K15:K22) -> 3459 | ... V10: =SUM(V15:V22) -> 3398.5688
B11: Edinburgh | D11: 177 | E11: 191 | F11: 179 | G11: 213 | H11: 349 | I11: 448 | J11: 573 | K11: 454 | L11: 446 | M11: 783 | N11: 767 | O11: 852 | P11: 1076.514 | Q11: 1194.4932 | R11: 1035.2243 | S11: 999.81571 | T11: 1037.8407 | U11: 1045.4904 | V11: 1166.1247
B12: Glasgow | D12: 1145 | E12: 1061 | F12: 1236 | G12: 1196 | H12: 1380 | I12: 1673 | J12: 1692 | K12: 1954 | L12: 2027 | M12: 2021 | N12: 1721 | O12: 1868 | P12: 1773.9363 | Q12: 1741.78 | R12: 1339.1363 | S12: 1101.6816 | T12: 1108.4019 | U12: 1176.065 | V12: 971.56869
B13: Prestwick | D13: .. | E13: .. | F13: .. | G13: .. | H13: .. | I13: .. | J13: .. | K13: .. | L13: .. | M13: .. | N13: 566 | O13: 673 | P13: 656.04063 | Q13: 644.14085 | R13: 376.33867 | S13: 409.1176 | T13: 413.72116 | U13: 363.66441 | V13: 382.07639
B14: Aberdeen | D14: .. | E14: .. | F14: .. | G14: .. | H14: .. | I14: .. | J14: .. | K14: .. | L14: .. | M14: .. | N14: .. | O14: .. | P14: .. | Q14: .. | R14: 180.41614 | S14: 163.52954 | T14: 164.33242 | U14: 197.0894 | V14: 178.73554
B15: Total these airports | D15: =SUM(D11:D14) -> 1322 | E15: =SUM(E11:E14) -> 1252 | F15: =SUM(F11:F14) -> 1415 | G15: =SUM(G11:G14) -> 1409 | H15: =SUM(H11:H14) -> 1729 | I15: =SUM(I11:I14) -> 2121 | J15: =SUM(J11:J14) -> 2265 | K15: =SUM(K11:K14) -> 2408 | ... V15: =SUM(V11:V14) -> 2698.5053
B16: Heathrow | D16: 366 | E16: 417 | F16: 388 | G16: 453 | H16: 314 | I16: 341 | J16: 373 | K16: 352 | L16: 364 | M16: 435 | N16: 383 | O16: 148.97937 | P16: 116.6999 | Q16: 101.98312 | R16: 108.63135 | S16: 87.112899 | T16: 76.288447 | U16: 84.121596 | V16: 73.947287
B17: Gatwick | D17: 128 | E17: 116 | F17: 159 | G17: 172 | H17: 188 | I17: 191 | J17: 187 | K17: 167 | L17: 183 | M17: 225 | N17: 186 | O17: 191.54293 | P17: 183.1651 | Q17: 215.31684 | R17: 139.50289 | S17: 126.7269 | T17: 146.77024 | U17: 190.14301 | V17: 133.71695
B18: Stanstead | D18: 9 | E18: 19 | F18: 12 | G18: 22 | H18: 38 | I18: 51 | J18: 69 | K18: 114 | L18: 121 | M18: 115 | N18: 102 | O18: 108.86125 | P18: 58.1303 | Q18: 80.665007 | R18: 47.020422 | S18: 44.473547 | T18: 35.050586 | U18: 35.51944 | V18: 24.341582
B19: Manchester | D19: 162 | E19: 150 | F19: 182 | G19: 152 | H19: 185 | I19: 148 | J19: 149 | K19: 182 | L19: 164 | M19: 156 | N19: 164 | O19: 159.38194 | P19: 157.96047 | Q19: 134.2183 | R19: 130.04927 | S19: 129.96024 | T19: 124.50617 | U19: 132.0811 | V19: 161.19265
B20: Newcastle | D20: .. | E20: .. | F20: .. | G20: .. | H20: .. | I20: .. | J20: .. | K20: .. | L20: .. | M20: .. | N20: .. | O20: 136.3094 | P20: 175.90094 | Q20: 127.95349 | R20: 105.25614 | S20: 118.85262 | T20: 82.53374 | U20: 90.530194 | V20: 79.803457
B21: Birmingham | D21: .. | E21: .. | F21: .. | G21: .. | H21: .. | I21: .. | J21: .. | K21: .. | L21: .. | M21: .. | N21: .. | O21: 38.790681 | P21: 22.06734 | Q21: 17.692106 | R21: 13.393699 | S21: 19.468914 | T21: 14.383582 | U21: 16.725366 | V21: 19.375857
B22: Other UK Airports | D22: 145 | E22: 169 | F22: 194 | G22: 173 | H22: 212 | I22: 258 | J22: 284 | K22: 236 | L22: 264 | M22: 274 | N22: 242 | O22: 384.83055 | P22: 296.69806 | Q22: 242.78903 | R22: 198.53618 | S22: 161.57666 | T22: 164.45904 | U22: 137.03117 | V22: 207.68569
B23: Channel Tunnel | D23: 25 | E23: 64 | F23: 60 | G23: 104 | H23: 90 | I23: 60 | J23: 44 | K23: 41 | L23: 54 | M23: 36 | N23: 52 | O23: 55 | P23: 65.028361 | Q23: 82.62653 | R23: 62.701383 | S23: 76 | T23: 55.309983 | U23: 63.756684 | V23: 59.492269
B24: Sea | C24: Total | D24: =SUM(D25:D27) -> 378 | E24: =SUM(E25:E27) -> 282 | F24: =SUM(F25:F27) -> 371 | G24: =SUM(G25:G27) -> 291 | H24: =SUM(H25:H27) -> 302 | I24: =SUM(I25:I27) -> 336 | J24: =SUM(J25:J27) -> 343 | K24: =SUM(K25:K27) -> 304 | ... V24: =SUM(V25:V27) -> 133.47884
B25: English Channel Ports | D25: 310 | E25: 212 | F25: 276 | G25: 221 | H25: 194 | I25: 224 | J25: 243 | K25: 213 | L25: 124 | M25: 109 | N25: 57 | O25: 119 | P25: 67.867111 | Q25: 107.49494 | R25: 109.29705 | S25: 118.14847 | T25: 107.74434 | U25: 74.159214 | V25: 104.99569
B26: English East Coast Ports | D26: 68 | E26: 66 | F26: 90 | G26: 68 | H26: 94 | I26: 89 | J26: 87 | K26: 85 | L26: 61 | M26: 54 | N26: 47 | O26: 45 | P26: 51.683772 | Q26: 45.856595 | R26: 37.127392 | S26: 33.836833 | T26: 43.137354 | U26: 35.125065 | V26: 25.644064
B27: Other UK Ports | D27: 0 | E27: 4 | F27: 5 | G27: 2 | H27: 14 | I27: 23 | J27: 13 | K27: 6 | L27: 9 | M27: 10 | N27: 1 | O27: 11 | P27: 36.116567 | Q27: 28.232091 | R27: 16.385302 | S27: 27.871133 | T27: 4.8242749 | U27: 3.7131416 | V27: 2.8390807
A29: by purpose of visit
B30: Package holiday | D30: 1306 | E30: 1160 | F30: 1351 | G30: 1224 | H30: 1560 | I30: 1785 | J30: 1847 | K30: 1978 | L30: 1903 | M30: 1969 | N30: 1580 | O30: 1681 | P30: 1686.5801 | Q30: 1512.2045 | R30: 1161.3058 | S30: 1194.8586 | T30: 1128.3531 | U30: 1210.2258 | V30: 1123.0171
B31: Other holiday | D31: 640 | E31: 661 | F31: 737 | G31: 739 | H31: 817 | I31: 897 | J31: 1007 | K31: 1042 | L31: 1084 | M31: 1212 | N31: 1505 | O31: 1694 | P31: 1642.9665 | Q31: 1827.5641 | R31: 1453.9356 | S31: 1378.244 | T31: 1322.9171 | U31: 1335.0238 | V31: 1363.444
B32: Business | D32: 286 | E32: 284 | F32: 328 | G32: 390 | H32: 326 | I32: 374 | J32: 338 | K32: 329 | L32: 305 | M32: 329 | N32: 394 | O32: 383 | P32: 457.61399 | Q32: 406.90904 | R32: 396.57153 | S32: 363.18594 | T32: 398.62477 | U32: 333.78878 | V32: 325.31777
B33: Visit friends / relatives | D33: 215 | E33: 302 | F33: 269 | G33: 312 | H33: 282 | I33: 358 | J33: 455 | K33: 391 | L33: 389 | M33: 598 | N33: 692 | O33: 859 | P33: 824.29345 | Q33: 912.70346 | R33: 799.63715 | S33: 611.49027 | T33: 669.73423 | U33: 672.79753 | V33: 710.86836
B34: Misc. and other | D34: 87 | E34: 61 | F34: 94 | G34: 111 | H34: 73 | I34: 90 | J34: 68 | K34: 64 | L34: 136 | M34: 110 | N34: 118 | O34: 174 | P34: 126.35483 | Q34: 104.12217 | R34: 87.566343 | S34: 69.765573 | T34: 59.674756 | U34: 93.379358 | V34: 68.892659
A36: by area visited
B37: EU | D37: 1993 | E37: 1875 | F37: 2099 | G37: 2073 | H37: 2322 | I37: 2759 | J37: 2985 | K37: 3092 | L37: 3008 | M37: 3204 | N37: 3276 | O37: 3709 | P37: 3661.9874 | Q37: 3692.0932 | R37: 2932.5908 | S37: 2709.0078 | T37: 2767.9199 | U37: 2844.6465 | V37: 2760.5189
B38: Other Europe | D38: 11 | E38: 12 | F38: 28 | G38: 24 | H38: 21 | I38: 15 | J38: 12 | K38: 14 | L38: 29 | M38: 32 | N38: 41 | O38: 61 | P38: 47.891304 | Q38: 64.30074 | R38: 49.665316 | S38: 48.014002 | T38: 63.521974 | U38: 50.278993 | V38: 60.055776
B39: North America | D39: 322 | E39: 353 | F39: 376 | G39: 383 | H39: 449 | I39: 465 | J39: 455 | K39: 388 | L39: 456 | M39: 497 | N39: 484 | O39: 503 | P39: 464.69055 | Q39: 477.49059 | R39: 365.40255 | S39: 343.78263 | T39: 284.69541 | U39: 297.02362 | V39: 266.86331
B40: Australia & New Zealand | D40: 21 | E40: 25 | F40: 25 | G40: 42 | H40: 31 | I40: 32 | J40: 39 | K40: 34 | L40: 32 | M40: 54 | N40: 77 | O40: 60 | P40: 70.778289 | Q40: 52.161311 | R40: 57.160126 | S40: 55.386055 | T40: 42.678901 | U40: 38.198991 | V40: 46.822031
B41: Asia | D41: 48 | E41: 71 | F41: 86 | G41: 94 | H41: 74 | I41: 94 | J41: 72 | K41: 80 | L41: 81 | M41: 154 | N41: 128 | O41: 158 | P41: 147.363 | Q41: 153.92673 | R41: 146.08833 | S41: 138.87041 | T41: 132.00557 | U41: 118.72315 | V41: 139.81691
B42: Rest of the World | D42: 139 | E42: 132 | F42: 165 | G42: 160 | H42: 161 | I42: 139 | J42: 153 | K42: 198 | L42: 212 | M42: 277 | N42: 282 | O42: 301 | P42: 345.09832 | Q42: 323.53063 | R42: 348.10936 | S42: 322.4835 | T42: 288.48212 | U42: 296.34396 | V42: 317.46299
A44: by means of leaving the UK and main purposes of visits
