Workbook

Sheet Cover Sheet
A1: ExampleApp Functional Specification
A3: Author: | B3: Tony Heap
A5: Version: | B5: This is a living document and is not formally version controlled.
B6: Accordingly, there is no formal sign-off of the document as a whole. Rather, each "acceptance criterion" is signed off individually (see the "Agreed" columns on the "Details" worksheet).
A8: Overview: | B8: This document (together with a number of supplementary documents) is the functional specification for the "ExampleApp" project.
B9: This document specifies what the system will do as opposed to how it will do it (i.e. It is not a technical specification).
B10: This document specifies only the changes to the system; it does not specify existing functionality.
A12: Structure: | B12: The functional specification consists of a set of "stories".
B13: Each story describes some aspect of the system's behaviour, either functional or non-functional.
B14: A story is the smallest unit of system delivery - a story is either delivered or it is not.
B15: In practice, stories are grouped together and delivered as (time-boxed) "increments" every 3-4 weeks.
B16: The "Summary" worksheet is an inventory of all the stories, along with various information for each one.
B17: In particular, the "Status" column in the "Summary" worksheet indicates the status of each story, from "being elaborated" right through to "gone live".
B18: The "Details" worksheet contains the detailed specification for each story.
B19: Each story is specified in "use case" format (ref. "Writing Effective Use Cases", Alistair Cockburn, 2001).
B20: See the column heading comments on the "Summary" and "Details" worksheets for further details on the format of the specification.
B21: The "Actors" workheet specifies all actors (users and external systems)
B22: The "Stats" worksheets show development progress for individual increments, in the form of a "burn down chart"

Sheet Summary
A1: Story ID | B1: Story Name | C1: As a... (Actor) | D1: I can... (Goal) | E1: Status | F1: Priority | G1: Dependencies | H1: Story Points | I1: Dev Increment | J1: Dev Owner | K1: Dev Complete Date | L1: Actual Dev Time (man days) | M1: Time Fixing Defects (man days) | N1: Notes | O1: Beta Test Phase | P1: Tester
A3: S001 | B3: Timeout | C3: Logged In User | D3: Have the system log me out if I do not use it for a period | E3: Live | I3: v7.3
A4: S002 | B4: Submission Warning | C4: Assessment Submitter | D4: Receive a warning before I submit my assessment | E4: Live | I4: v7.3
A5: S003 | B5: Submission E-mail | C5: Assessment Submitter | D5: Receive an e-mail confirming my assessment submission | E5: Live | I5: v7.3
A6: S004 | B6: Approval E-mail Log | C6: DIP Team | D6: View a record of the sending of an approval e-mail | E6: Live | I6: v7.3
A7: S005 | B7: Thingy New User E-mail | C7: XYZ ABC User | D7: Send thingy-specific "new user" e-mails when I create user accounts | E7: Live | I7: v7.3
A8: S006 | B8: Thingy "Not Relevant" Extras | C8: Thingy Assessment Completer | D8: Be able to answer "not relevant" for certain requirements | E8: Live | I8: v7.3
A9: S007 | B9: Thingy KB Doc Change | C9: General User | D9: View an amended thingy Knowledge Base document | E9: Live | I9: v7.3
A10: S008 | B10: Thingy Footer Details | C10: Thingy User | D10: View helpdesk details in any page footer | E10: Live | I10: v7.3
A11: S009 | B11: Thingy Request Registration | C11: Thingy User | D11: View helpdesk details when self registering for a Thingy | E11: Live | I11: v7.3
A12: S010 | B12: Add Widget Comments | C12: Assessment Completer | D12: Add and amend general comments for my requirement response | E12: Live | I12: v7.3
A13: S012 | B13: View Widgets List (Enhancements) | C13: General User | D13: Better understand the requirements list | E13: Implement | F13: Must | H13: 2 | I13: v8.0 (i1) | J13: CC | K13: 40213 | O13: Phase 1
A14: S013 | B14: View Widget Header Information (v8+) | C14: General User | D14: View key information about a (v8+) requirement | E14: Implement | F14: Must | H14: 2 | I14: v8.0 (i1) | J14: CC | K14: 40204 | O14: Phase 1
A15: S014 | B15: View Widget Description (v8+) | C15: General User | D15: View the requirement description for a (v8+) requirement | E15: Implement | F15: Must | H15: 0.5 | I15: v8.0 (i1) | J15: CC | K15: 40205 | O15: Phase 1
A16: S015 | B16: View Widget Guidance Text (v8+) | C16: General User | D16: View the guidance text for a (v8+) requirement | E16: Implement | F16: Must | H16: 0.25 | I16: v8.0 (i1) | J16: CC | K16: 40205 | O16: Phase 1
A17: S016 | B17: View Knowledge Base Resources (v8+) | C17: General User | D17: View and access the knowledge base resources that are relevant to a (v8+) requirement | E17: Implement | F17: Must | G17: S075 | H17: 2 | I17: v8.0 (i1) | J17: CC | K17: 40207 | O17: Phase 1
A18: S017 | B18: View Widget Origins (v8+) | C18: General User | D18: View the requirement origins for a (v8+) requirement | E18: Implement | F18: Should | H18: 0.5 | I18: v8.0 (i1) | J18: CC | K18: 40205 | O18: Phase 1
A19: S068 | B19: View Widget Changes (v8+) | C19: General User | D19: View a list of material changes that have been made in this (major) version of the (v8+) requirements | E19: Implement | F19: Should | H19: 0.5 | I19: v8.0 (i1) | J19: CC | K19: 40205 | O19: Phase 1
A20: S018 | B20: View Training Tool Text (v8+) | C20: General User | D20: View the training tool text for a (v8+) requirement | E20: Implement | F20: Should | H20: 0.25 | I20: v8.0 (i1) | J20: CC | K20: 40206
A21: S019 | B21: View Training Tool Custom Text (v8+) | C21: General User | D21: View (v8+) requirement-specific training tool text | E21: Implement | F21: Should | H21: 0.25 | I21: v8.0 (i1) | J21: CC | K21: 40206
A22: S020 | B22: View Attainment Levels (v8+) | C22: General User | D22: View attainment levels and attainment criteria for a (v8+) requirement | E22: Implement | F22: Must | H22: 3 | I22: v8.0 (i2) | J22: CC | K22: 40233 | L22: 3 | O22: Phase 1
A23: S021 | B23: View Evidence Types | C23: General User | D23: View standard evidence types against each attainment criterion | E23: Implement | F23: Must | G23: S020 | H23: 5 | I23: v8.0 (i2) | J23: RJM | K23: 40232 | L23: 5.5 | O23: Phase 1
A24: S049 | B24: Expand and Collapse Widget (v8+) | C24: General User | D24: Expand or collapse the various sections of the (v8+) requirement page | E24: Implement | F24: Must | G24: S014-S020 | H24: 2 | I24: v8.0 (i1) | J24: CC | K24: 40205 | O24: Phase 1
A25: S023 | B25: Indicate Widget As Not Relevant (v8+) | C25: Organisation User | D25: Indicate that a (v8+) requirement is not relevant to my organisation | E25: Implement | F25: Must | H25: 1 | I25: v8.0 (i2) | J25: CC | K25: 40234 | L25: 1 | O25: Phase 2
A26: S024 | B26: Enter Comments for an Attainment Criterion | C26: Organisation User | D26: Enter comments for an attainment criterion | E26: Implement | F26: Must | H26: 1 | I26: v8.0 (i2) | J26: CC | K26: 40242 | L26: 4 | N26: Much more complicated than initially estimated for | O26: Phase 1
A27: S025 | B27: Add Custom Evidence Type | C27: Organisation User | D27: Add a custom evidence type to an assessment criterion (because the standard evidence types are not appropriate for me) | E27: Implement | F27: Must | H27: 4 | I27: v8.0 (i2) | J27: RJM | K27: 40245 | L27: 5 | N27: more complicated than originally thought. Required integration with main page for testing save functionality | O27: Phase 1
A28: S026 | B28: Indicate Evidence Obtained | C28: Organisation User | D28: Indicate that I have obtained a particular evidence type | E28: Implement | F28: Must | H28: 2 | I28: v8.0 (i2) | J28: RJM | K28: 40238 | L28: 3 | O28: Phase 1
A29: S027 | B29: Enter Evidence Comments | C29: Organisation User | D29: Enter comments against a specific evidence type | E29: Implement | F29: Must | H29: 2 | I29: v8.0 (i2) | J29: RJM | K29: 40239 | L29: 2 | O29: Phase 1
A30: S028 | B30: Specify External Evidence Location | C30: Organisation User | D30: Specify an external location for my evidence | E30: Implement | F30: Should | H30: 5 | I30: v8.0 (i3) | J30: RJM | K30: 40256 | L30: 4 | O30: Phase 1
A31: S131 | B31: Specifiy Evidence Location Improvement | C31: Organisation User | D31: Specify an external location for my evidence (improved UI) | E31: Implement | F31: Must | G31: S028, S030 | H31: 2 | I31: v8.0 (i4) | J31: RJM | K31: 40275 | L31: 4 | N31: Was more complex than anticipated, plus all of the associated bubbling of events needed to be changed. | O31: Phase 1
A32: S030 | B32: Upload Evidence | C32: Organisation User | D32: Upload evidence to the PQRT server | E32: Implement | F32: Should | H32: 3 | I32: v8.0 (i4) | J32: RJM | K32: 40282 | L32: 4 | O32: Phase 2
A33: S031 | B33: View Evidence | C33: Organisation User | D33: View evidence files that I have previously specified in my requirement response | E33: Implement | F33: Should | G33: S028, S030 | H33: 2 | I33: v8.0 (i4) | J33: RJM | K33: 40284 | L33: 3 | O33: Phase 2
A34: S029 | B34: Specify Duplicate Evidence | C34: Organisation User | D34: Indicate that an evidence type is a duplicate of another one I've already specified (and cross reference it) | E34: Withdrawn | F34: Must | G34: S029 | H34: 4 | I34: N/A | J34: RJM | O34: N/A
A35: S140 | B35: View Duplicate Evidence | C35: Organisation User | D35: View duplicate evidence files that I have previously specified in my requirement response | E35: Withdrawn | F35: Should | H35: 1 | I35: N/A | J35: RJM | O35: N/A
A36: S139 | B36: Cannot Delete Referenced Custom Evidence | C36: Organisation User | D36: Be prevented from deleting custom evidence which is referenced from elsewhere | E36: Withdrawn | F36: Must | H36: 2 | I36: N/A | J36: RJM | O36: N/A
A37: S149 | B37: Link to Existing Uploaded Evidence | C37: Organisation User | D37: Specify an existing uploaded evidence file against another evidence item | E37: Withdrawn | F37: Must | H37: 4 | I37: v8.0 (i5) | J37: RJM | K37: 40291 | L37: 4 | N37: Superseded by S163 | O37: N/A
A38: S163 | B38: Link to Existing Uploaded Evidence (Mark 2) | C38: Organisation User | D38: Specify an existing uploaded evidence file against another evidence item (enhanced/simplified version) | E38: Implement | F38: Must | H38: 1 | I38: v8.0 (i5) | J38: RJM | K38: 40298 | L38: 1 | O38: Phase 2
A39: S032 | B39: Configure Evidence Provision Status | C39: Sys Admin | D39: Configure whether evidence provision is mandatory or optional for each org type | E39: Implement | F39: Must | H39: 0.5 | I39: v8.0 (i3) | J39: NL | K39: 40255 | L39: 0.5 | O39: N/A
A40: S033 | B40: Indicate Attainment Criterion Achieved | C40: Organisation User | D40: Indicate a given attainment criterion as achieved either directly or indirectly | E40: Implement | F40: Must | H40: 6 | I40: v8.0 (i3) | J40: CC | K40: 40260 | L40: 5 | O40: Phase 1
A41: S034 | B41: Indicate Attainment Level 0 (v8+) | C41: Organisation User | D41: Explicitly indicate that my organisation is at Attainment Level 0 | E41: Implement | F41: Must | H41: 1.5 | I41: v8.0 (i3) | J41: CC | K41: 40255 | L41: 1.5 | O41: Phase 1
...

Sheet Details
A1: Story ID | B1: Story Name | C1: As a... (Actor) | D1: I can... (Goal) | E1: Flow | F1: Step | G1: When I... (Action) | H1: Then... (Acceptance Criterion) | I1: Prototyped | J1: Agreed PW/MG | K1: Agreed TUG | L1: Agreed Dev | M1: Notes | N1: Test Status | O1: Defect | P1: Defect Priority | Q1: Defect Status | R1: Defect Notes
A2: S01 | B2: Ensure form displays to project specifications | C2: General user | D2: Access all of the items, widgets, buttons, ect…within the webpage form. | E2: Main | F2: 1 | G2: Request to view the web form online | H2: Once the page loads, all widgets are displayed | I2: Y | J2: NA | K2: NA | L2: NA | N2: Pass
A3: S011 | B3: Test clear button | C3: General user | D3: remove current form input in text fields | E3: Main | F3: 1 | G3: Click the "clear" button on form page | H3: The text input is removed from the text fields, and the blank/default field inputs are returned to default state | I3: Y | J3: NA | K3: NA | L3: NA | N3: Pass
A4: S0111 | B4: Submit button | C4: General user | D4: submit input to form | E4: Main | F4: 1 | G4: click the "submit" button on the form | H4: The text items are scraped and echoed out to the user | I4: Y | J4: NA | K4: NA | L4: NA | N4: Pending
A9: S012 | B9: View Widgets List (Enhancements) | C9: General User | D9: Better understand the widgets list | E9: Main | F9: 1 | G9: Request to view the widgets list (any org type)
F10: 2 | H10: The column headings indicate what happens when the column content is clicked | I10: Y | J10: 40135 | K10: 40142 | L10: CMC | N10: Pass
F11: 3 | H11: Column 1 header is "Req No" (previously "Seq No") | I11: Y | J11: 40135 | K11: 40142 | L11: CMC | N11: Pass
F12: 4 | H12: The widgets are grouped by initiative (with initiative sub-headers and colour coding) | I12: Y | J12: 40140 | K12: 40142 | L12: CMC | N12: Pass
F13: 5 | H13: A new column "Key Req" indicates whether key widget (including use of icons and/or colour) | I13: Y | J13: 40140 | K13: 40142 | L13: CMC | M13: CMC: Will need to have ALT text for the Icon as well for accessibility | N13: Pass
F14: 6 | H14: For each answered key widget, the Attainment Level column includes a "status" indicator showing whether or not Attainment Level 2 reached | I14: Y | J14: 40140 | K14: 40142 | L14: CMC | M14: CMC: Again also needs ALT text for icon | N14: Pass | O14: 1) Alt text should read "Attainment Level 2 met/not met for Key Widget". | P14: Medium | Q14: Closed | R14: CMC: (1) Currently alt text reads "Key Widget Minimum Level Met/Not met". Think this is a better wording as there is no guarantee that 2 will remain as the min level for key widgets.
N15: Pass | O15: It's showing the cross icon correctly but it's showing the key icon instead of the tick icon | P15: Medium | Q15: Closed | R15: (2)You can test this as have set page to display for V7 assessment sets in order to allow testing. Suggest using V7 assessment for organisation code REM.
A17: S013 | B17: View Widget Header Information (v8+) | C17: General User | D17: View key information about a (v8+) widget | E17: Main | F17: 1 | G17: Request to view a specific (v8+) widget
F18: 2 | H18: The header panel is re-organised to list key data down the RHS (widget no, initiative, whether key widget, org type, widget version number) | I18: Y | J18: 40133 | K18: 40142 | L18: CMC | N18: Pass
F19: 3 | H19: The version number is of the format <major>.<minor> e.g. 8.0. Note that individual widgets in the same set can be at different minor versions. | I19: Y | J19: 40147 | K19: 40254 | L19: CMC | M19: CMC: Needs investigation as to how this will integrate with RATI tool | N19: Pass
F20: 4 | H20: The HORUS categorisation is removed (this only applies for v8+ widgets - it is to be retained for v7- widgets) | I20: Y | J20: 40133 | K20: 40142 | L20: CMC | M20: TBC knock-on effect on TDB. CMC Will definitely have knock on effect on TDB will require at the least some TDB reports being pulled and at worst changes to TDB data structures and associated batch and SP processes as well. | N20: Pass
F21: 5 | H21: The MSPrPe categorisation is removed (this only applies for v8+ widgets - it is to be retained for v7- widgets) | I21: Y | J21: 40133 | K21: 40142 | L21: CMC | N21: Pass
F22: 6 | H22: The Category categorisation is removed (this only applies for v8+ widgets - it is to be retained for v7- widgets) | I22: Y | J22: 40133 | K22: 40142 | L22: CMC | N22: Pass
F23: 7 | H23: The header panel is colour coded to indicate which initiative it belongs to (see PQRT v8 Colour Palette v1) | I23: Y | J23: 40133 | K23: 40142 | L23: CMC | N23: Pass
F24: 8 | H24: The header panel is colour coded to indicate whether it is a key widget (see PQRT v8 Colour Palette v1) | I24: Y | J24: 40133 | K24: 40142 | L24: CMC | N24: Pass
A26: S014 | B26: View Widget Description (v8+) | C26: General User | D26: View the widget description for a (v8+) widget | E26: Main | F26: 1 | G26: Request to view a specific (v8+) widget
F27: 2 | G27: Precondition: the relevant widget text has been converted from RATML into HTML by S065 (Import Widgets Data)
F28: 3 | H28: The widget description for the widget appears below the header panel (heading: "Widget Description"). This is the text that previously appeared with the widget question in the blue box on the Guidance Document. | I28: Y | J28: 40135 | K28: 40142 | L28: CMC | N28: Pass
A30: S015 | B30: View Widget Guidance Text (v8+) | C30: General User | D30: View the guidance text for a (v8+) widget | E30: Main | F30: 1 | G30: Request to view a specific (v8+) widget
F31: 2 | G31: Precondition: the relevant widget text has been converted from RATML into HTML by S065 (Import Widgets Data)
F32: 3 | H32: The guidance text is presented (correctly formatted) | I32: Y | J32: 40135 | K32: 40142 | L32: CMC | N32: Pass | O32: 1) Paragraph indenting is out. The answer here (I think) is to remove the 5 x &nbsp; at the beginning of each para in the HTML. 2) In IE, the first H3 displays fine but the second and subsequent ones are indented and too small. It seems to be because they are embedded within a <ul> (but so is the first one!), because if I close the <ul> before the <h3> and open it again afterwards it's OK. But then the paragraph numbering goes to cock, unless youe explicitly use the "Start" attribute of <ul>. | P32: Medium | Q32: Closed | R32: CMC:I copied the HTML as was given in the prototype at the time of development. The HTML which will get produced is really part of the publish story, as such . not sure there's too much point frigging with the test HTML to get the result we want. Propose leaving this till testing of the publish process. TH 16/3: I will attempt to "fix" these in the prototype and then you can take the latest cut of the prototype HTML TH 22/3: fixed in prototype (see email from me the other day) CMC 06/04 Think this is now fixed looks ok to me with published data from RATTY anyway TH 12/04: the publish function may work OK but the test data itself needs to be valid, both for manual and automated testing purposes CMC 26/04 Guidance text fixed for Acute Test widget 101
F33: 4 | H33: The guidance text has paragraph numbers (for easy reference) | I33: Y | J33: 40133 | K33: 40142 | L33: CMC | N33: Pass
A35: S016 | B35: View Knowledge Base Resources (v8+) | C35: General User | D35: View and access the knowledge base resources that are relevant to a (v8+) widget | E35: Main | F35: 1 | G35: Request to view a specific (v8+) widget
F36: 2 | H36: There is a list of all knowledge base resources relevant to the widget | I36: Y | J36: 40135 | K36: 40142 | L36: CMC | N36: Pass
F37: 3 | H37: The title of section is "Knowledge Base Resources" | I37: Y | J37: 40135 | K37: 40142 | L37: CMC | N37: Pass
F38: 4 | H38: The resources are grouped into "Key Resources", "Exemplars" and "Useful Websites" | I38: Y | J38: 40135 | K38: 40142 | L38: CMC | N38: Pass | O38: 1) Order of tabs should be Key Resources, Exemplar Materials, Useful Web Sites | P38: Medium | Q38: Closed | R38: CMC:Fixed as part of reskin of widgets page
F39: 5 | H39: The resources are tabulated | I39: Y | J39: 40135 | K39: 40142 | L39: CMC | N39: Pass
F40: 6 | H40: Each resource title is a hyperlink through to the resource (be it a document on our server or an external URL) | I40: Y | J40: 40135 | K40: 40142 | L40: CMC | N40: Pass | O40: Visited weblinks are the same colour as not visited links (OK) but with no underline (not OK) | P40: Medium | Q40: Closed | R40: CMC: Are now underlined as per re-skin of widgets page 22/10 TH: Failed retest. Note that some links are not underlined even before I have visited them.
F41: 7 | H41: When a hyperlink is clicked, the resoruce is displayed in a new tab or window | I41: Y | J41: 40189 | K41: N/A | L41: CMC | N41: Pass
F42: 8 | H42: For each resource there is a description of the resource to help users determine the content of the resource and whether it will be useful to them | I42: Y | J42: 40133 | K42: 40142 | L42: CMC | N42: Pass
F43: 9 | H43: For each resource there is an indicator indicating whether the resource is located internally on the PQRT website or whether it is on an external web page (this gives the user a hint that the content they are looking at is not "owned" by XYZ ABC).. | I43: Y | J43: 40147 | K43: 40142 | L43: CMC | N43: Pass | O43: 1) Can you put a tooltip on the external web site link saying "External web site link" (as per prototype) 2) Can you include the external website link within the <a> tag so it is clickable along with the link itself. | P43: Low | Q43: Closed | R43: CMC: Ok have added tooltip to the a href as well as the image and added the space, try again.
F44: 10 | H44: For each internally located resource, the file type and size is displayed | I44: Y | J44: 40147 | K44: 40142 | L44: CMC | M44: CMC: Possible security access implications as will need to access file system to get this information. TH: the fiel type and size will be in the DB (calculated by RATty) | N44: Pass | O44: Can you remove the leading dot e.g. "DOC", not ".DOC" | P44: Low | Q44: Closed | R44: CMC:Data issue only, fixed in test data set up script
A46: S017 | B46: View Widget Origins (v8+) | C46: General User | D46: View the widget origins for a (v8+) widget | E46: Main | F46: 1 | G46: Request to view a specific (v8+) widget
F47: 2 | G47: Precondition: the relevant widget text has been converted from RATML into HTML by S065 (Import Widgets Data)
F48: 3 | H48: There is a section containing the widget origins (after the (optional) Training section) | I48: Y | J48: 40133 | K48: 40142 | L48: CMC | N48: Pass
F49: 4 | H49: The widget origins section is a bullet list of free format text items | I49: Y | J49: 40133 | K49: 40142 | L49: CMC | N49: Pass
...

Sheet Actors
A1: Actor Name | B1: Description
A2: General User | B2: Any user, whether logged in or not
A3: Anonymous User | B3: Any user who is not logged in
A4: Logged In User | B4: Any user who is logged in
A5: Organisation User | B5: User responsible for basic operations within their organisation e.g. entering widget responses
A6: Organisation Reviewer | B6: User responsible for reviewing widget responses for their organisation
A7: Organisation Administrator | B7: User responsible for performing admin tasks for their organisation
A8: Organisation Auditor | B8: User responsible to auditing assessments for a specific organisation
A9: XYZ ABC User | B9: User within XYZ ABC responsible for performing various cross-organisation admin tasks
A10: Sys Admin | B10: System administrator

Sheet Stats (Summary)
A1: Story Point Count Summary
A3: Increment | B3: Story Points | C3: Man Days | D3: Velocity
A5: ='Stats (i1)'!$A$2 -> v8.0 (i1) | B5: ='Stats (i1)'!$E$2 -> 30.75 | C5: ='Stats (i1)'!$C$2 -> 29 | D5: =B5/C5 -> 1.0603448
A6: ='Stats (i2)'!$A$2 -> v8.0 (i2) | B6: ='Stats (i2)'!$E$2 -> 47 | C6: ='Stats (i2)'!$C$2 -> 60 | D6: =B6/C6 -> 0.78333333
A7: ='Stats (i3)'!$A$2 -> v8.0 (i3) | B7: ='Stats (i3)'!$E$2 -> 58 | C7: ='Stats (i3)'!$C$2 -> 59 | D7: =B7/C7 -> 0.98305085
A8: ='Stats (i4)'!$A$2 -> v8.0 (i4) | B8: ='Stats (i4)'!$E$2 -> 48 | C8: ='Stats (i4)'!$C$2 -> 70 | D8: =B8/C8 -> 0.68571429
A9: ='Stats (i5)'!$A$2 -> v8.0 (i5) | B9: ='Stats (i5)'!$E$2 -> 50.5 | C9: ='Stats (i5)'!$C$2 -> 59.5 | D9: =B9/C9 -> 0.8487395
A10: ='Stats (i6)'!$A$2 -> v8.0 (i6) | B10: ='Stats (i6)'!$E$2 -> 37 | C10: ='Stats (i6)'!$C$2 -> 37 | D10: =B10/C10 -> 1
A11: ='Stats (i7)'!$A$2 -> v8.0 (i7) | B11: ='Stats (i7)'!$E$2 -> 22.5 | C11: ='Stats (i7)'!$C$2 -> 69.5 | D11: =B11/C11 -> 0.32374101
A12: ='Stats (i8)'!$A$2 -> v8.0 (i8) | B12: ='Stats (i8)'!$E$2 -> 13 | C12: ='Stats (i8)'!$C$2 -> 37 | D12: =B12/C12 -> 0.35135135
A14: Total | B14: =SUM(B5:B13) -> 306.75 | C14: =SUM(C5:C13) -> 421 | D14: =B14/C14 -> 0.72862233

Sheet Stats (i1)
A1: Increment Name | B1: Total Story Points In Scope | C1: Total Man Days | D1: Estimated Velocity | E1: Total Story Points Delivered | F1: Actual Velocity | I1: Date | J1: Man Days (Today) | K1: Man Days (Cumulative) | L1: Story Points (Est Cumulative) | M1: Story Points (Actual Today) | N1: Story Points (Actual Cumulative)
A2: v8.0 (i1) | B2: {=SUM(Summary!H3:H204*IF(Summary!I3:I204=A2,1,0))} -> 30.75 | C2: =SUM(J2:J16) -> 29 | D2: =B2/C2 -> 1.0603448 | E2: =N16 -> 30.75 | F2: =E2/C2 -> 1.0603448 | H2: Week 1 | I2: 40203 | J2: 1 | K2: =J2 -> 1 | L2: =K2*$D$2 -> 1.0603448 | M2: {=SUM(Summary!$H$3:$H$204*IF(Summary!I$3:I$204=A$2,1,0)*IF(Summary!K$3:K$204=I2,1,0))} -> 0 | N2: =M2 -> 0 | P2: =IF(Summary!I3='Stats (i1)'!$A$2,Summary!H3,0) -> 0
I3: =I2+1 -> 40204 | J3: 1 | K3: =J3+K2 -> 2 | L3: =K3*$D$2 -> 2.1206897 | M3: {=SUM(Summary!$H$3:$H$204*IF(Summary!I$3:I$204=A$2,1,0)*IF(Summary!K$3:K$204=I3,1,0))} -> 2 | N3: =N2+M3 -> 2 | P3: =IF(Summary!I4='Stats (i1)'!$A$2,Summary!H4,0) -> 0
I4: =I3+1 -> 40205 | J4: 1 | K4: =J4+K3 -> 3 | L4: =K4*$D$2 -> 3.1810345 | M4: {=SUM(Summary!$H$3:$H$204*IF(Summary!I$3:I$204=A$2,1,0)*IF(Summary!K$3:K$204=I4,1,0))} -> 3.75 | N4: =N3+M4 -> 5.75 | P4: =IF(Summary!I5='Stats (i1)'!$A$2,Summary!H5,0) -> 0
I5: =I4+1 -> 40206 | J5: 1 | K5: =J5+K4 -> 4 | L5: =K5*$D$2 -> 4.2413793 | M5: {=SUM(Summary!$H$3:$H$204*IF(Summary!I$3:I$204=A$2,1,0)*IF(Summary!K$3:K$204=I5,1,0))} -> 0.5 | N5: =N4+M5 -> 6.25 | P5: =IF(Summary!I6='Stats (i1)'!$A$2,Summary!H6,0) -> 0
I6: =I5+1 -> 40207 | J6: 1 | K6: =J6+K5 -> 5 | L6: =K6*$D$2 -> 5.3017241 | M6: {=SUM(Summary!$H$3:$H$204*IF(Summary!I$3:I$204=A$2,1,0)*IF(Summary!K$3:K$204=I6,1,0))} -> 2 | N6: =N5+M6 -> 8.25 | P6: =IF(Summary!I7='Stats (i1)'!$A$2,Summary!H7,0) -> 0
H7: Week 2 | I7: =I6+3 -> 40210 | J7: 0 | K7: =J7+K6 -> 5 | L7: =K7*$D$2 -> 5.3017241 | M7: {=SUM(Summary!$H$3:$H$204*IF(Summary!I$3:I$204=A$2,1,0)*IF(Summary!K$3:K$204=I7,1,0))} -> 0 | N7: =N6+M7 -> 8.25 | P7: =IF(Summary!I8='Stats (i1)'!$A$2,Summary!H8,0) -> 0
I8: =I7+1 -> 40211 | J8: 0 | K8: =J8+K7 -> 5 | L8: =K8*$D$2 -> 5.3017241 | M8: {=SUM(Summary!$H$3:$H$204*IF(Summary!I$3:I$204=A$2,1,0)*IF(Summary!K$3:K$204=I8,1,0))} -> 0 | N8: =N7+M8 -> 8.25 | P8: =IF(Summary!I9='Stats (i1)'!$A$2,Summary!H9,0) -> 0
I9: =I8+1 -> 40212 | J9: 3 | K9: =J9+K8 -> 8 | L9: =K9*$D$2 -> 8.4827586 | M9: {=SUM(Summary!$H$3:$H$204*IF(Summary!I$3:I$204=A$2,1,0)*IF(Summary!K$3:K$204=I9,1,0))} -> 0 | N9: =N8+M9 -> 8.25 | P9: =IF(Summary!I10='Stats (i1)'!$A$2,Summary!H10,0) -> 0
I10: =I9+1 -> 40213 | J10: 3 | K10: =J10+K9 -> 11 | L10: =K10*$D$2 -> 11.663793 | M10: {=SUM(Summary!$H$3:$H$204*IF(Summary!I$3:I$204=A$2,1,0)*IF(Summary!K$3:K$204=I10,1,0))} -> 5 | N10: =N9+M10 -> 13.25 | P10: =IF(Summary!I11='Stats (i1)'!$A$2,Summary!H11,0) -> 0
I11: =I10+1 -> 40214 | J11: 3 | K11: =J11+K10 -> 14 | L11: =K11*$D$2 -> 14.844828 | M11: {=SUM(Summary!$H$3:$H$204*IF(Summary!I$3:I$204=A$2,1,0)*IF(Summary!K$3:K$204=I11,1,0))} -> 0 | N11: =N10+M11 -> 13.25 | P11: =IF(Summary!I12='Stats (i1)'!$A$2,Summary!H12,0) -> 0
H12: Week 3 | I12: =I11+3 -> 40217 | J12: 3 | K12: =J12+K11 -> 17 | L12: =K12*$D$2 -> 18.025862 | M12: {=SUM(Summary!$H$3:$H$204*IF(Summary!I$3:I$204=A$2,1,0)*IF(Summary!K$3:K$204=I12,1,0))} -> 2 | N12: =N11+M12 -> 15.25 | P12: =IF(Summary!I13='Stats (i1)'!$A$2,Summary!H13,0) -> 2
I13: =I12+1 -> 40218 | J13: 3 | K13: =J13+K12 -> 20 | L13: =K13*$D$2 -> 21.206897 | M13: {=SUM(Summary!$H$3:$H$204*IF(Summary!I$3:I$204=A$2,1,0)*IF(Summary!K$3:K$204=I13,1,0))} -> 0 | N13: =N12+M13 -> 15.25 | P13: =IF(Summary!I14='Stats (i1)'!$A$2,Summary!H14,0) -> 2
I14: =I13+1 -> 40219 | J14: 3 | K14: =J14+K13 -> 23 | L14: =K14*$D$2 -> 24.387931 | M14: {=SUM(Summary!$H$3:$H$204*IF(Summary!I$3:I$204=A$2,1,0)*IF(Summary!K$3:K$204=I14,1,0))} -> 5 | N14: =N13+M14 -> 20.25 | P14: =IF(Summary!I15='Stats (i1)'!$A$2,Summary!H15,0) -> 0.5
I15: =I14+1 -> 40220 | J15: 3 | K15: =J15+K14 -> 26 | L15: =K15*$D$2 -> 27.568966 | M15: {=SUM(Summary!$H$3:$H$204*IF(Summary!I$3:I$204=A$2,1,0)*IF(Summary!K$3:K$204=I15,1,0))} -> 2.5 | N15: =N14+M15 -> 22.75 | P15: =IF(Summary!I16='Stats (i1)'!$A$2,Summary!H16,0) -> 0.25
I16: =I15+1 -> 40221 | J16: 3 | K16: =J16+K15 -> 29 | L16: =K16*$D$2 -> 30.75 | M16: {=SUM(Summary!$H$3:$H$204*IF(Summary!I$3:I$204=A$2,1,0)*IF(Summary!K$3:K$204=I16,1,0))} -> 8 | N16: =N15+M16 -> 30.75 | P16: =IF(Summary!I17='Stats (i1)'!$A$2,Summary!H17,0) -> 2
P17: =IF(Summary!I18='Stats (i1)'!$A$2,Summary!H18,0) -> 0.5
P18: =IF(Summary!I19='Stats (i1)'!$A$2,Summary!H19,0) -> 0.5
P19: =IF(Summary!I20='Stats (i1)'!$A$2,Summary!H20,0) -> 0.25
P20: =IF(Summary!I21='Stats (i1)'!$A$2,Summary!H21,0) -> 0.25
P21: =IF(Summary!I22='Stats (i1)'!$A$2,Summary!H22,0) -> 0

Sheet Stats (i2)
A1: Increment Name | B1: Total Story Points In Scope | C1: Total Man Days | D1: Estimated Velocity | E1: Total Story Points Delivered | F1: Actual Velocity | I1: Date | J1: Man Days (Today) | K1: Man Days (Cumulative) | L1: Story Points (Est Cumulative) | M1: Story Points (Actual Today) | N1: Story Points (Actual Cumulative)
A2: v8.0 (i2) | B2: {=SUM(Summary!H3:H204*IF(Summary!I3:I204=A2,1,0))} -> 47 | C2: =SUM(J2:J17) -> 60 | D2: =B2/C2 -> 0.78333333 | E2: =N17 -> 47 | F2: =E2/C2 -> 0.78333333 | H2: Week 1 | I2: 40224 | J2: 0 | K2: =J2 -> 0 | L2: =K2*$D$2 -> 0 | M2: {=SUM(Summary!$H$3:$H$204*IF(Summary!I$3:I$204=A$2,1,0)*IF(Summary!K$3:K$204=I2,1,0))} -> 0 | N2: =M2 -> 0
I3: =I2+1 -> 40225 | J3: 2 | K3: =J3+K2 -> 2 | L3: =K3*$D$2 -> 1.5666667 | M3: {=SUM(Summary!$H$3:$H$204*IF(Summary!I$3:I$204=A$2,1,0)*IF(Summary!K$3:K$204=I3,1,0))} -> 0 | N3: =N2+M3 -> 0
I4: =I3+1 -> 40226 | J4: 4 | K4: =J4+K3 -> 6 | L4: =K4*$D$2 -> 4.7 | M4: {=SUM(Summary!$H$3:$H$204*IF(Summary!I$3:I$204=A$2,1,0)*IF(Summary!K$3:K$204=I4,1,0))} -> 0.5 | N4: =N3+M4 -> 0.5
I5: =I4+1 -> 40227 | J5: 4 | K5: =J5+K4 -> 10 | L5: =K5*$D$2 -> 7.8333333 | M5: {=SUM(Summary!$H$3:$H$204*IF(Summary!I$3:I$204=A$2,1,0)*IF(Summary!K$3:K$204=I5,1,0))} -> 2 | N5: =N4+M5 -> 2.5
I6: =I5+1 -> 40228 | J6: 4 | K6: =J6+K5 -> 14 | L6: =K6*$D$2 -> 10.966667 | M6: {=SUM(Summary!$H$3:$H$204*IF(Summary!I$3:I$204=A$2,1,0)*IF(Summary!K$3:K$204=I6,1,0))} -> 0 | N6: =N5+M6 -> 2.5
H7: Week 2 | I7: =I6+3 -> 40231 | J7: 5 | K7: =J7+K6 -> 19 | L7: =K7*$D$2 -> 14.883333 | M7: {=SUM(Summary!$H$3:$H$204*IF(Summary!I$3:I$204=A$2,1,0)*IF(Summary!K$3:K$204=I7,1,0))} -> 0.5 | N7: =N6+M7 -> 3
I8: =I7+1 -> 40232 | J8: 5 | K8: =J8+K7 -> 24 | L8: =K8*$D$2 -> 18.8 | M8: {=SUM(Summary!$H$3:$H$204*IF(Summary!I$3:I$204=A$2,1,0)*IF(Summary!K$3:K$204=I8,1,0))} -> 7 | N8: =N7+M8 -> 10
I9: =I8+1 -> 40233 | J9: 5 | K9: =J9+K8 -> 29 | L9: =K9*$D$2 -> 22.716667 | M9: {=SUM(Summary!$H$3:$H$204*IF(Summary!I$3:I$204=A$2,1,0)*IF(Summary!K$3:K$204=I9,1,0))} -> 6 | N9: =N8+M9 -> 16
I10: =I9+1 -> 40234 | J10: 5 | K10: =J10+K9 -> 34 | L10: =K10*$D$2 -> 26.633333 | M10: {=SUM(Summary!$H$3:$H$204*IF(Summary!I$3:I$204=A$2,1,0)*IF(Summary!K$3:K$204=I10,1,0))} -> 9 | N10: =N9+M10 -> 25
I11: =I10+1 -> 40235 | J11: 5 | K11: =J11+K10 -> 39 | L11: =K11*$D$2 -> 30.55 | M11: {=SUM(Summary!$H$3:$H$204*IF(Summary!I$3:I$204=A$2,1,0)*IF(Summary!K$3:K$204=I11,1,0))} -> 0 | N11: =N10+M11 -> 25
H12: Week 3 | I12: =I11+3 -> 40238 | J12: 4 | K12: =J12+K11 -> 43 | L12: =K12*$D$2 -> 33.683333 | M12: {=SUM(Summary!$H$3:$H$204*IF(Summary!I$3:I$204=A$2,1,0)*IF(Summary!K$3:K$204=I12,1,0))} -> 2 | N12: =N11+M12 -> 27
I13: =I12+1 -> 40239 | J13: 4 | K13: =J13+K12 -> 47 | L13: =K13*$D$2 -> 36.816667 | M13: {=SUM(Summary!$H$3:$H$204*IF(Summary!I$3:I$204=A$2,1,0)*IF(Summary!K$3:K$204=I13,1,0))} -> 2 | N13: =N12+M13 -> 29
I14: =I13+1 -> 40240 | J14: 4 | K14: =J14+K13 -> 51 | L14: =K14*$D$2 -> 39.95 | M14: {=SUM(Summary!$H$3:$H$204*IF(Summary!I$3:I$204=A$2,1,0)*IF(Summary!K$3:K$204=I14,1,0))} -> 0 | N14: =N13+M14 -> 29
I15: =I14+1 -> 40241 | J15: 4 | K15: =J15+K14 -> 55 | L15: =K15*$D$2 -> 43.083333 | M15: {=SUM(Summary!$H$3:$H$204*IF(Summary!I$3:I$204=A$2,1,0)*IF(Summary!K$3:K$204=I15,1,0))} -> 8 | N15: =N14+M15 -> 37
I16: =I15+1 -> 40242 | J16: 4 | K16: =J16+K15 -> 59 | L16: =K16*$D$2 -> 46.216667 | M16: {=SUM(Summary!$H$3:$H$204*IF(Summary!I$3:I$204=A$2,1,0)*IF(Summary!K$3:K$204=I16,1,0))} -> 6 | N16: =N15+M16 -> 43
H17: Week 4 | I17: =I16+3 -> 40245 | J17: 1 | K17: =J17+K16 -> 60 | L17: =K17*$D$2 -> 47 | M17: {=SUM(Summary!$H$3:$H$204*IF(Summary!I$3:I$204=A$2,1,0)*IF(Summary!K$3:K$204=I17,1,0))} -> 4 | N17: =N16+M17 -> 47

Sheet Stats (i3)
A1: Increment Name | B1: Total Story Points In Scope | C1: Total Man Days | D1: Estimated Velocity | E1: Total Story Points Delivered | F1: Actual Velocity | I1: Date | J1: Man Days (Today) | K1: Man Days (Cumulative) | L1: Story Points (Est Cumulative) | M1: Story Points (Actual Today) | N1: Story Points (Actual Cumulative) | P1: Chris | Q1: Richard | R1: Tom | S1: Des | T1: Niall
A2: v8.0 (i3) | B2: {=SUM(Summary!H3:H204*IF(Summary!I3:I204=A2,1,0))} -> 58 | C2: =SUM(J2:J18) -> 59 | D2: =B2/C2 -> 0.98305085 | E2: =N18 -> 58 | F2: =E2/C2 -> 0.98305085 | H2: Week 1 | I2: 40245 | J2: =SUM(P2:T2) -> 4 | K2: =J2 -> 4 | L2: =K2*$D$2 -> 3.9322034 | M2: {=SUM(Summary!$H$3:$H$204*IF(Summary!I$3:I$204=A$2,1,0)*IF(Summary!K$3:K$204=I2,1,0))} -> 0 | N2: =M2 -> 0 | P2: 1 | Q2: 0 | R2: 1 | S2: 2
C3: aim for | D3: 0.8 | I3: =I2+1 -> 40246 | J3: =SUM(P3:T3) -> 3 | K3: =J3+K2 -> 7 | L3: =K3*$D$2 -> 6.8813559 | M3: {=SUM(Summary!$H$3:$H$204*IF(Summary!I$3:I$204=A$2,1,0)*IF(Summary!K$3:K$204=I3,1,0))} -> 0 | N3: =N2+M3 -> 0 | Q3: 1 | R3: 1 | S3: 1
D4: =C2*D3 -> 47.2 | I4: =I3+1 -> 40247 | J4: =SUM(P4:T4) -> 3 | K4: =J4+K3 -> 10 | L4: =K4*$D$2 -> 9.8305085 | M4: {=SUM(Summary!$H$3:$H$204*IF(Summary!I$3:I$204=A$2,1,0)*IF(Summary!K$3:K$204=I4,1,0))} -> 0 | N4: =N3+M4 -> 0 | Q4: 1 | R4: 1 | S4: 1
I5: =I4+1 -> 40248 | J5: =SUM(P5:T5) -> 3 | K5: =J5+K4 -> 13 | L5: =K5*$D$2 -> 12.779661 | M5: {=SUM(Summary!$H$3:$H$204*IF(Summary!I$3:I$204=A$2,1,0)*IF(Summary!K$3:K$204=I5,1,0))} -> 0 | N5: =N4+M5 -> 0 | Q5: 1 | R5: 1 | S5: 1
I6: =I5+1 -> 40249 | J6: =SUM(P6:T6) -> 3 | K6: =J6+K5 -> 16 | L6: =K6*$D$2 -> 15.728814 | M6: {=SUM(Summary!$H$3:$H$204*IF(Summary!I$3:I$204=A$2,1,0)*IF(Summary!K$3:K$204=I6,1,0))} -> 0 | N6: =N5+M6 -> 0 | Q6: 1 | R6: 1 | S6: 1
H7: Week 2 | I7: =I6+3 -> 40252 | J7: =SUM(P7:T7) -> 6 | K7: =J7+K6 -> 22 | L7: =K7*$D$2 -> 21.627119 | M7: {=SUM(Summary!$H$3:$H$204*IF(Summary!I$3:I$204=A$2,1,0)*IF(Summary!K$3:K$204=I7,1,0))} -> 0 | N7: =N6+M7 -> 0 | P7: 1 | Q7: 1 | R7: 1 | S7: 2 | T7: 1
I8: =I7+1 -> 40253 | J8: =SUM(P8:T8) -> 5 | K8: =J8+K7 -> 27 | L8: =K8*$D$2 -> 26.542373 | M8: {=SUM(Summary!$H$3:$H$204*IF(Summary!I$3:I$204=A$2,1,0)*IF(Summary!K$3:K$204=I8,1,0))} -> 5.5 | N8: =N7+M8 -> 5.5 | P8: 1 | Q8: 1 | R8: 1 | S8: 1 | T8: 1
I9: =I8+1 -> 40254 | J9: =SUM(P9:T9) -> 5 | K9: =J9+K8 -> 32 | L9: =K9*$D$2 -> 31.457627 | M9: {=SUM(Summary!$H$3:$H$204*IF(Summary!I$3:I$204=A$2,1,0)*IF(Summary!K$3:K$204=I9,1,0))} -> 6 | N9: =N8+M9 -> 11.5 | P9: 1 | Q9: 1 | R9: 1 | S9: 1 | T9: 1
I10: =I9+1 -> 40255 | J10: =SUM(P10:T10) -> 5 | K10: =J10+K9 -> 37 | L10: =K10*$D$2 -> 36.372881 | M10: {=SUM(Summary!$H$3:$H$204*IF(Summary!I$3:I$204=A$2,1,0)*IF(Summary!K$3:K$204=I10,1,0))} -> 3 | N10: =N9+M10 -> 14.5 | P10: 1 | Q10: 1 | R10: 1 | S10: 1 | T10: 1
I11: =I10+1 -> 40256 | J11: =SUM(P11:T11) -> 4 | K11: =J11+K10 -> 41 | L11: =K11*$D$2 -> 40.305085 | M11: {=SUM(Summary!$H$3:$H$204*IF(Summary!I$3:I$204=A$2,1,0)*IF(Summary!K$3:K$204=I11,1,0))} -> 8 | N11: =N10+M11 -> 22.5 | P11: 1 | Q11: 1 | R11: 1 | S11: 1
H12: Week 3 | I12: =I11+3 -> 40259 | J12: =SUM(P12:T12) -> 4 | K12: =J12+K11 -> 45 | L12: =K12*$D$2 -> 44.237288 | M12: {=SUM(Summary!$H$3:$H$204*IF(Summary!I$3:I$204=A$2,1,0)*IF(Summary!K$3:K$204=I12,1,0))} -> 0 | N12: =N11+M12 -> 22.5 | P12: 1 | Q12: 1 | R12: 1 | S12: 1
I13: =I12+1 -> 40260 | J13: =SUM(P13:T13) -> 5 | K13: =J13+K12 -> 50 | L13: =K13*$D$2 -> 49.152542 | M13: {=SUM(Summary!$H$3:$H$204*IF(Summary!I$3:I$204=A$2,1,0)*IF(Summary!K$3:K$204=I13,1,0))} -> 17.5 | N13: =N12+M13 -> 40 | P13: 1 | Q13: 1 | R13: 1 | S13: 1 | T13: 1
I14: =I13+1 -> 40261 | J14: =SUM(P14:T14) -> 4 | K14: =J14+K13 -> 54 | L14: =K14*$D$2 -> 53.084746 | M14: {=SUM(Summary!$H$3:$H$204*IF(Summary!I$3:I$204=A$2,1,0)*IF(Summary!K$3:K$204=I14,1,0))} -> 2 | N14: =N13+M14 -> 42 | P14: 1 | Q14: 1 | R14: 1 | T14: 1
I15: =I14+1 -> 40262 | J15: =SUM(P15:T15) -> 4 | K15: =J15+K14 -> 58 | L15: =K15*$D$2 -> 57.016949 | M15: {=SUM(Summary!$H$3:$H$204*IF(Summary!I$3:I$204=A$2,1,0)*IF(Summary!K$3:K$204=I15,1,0))} -> 1 | N15: =N14+M15 -> 43 | P15: 1 | Q15: 1 | R15: 1 | T15: 1
I16: =I15+1 -> 40263 | J16: =SUM(P16:T16) -> 0 | K16: =J16+K15 -> 58 | L16: =K16*$D$2 -> 57.016949 | M16: {=SUM(Summary!$H$3:$H$204*IF(Summary!I$3:I$204=A$2,1,0)*IF(Summary!K$3:K$204=I16,1,0))} -> 3 | N16: =N15+M16 -> 46
H17: Week 4 | I17: =I16+3 -> 40266 | J17: =SUM(P17:T17) -> 0 | K17: =J17+K16 -> 58 | L17: =K17*$D$2 -> 57.016949 | M17: {=SUM(Summary!$H$3:$H$204*IF(Summary!I$3:I$204=A$2,1,0)*IF(Summary!K$3:K$204=I17,1,0))} -> 0 | N17: =N16+M17 -> 46
I18: =I17+1 -> 40267 | J18: =SUM(P18:T18) -> 1 | K18: =J18+K17 -> 59 | L18: =K18*$D$2 -> 58 | M18: {=SUM(Summary!$H$3:$H$204*IF(Summary!I$3:I$204=A$2,1,0)*IF(Summary!K$3:K$204=I18,1,0))} -> 12 | N18: =N17+M18 -> 58 | R18: 1

Sheet Stats (i4)
A1: Increment Name | B1: Total Story Points In Scope | C1: Total Man Days | D1: Estimated Velocity | E1: Total Story Points Delivered | F1: Actual Velocity | I1: Date | J1: Man Days (Today) | K1: Man Days (Cumulative) | L1: Story Points (Est Cumulative) | M1: Story Points (Actual Today) | N1: Story Points (Actual Cumulative) | P1: Chris | Q1: Richard | R1: Tom | S1: Des | T1: Niall
A2: v8.0 (i4) | B2: {=SUM(Summary!H3:H204*IF(Summary!I3:I204=A2,1,0))} -> 48 | C2: =SUM(J2:J20) -> 70 | D2: =B2/C2 -> 0.68571429 | E2: =N20 -> 48 | F2: =E2/C2 -> 0.68571429 | H2: Week 1 | I2: 40266 | J2: =SUM(P2:T2) -> 0 | K2: =J2 -> 0 | L2: =K2*$D$2 -> 0 | M2: {=SUM(Summary!$H$3:$H$204*IF(Summary!I$3:I$204=A$2,1,0)*IF(Summary!K$3:K$204=I2,1,0))} -> 0 | N2: =M2 -> 0 | P2: 0 | Q2: 0 | R2: 0 | S2: 0 | T2: 0
C3: aim for | D3: 0.75 | I3: =I2+1 -> 40267 | J3: =SUM(P3:T3) -> 3 | K3: =J3+K2 -> 3 | L3: =K3*$D$2 -> 2.0571429 | M3: {=SUM(Summary!$H$3:$H$204*IF(Summary!I$3:I$204=A$2,1,0)*IF(Summary!K$3:K$204=I3,1,0))} -> 0.5 | N3: =N2+M3 -> 0.5 | P3: 1 | Q3: 1 | R3: 0 | S3: 1 | T3: 0
D4: =C2*D3 -> 52.5 | I4: =I3+1 -> 40268 | J4: =SUM(P4:T4) -> 4 | K4: =J4+K3 -> 7 | L4: =K4*$D$2 -> 4.8 | M4: {=SUM(Summary!$H$3:$H$204*IF(Summary!I$3:I$204=A$2,1,0)*IF(Summary!K$3:K$204=I4,1,0))} -> 1 | N4: =N3+M4 -> 1.5 | P4: 1 | Q4: 1 | R4: 1 | S4: 1 | T4: 0
I5: =I4+1 -> 40269 | J5: =SUM(P5:T5) -> 4 | K5: =J5+K4 -> 11 | L5: =K5*$D$2 -> 7.5428571 | M5: {=SUM(Summary!$H$3:$H$204*IF(Summary!I$3:I$204=A$2,1,0)*IF(Summary!K$3:K$204=I5,1,0))} -> 3 | N5: =N4+M5 -> 4.5 | P5: 1 | Q5: 1 | R5: 1 | S5: 1 | T5: 0
I6: =I5+1 -> 40270 | J6: =SUM(P6:T6) -> 0 | K6: =J6+K5 -> 11 | L6: =K6*$D$2 -> 7.5428571 | M6: {=SUM(Summary!$H$3:$H$204*IF(Summary!I$3:I$204=A$2,1,0)*IF(Summary!K$3:K$204=I6,1,0))} -> 0 | N6: =N5+M6 -> 4.5 | P6: 0 | Q6: 0 | R6: 0 | S6: 0 | T6: 0
H7: Week 2 | I7: =I6+3 -> 40273 | J7: =SUM(P7:T7) -> 0 | K7: =J7+K6 -> 11 | L7: =K7*$D$2 -> 7.5428571 | M7: {=SUM(Summary!$H$3:$H$204*IF(Summary!I$3:I$204=A$2,1,0)*IF(Summary!K$3:K$204=I7,1,0))} -> 0 | N7: =N6+M7 -> 4.5 | P7: 0 | Q7: 0 | R7: 0 | S7: 0 | T7: 0
I8: =I7+1 -> 40274 | J8: =SUM(P8:T8) -> 5 | K8: =J8+K7 -> 16 | L8: =K8*$D$2 -> 10.971429 | M8: {=SUM(Summary!$H$3:$H$204*IF(Summary!I$3:I$204=A$2,1,0)*IF(Summary!K$3:K$204=I8,1,0))} -> 0 | N8: =N7+M8 -> 4.5 | P8: 1 | Q8: 1 | R8: 1 | S8: 1 | T8: 1
I9: =I8+1 -> 40275 | J9: =SUM(P9:T9) -> 5 | K9: =J9+K8 -> 21 | L9: =K9*$D$2 -> 14.4 | M9: {=SUM(Summary!$H$3:$H$204*IF(Summary!I$3:I$204=A$2,1,0)*IF(Summary!K$3:K$204=I9,1,0))} -> 2 | N9: =N8+M9 -> 6.5 | P9: 1 | Q9: 1 | R9: 1 | S9: 1 | T9: 1
I10: =I9+1 -> 40276 | J10: =SUM(P10:T10) -> 5 | K10: =J10+K9 -> 26 | L10: =K10*$D$2 -> 17.828571 | M10: {=SUM(Summary!$H$3:$H$204*IF(Summary!I$3:I$204=A$2,1,0)*IF(Summary!K$3:K$204=I10,1,0))} -> 0 | N10: =N9+M10 -> 6.5 | P10: 1 | Q10: 1 | R10: 1 | S10: 1 | T10: 1
I11: =I10+1 -> 40277 | J11: =SUM(P11:T11) -> 7 | K11: =J11+K10 -> 33 | L11: =K11*$D$2 -> 22.628571 | M11: {=SUM(Summary!$H$3:$H$204*IF(Summary!I$3:I$204=A$2,1,0)*IF(Summary!K$3:K$204=I11,1,0))} -> 1.5 | N11: =N10+M11 -> 8 | P11: 1 | Q11: 2 | R11: 1 | S11: 2 | T11: 1
H12: Week 3 | I12: =I11+3 -> 40280 | J12: =SUM(P12:T12) -> 5 | K12: =J12+K11 -> 38 | L12: =K12*$D$2 -> 26.057143 | M12: {=SUM(Summary!$H$3:$H$204*IF(Summary!I$3:I$204=A$2,1,0)*IF(Summary!K$3:K$204=I12,1,0))} -> 0 | N12: =N11+M12 -> 8 | P12: 1 | Q12: 1 | R12: 1 | S12: 1 | T12: 1
I13: =I12+1 -> 40281 | J13: =SUM(P13:T13) -> 5 | K13: =J13+K12 -> 43 | L13: =K13*$D$2 -> 29.485714 | M13: {=SUM(Summary!$H$3:$H$204*IF(Summary!I$3:I$204=A$2,1,0)*IF(Summary!K$3:K$204=I13,1,0))} -> 5 | N13: =N12+M13 -> 13 | P13: 1 | Q13: 1 | R13: 1 | S13: 1 | T13: 1
I14: =I13+1 -> 40282 | J14: =SUM(P14:T14) -> 5 | K14: =J14+K13 -> 48 | L14: =K14*$D$2 -> 32.914286 | M14: {=SUM(Summary!$H$3:$H$204*IF(Summary!I$3:I$204=A$2,1,0)*IF(Summary!K$3:K$204=I14,1,0))} -> 3 | N14: =N13+M14 -> 16 | P14: 1 | Q14: 1 | R14: 1 | S14: 1 | T14: 1
I15: =I14+1 -> 40283 | J15: =SUM(P15:T15) -> 5 | K15: =J15+K14 -> 53 | L15: =K15*$D$2 -> 36.342857 | M15: {=SUM(Summary!$H$3:$H$204*IF(Summary!I$3:I$204=A$2,1,0)*IF(Summary!K$3:K$204=I15,1,0))} -> 2 | N15: =N14+M15 -> 18 | P15: 1 | Q15: 1 | R15: 1 | S15: 1 | T15: 1
I16: =I15+1 -> 40284 | J16: =SUM(P16:T16) -> 7 | K16: =J16+K15 -> 60 | L16: =K16*$D$2 -> 41.142857 | M16: {=SUM(Summary!$H$3:$H$204*IF(Summary!I$3:I$204=A$2,1,0)*IF(Summary!K$3:K$204=I16,1,0))} -> 12 | N16: =N15+M16 -> 30 | P16: 1 | Q16: 2 | R16: 1 | S16: 2 | T16: 1
H17: Week 4 | I17: =I16+3 -> 40287 | J17: =SUM(P17:T17) -> 5 | K17: =J17+K16 -> 65 | L17: =K17*$D$2 -> 44.571429 | M17: {=SUM(Summary!$H$3:$H$204*IF(Summary!I$3:I$204=A$2,1,0)*IF(Summary!K$3:K$204=I17,1,0))} -> 3 | N17: =N16+M17 -> 33 | P17: 1 | Q17: 1 | R17: 1 | S17: 1 | T17: 1
I18: =I17+1 -> 40288 | J18: =SUM(P18:T18) -> 3 | K18: =J18+K17 -> 68 | L18: =K18*$D$2 -> 46.628571 | M18: {=SUM(Summary!$H$3:$H$204*IF(Summary!I$3:I$204=A$2,1,0)*IF(Summary!K$3:K$204=I18,1,0))} -> 6 | N18: =N17+M18 -> 39 | P18: 0 | Q18: 0 | R18: 1 | S18: 1 | T18: 1
I19: =I18+1 -> 40289 | J19: =SUM(P19:T19) -> 1.5 | K19: =J19+K18 -> 69.5 | L19: =K19*$D$2 -> 47.657143 | M19: {=SUM(Summary!$H$3:$H$204*IF(Summary!I$3:I$204=A$2,1,0)*IF(Summary!K$3:K$204=I19,1,0))} -> 6 | N19: =N18+M19 -> 45 | P19: 0 | Q19: 0 | R19: 1 | S19: 0 | T19: 0.5
I20: =I19+1 -> 40290 | J20: =SUM(P20:T20) -> 0.5 | K20: =J20+K19 -> 70 | L20: =K20*$D$2 -> 48 | M20: {=SUM(Summary!$H$3:$H$204*IF(Summary!I$3:I$204=A$2,1,0)*IF(Summary!K$3:K$204=I20,1,0))} -> 3 | N20: =N19+M20 -> 48 | P20: 0 | Q20: 0 | R20: 0.5 | S20: 0 | T20: 0

Sheet Stats (i5)
A1: Increment Name | B1: Total Story Points In Scope | C1: Total Man Days | D1: Estimated Velocity | E1: Total Story Points Delivered | F1: Actual Velocity | I1: Date | J1: Man Days (Today) | K1: Man Days (Cumulative) | L1: Story Points (Est Cumulative) | M1: Story Points (Actual Today) | N1: Story Points (Actual Cumulative) | P1: Chris | Q1: Richard | R1: Tom | S1: Des | T1: Niall
A2: v8.0 (i5) | B2: {=SUM(Summary!H3:H204*IF(Summary!I3:I204=A2,1,0))} -> 50.5 | C2: =SUM(J2:J23) -> 59.5 | D2: =B2/C2 -> 0.8487395 | E2: =N23 -> 50.5 | F2: =E2/C2 -> 0.8487395 | H2: Week 1 | I2: 40287 | J2: =SUM(P2:T2) -> 0 | K2: =J2 -> 0 | L2: =K2*$D$2 -> 0 | M2: {=SUM(Summary!$H$3:$H$204*IF(Summary!I$3:I$204=A$2,1,0)*IF(Summary!K$3:K$204=I2,1,0))} -> 0 | N2: =M2 -> 0 | P2: 0 | Q2: 0 | R2: 0 | S2: 0 | T2: 0
C3: aim for | D3: 0.75 | I3: =I2+1 -> 40288 | J3: =SUM(P3:T3) -> 2 | K3: =J3+K2 -> 2 | L3: =K3*$D$2 -> 1.697479 | M3: {=SUM(Summary!$H$3:$H$204*IF(Summary!I$3:I$204=A$2,1,0)*IF(Summary!K$3:K$204=I3,1,0))} -> 0 | N3: =N2+M3 -> 0 | P3: 1 | Q3: 1 | R3: 0 | S3: 0 | T3: 0
D4: =C2*D3 -> 44.625 | I4: =I3+1 -> 40289 | J4: =SUM(P4:T4) -> 3.5 | K4: =J4+K3 -> 5.5 | L4: =K4*$D$2 -> 4.6680672 | M4: {=SUM(Summary!$H$3:$H$204*IF(Summary!I$3:I$204=A$2,1,0)*IF(Summary!K$3:K$204=I4,1,0))} -> 0 | N4: =N3+M4 -> 0 | P4: 1 | Q4: 1 | R4: 0 | S4: 1 | T4: 0.5
I5: =I4+1 -> 40290 | J5: =SUM(P5:T5) -> 4.5 | K5: =J5+K4 -> 10 | L5: =K5*$D$2 -> 8.487395 | M5: {=SUM(Summary!$H$3:$H$204*IF(Summary!I$3:I$204=A$2,1,0)*IF(Summary!K$3:K$204=I5,1,0))} -> 1 | N5: =N4+M5 -> 1 | P5: 1 | Q5: 1 | R5: 0.5 | S5: 1 | T5: 1
I6: =I5+1 -> 40291 | J6: =SUM(P6:T6) -> 4.5 | K6: =J6+K5 -> 14.5 | L6: =K6*$D$2 -> 12.306723 | M6: {=SUM(Summary!$H$3:$H$204*IF(Summary!I$3:I$204=A$2,1,0)*IF(Summary!K$3:K$204=I6,1,0))} -> 4 | N6: =N5+M6 -> 5 | P6: 0.5 | Q6: 1.5 | R6: 0.5 | S6: 1.5 | T6: 0.5
H7: Week 2 | I7: =I6+3 -> 40294 | J7: =SUM(P7:T7) -> 3 | K7: =J7+K6 -> 17.5 | L7: =K7*$D$2 -> 14.852941 | M7: {=SUM(Summary!$H$3:$H$204*IF(Summary!I$3:I$204=A$2,1,0)*IF(Summary!K$3:K$204=I7,1,0))} -> 1 | N7: =N6+M7 -> 6 | P7: 1 | Q7: 1 | R7: 1 | S7: 0 | T7: 0
I8: =I7+1 -> 40295 | J8: =SUM(P8:T8) -> 2.5 | K8: =J8+K7 -> 20 | L8: =K8*$D$2 -> 16.97479 | M8: {=SUM(Summary!$H$3:$H$204*IF(Summary!I$3:I$204=A$2,1,0)*IF(Summary!K$3:K$204=I8,1,0))} -> 5.5 | N8: =N7+M8 -> 11.5 | P8: 0.5 | Q8: 1 | R8: 1 | S8: 0 | T8: 0
I9: =I8+1 -> 40296 | J9: =SUM(P9:T9) -> 3.5 | K9: =J9+K8 -> 23.5 | L9: =K9*$D$2 -> 19.945378 | M9: {=SUM(Summary!$H$3:$H$204*IF(Summary!I$3:I$204=A$2,1,0)*IF(Summary!K$3:K$204=I9,1,0))} -> 1 | N9: =N8+M9 -> 12.5 | P9: 1 | Q9: 1 | R9: 1 | S9: 0 | T9: 0.5
I10: =I9+1 -> 40297 | J10: =SUM(P10:T10) -> 4 | K10: =J10+K9 -> 27.5 | L10: =K10*$D$2 -> 23.340336 | M10: {=SUM(Summary!$H$3:$H$204*IF(Summary!I$3:I$204=A$2,1,0)*IF(Summary!K$3:K$204=I10,1,0))} -> 4 | N10: =N9+M10 -> 16.5 | P10: 1 | Q10: 1 | R10: 1 | S10: 0 | T10: 1
I11: =I10+1 -> 40298 | J11: =SUM(P11:T11) -> 5 | K11: =J11+K10 -> 32.5 | L11: =K11*$D$2 -> 27.584034 | M11: {=SUM(Summary!$H$3:$H$204*IF(Summary!I$3:I$204=A$2,1,0)*IF(Summary!K$3:K$204=I11,1,0))} -> 4.5 | N11: =N10+M11 -> 21 | P11: 1 | Q11: 2 | R11: 1 | S11: 0 | T11: 1
H12: Week 3 | I12: =I11+3 -> 40301 | J12: =SUM(P12:T12) -> 0 | K12: =J12+K11 -> 32.5 | L12: =K12*$D$2 -> 27.584034 | M12: {=SUM(Summary!$H$3:$H$204*IF(Summary!I$3:I$204=A$2,1,0)*IF(Summary!K$3:K$204=I12,1,0))} -> 0 | N12: =N11+M12 -> 21 | P12: 0 | Q12: 0 | R12: 0 | S12: 0 | T12: 0
I13: =I12+1 -> 40302 | J13: =SUM(P13:T13) -> 2 | K13: =J13+K12 -> 34.5 | L13: =K13*$D$2 -> 29.281513 | M13: {=SUM(Summary!$H$3:$H$204*IF(Summary!I$3:I$204=A$2,1,0)*IF(Summary!K$3:K$204=I13,1,0))} -> 0 | N13: =N12+M13 -> 21 | P13: 0 | Q13: 0 | R13: 1 | S13: 1 | T13: 0
I14: =I13+1 -> 40303 | J14: =SUM(P14:T14) -> 2.5 | K14: =J14+K13 -> 37 | L14: =K14*$D$2 -> 31.403361 | M14: {=SUM(Summary!$H$3:$H$204*IF(Summary!I$3:I$204=A$2,1,0)*IF(Summary!K$3:K$204=I14,1,0))} -> 4.5 | N14: =N13+M14 -> 25.5 | P14: 0 | Q14: 0 | R14: 1 | S14: 1 | T14: 0.5
I15: =I14+1 -> 40304 | J15: =SUM(P15:T15) -> 3 | K15: =J15+K14 -> 40 | L15: =K15*$D$2 -> 33.94958 | M15: {=SUM(Summary!$H$3:$H$204*IF(Summary!I$3:I$204=A$2,1,0)*IF(Summary!K$3:K$204=I15,1,0))} -> 0 | N15: =N14+M15 -> 25.5 | P15: 0 | Q15: 0 | R15: 1 | S15: 1 | T15: 1
I16: =I15+1 -> 40305 | J16: =SUM(P16:T16) -> 4 | K16: =J16+K15 -> 44 | L16: =K16*$D$2 -> 37.344538 | M16: {=SUM(Summary!$H$3:$H$204*IF(Summary!I$3:I$204=A$2,1,0)*IF(Summary!K$3:K$204=I16,1,0))} -> 2 | N16: =N15+M16 -> 27.5 | P16: 0 | Q16: 0 | R16: 1 | S16: 2 | T16: 1
H17: Week 4 | I17: =I16+3 -> 40308 | J17: =SUM(P17:T17) -> 3 | K17: =J17+K16 -> 47 | L17: =K17*$D$2 -> 39.890756 | M17: {=SUM(Summary!$H$3:$H$204*IF(Summary!I$3:I$204=A$2,1,0)*IF(Summary!K$3:K$204=I17,1,0))} -> 5 | N17: =N16+M17 -> 32.5 | P17: 1 | Q17: 0 | R17: 0 | S17: 1 | T17: 1
I18: =I17+1 -> 40309 | J18: =SUM(P18:T18) -> 3 | K18: =J18+K17 -> 50 | L18: =K18*$D$2 -> 42.436975 | M18: {=SUM(Summary!$H$3:$H$204*IF(Summary!I$3:I$204=A$2,1,0)*IF(Summary!K$3:K$204=I18,1,0))} -> 0 | N18: =N17+M18 -> 32.5 | P18: 1 | Q18: 0 | R18: 0 | S18: 1 | T18: 1
I19: =I18+1 -> 40310 | J19: =SUM(P19:T19) -> 3 | K19: =J19+K18 -> 53 | L19: =K19*$D$2 -> 44.983193 | M19: {=SUM(Summary!$H$3:$H$204*IF(Summary!I$3:I$204=A$2,1,0)*IF(Summary!K$3:K$204=I19,1,0))} -> 3 | N19: =N18+M19 -> 35.5 | P19: 1 | Q19: 0 | R19: 0 | S19: 1 | T19: 1
I20: =I19+1 -> 40311 | J20: =SUM(P20:T20) -> 3 | K20: =J20+K19 -> 56 | L20: =K20*$D$2 -> 47.529412 | M20: {=SUM(Summary!$H$3:$H$204*IF(Summary!I$3:I$204=A$2,1,0)*IF(Summary!K$3:K$204=I20,1,0))} -> 5 | N20: =N19+M20 -> 40.5 | P20: 1 | Q20: 0 | R20: 0 | S20: 1 | T20: 1
I21: =I20+1 -> 40312 | J21: =SUM(P21:T21) -> 2.5 | K21: =J21+K20 -> 58.5 | L21: =K21*$D$2 -> 49.651261 | M21: {=SUM(Summary!$H$3:$H$204*IF(Summary!I$3:I$204=A$2,1,0)*IF(Summary!K$3:K$204=I21,1,0))} -> 8.5 | N21: =N20+M21 -> 49 | P21: 1 | Q21: 0 | R21: 0 | S21: 1 | T21: 0.5
H22: Week 5 | I22: =I21+3 -> 40315 | J22: =SUM(P22:T22) -> 0 | K22: =J22+K21 -> 58.5 | L22: =K22*$D$2 -> 49.651261 | M22: {=SUM(Summary!$H$3:$H$204*IF(Summary!I$3:I$204=A$2,1,0)*IF(Summary!K$3:K$204=I22,1,0))} -> 0 | N22: =N21+M22 -> 49 | P22: 0 | Q22: 0 | R22: 0 | S22: 0 | T22: 0
I23: =I22+1 -> 40316 | J23: =SUM(P23:T23) -> 1 | K23: =J23+K22 -> 59.5 | L23: =K23*$D$2 -> 50.5 | M23: {=SUM(Summary!$H$3:$H$204*IF(Summary!I$3:I$204=A$2,1,0)*IF(Summary!K$3:K$204=I23,1,0))} -> 1.5 | N23: =N22+M23 -> 50.5 | P23: 1 | Q23: 0 | R23: 0 | S23: 0 | T23: 0

Sheet Stats (i6)
A1: Increment Name | B1: Total Story Points In Scope | C1: Total Man Days | D1: Estimated Velocity | E1: Total Story Points Delivered | F1: Actual Velocity | I1: Date | J1: Man Days (Today) | K1: Man Days (Cumulative) | L1: Story Points (Est Cumulative) | M1: Story Points (Actual Today) | N1: Story Points (Actual Cumulative) | P1: Chris | Q1: Richard | R1: Tom | S1: Des | T1: Niall
A2: v8.0 (i6) | B2: {=SUM(Summary!H3:H204*IF(Summary!I3:I204=A2,1,0))} -> 37 | C2: =SUM(J2:J16) -> 37 | D2: =B2/C2 -> 1 | E2: =N16 -> 37 | F2: =E2/C2 -> 1 | H2: Week 1 | I2: 40315 | J2: =SUM(P2:T2) -> 0 | K2: =J2 -> 0 | L2: =K2*$D$2 -> 0 | M2: {=SUM(Summary!$H$3:$H$204*IF(Summary!I$3:I$204=A$2,1,0)*IF(Summary!K$3:K$204=I2,1,0))} -> 0 | N2: =M2 -> 0 | P2: 0 | Q2: 0 | R2: 0 | S2: 0 | T2: 0
C3: aim for | D3: 0.75 | I3: =I2+1 -> 40316 | J3: =SUM(P3:T3) -> 2 | K3: =J3+K2 -> 2 | L3: =K3*$D$2 -> 2 | M3: {=SUM(Summary!$H$3:$H$204*IF(Summary!I$3:I$204=A$2,1,0)*IF(Summary!K$3:K$204=I3,1,0))} -> 0.5 | N3: =N2+M3 -> 0.5 | P3: 0 | Q3: 1 | R3: 0 | S3: 1 | T3: 0
D4: =C2*D3 -> 27.75 | I4: =I3+1 -> 40317 | J4: =SUM(P4:T4) -> 3 | K4: =J4+K3 -> 5 | L4: =K4*$D$2 -> 5 | M4: {=SUM(Summary!$H$3:$H$204*IF(Summary!I$3:I$204=A$2,1,0)*IF(Summary!K$3:K$204=I4,1,0))} -> 1 | N4: =N3+M4 -> 1.5 | P4: 1 | Q4: 1 | R4: 0 | S4: 1 | T4: 0
I5: =I4+1 -> 40318 | J5: =SUM(P5:T5) -> 3 | K5: =J5+K4 -> 8 | L5: =K5*$D$2 -> 8 | M5: {=SUM(Summary!$H$3:$H$204*IF(Summary!I$3:I$204=A$2,1,0)*IF(Summary!K$3:K$204=I5,1,0))} -> 0 | N5: =N4+M5 -> 1.5 | P5: 1 | Q5: 1 | R5: 0 | S5: 1 | T5: 0
I6: =I5+1 -> 40319 | J6: =SUM(P6:T6) -> 2 | K6: =J6+K5 -> 10 | L6: =K6*$D$2 -> 10 | M6: {=SUM(Summary!$H$3:$H$204*IF(Summary!I$3:I$204=A$2,1,0)*IF(Summary!K$3:K$204=I6,1,0))} -> 2 | N6: =N5+M6 -> 3.5 | P6: 0 | Q6: 1 | R6: 0 | S6: 1 | T6: 0
H7: Week 2 | I7: =I6+3 -> 40322 | J7: =SUM(P7:T7) -> 2 | K7: =J7+K6 -> 12 | L7: =K7*$D$2 -> 12 | M7: {=SUM(Summary!$H$3:$H$204*IF(Summary!I$3:I$204=A$2,1,0)*IF(Summary!K$3:K$204=I7,1,0))} -> 0 | N7: =N6+M7 -> 3.5 | P7: 0 | Q7: 1 | R7: 0 | S7: 1 | T7: 0
I8: =I7+1 -> 40323 | J8: =SUM(P8:T8) -> 3 | K8: =J8+K7 -> 15 | L8: =K8*$D$2 -> 15 | M8: {=SUM(Summary!$H$3:$H$204*IF(Summary!I$3:I$204=A$2,1,0)*IF(Summary!K$3:K$204=I8,1,0))} -> 2 | N8: =N7+M8 -> 5.5 | P8: 1 | Q8: 1 | R8: 0 | S8: 1 | T8: 0
I9: =I8+1 -> 40324 | J9: =SUM(P9:T9) -> 3 | K9: =J9+K8 -> 18 | L9: =K9*$D$2 -> 18 | M9: {=SUM(Summary!$H$3:$H$204*IF(Summary!I$3:I$204=A$2,1,0)*IF(Summary!K$3:K$204=I9,1,0))} -> 2 | N9: =N8+M9 -> 7.5 | P9: 1 | Q9: 1 | R9: 0 | S9: 1 | T9: 0
I10: =I9+1 -> 40325 | J10: =SUM(P10:T10) -> 3 | K10: =J10+K9 -> 21 | L10: =K10*$D$2 -> 21 | M10: {=SUM(Summary!$H$3:$H$204*IF(Summary!I$3:I$204=A$2,1,0)*IF(Summary!K$3:K$204=I10,1,0))} -> 7 | N10: =N9+M10 -> 14.5 | P10: 1 | Q10: 1 | R10: 0 | S10: 1 | T10: 0
I11: =I10+1 -> 40326 | J11: =SUM(P11:T11) -> 4 | K11: =J11+K10 -> 25 | L11: =K11*$D$2 -> 25 | M11: {=SUM(Summary!$H$3:$H$204*IF(Summary!I$3:I$204=A$2,1,0)*IF(Summary!K$3:K$204=I11,1,0))} -> 5 | N11: =N10+M11 -> 19.5 | P11: 1 | Q11: 1 | R11: 0 | S11: 2 | T11: 0
H12: Week 3 | I12: =I11+3 -> 40329 | J12: =SUM(P12:T12) -> 0 | K12: =J12+K11 -> 25 | L12: =K12*$D$2 -> 25 | M12: {=SUM(Summary!$H$3:$H$204*IF(Summary!I$3:I$204=A$2,1,0)*IF(Summary!K$3:K$204=I12,1,0))} -> 0 | N12: =N11+M12 -> 19.5 | P12: 0 | Q12: 0 | R12: 0 | S12: 0 | T12: 0
I13: =I12+1 -> 40330 | J13: =SUM(P13:T13) -> 2 | K13: =J13+K12 -> 27 | L13: =K13*$D$2 -> 27 | M13: {=SUM(Summary!$H$3:$H$204*IF(Summary!I$3:I$204=A$2,1,0)*IF(Summary!K$3:K$204=I13,1,0))} -> 5 | N13: =N12+M13 -> 24.5 | P13: 1 | Q13: 1 | R13: 0 | S13: 0 | T13: 0
I14: =I13+1 -> 40331 | J14: =SUM(P14:T14) -> 4 | K14: =J14+K13 -> 31 | L14: =K14*$D$2 -> 31 | M14: {=SUM(Summary!$H$3:$H$204*IF(Summary!I$3:I$204=A$2,1,0)*IF(Summary!K$3:K$204=I14,1,0))} -> 5 | N14: =N13+M14 -> 29.5 | P14: 1 | Q14: 1 | R14: 1 | S14: 1 | T14: 0
I15: =I14+1 -> 40332 | J15: =SUM(P15:T15) -> 3 | K15: =J15+K14 -> 34 | L15: =K15*$D$2 -> 34 | M15: {=SUM(Summary!$H$3:$H$204*IF(Summary!I$3:I$204=A$2,1,0)*IF(Summary!K$3:K$204=I15,1,0))} -> 0 | N15: =N14+M15 -> 29.5 | P15: 1 | Q15: 1 | R15: 0 | S15: 1 | T15: 0
I16: =I15+1 -> 40333 | J16: =SUM(P16:T16) -> 3 | K16: =J16+K15 -> 37 | L16: =K16*$D$2 -> 37 | M16: {=SUM(Summary!$H$3:$H$204*IF(Summary!I$3:I$204=A$2,1,0)*IF(Summary!K$3:K$204=I16,1,0))} -> 7.5 | N16: =N15+M16 -> 37 | P16: 1 | Q16: 1 | R16: 0 | S16: 1 | T16: 0

Sheet Stats (i7)
A1: Increment Name | B1: Total Story Points In Scope | C1: Total Man Days | D1: Estimated Velocity | E1: Total Story Points Delivered | F1: Actual Velocity | I1: Date | J1: Man Days (Today) | K1: Man Days (Cumulative) | L1: Story Points (Est Cumulative) | M1: Story Points (Actual Today) | N1: Story Points (Actual Cumulative) | P1: Chris | Q1: Richard | R1: Tom | S1: Des | T1: Niall
A2: v8.0 (i7) | B2: {=SUM(Summary!H3:H204*IF(Summary!I3:I204=A2,1,0))} -> 22.5 | C2: =SUM(J2:J16) -> 69.5 | D2: =B2/C2 -> 0.32374101 | E2: =N16 -> 22.5 | F2: =E2/C2 -> 0.32374101 | H2: Week 1 | I2: 40336 | J2: =SUM(P2:T2) -> 2 | K2: =J2 -> 2 | L2: =K2*$D$2 -> 0.64748201 | M2: {=SUM(Summary!$H$3:$H$204*IF(Summary!I$3:I$204=A$2,1,0)*IF(Summary!K$3:K$204=I2,1,0))} -> 0 | N2: =M2 -> 0 | P2: 0 | Q2: 0 | R2: 1 | S2: 1 | T2: 0
C3: aim for | D3: 0.75 | I3: =I2+1 -> 40337 | J3: =SUM(P3:T3) -> 2.5 | K3: =J3+K2 -> 4.5 | L3: =K3*$D$2 -> 1.4568345 | M3: {=SUM(Summary!$H$3:$H$204*IF(Summary!I$3:I$204=A$2,1,0)*IF(Summary!K$3:K$204=I3,1,0))} -> 0 | N3: =N2+M3 -> 0 | P3: 0.5 | Q3: 0.5 | R3: 0.5 | S3: 0.5 | T3: 0.5
D4: =C2*D3 -> 52.125 | I4: =I3+1 -> 40338 | J4: =SUM(P4:T4) -> 5 | K4: =J4+K3 -> 9.5 | L4: =K4*$D$2 -> 3.0755396 | M4: {=SUM(Summary!$H$3:$H$204*IF(Summary!I$3:I$204=A$2,1,0)*IF(Summary!K$3:K$204=I4,1,0))} -> 0 | N4: =N3+M4 -> 0 | P4: 1 | Q4: 1 | R4: 1 | S4: 1 | T4: 1
I5: =I4+1 -> 40339 | J5: =SUM(P5:T5) -> 5 | K5: =J5+K4 -> 14.5 | L5: =K5*$D$2 -> 4.6942446 | M5: {=SUM(Summary!$H$3:$H$204*IF(Summary!I$3:I$204=A$2,1,0)*IF(Summary!K$3:K$204=I5,1,0))} -> 2 | N5: =N4+M5 -> 2 | P5: 1 | Q5: 1 | R5: 1 | S5: 1 | T5: 1
I6: =I5+1 -> 40340 | J6: =SUM(P6:T6) -> 5 | K6: =J6+K5 -> 19.5 | L6: =K6*$D$2 -> 6.3129496 | M6: {=SUM(Summary!$H$3:$H$204*IF(Summary!I$3:I$204=A$2,1,0)*IF(Summary!K$3:K$204=I6,1,0))} -> 1 | N6: =N5+M6 -> 3 | P6: 1 | Q6: 1 | R6: 1 | S6: 1 | T6: 1
H7: Week 2 | I7: =I6+3 -> 40343 | J7: =SUM(P7:T7) -> 5 | K7: =J7+K6 -> 24.5 | L7: =K7*$D$2 -> 7.9316547 | M7: {=SUM(Summary!$H$3:$H$204*IF(Summary!I$3:I$204=A$2,1,0)*IF(Summary!K$3:K$204=I7,1,0))} -> 0 | N7: =N6+M7 -> 3 | P7: 1 | Q7: 1 | R7: 1 | S7: 1 | T7: 1
I8: =I7+1 -> 40344 | J8: =SUM(P8:T8) -> 5 | K8: =J8+K7 -> 29.5 | L8: =K8*$D$2 -> 9.5503597 | M8: {=SUM(Summary!$H$3:$H$204*IF(Summary!I$3:I$204=A$2,1,0)*IF(Summary!K$3:K$204=I8,1,0))} -> 1.5 | N8: =N7+M8 -> 4.5 | P8: 1 | Q8: 1 | R8: 1 | S8: 1 | T8: 1
I9: =I8+1 -> 40345 | J9: =SUM(P9:T9) -> 5 | K9: =J9+K8 -> 34.5 | L9: =K9*$D$2 -> 11.169065 | M9: {=SUM(Summary!$H$3:$H$204*IF(Summary!I$3:I$204=A$2,1,0)*IF(Summary!K$3:K$204=I9,1,0))} -> 0 | N9: =N8+M9 -> 4.5 | P9: 1 | Q9: 1 | R9: 1 | S9: 1 | T9: 1
I10: =I9+1 -> 40346 | J10: =SUM(P10:T10) -> 5 | K10: =J10+K9 -> 39.5 | L10: =K10*$D$2 -> 12.78777 | M10: {=SUM(Summary!$H$3:$H$204*IF(Summary!I$3:I$204=A$2,1,0)*IF(Summary!K$3:K$204=I10,1,0))} -> 2 | N10: =N9+M10 -> 6.5 | P10: 1 | Q10: 1 | R10: 1 | S10: 1 | T10: 1
I11: =I10+1 -> 40347 | J11: =SUM(P11:T11) -> 5 | K11: =J11+K10 -> 44.5 | L11: =K11*$D$2 -> 14.406475 | M11: {=SUM(Summary!$H$3:$H$204*IF(Summary!I$3:I$204=A$2,1,0)*IF(Summary!K$3:K$204=I11,1,0))} -> 1.5 | N11: =N10+M11 -> 8 | P11: 0 | Q11: 2 | R11: 1 | S11: 1 | T11: 1
H12: Week 3 | I12: =I11+3 -> 40350 | J12: =SUM(P12:T12) -> 5 | K12: =J12+K11 -> 49.5 | L12: =K12*$D$2 -> 16.02518 | M12: {=SUM(Summary!$H$3:$H$204*IF(Summary!I$3:I$204=A$2,1,0)*IF(Summary!K$3:K$204=I12,1,0))} -> 0 | N12: =N11+M12 -> 8 | P12: 1 | Q12: 1 | R12: 1 | S12: 1 | T12: 1
I13: =I12+1 -> 40351 | J13: =SUM(P13:T13) -> 5 | K13: =J13+K12 -> 54.5 | L13: =K13*$D$2 -> 17.643885 | M13: {=SUM(Summary!$H$3:$H$204*IF(Summary!I$3:I$204=A$2,1,0)*IF(Summary!K$3:K$204=I13,1,0))} -> 1 | N13: =N12+M13 -> 9 | P13: 1 | Q13: 1 | R13: 1 | S13: 1 | T13: 1
I14: =I13+1 -> 40352 | J14: =SUM(P14:T14) -> 5 | K14: =J14+K13 -> 59.5 | L14: =K14*$D$2 -> 19.26259 | M14: {=SUM(Summary!$H$3:$H$204*IF(Summary!I$3:I$204=A$2,1,0)*IF(Summary!K$3:K$204=I14,1,0))} -> 8 | N14: =N13+M14 -> 17 | P14: 1 | Q14: 1 | R14: 1 | S14: 1 | T14: 1
I15: =I14+1 -> 40353 | J15: =SUM(P15:T15) -> 5 | K15: =J15+K14 -> 64.5 | L15: =K15*$D$2 -> 20.881295 | M15: {=SUM(Summary!$H$3:$H$204*IF(Summary!I$3:I$204=A$2,1,0)*IF(Summary!K$3:K$204=I15,1,0))} -> 0.5 | N15: =N14+M15 -> 17.5 | P15: 1 | Q15: 1 | R15: 1 | S15: 1 | T15: 1
I16: =I15+1 -> 40354 | J16: =SUM(P16:T16) -> 5 | K16: =J16+K15 -> 69.5 | L16: =K16*$D$2 -> 22.5 | M16: {=SUM(Summary!$H$3:$H$204*IF(Summary!I$3:I$204=A$2,1,0)*IF(Summary!K$3:K$204=I16,1,0))} -> 5 | N16: =N15+M16 -> 22.5 | P16: 1 | Q16: 1 | R16: 1 | S16: 1 | T16: 1

Sheet Stats (i8)
A1: Increment Name | B1: Total Story Points In Scope | C1: Total Man Days | D1: Estimated Velocity | E1: Total Story Points Delivered | F1: Actual Velocity | I1: Date | J1: Man Days (Today) | K1: Man Days (Cumulative) | L1: Story Points (Est Cumulative) | M1: Story Points (Actual Today) | N1: Story Points (Actual Cumulative) | P1: Chris | Q1: Richard | R1: Tom | S1: Des | T1: Niall
A2: v8.0 (i8) | B2: {=SUM(Summary!H3:H204*IF(Summary!I3:I204=A2,1,0))} -> 15 | C2: =SUM(J2:J19) -> 37 | D2: =B2/C2 -> 0.40540541 | E2: =N19 -> 13 | F2: =E2/C2 -> 0.35135135 | H2: Week 1 | I2: 40357 | J2: =SUM(P2:T2) -> 1 | K2: =J2 -> 1 | L2: =K2*$D$2 -> 0.40540541 | M2: {=SUM(Summary!$H$3:$H$204*IF(Summary!I$3:I$204=A$2,1,0)*IF(Summary!K$3:K$204=I2,1,0))} -> 0 | N2: =M2 -> 0 | P2: 0 | Q2: 0 | R2: 0 | S2: 1 | T2: 0
C3: aim for | D3: 0.75 | I3: =I2+1 -> 40358 | J3: =SUM(P3:T3) -> 4 | K3: =J3+K2 -> 5 | L3: =K3*$D$2 -> 2.027027 | M3: {=SUM(Summary!$H$3:$H$204*IF(Summary!I$3:I$204=A$2,1,0)*IF(Summary!K$3:K$204=I3,1,0))} -> 0 | N3: =N2+M3 -> 0 | P3: 1 | Q3: 1 | R3: 1 | S3: 1 | T3: 0
D4: =C2*D3 -> 27.75 | I4: =I3+1 -> 40359 | J4: =SUM(P4:T4) -> 4 | K4: =J4+K3 -> 9 | L4: =K4*$D$2 -> 3.6486486 | M4: {=SUM(Summary!$H$3:$H$204*IF(Summary!I$3:I$204=A$2,1,0)*IF(Summary!K$3:K$204=I4,1,0))} -> 1 | N4: =N3+M4 -> 1 | P4: 1 | Q4: 1 | R4: 1 | S4: 1 | T4: 0
I5: =I4+1 -> 40360 | J5: =SUM(P5:T5) -> 3 | K5: =J5+K4 -> 12 | L5: =K5*$D$2 -> 4.8648649 | M5: {=SUM(Summary!$H$3:$H$204*IF(Summary!I$3:I$204=A$2,1,0)*IF(Summary!K$3:K$204=I5,1,0))} -> 1 | N5: =N4+M5 -> 2 | P5: 1 | Q5: 1 | R5: 1 | S5: 0 | T5: 0
I6: =I5+1 -> 40361 | J6: =SUM(P6:T6) -> 2 | K6: =J6+K5 -> 14 | L6: =K6*$D$2 -> 5.6756757 | M6: {=SUM(Summary!$H$3:$H$204*IF(Summary!I$3:I$204=A$2,1,0)*IF(Summary!K$3:K$204=I6,1,0))} -> 0 | N6: =N5+M6 -> 2 | P6: 1 | Q6: 0 | R6: 1 | S6: 0 | T6: 0
