Workbook

Sheet Introduction
B1: Annual GDP and GDPR
B3: Quarterly GDP and GDPR | F3: SUMMARY PAGE
B5: Seasonally adjusted and annualised quarterly GDP and GDPR | F5: SUMMARY PAGE
B7: Year-on-Year Growth Rates per Sector | F7: Sector Ratings
B9: Seasonally adjusted and annualised quarterly Rates per Sector
B11: Yearly Provincial Contribution Rates per Sector
B13: Yearly Provincial Sector as a % of National Sector GDP
B15: Ethekwini Municipal Area GDP
B17: Msunduzi Municipal Area GDP
B19: Mthlatuze Municipal Area GDP
B21: Hibiscus Coast Municipal GDP
B23: Newcastle Municipal GDP | D23: Model Assumptions
B25: Comparitive Growth Rates | D25: Stable structural relationship between SA and KZN economy
B27: Comparitive Contribution Rates | D27: Stable relationship between GDP and Fuel Consumption
B29: KZN GDP and Provincial Government Budget | D29: Fuel Consumption per R1 GDP are location insensitive
B31: KZN Socio Economic Analysis
B32: KZN Economic Analysis

Sheet Summary
A1: SUMMARY PAGE
A3: Annual GDP and GDPR
A35: Quarterly GDP and GDPR
A103: Seasonally adjusted and annualised quarterly GDP and GDPR
A163: Ethekwini Municipal Area
A196: Msunduzi Municipal Area
A230: Mthlatuze Municipal Area
A266: Hibiscus Coast Municipal Area
A302: Newcastle Municipal Area

Sheet Sector Summary
A1: SUMMARY PAGE
A3: PLEASE TAKE NOTE
A4: BLACK = NON-SEASONAL ANNUAL RATE
A5: RED = SEASONAL ANNUAL RATE

Sheet Annual
A1: Annual GDP and GDPR
A3: SA – GDP by activity
A4: Constant 2005 prices - Rand million
A5: National Industry | B5: 1995 | C5: 1996 | D5: 1997 | E5: 1998 | F5: 1999 | G5: 2000 | H5: 2001 | I5: 2002 | J5: 2003 | K5: 2004 | L5: 2005 | M5: 2006 | N5: 2007 | O5: 2008 | P5: 2009 | Q5: 2010 | R5: 2011 | S5: 2012 | T5: 2013
A6: Primary Industries | B6: =SUM(B7:B8) -> 127206.68 | C6: =SUM(C7:C8) -> 132737.49 | D6: =SUM(D7:D8) -> 134732.09 | E6: =SUM(E7:E8) -> 132879.43 | F6: =SUM(F7:F8) -> 133396.86 | G6: =SUM(G7:G8) -> 133856.6 | H6: =SUM(H7:H8) -> 132609.54 | I6: =SUM(I7:I8) -> 135785.81 | ... T6: =SUM(T7:T8) -> 142490.08
A7: Agriculture, forestry and fishing | B7: 26405.124 | C7: 32742.354 | D7: 33037.035 | E7: 31286.072 | F7: 33225.809 | G7: 34787.422 | H7: 33639.437 | I7: 35826 | J7: 36070 | K7: 36380 | L7: 37402.2 | M7: 35359 | N7: 36301 | O7: 42143.138 | P7: 41454.14 | Q7: 41613.903 | R7: 41586.853 | S7: 42433.445 | T7: 43414.14
A8: Mining and quarrying | B8: 100801.55 | C8: 99995.14 | D8: 101695.06 | E8: 101593.36 | F8: 100171.06 | G8: 99069.174 | H8: 98970.105 | I8: 99959.806 | J8: 103354.82 | K8: 104915.26 | L8: 105991.9 | M8: 105364.26 | N8: 105335.68 | O8: 99395.847 | P8: 94057.359 | Q8: 99383.17 | R8: 99687.222 | S8: 96082.321 | T8: 99075.942
A9: Secondary Industries | B9: =SUM(B10:B12) -> 248296.2 | C9: =SUM(C10:C12) -> 254358.8 | D9: =SUM(D10:D12) -> 261763.46 | E9: =SUM(E10:E12) -> 257891.65 | F9: =SUM(F10:F12) -> 258636.33 | G9: =SUM(G10:G12) -> 277586.36 | H9: =SUM(H10:H12) -> 284951.66 | I9: =SUM(I10:I12) -> 293957 | ... T9: =SUM(T10:T12) -> 395262.28
A10: Manufacturing | B10: 196934.25 | C10: 199691.33 | D10: 205083 | E10: 204672.83 | F10: 205900.87 | G10: 222578.84 | H10: 229701.36 | I10: 236133 | J10: 232581 | K10: 243965 | L10: 259101 | M10: 275782.4 | N10: 290246 | O10: 297888.57 | P10: 267722.57 | Q10: 282508.71 | R10: 291785.14 | S10: 297808.31 | T10: 300050.43
A11: Electricity, gas and water | B11: 25843.26 | C11: 28634.332 | D11: 29751.071 | E11: 27876.753 | F11: 27737.369 | G11: 28597.228 | H11: 27539.13 | I11: 28503 | J11: 29344 | K11: 31335 | L11: 33010.2 | M11: 34139 | N11: 35294 | O11: 34195.636 | P11: 33711.906 | Q11: 34538.154 | R11: 35049.055 | S11: 34476.319 | T11: 34332.855
A12: Construction | B12: 25518.69 | C12: 26033.14 | D12: 26929.389 | E12: 25342.07 | F12: 24998.088 | G12: 26410.289 | H12: 27711.166 | I12: 29321 | J12: 31575 | K12: 34451 | L12: 38558 | M12: 42582 | N12: 48971 | O12: 53145.384 | P12: 57278.524 | Q12: 57706.903 | R12: 57869.458 | S12: 59206.362 | T12: 60879
A13: Tertiary industries | B13: =SUM(B14:B18) -> 636192.82 | C13: =SUM(C14:C18) -> 662878.91 | D13: =SUM(D14:D18) -> 679765.27 | E13: =SUM(E14:E18) -> 693351.13 | F13: =SUM(F14:F18) -> 719841.56 | G13: =SUM(G14:G18) -> 748200.15 | H13: =SUM(H14:H18) -> 774956.39 | I13: =SUM(I14:I18) -> 806527.2 | ... T13: =SUM(T14:T18) -> 1240201.3
A14: Wholesale & retail trade; hotels & restaurants | B14: 131650.34 | C14: 136521.41 | D14: 137067.49 | E14: 138849.37 | F14: 149401.92 | G14: 161503.48 | H14: 164572.04 | I14: 168357.2 | J14: 172845.2 | K14: 182175 | L14: 195012.2 | M14: 206636 | N14: 217607 | O14: 219749.14 | P14: 217073.92 | Q14: 225337.56 | R14: 235294.55 | S14: 244278.14 | T14: 249606.79
A15: Transport , storage and communication | B15: 74969.254 | C15: 79542.379 | D15: 85587.6 | E15: 90294.918 | F15: 94990.253 | G15: 102874.44 | H15: 108944.04 | I15: 118749 | J15: 126287 | K15: 132459 | L15: 139471.8 | M15: 146607 | N15: 156289 | O15: 162522.04 | P15: 163999.44 | Q15: 167313.42 | R15: 172530.12 | S15: 176699.46 | T15: 180108.46
A16: Finance, real estate and business services | B16: 174720 | C16: 186575.4 | D16: 195355.8 | E16: 199853 | F16: 210066.6 | G16: 216747.2 | H16: 234450.1 | I16: 249165 | J16: 261123 | K16: 279544 | L16: 295503.5 | M16: 324002 | N16: 349500.92 | O16: 375240.47 | P16: 378986.81 | Q16: 387188.66 | R16: 405479.22 | S16: 420473.37 | T16: 430597
A17: Personal services | B17: 63819.642 | C17: 65516.096 | D17: 65494.661 | E17: 69562.679 | F17: 72254.154 | G17: 75735.383 | H17: 77438.116 | I17: 79346 | J17: 83756 | K17: 85219 | L17: 88454.7 | M17: 93073 | N17: 98247 | O17: 102105.56 | P17: 101233.11 | Q17: 101670.85 | R17: 104025.73 | S17: 106180.87 | T17: 108045.05
A18: General government services | B18: 191033.58 | C18: 194723.63 | D18: 196259.72 | E18: 194791.17 | F18: 193128.63 | G18: 191339.64 | H18: 189552.09 | I18: 190910 | J18: 196193 | K18: 199947 | L18: 208560.8 | M18: 214947 | N18: 223284 | O18: 233416 | P18: 242542 | Q18: 250014 | R18: 260494 | S18: 267714 | T18: 271844
A19: All industries at basic prices | B19: =B13+B9+B6 -> 1011695.7 | C19: =C13+C9+C6 -> 1049975.2 | D19: =D13+D9+D6 -> 1076260.8 | E19: =E13+E9+E6 -> 1084122.2 | F19: =F13+F9+F6 -> 1111874.7 | G19: =G13+G9+G6 -> 1159643.1 | H19: =H13+H9+H6 -> 1192517.6 | I19: =I13+I9+I6 -> 1236270 | ... T19: =T13+T9+T6 -> 1777953.7
A20: Taxes less subsidies on products | B20: 133676.76 | C20: 140208.86 | D20: 144304.78 | E20: 142661.12 | F20: 141889.98 | G20: 144129.16 | H20: 146201.17 | I20: 150165 | J20: 154193 | K20: 161940 | L20: 170015 | M20: 180630 | N20: 190089 | O20: 194792 | P20: 188839 | Q20: 195733 | R20: 205542 | S20: 211091 | T20: 215479
A21: SA - GDP at constant 2005 prices | B21: =B19+B20 -> 1145372.5 | C21: =C19+C20 -> 1190184.1 | D21: =D19+D20 -> 1220565.6 | E21: =E19+E20 -> 1226783.3 | F21: =F19+F20 -> 1253764.7 | G21: =G19+G20 -> 1303772.3 | H21: =H19+H20 -> 1338718.8 | I21: =I19+I20 -> 1386435 | ... T21: =T19+T20 -> 1993432.7
A23: KZN – GDPR by activity
A24: Constant 2005 prices - Rand million
A25: Provincial Industry | B25: 1995 | C25: 1996 | D25: 1997 | E25: 1998 | F25: 1999 | G25: 2000 | H25: 2001 | I25: 2002 | J25: 2003 | K25: 2004 | L25: 2005 | M25: 2006 | N25: 2007 | O25: 2008 | P25: 2009 | Q25: 2010 | R25: 2011 | S25: 2012 | T25: 2013
A26: Primary Industries | B26: =B27+B28 -> 12647.433 | C26: =C27+C28 -> 15724.196 | D26: =D27+D28 -> 15757.65 | E26: =E27+E28 -> 15760.501 | F26: =F27+F28 -> 13821.738 | G26: 14059.846 | H26: 13804.539 | I26: 13819.258 | J26: 14560.827 | K26: 14670.86 | L26: 13796.857 | M26: 13726.996 | N26: 14230.05 | O26: 15530.125 | P26: 15243.988 | Q26: =SUM(Q27:Q28) -> 15537.976 | R26: =SUM(R27:R28) -> 15614.797 | S26: =SUM(S27:S28) -> 15988.264 | T26: =SUM(T27:T28) -> 16466.299
A27: Agriculture, forestry and fishing | B27: 8243.6494 | C27: 9590.1168 | D27: 9555.8073 | E27: 9642.4591 | F27: 9388.88 | G27: 9741.35 | H27: 9706.76 | I27: 10158.474 | J27: 10684.788 | K27: 10717 | L27: 10091.489 | M27: 10144.925 | N27: 10559.454 | O27: 12095.033 | P27: 11746.697 | Q27: 12023.463 | R27: 12148.83 | S27: 12455.255 | T27: =SUM(Quarterly!BV27:BY27) -> 12882.147
A28: Mining and quarrying | B28: 4403.7833 | C28: 6134.0795 | D28: 6201.8427 | E28: 6118.0414 | F28: 4432.8582 | G28: 4318.4962 | H28: 4097.7793 | I28: 3660.7832 | J28: 3875.7421 | K28: 3953.3719 | L28: 3705.9903 | M28: 3582.1283 | N28: 3671.407 | O28: 3431.4323 | P28: 3211.9769 | Q28: 3514.5131 | R28: 3465.9669 | S28: 3533.0086 | T28: =SUM(Quarterly!BV28:BY28) -> 3584.1511
A29: Secondary Industries | B29: =B30+B31+B32 -> 50300.616 | C29: =C30+C31+C32 -> 51439.133 | D29: =D30+D31+D32 -> 52980.98 | E29: =E30+E31+E32 -> 51933.881 | F29: =F30+F31+F32 -> 52382.09 | G29: 56563.711 | H29: 59380.107 | I29: 59989.937 | J29: 59093.765 | K29: 62217.716 | L29: 66446.722 | M29: 70391.388 | N29: 74568.824 | O29: 76572.692 | P29: 70148.665 | Q29: =SUM(Q30:Q32) -> 74297.62 | R29: =SUM(R30:R32) -> 76373.065 | S29: =SUM(S30:S32) -> 77717.658 | T29: =SUM(T30:T32) -> 78410.042
A30: Manufacturing | B30: 41206.6 | C30: 41926.886 | D30: 43038.36 | E30: 42844.617 | F30: 43531.509 | G30: 47270.843 | H30: 48677.683 | I30: 49960.634 | J30: 49502.968 | K30: 51829.694 | L30: 55026.96 | M30: 58348.48 | N30: 61440.731 | O30: 63013.372 | P30: 56740.803 | Q30: 60192.776 | R30: 62165.176 | S30: 63485.736 | T30: =SUM(Quarterly!BV30:BY30) -> 63959.502
A31: Electricity, gas and water | B31: 4495.2863 | C31: 4993.0969 | D31: 5165.0171 | E31: 4849.3541 | F31: 4852.2025 | G31: 5136.9116 | H31: 5128.9257 | I31: 5626.6256 | J31: 4979.0051 | K31: 5343.3901 | L31: 5691.2969 | M31: 5879.2136 | N31: 6075.1904 | O31: 5830.7275 | P31: 5602.3111 | Q31: 5669.0461 | R31: 5736.8007 | S31: 5547.3043 | T31: =SUM(Quarterly!BV31:BY31) -> 5508.4458
A32: Construction | B32: 4598.7298 | C32: 4519.1498 | D32: 4777.6035 | E32: 4239.9102 | F32: 3998.3783 | G32: 4155.9562 | H32: 5573.498 | I32: 4402.6768 | J32: 4611.7926 | K32: 5044.6319 | L32: 5728.5484 | M32: 6163.7935 | N32: 7052.9033 | O32: 7656.3255 | P32: 8298.9292 | Q32: 8435.798 | R32: 8471.0883 | S32: 8684.6185 | T32: =SUM(Quarterly!BV32:BY32) -> 8942.0946
A33: Tertiary industries | B33: =SUM(B34:B38) -> 99772.901 | C33: =SUM(C34:C38) -> 103962.56 | D33: =SUM(D34:D38) -> 105537.09 | E33: =SUM(E34:E38) -> 108436.23 | F33: =SUM(F34:F38) -> 111911.67 | G33: 116046.82 | H33: 121244.05 | I33: 126098.8 | J33: 132006.66 | K33: 137951.47 | L33: 147296.36 | M33: 155772.09 | N33: 165536.18 | O33: 172740.71 | P33: 174996.29 | Q33: =SUM(Q34:Q38) -> 180722.53 | R33: =SUM(R34:R38) -> 188235.78 | S33: =SUM(S34:S38) -> 193978.65 | T33: =SUM(T34:T38) -> 198221.68
A34: Wholesale & retail trade; hotels & restaurants | B34: 21355.843 | C34: 21835.713 | D34: 21956.732 | E34: 22150.158 | F34: 23734.656 | G34: 25691.399 | H34: 27698.397 | I34: 28376.888 | J34: 29361.146 | K34: 30957.43 | L34: 32959.681 | M34: 35070.016 | N34: 37031.186 | O34: 37423.088 | P34: 37446.864 | Q34: 39008.245 | R34: 40992.229 | S34: 42524.566 | T34: =SUM(Quarterly!BV34:BY34) -> 43728.354
A35: Transport , storage and communication | B35: 17467.023 | C35: 18247.31 | D35: 19261.839 | E35: 20134.14 | F35: 20849.208 | G35: 22194.91 | H35: 23152.354 | I35: 25318.289 | J35: 27088.303 | K35: 28301.562 | L35: 29975.763 | M35: 31534.57 | N35: 33783.704 | O35: 35198.833 | P35: 35759.306 | Q35: 36715.879 | R35: 37781.343 | S35: 38749.746 | T35: =SUM(Quarterly!BV35:BY35) -> 39414.538
A36: Finance, real estate and business services | B36: 24397.324 | C36: 26067.429 | D36: 27172.628 | E36: 27832.073 | F36: 29524.634 | G36: 29876.96 | H36: 31579.969 | I36: 33176.274 | J36: 35030.692 | K36: 37561.687 | L36: 41534.132 | M36: 44730.09 | N36: 48201.169 | O36: 51760.699 | P36: 52599.709 | Q36: 53885.893 | R36: 56479.573 | S36: 58367.887 | T36: =SUM(Quarterly!BV36:BY36) -> 59824.321
A37: Personal services | B37: 10462.035 | C37: 10733.983 | D37: 10723.031 | E37: 11390.053 | F37: 11811.006 | G37: 12366.988 | H37: 12655.308 | I37: 12960.485 | J37: 13682.568 | K37: 13924.515 | L37: 14394.744 | M37: 15158.467 | N37: 15993.348 | O37: 16596.258 | P37: 16592.493 | Q37: 16703.006 | R37: 17129.72 | S37: 17516.427 | T37: =SUM(Quarterly!BV37:BY37) -> 17865.338
A38: General government services | B38: 26090.676 | C38: 27078.126 | D38: 26422.865 | E38: 26929.808 | F38: 25992.162 | G38: 25916.567 | H38: 26158.024 | I38: 26266.861 | J38: 26844.074 | K38: 27206.323 | L38: 28431.677 | M38: 29278.956 | N38: 30470.367 | O38: 31970.944 | P38: 33217.019 | Q38: 34409.511 | R38: 35852.917 | S38: 36820.026 | T38: =SUM(Quarterly!BV38:BY38) -> 37389.131
A39: All industries at basic prices | B39: =B33+B29+B26 -> 162720.95 | C39: =C33+C29+C26 -> 171125.89 | D39: =D33+D29+D26 -> 174275.72 | E39: =E33+E29+E26 -> 176130.61 | F39: =F33+F29+F26 -> 178115.49 | G39: 186451.17 | H39: 194342.91 | I39: 199907.99 | J39: 205661.25 | K39: 214840.04 | L39: 227539.94 | M39: 239890.48 | N39: 254335.06 | O39: 264843.53 | P39: 260388.94 | Q39: =Q26+Q29+Q33 -> 270558.13 | R39: =R26+R29+R33 -> 280223.64 | S39: =S26+S29+S33 -> 287684.57 | T39: =T26+T29+T33 -> 293098.02
A40: Taxes less subsidies on products | B40: 21530.728 | C40: 22661.717 | D40: 23287.012 | E40: 23156.565 | F40: 22702.228 | G40: 23280.712 | H40: 24730.666 | I40: 24615.022 | J40: 25021.001 | K40: 26215.374 | L40: 27399.009 | M40: 29154.713 | N40: 30569.553 | O40: 31373.999 | P40: 30500.475 | Q40: 32059.683 | R40: 33164.225 | S40: 34497.679 | T40: =SUM(Quarterly!BV40:BY40) -> 34688.413
A41: KZN - GDPR at constant 2005 prices | B41: =B40+B39 -> 184251.68 | C41: =C40+C39 -> 193787.61 | D41: =D40+D39 -> 197562.74 | E41: =E40+E39 -> 199287.18 | F41: =F40+F39 -> 200817.72 | G41: 209731.89 | H41: 219073.58 | I41: 224523.01 | J41: 230682.27 | K41: 241055.47 | L41: 254938.58 | M41: 269045.17 | N41: 284904.87 | O41: 296224.5 | P41: 290947.35 | Q41: =Q39+Q40 -> 302617.81 | R41: =R39+R40 -> 313387.87 | S41: =S39+S40 -> 322182.25 | T41: =T39+T40 -> 327786.44
A43: Structure Relationship
...

Sheet Quarterly
A1: Quarterly GDP and GDPR
A3: SA – GDP by activity
A4: Constant 2005 prices - Rand million
A5: National Industry | B5: 1995q1 | C5: 1995q2 | D5: 1995q3 | E5: 1995q4 | F5: 1996q1 | G5: 1996q2 | H5: 1996q3 | I5: 1996q4 | J5: 1997q1 | K5: 1997q2 | L5: 1997q3 | M5: 1997q4 | N5: 1998q1 | O5: 1998q2 | P5: 1998q3 | Q5: 1998q4 | R5: 1999q1 | S5: 1999q2 | T5: 1999q3 | U5: 1999q4 | V5: 2000q1 | W5: 2000q2 | X5: 2000q3 | Y5: 2000q4 | Z5: 2001q1 | AA5: 2001q2 | AB5: 2001q3 | AC5: 2001q4 | AD5: 2002q1 | AE5: 2002q2 | AF5: 2002q3 | AG5: 2002q4 | AH5: 2003q1 | AI5: 2003q2 | AJ5: 2003q3 | AK5: 2003q4 | AL5: 2004q1 | AM5: 2004q2 | AN5: 2004q3 | AO5: 2004q4 | AP5: 2005q1 | AQ5: 2005q2 | AR5: 2005q3 | AS5: 2005q4 | AT5: 2006q1 | AU5: 2006q2 | AV5: 2006q3 | AW5: 2006q4 | AX5: 2007q1 | AY5: 2007q2 | AZ5: 2007q3 | BA5: 2007q4 | BB5: 2008q1 | BC5: 2008q2 | BD5: 2008q3 | BE5: 2008q4 | BF5: 2009q1 | BG5: 2009q2 | BH5: 2009q3 | BI5: 2009q4 | BJ5: 2010q1 | BK5: 2010q2 | BL5: 2010q3 | BM5: 2010q4 | BN5: 2011q1 | BO5: 2011q2 | BP5: 2011q3 | BQ5: 2011q4 | BR5: 2012q1 | BS5: 2012q2 | BT5: 2012q3 | BU5: 2012q4 | BV5: 2013q1 | BW5: 2013q2 | BX5: 2013q3 | BY5: 2013q4
A6: Primary Industries | B6: =SUM(B7:B8) -> 30258.8 | C6: =SUM(C7:C8) -> 32377.82 | D6: =SUM(D7:D8) -> 33293.89 | E6: =SUM(E7:E8) -> 31276.16 | F6: =SUM(F7:F8) -> 30465.08 | G6: =SUM(G7:G8) -> 37121.12 | H6: =SUM(H7:H8) -> 34049.1 | I6: =SUM(I7:I8) -> 31102.19 | ... BY6: =SUM(BY7:BY8) -> 32721.635
A7: Agriculture, forestry and fishing | B7: 5062.1 | C7: 7356.02 | D7: 7888 | E7: 6099 | F7: 5558.1 | G7: 12384.12 | H7: 8868.1 | I7: 5932.03 | J7: 6137.03 | K7: 12139 | L7: 8805 | M7: 5956 | N7: 5940 | O7: 11721.07 | P7: 8501 | Q7: 5124 | R7: 6517.96 | S7: 12954.96 | T7: 9061.22 | U7: 4691.67 | V7: 5537.12 | W7: 11101.1 | X7: 12376.1 | Y7: 5773.1 | Z7: 6153.1 | AA7: 12832.12 | AB7: 9836.12 | AC7: 4818.1 | AD7: 6730 | AE7: 14095 | AF7: 9261 | AG7: 5740 | AH7: 6181 | AI7: 15590 | AJ7: 9732 | AK7: 4567 | AL7: 6217 | AM7: 14145 | AN7: 10694 | AO7: 5324 | AP7: 7163.8 | AQ7: 13125.8 | AR7: 11715.8 | AS7: 5396.8 | AT7: 7085.25 | AU7: 11987.2 | AV7: 10591.3 | AW7: 5695.25 | AX7: 7315.25 | AY7: 12354.25 | AZ7: 10809.25 | BA7: 5822.25 | BB7: 8703.25 | BC7: 14401.25 | BD7: 12449.25 | BE7: 6589.39 | BF7: 8535.425 | BG7: 13896.321 | BH7: 12114.781 | BI7: 6907.613 | BJ7: 8686.153 | BK7: 14243.173 | BL7: 11909.646 | BM7: 6774.928 | BN7: 8524.77 | BO7: 14163.233 | BP7: 12022.434 | BQ7: 6876.413 | BR7: 8978.103 | BS7: 15041.18 | BT7: 11691.576 | BU7: 6722.582 | BV7: 9415 | BW7: 16059.28 | BX7: 11347 | BY7: 6592.86
A8: Mining and quarrying | B8: 25196.7 | C8: 25021.8 | D8: 25405.89 | E8: 25177.16 | F8: 24906.98 | G8: 24737 | H8: 25181 | I8: 25170.16 | J8: 24808.9 | K8: 25306 | L8: 25838 | M8: 25742.16 | N8: 25391.1 | O8: 25393.1 | P8: 25469 | Q8: 25340.16 | R8: 24818.9 | S8: 24945 | T8: 25190 | U8: 25217.16 | V8: 24545.02 | W8: 24844 | X8: 24830 | Y8: 24850.15 | Z8: 24393.95 | AA8: 24949 | AB8: 24964 | AC8: 24663.15 | AD8: 24272.1 | AE8: 24939.2 | AF8: 25304.2 | AG8: 25444.31 | AH8: 24976.66 | AI8: 25819 | AJ8: 26341 | AK8: 26218.16 | AL8: 26218.07 | AM8: 26148 | AN8: 26941 | AO8: 25608.19 | AP8: 27314.2 | AQ8: 26780.05 | AR8: 26435.75 | AS8: 25461.9 | AT8: 25829.3 | AU8: 26141.25 | AV8: 26338.25 | AW8: 27055.46 | AX8: 26386.46 | AY8: 26250 | AZ8: 26459 | BA8: 26240.22 | BB8: 24067.695 | BC8: 25313.695 | BD8: 24890.765 | BE8: 25123.695 | BF8: 22503.124 | BG8: 23592.386 | BH8: 23799.131 | BI8: 24162.719 | BJ8: 24643.346 | BK8: 23521.241 | BL8: 25355.421 | BM8: 25863.163 | BN8: 25030.861 | BO8: 25608.498 | BP8: 24409.997 | BQ8: 24637.864 | BR8: 22684.654 | BS8: 25284.901 | BT8: 24231.372 | BU8: 23881.392 | BV8: 23480.768 | BW8: 24586.21 | BX8: 24880.189 | BY8: 26128.775
A9: Secondary Industries | B9: =SUM(B10:B12) -> 59838.294 | C9: =SUM(C10:C12) -> 60951.914 | D9: =SUM(D10:D12) -> 64373.854 | E9: =SUM(E10:E12) -> 63132.141 | F9: =SUM(F10:F12) -> 61155.882 | G9: =SUM(G10:G12) -> 62054.545 | H9: =SUM(H10:H12) -> 65627.743 | I9: =SUM(I10:I12) -> 65520.633 | ... BY9: =SUM(BY10:BY12) -> 103470.04
A10: Manufacturing | B10: 47012.75 | C10: 47913.75 | D10: 51302.75 | E10: 50705 | F10: 48082.77 | G10: 48476.78 | H10: 51529 | I10: 51602.78 | J10: 48886 | K10: 50565 | L10: 53014 | M10: 52618 | N10: 49839.83 | O10: 50694 | P10: 52238 | Q10: 51901 | R10: 48787.87 | S10: 50065 | T10: 52918 | U10: 54130 | V10: 52235.84 | W10: 54092 | X10: 57401 | Y10: 58850 | Z10: 55589.68 | AA10: 56707.68 | AB10: 58319 | AC10: 59085 | AD10: 55853 | AE10: 57999 | AF10: 61089.4 | AG10: 61191.6 | AH10: 56905 | AI10: 57095 | AJ10: 59577 | AK10: 59004 | AL10: 57990 | AM10: 59585 | AN10: 63263 | AO10: 63127 | AP10: 60082.8 | AQ10: 63866.1 | AR10: 67716.1 | AS10: 67436 | AT10: 64270.2 | AU10: 67358.2 | AV10: 71460 | AW10: 72694 | AX10: 68753 | AY10: 71153 | AZ10: 74004 | BA10: 76336 | BB10: 70732.4 | BC10: 75966.4 | BD10: 77526.438 | BE10: 73663.33 | BF10: 63676.25 | BG10: 64777.98 | BH10: 69106.157 | BI10: 70162.182 | BJ10: 66216.616 | BK10: 70464.499 | BL10: 72845.894 | BM10: 72981.701 | BN10: 70096.904 | BO10: 71797.959 | BP10: 74585.281 | BQ10: 75304.996 | BR10: 70547.963 | BS10: 73218.038 | BT10: 76219.576 | BU10: 77822.734 | BV10: 70339.52 | BW10: 75088.639 | BX10: 75946.736 | BY10: 78675.531
A11: Electricity, gas and water | B11: 6403 | C11: 6528.26 | D11: 6634 | E11: 6278 | F11: 6526 | G11: 6953 | H11: 7530.6 | I11: 7624.73 | J11: 7238 | K11: 7506.07 | L11: 7602 | M11: 7405 | N11: 6851.4 | O11: 7016.75 | P11: 7067.6 | Q11: 6941 | R11: 6573.8 | S11: 6922.6 | T11: 7126.97 | U11: 7114 | V11: 6839.6 | W11: 7181.63 | X11: 7423 | Y11: 7153 | Z11: 6694 | AA11: 6876 | AB11: 7089.13 | AC11: 6880 | AD11: 6798 | AE11: 7124.4 | AF11: 7366.4 | AG11: 7214.2 | AH11: 7042 | AI11: 7319 | AJ11: 7563 | AK11: 7420 | AL11: 7468.4 | AM11: 7812.6 | AN11: 8128 | AO11: 7926 | AP11: 7862.2 | AQ11: 8221 | AR11: 8445 | AS11: 8482 | AT11: 8082.4 | AU11: 8492.4 | AV11: 8775.2 | AW11: 8789 | AX11: 8373.25 | AY11: 8739.25 | AZ11: 9126.25 | BA11: 9055.25 | BB11: 8136.5 | BC11: 8396.5 | BD11: 9045.5 | BE11: 8617.14 | BF11: 7969.214 | BG11: 8305.971 | BH11: 8754.956 | BI11: 8681.769 | BJ11: 8204.278 | BK11: 8525.336 | BL11: 8909.241 | BM11: 8899.296 | BN11: 8377.685 | BO11: 8714.789 | BP11: 9011.287 | BQ11: 8945.299 | BR11: 8339.539 | BS11: 8539.729 | BT11: 8874.6 | BU11: 8722.451 | BV11: 8112.638 | BW11: 8544.068 | BX11: 8954.6454 | BY11: 8721.504
A12: Construction | B12: 6422.544 | C12: 6509.904 | D12: 6437.104 | E12: 6149.141 | F12: 6547.112 | G12: 6624.765 | H12: 6568.143 | I12: 6293.123 | J12: 6674.916 | K12: 6715.36 | L12: 6636.09 | M12: 6903.022 | N12: 6480.615 | O12: 6318.006 | P12: 6142.888 | Q12: 6400.561 | R12: 6226.694 | S12: 6219.189 | T12: 6121.623 | U12: 6430.582 | V12: 6333.016 | W12: 6478.114 | X12: 6553.164 | Y12: 7045.996 | Z12: 6835.854 | AA12: 6892.142 | AB12: 6790.824 | AC12: 7192.345 | AD12: 7135 | AE12: 7142 | AF12: 7285 | AG12: 7759 | AH12: 7718 | AI12: 7719 | AJ12: 7860 | AK12: 8278 | AL12: 8203 | AM12: 8391 | AN12: 8709 | AO12: 9148 | AP12: 9169 | AQ12: 9427 | AR12: 9755 | AS12: 10207 | AT12: 10149 | AU12: 10403 | AV12: 10770 | AW12: 11260 | AX12: 11706 | AY12: 11835 | AZ12: 12111 | BA12: 13319 | BB12: 12860.1 | BC12: 13017.2 | BD12: 13344.08 | BE12: 13924 | BF12: 14024.88 | BG12: 14046.88 | BH12: 14299.88 | BI12: 14906.88 | BJ12: 14418 | BK12: 14261 | BL12: 14241 | BM12: 14786.9 | BN12: 14382.1 | BO12: 14314.1 | BP12: 14322.1 | BQ12: 14851.16 | BR12: 14567.1 | BS12: 14549.1 | BT12: 14708.1 | BU12: 15382.06 | BV12: 14865 | BW12: 14876 | BX12: 15065 | BY12: 16073
A13: Tertiary industries | B13: =SUM(B14:B18) -> 153604.77 | C13: =SUM(C14:C18) -> 155355.7 | D13: =SUM(D14:D18) -> 160579.76 | E13: =SUM(E14:E18) -> 166652.99 | F13: =SUM(F14:F18) -> 160373.11 | G13: =SUM(G14:G18) -> 162200.92 | H13: =SUM(H14:H18) -> 167002.95 | I13: =SUM(I14:I18) -> 173302.31 | ... BY13: =SUM(BY14:BY18) -> 321456.49
A14: Wholesale & retail trade; hotels & restaurants | B14: 30073.34 | C14: 30851 | D14: 32904 | E14: 37822 | F14: 31777.41 | G14: 32290 | H14: 33855 | I14: 38599 | J14: 32449.873 | K14: 32660.873 | L14: 33914.872 | M14: 38041.872 | N14: 32465.37 | O14: 33179 | P14: 34404 | Q14: 38801 | R14: 33899.92 | S14: 35209 | T14: 37235 | U14: 43058 | V14: 37121.14 | W14: 38512.14 | X14: 40140.2 | Y14: 45730 | Z14: 38628.26 | AA14: 39421.26 | AB14: 40506.26 | AC14: 46016.26 | AD14: 39112.8 | AE14: 40078.8 | AF14: 41609.8 | AG14: 47555.8 | AH14: 39758.1 | AI14: 40820.1 | AJ14: 43057 | AK14: 49210 | AL14: 41559 | AM14: 42792 | AN14: 44739 | AO14: 53085 | AP14: 44713.6 | AQ14: 45740.6 | AR14: 47897 | AS14: 56661 | AT14: 47122 | AU14: 48496 | AV14: 50913 | AW14: 60105 | AX14: 50059 | AY14: 51313 | AZ14: 53701 | BA14: 62534 | BB14: 52156.609 | BC14: 52318.119 | BD14: 53124.549 | BE14: 62149.863 | BF14: 51506.209 | BG14: 51223.484 | BH14: 53059.02 | BI14: 61285.207 | BJ14: 52037.182 | BK14: 53120.19 | BL14: 55521.891 | BM14: 64658.297 | BN14: 54224.274 | BO14: 55200.272 | BP14: 57967.38 | BQ14: 67902.624 | BR14: 56782.36 | BS14: 57493.337 | BT14: 59979.42 | BU14: 70023.023 | BV14: 58054.918 | BW14: 58890.277 | BX14: 61193.732 | BY14: 71467.867
A15: Transport , storage and communication | B15: 17874.6 | C15: 17916.65 | D15: 19388 | E15: 19790 | F15: 19268 | G15: 19181 | H15: 20490.38 | I15: 20603 | J15: 20408 | K15: 20599.6 | L15: 22022 | M15: 22558 | N15: 22050.8 | O15: 22140 | P15: 22920.12 | Q15: 23184 | R15: 22545 | S15: 23058.6 | T15: 24412.65 | U15: 24974 | V15: 24539 | W15: 25166.6 | X15: 26411.84 | Y15: 26757 | Z15: 25921.04 | AA15: 26414 | AB15: 27868 | AC15: 28741 | AD15: 28219 | AE15: 28976.6 | AF15: 30425.6 | AG15: 31127.8 | AH15: 30280 | AI15: 30872 | AJ15: 32080 | AK15: 33055 | AL15: 31536 | AM15: 32203 | AN15: 33963 | AO15: 34757 | AP15: 33324.9 | AQ15: 34034.9 | AR15: 35687 | AS15: 36425 | AT15: 34860 | AU15: 35709 | AV15: 37790 | AW15: 38248 | AX15: 37390 | AY15: 38228 | AZ15: 40002 | BA15: 40669 | BB15: 39017.254 | BC15: 39778.156 | BD15: 41545.39 | BE15: 42181.239 | BF15: 39881.66 | BG15: 40081.723 | BH15: 41692.247 | BI15: 42343.81 | BJ15: 40141.228 | BK15: 40893.445 | BL15: 42756.827 | BM15: 43521.92 | BN15: 41353.794 | BO15: 42233.84 | BP15: 44032.83 | BQ15: 44909.656 | BR15: 42585.497 | BS15: 43356.485 | BT15: 44995.333 | BU15: 45762.145 | BV15: 43369.448 | BW15: 44124.117 | BX15: 45926.782 | BY15: 46688.112
A16: Finance, real estate and business services | B16: 42556.1 | C16: 42973 | D16: 44240.3 | E16: 44950.6 | F16: 44425 | G16: 45833.1 | H16: 47500.3 | I16: 48817 | J16: 48114.8 | K16: 48886.8 | L16: 49171.8 | M16: 49182.4 | N16: 48536.6 | O16: 49922.3 | P16: 50635.3 | Q16: 50758.8 | R16: 51054.2 | S16: 52293 | T16: 53176.6 | U16: 53542.8 | V16: 52888.1 | W16: 53699.6 | X16: 54622 | Y16: 55537.5 | Z16: 56218.6 | AA16: 58088.5 | AB16: 59463.3 | AC16: 60679.7 | AD16: 62383 | AE16: 62225 | AF16: 61925 | AG16: 62632 | AH16: 65193 | AI16: 64824 | AJ16: 65121 | AK16: 65985 | AL16: 69261 | AM16: 69354 | AN16: 69721 | AO16: 71208 | AP16: 73169.1 | AQ16: 73288 | AR16: 73956 | AS16: 75091 | AT16: 79305 | AU16: 80254 | AV16: 81374 | AW16: 83069 | AX16: 86091 | AY16: 85714 | AZ16: 87185 | BA16: 90511 | BB16: 91562 | BC16: 92840 | BD16: 94186 | BE16: 96653 | BF16: 94300.9 | BG16: 94221.91 | BH16: 94319 | BI16: 96145 | BJ16: 95658.6 | BK16: 96321.06 | BL16: 96651 | BM16: 98558 | BN16: 99559.1 | BO16: 100356.1 | BP16: 101565.02 | BQ16: 103999 | BR16: 105061.1 | BS16: 104615.1 | BT16: 104333.1 | BU16: 106464.07 | BV16: 106799 | BW16: 108365 | BX16: 107820 | BY16: 107613
A17: Personal services | B17: 15489.027 | C17: 15927.348 | D17: 16210.662 | E17: 16192.586 | F17: 16382.948 | G17: 16318.07 | H17: 16403.519 | I17: 16411.555 | J17: 16232.787 | K17: 16416.974 | L17: 16551.23 | M17: 16293.67 | N17: 16752.634 | O17: 17240.631 | P17: 17763.096 | Q17: 17806.318 | R17: 17715.541 | S17: 17942.23 | T17: 18331.776 | U17: 18264.605 | V17: 18400 | W17: 18733 | X17: 19313.1 | Y17: 19289.287 | Z17: 19142.092 | AA17: 19234.897 | AB17: 19611.719 | AC17: 19449.408 | AD17: 19376.69 | AE17: 19614.329 | AF17: 20157.27 | AG17: 20197.711 | AH17: 20362 | AI17: 20836 | AJ17: 21469 | AK17: 21089 | AL17: 20771.6 | AM17: 21194.4 | AN17: 21649 | AO17: 21604 | AP17: 21793.2 | AQ17: 22005.2 | AR17: 22373.2 | AS17: 22283.1 | AT17: 23051 | AU17: 23178 | AV17: 23381 | AW17: 23463 | AX17: 24555 | AY17: 24843 | AZ17: 24839 | BA17: 24010 | BB17: 25606.5 | BC17: 26011.6 | BD17: 25841.6 | BE17: 24646.15 | BF17: 25224.428 | BG17: 25428.403 | BH17: 25450.317 | BI17: 25129.962 | BJ17: 25128.698 | BK17: 25503.328 | BL17: 25636.247 | BM17: 25402.577 | BN17: 26010.337 | BO17: 26168.561 | BP17: 26052.007 | BQ17: 25794.825 | BR17: 26428.081 | BS17: 26953.854 | BT17: 26792.118 | BU17: 26006.808 | BV17: 26937.594 | BW17: 27350.109 | BX17: 27264.835 | BY17: 26492.509
A18: General government services | B18: 47611.7 | C18: 47687.7 | D18: 47836.8 | E18: 47897.8 | F18: 48519.75 | G18: 48578.75 | H18: 48753.75 | I18: 48871.75 | J18: 48945 | K18: 48962 | L18: 49141 | M18: 49212 | N18: 48654.7 | O18: 48704.7 | P18: 48697.8 | Q18: 48733.8 | R18: 48267 | S18: 48347 | T18: 48320 | U18: 48195 | V18: 47824.25 | W18: 47893.3 | X18: 47873.3 | Y18: 47749.15 | Z18: 47533.75 | AA18: 47470.75 | AB18: 47303.75 | AC18: 47243.75 | AD18: 47144 | AE18: 47698 | AF18: 47955 | AG18: 48113 | AH18: 48264 | AI18: 48972 | AJ18: 49331 | AK18: 49626 | AL18: 49094 | AM18: 49848 | AN18: 50171 | AO18: 50834 | AP18: 51032 | AQ18: 52145 | AR18: 52604.9 | AS18: 52778.9 | AT18: 52881 | AU18: 53540 | AV18: 53892 | AW18: 54634 | AX18: 55106 | AY18: 55460 | AZ18: 56041 | BA18: 56677 | BB18: 57252 | BC18: 57900 | BD18: 58795 | BE18: 59469 | BF18: 59561 | BG18: 60608 | BH18: 60958 | BI18: 61415 | BJ18: 61217 | BK18: 62339 | BL18: 62802 | BM18: 63656 | BN18: 63511 | BO18: 64925 | BP18: 65495 | BQ18: 66563 | BR18: 65452 | BS18: 66643 | BT18: 67250 | BU18: 68369 | BV18: 66904 | BW18: 67806 | BX18: 67939 | BY18: 69195
A19: All industries at basic prices | B19: =B13+B9+B6 -> 243701.86 | C19: =C13+C9+C6 -> 248685.43 | D19: =D13+D9+D6 -> 258247.51 | E19: =E13+E9+E6 -> 261061.29 | F19: =F13+F9+F6 -> 251994.07 | G19: =G13+G9+G6 -> 261376.58 | H19: =H13+H9+H6 -> 266679.79 | I19: =I13+I9+I6 -> 269925.13 | ... BY19: =BY13+BY9+BY6 -> 457648.16
A20: Taxes less subsidies on products | B20: 33235.871 | C20: 33241.522 | D20: 33531.924 | E20: 33667.398 | F20: 34509.038 | G20: 34878.722 | H20: 35196.079 | I20: 35625.014 | J20: 35904.12 | K20: 36008.799 | L20: 36166.786 | M20: 36225.119 | N20: 35451.63 | O20: 35103.333 | P20: 35807.525 | Q20: 36298.649 | R20: 34779.415 | S20: 34720.163 | T20: 35829.062 | U20: 36561.295 | V20: 35228.343 | W20: 35286.01 | X20: 36444.759 | Y20: 37170.049 | Z20: 35800.585 | AA20: 35833.764 | AB20: 36888.876 | AC20: 37677.956 | AD20: 36282 | AE20: 37312 | AF20: 38018 | AG20: 38553 | AH20: 37315 | AI20: 38479 | AJ20: 38792 | AK20: 39607 | AL20: 38569 | AM20: 40241 | AN20: 41066 | AO20: 42064 | AP20: 40702 | AQ20: 42368 | AR20: 43136 | AS20: 43809 | AT20: 42815 | AU20: 44740 | AV20: 45411 | AW20: 47664 | AX20: 46050 | AY20: 47125 | AZ20: 47919 | BA20: 48995 | BB20: 47583 | BC20: 48943 | BD20: 48901 | BE20: 49365 | BF20: 46615 | BG20: 46591 | BH20: 46949 | BI20: 48684 | BJ20: 47586 | BK20: 48541 | BL20: 49189 | BM20: 50417 | BN20: 49792 | BO20: 50892 | BP20: 51570 | BQ20: 53288 | BR20: 51858 | BS20: 52599 | BT20: 52442 | BU20: 54192 | BV20: 52616 | BW20: 53795 | BX20: 53437 | BY20: 55631
A21: SA - GDP at constant 2005 prices | B21: =B19+B20 -> 276937.73 | C21: =C19+C20 -> 281926.95 | D21: =D19+D20 -> 291779.43 | E21: =E19+E20 -> 294728.69 | F21: =F19+F20 -> 286503.11 | G21: =G19+G20 -> 296255.31 | H21: =H19+H20 -> 301875.87 | I21: =I19+I20 -> 305550.14 | ... BY21: =BY19+BY20 -> 513279.16
A23: KZN – GDPR by activity
A24: Constant 2005 prices - Rand million
A25: Provincial Industry | B25: =B5 -> 1995q1 | C25: =C5 -> 1995q2 | D25: =D5 -> 1995q3 | E25: =E5 -> 1995q4 | F25: =F5 -> 1996q1 | G25: =G5 -> 1996q2 | H25: =H5 -> 1996q3 | I25: =I5 -> 1996q4 | ... BY25: =BY5 -> 2013q4
A26: Primary Industries | B26: =SUM(B27:B28) -> 2681.1665 | C26: =SUM(C27:C28) -> 3389.6847 | D26: =SUM(D27:D28) -> 3572.5483 | E26: =SUM(E27:E28) -> 3004.0318 | F26: =SUM(F27:F28) -> 3155.8356 | G26: =SUM(G27:G28) -> 5144.7249 | H26: =SUM(H27:H28) -> 4142.132 | I26: =SUM(I27:I28) -> 3281.5028 | ... BY26: =SUM(BY27:BY28) -> 2901.5088
A27: Agriculture, forestry and fishing | B27: =B7*Annual!$B46/100 -> 1580.3818 | C27: =C7*Annual!$B46/100 -> 2296.541 | D27: =D7*Annual!$B46/100 -> 2462.6245 | E27: =E7*Annual!$B46/100 -> 1904.1008 | F27: =F7*Annual!$C46/100 -> 1627.9474 | G27: =G7*Annual!$C46/100 -> 3627.2639 | H27: =H7*Annual!$C46/100 -> 2597.4344 | I27: =I7*Annual!$C46/100 -> 1737.4701 | J27: =J7*Annual!$D46/100 -> 1775.1071 | K27: =K7*Annual!$D46/100 -> 3511.1488 | L27: =L7*Annual!$D46/100 -> 2546.8049 | M27: =M7*Annual!$D46/100 -> 1722.7451 | N27: =N7*Annual!$E46/100 -> 1830.7254 | O27: =O7*Annual!$E46/100 -> 3612.4681 | P27: =P7*Annual!$E46/100 -> 2620.0331 | Q27: =Q7*Annual!$E46/100 -> 1579.2318 | R27: =R7*Annual!$F46/100 -> 1841.8316 | S27: =S7*Annual!$F46/100 -> 3660.7857 | T27: =T7*Annual!$F46/100 -> 2560.5007 | U27: =U7*Annual!$F46/100 -> 1325.7624 | V27: =V7*Annual!$G46/100 -> 1550.5324 | W27: =W7*Annual!$G46/100 -> 3108.5863 | X27: =X7*Annual!$G46/100 -> 3465.6182 | Y27: =Y7*Annual!$G46/100 -> 1616.6127 | Z27: =Z7*Annual!H46/100 -> 1775.4954 | AA27: =AA7*Annual!H46/100 -> 3702.7466 | AB27: =AB7*Annual!H46/100 -> 2838.2418 | AC27: =AC7*Annual!H46/100 -> 1390.2772 | AD27: =AD7*Annual!$I46/100 -> 1908.2936 | AE27: =AE7*Annual!$I46/100 -> 3996.6417 | AF27: =AF7*Annual!$I46/100 -> 2625.9595 | AG27: =AG7*Annual!$I46/100 -> 1627.5788 | AH27: =AH7*Annual!$J46/100 -> 1830.9586 | AI27: =AI7*Annual!$J46/100 -> 4618.1273 | AJ27: =AJ7*Annual!$J46/100 -> 2882.8489 | AK27: =AK7*Annual!$J46/100 -> 1352.8536 | AL27: =AL7*Annual!$K46/100 -> 1831.4345 | AM27: =AM7*Annual!$K46/100 -> 4166.9038 | AN27: =AN7*Annual!$K46/100 -> 3150.2912 | AO27: =AO7*Annual!$K46/100 -> 1568.3701 | AP27: =AP7*Annual!$L46/100 -> 1932.8652 | AQ27: =AQ7*Annual!$L46/100 -> 3541.4728 | AR27: =AR7*Annual!$L46/100 -> 3161.0406 | AS27: =AS7*Annual!$L46/100 -> 1456.1109 | AT27: =AT7*Annual!$M46/100 -> 2032.844 | AU27: =AU7*Annual!$M46/100 -> 3439.2728 | AV27: =AV7*Annual!$M46/100 -> 3038.7722 | AW27: =AW7*Annual!$M46/100 -> 1634.0362 | AX27: =AX7*Annual!$N46/100 -> 2127.9041 | AY27: =AY7*Annual!$N46/100 -> 3593.6789 | AZ27: =AZ7*Annual!$N46/100 -> 3144.2599 | BA27: =BA7*Annual!$N46/100 -> 1693.6112 | BB27: =BB7*Annual!$O46/100 -> 2497.823 | BC27: =BC7*Annual!$O46/100 -> 4133.1426 | BD27: =BD7*Annual!$O46/100 -> 3572.9208 | BE27: =BE7*Annual!$O46/100 -> 1891.1475 | BF27: =BF7*Annual!P46/100 -> 2418.6498 | BG27: =BG7*Annual!P46/100 -> 3937.7459 | BH27: =BH7*Annual!P46/100 -> 3432.9179 | BI27: =BI7*Annual!P46/100 -> 1957.3832 | BJ27: =BJ7*Annual!Q46/100 -> 2509.6815 | BK27: =BK7*Annual!Q46/100 -> 4115.2657 | BL27: =BL7*Annual!Q46/100 -> 3441.0421 | BM27: =BM7*Annual!Q46/100 -> 1957.4732 | BN27: =BN7*Annual!$R46/100 -> 2490.3539 | BO27: =BO7*Annual!$R46/100 -> 4137.5265 | BP27: =BP7*Annual!$R46/100 -> 3512.1317 | BQ27: =BQ7*Annual!$R46/100 -> 2008.8169 | BR27: =BR7*Annual!$S46/100 -> 2635.2931 | BS27: =BS7*Annual!$S46/100 -> 4414.9547 | BT27: =BT7*Annual!$S46/100 -> 3431.7639 | BU27: =BU7*Annual!$S46/100 -> 1973.2425 | BV27: =BV7*Annual!$T46/100 -> 2793.6847 | BW27: =BW7*Annual!$T46/100 -> 4765.2219 | BX27: =BX7*Annual!$T46/100 -> 3366.9612 | BY27: =BY7*Annual!$U46/100 -> 1956.2796
A28: Mining and quarrying | B28: =B8*Annual!$B47/100 -> 1100.7847 | C28: =C8*Annual!$B47/100 -> 1093.1437 | D28: =D8*Annual!$B47/100 -> 1109.9237 | E28: =E8*Annual!$B47/100 -> 1099.931 | F28: =F8*Annual!$C47/100 -> 1527.8882 | G28: =G8*Annual!$C47/100 -> 1517.461 | H28: =H8*Annual!$C47/100 -> 1544.6976 | I28: =I8*Annual!$C47/100 -> 1544.0327 | J28: =J8*Annual!$D47/100 -> 1512.9634 | K28: =K8*Annual!$D47/100 -> 1543.2789 | L28: =L8*Annual!$D47/100 -> 1575.7227 | M28: =M8*Annual!$D47/100 -> 1569.8779 | N28: =N8*Annual!$E47/100 -> 1529.0743 | O28: =O8*Annual!$E47/100 -> 1529.1948 | P28: =P8*Annual!$E47/100 -> 1533.7655 | Q28: =Q8*Annual!$E47/100 -> 1526.0067 | R28: =R8*Annual!$F47/100 -> 1098.3079 | S28: =S8*Annual!$F47/100 -> 1103.8882 | T28: =T8*Annual!$F47/100 -> 1114.7302 | U28: =U8*Annual!$F47/100 -> 1115.9321 | V28: =V8*Annual!$G47/100 -> 1069.935 | W28: =W8*Annual!$G47/100 -> 1082.9678 | X28: =X8*Annual!$G47/100 -> 1082.3575 | Y28: =Y8*Annual!$G47/100 -> 1083.2358 | Z28: =Z8*Annual!H47/100 -> 1010.0123 | AA28: =AA8*Annual!H47/100 -> 1032.9937 | AB28: =AB8*Annual!H47/100 -> 1033.6148 | AC28: =AC8*Annual!H47/100 -> 1021.1583 | AD28: =AD8*Annual!$I47/100 -> 888.90625 | AE28: =AE8*Annual!$I47/100 -> 913.33716 | AF28: =AF8*Annual!$I47/100 -> 926.70439 | AG28: =AG8*Annual!$I47/100 -> 931.83557 | AH28: =AH8*Annual!$J47/100 -> 936.60937 | AI28: =AI8*Annual!$J47/100 -> 968.19661 | AJ28: =AJ8*Annual!$J47/100 -> 987.77128 | AK28: =AK8*Annual!$J47/100 -> 983.16486 | AL28: =AL8*Annual!$K47/100 -> 987.93811 | AM28: =AM8*Annual!$K47/100 -> 985.29776 | AN28: =AN8*Annual!$K47/100 -> 1015.1792 | AO28: =AO8*Annual!$K47/100 -> 964.95687 | AP28: =AP8*Annual!$L47/100 -> 955.03676 | AQ28: =AQ8*Annual!$L47/100 -> 936.36028 | AR28: =AR8*Annual!$L47/100 -> 924.32189 | AS28: =AS8*Annual!$L47/100 -> 890.27137 | AT28: =AT8*Annual!$M47/100 -> 878.13335 | AU28: =AU8*Annual!$M47/100 -> 888.73889 | AV28: =AV8*Annual!$M47/100 -> 895.43641 | AW28: =AW8*Annual!$M47/100 -> 919.8198 | AX28: =AX8*Annual!$N47/100 -> 919.68298 | AY28: =AY8*Annual!$N47/100 -> 914.92676 | AZ28: =AZ8*Annual!$N47/100 -> 922.21132 | BA28: =BA8*Annual!$N47/100 -> 914.58588 | BB28: =BB8*Annual!$O47/100 -> 830.88649 | BC28: =BC8*Annual!$O47/100 -> 873.90201 | BD28: =BD8*Annual!$O47/100 -> 859.30125 | BE28: =BE8*Annual!$O47/100 -> 867.34266 | BF28: =BF8*Annual!P47/100 -> 768.46209 | BG28: =BG8*Annual!P47/100 -> 805.65944 | BH28: =BH8*Annual!P47/100 -> 812.7196 | BI28: =BI8*Annual!P47/100 -> 825.13581 | BJ28: =BJ8*Annual!Q47/100 -> 871.46912 | BK28: =BK8*Annual!Q47/100 -> 831.78782 | BL28: =BL8*Annual!Q47/100 -> 896.65041 | BM28: =BM8*Annual!Q47/100 -> 914.60583 | BN28: =BN8*Annual!$R47/100 -> 870.28342 | BO28: =BO8*Annual!$R47/100 -> 890.36694 | BP28: =BP8*Annual!$R47/100 -> 848.69696 | BQ28: =BQ8*Annual!$R47/100 -> 856.61953 | BR28: =BR8*Annual!$S47/100 -> 834.12929 | BS28: =BS8*Annual!$S47/100 -> 929.74204 | BT28: =BT8*Annual!$S47/100 -> 891.00311 | BU28: =BU8*Annual!$S47/100 -> 878.13412 | BV28: =BV8*Annual!$T47/100 -> 849.43549 | BW28: =BW8*Annual!$T47/100 -> 889.42573 | BX28: =BX8*Annual!$T47/100 -> 900.06066 | BY28: =BY8*Annual!$U47/100 -> 945.22923
A29: Secondary Industries | B29: =SUM(B30:B32) -> 12108.14 | C29: =SUM(C30:C32) -> 12334.197 | D29: =SUM(D30:D32) -> 13048.586 | E29: =SUM(E30:E32) -> 12809.694 | F29: =SUM(F30:F32) -> 12369.88 | G29: =SUM(G30:G32) -> 12540.544 | H29: =SUM(H30:H32) -> 13272.273 | I29: =SUM(I30:I32) -> 13256.436 | ... BY29: =SUM(BY30:BY32) -> 20530.824
A30: Manufacturing | B30: =B10*Annual!$B49/100 -> 9836.9662 | C30: =C10*Annual!$B49/100 -> 10025.492 | D30: =D10*Annual!$B49/100 -> 10734.607 | E30: =E10*Annual!$B49/100 -> 10609.534 | F30: =F10*Annual!$C49/100 -> 10095.385 | G30: =G10*Annual!$C49/100 -> 10178.11 | H30: =H10*Annual!$C49/100 -> 10818.95 | I30: =I10*Annual!$C49/100 -> 10834.441 | J30: =J10*Annual!$D49/100 -> 10259.131 | K30: =K10*Annual!$D49/100 -> 10611.483 | L30: =L10*Annual!$D49/100 -> 11125.425 | M30: =M10*Annual!$D49/100 -> 11042.322 | N30: =N10*Annual!$E49/100 -> 10433.082 | O30: =O10*Annual!$E49/100 -> 10611.887 | P30: =P10*Annual!$E49/100 -> 10935.096 | Q30: =Q10*Annual!$E49/100 -> 10864.551 | R30: =R10*Annual!$F49/100 -> 10314.719 | S30: =S10*Annual!$F49/100 -> 10584.729 | T30: =T10*Annual!$F49/100 -> 11187.91 | U30: =U10*Annual!$F49/100 -> 11444.151 | V30: =V10*Annual!$G49/100 -> 11093.742 | W30: =W10*Annual!$G49/100 -> 11487.949 | X30: =X10*Annual!$G49/100 -> 12190.708 | Y30: =Y10*Annual!$G49/100 -> 12498.444 | Z30: =Z10*Annual!H49/100 -> 11780.413 | AA30: =AA10*Annual!H49/100 -> 12017.336 | AB30: =AB10*Annual!H49/100 -> 12358.803 | AC30: =AC10*Annual!H49/100 -> 12521.131 | AD30: =AD10*Annual!$I49/100 -> 11817.287 | AE30: =AE10*Annual!$I49/100 -> 12271.334 | AF30: =AF10*Annual!$I49/100 -> 12925.195 | AG30: =AG10*Annual!$I49/100 -> 12946.819 | AH30: =AH10*Annual!$J49/100 -> 12111.765 | AI30: =AI10*Annual!$J49/100 -> 12152.205 | AJ30: =AJ10*Annual!$J49/100 -> 12680.478 | AK30: =AK10*Annual!$J49/100 -> 12558.52 | AL30: =AL10*Annual!$K49/100 -> 12319.816 | AM30: =AM10*Annual!$K49/100 -> 12658.67 | AN30: =AN10*Annual!$K49/100 -> 13440.051 | AO30: =AO10*Annual!$K49/100 -> 13411.158 | AP30: =AP10*Annual!$L49/100 -> 12760.174 | AQ30: =AQ10*Annual!$L49/100 -> 13563.658 | AR30: =AR10*Annual!$L49/100 -> 14381.307 | AS30: =AS10*Annual!$L49/100 -> 14321.821 | AT30: =AT10*Annual!$M49/100 -> 13597.925 | AU30: =AU10*Annual!$M49/100 -> 14251.267 | AV30: =AV10*Annual!$M49/100 -> 15119.103 | AW30: =AW10*Annual!$M49/100 -> 15380.185 | AX30: =AX10*Annual!$N49/100 -> 14553.98 | AY30: =AY10*Annual!$N49/100 -> 15062.024 | AZ30: =AZ10*Annual!$N49/100 -> 15665.538 | BA30: =BA10*Annual!$N49/100 -> 16159.188 | BB30: =BB10*Annual!$O49/100 -> 14962.263 | BC30: =BC10*Annual!$O49/100 -> 16069.428 | BD30: =BD10*Annual!$O49/100 -> 16399.428 | BE30: =BE10*Annual!$O49/100 -> 15582.252 | BF30: =BF10*Annual!P49/100 -> 13495.469 | BG30: =BG10*Annual!P49/100 -> 13728.968 | BH30: =BH10*Annual!P49/100 -> 14646.277 | BI30: =BI10*Annual!P49/100 -> 14870.089 | BJ30: =BJ10*Annual!Q49/100 -> 14108.457 | BK30: =BK10*Annual!Q49/100 -> 15013.533 | BL30: =BL10*Annual!Q49/100 -> 15520.926 | BM30: =BM10*Annual!Q49/100 -> 15549.861 | BN30: =BN10*Annual!$R49/100 -> 14934.23 | BO30: =BO10*Annual!$R49/100 -> 15296.642 | BP30: =BP10*Annual!$R49/100 -> 15890.484 | BQ30: =BQ10*Annual!$R49/100 -> 16043.82 | BR30: =BR10*Annual!$S49/100 -> 15039.169 | BS30: =BS10*Annual!$S49/100 -> 15608.366 | BT30: =BT10*Annual!$S49/100 -> 16248.223 | BU30: =BU10*Annual!$S49/100 -> 16589.979 | BV30: =BV10*Annual!$T49/100 -> 14993.749 | BW30: =BW10*Annual!$T49/100 -> 16006.083 | BX30: =BX10*Annual!$T49/100 -> 16188.997 | BY30: =BY10*Annual!$U49/100 -> 16770.674
A31: Electricity, gas and water | B31: =B11*Annual!$B50/100 -> 1113.765 | C31: =C11*Annual!$B50/100 -> 1135.5533 | D31: =D11*Annual!$B50/100 -> 1153.9461 | E31: =E11*Annual!$B50/100 -> 1092.022 | F31: =F11*Annual!$C50/100 -> 1137.9679 | G31: =G11*Annual!$C50/100 -> 1212.4258 | H31: =H11*Annual!$C50/100 -> 1313.1445 | I31: =I11*Annual!$C50/100 -> 1329.5584 | J31: =J11*Annual!$D50/100 -> 1256.5731 | K31: =K11*Annual!$D50/100 -> 1303.1121 | L31: =L11*Annual!$D50/100 -> 1319.7663 | M31: =M11*Annual!$D50/100 -> 1285.5656 | N31: =N11*Annual!$E50/100 -> 1191.8484 | O31: =O11*Annual!$E50/100 -> 1220.6122 | P31: =P11*Annual!$E50/100 -> 1229.4579 | Q31: =Q11*Annual!$E50/100 -> 1207.435 | R31: =R11*Annual!$F50/100 -> 1149.9796 | S31: =S11*Annual!$F50/100 -> 1210.9965 | T31: =T11*Annual!$F50/100 -> 1246.7477 | U31: =U11*Annual!$F50/100 -> 1244.4788 | V31: =V11*Annual!$G50/100 -> 1228.5953 | W31: =W11*Annual!$G50/100 -> 1290.0341 | X31: =X11*Annual!$G50/100 -> 1333.3913 | Y31: =Y11*Annual!$G50/100 -> 1284.8913 | Z31: =Z11*Annual!H50/100 -> 1246.6998 | AA31: =AA11*Annual!H50/100 -> 1280.5957 | AB31: =AB11*Annual!H50/100 -> 1320.2894 | AC31: =AC11*Annual!H50/100 -> 1281.3407 | AD31: =AD11*Annual!$I50/100 -> 1341.957 | AE31: =AE11*Annual!$I50/100 -> 1406.3899 | AF31: =AF11*Annual!$I50/100 -> 1454.1618 | AG31: =AG11*Annual!$I50/100 -> 1424.1168 | AH31: =AH11*Annual!$J50/100 -> 1194.8662 | AI31: =AI11*Annual!$J50/100 -> 1241.8668 | AJ31: =AJ11*Annual!$J50/100 -> 1283.268 | AK31: =AK11*Annual!$J50/100 -> 1259.0042 | AL31: =AL11*Annual!$K50/100 -> 1273.5463 | AM31: =AM11*Annual!$K50/100 -> 1332.2409 | AN31: =AN11*Annual!$K50/100 -> 1386.0244 | AO31: =AO11*Annual!$K50/100 -> 1351.5784 | AP31: =AP11*Annual!$L50/100 -> 1355.5239 | AQ31: =AQ11*Annual!$L50/100 -> 1417.3847 | AR31: =AR11*Annual!$L50/100 -> 1456.0046 | AS31: =AS11*Annual!$L50/100 -> 1462.3838 | AT31: =AT11*Annual!$M50/100 -> 1391.9024 | AU31: =AU11*Annual!$M50/100 -> 1462.5101 | AV31: =AV11*Annual!$M50/100 -> 1511.2123 | AW31: =AW11*Annual!$M50/100 -> 1513.5888 | AX31: =AX11*Annual!$N50/100 -> 1441.2956 | AY31: =AY11*Annual!$N50/100 -> 1504.2956 | AZ31: =AZ11*Annual!$N50/100 -> 1570.9103 | BA31: =BA11*Annual!$N50/100 -> 1558.689 | BB31: =BB11*Annual!$O50/100 -> 1387.3617 | BC31: =BC11*Annual!$O50/100 -> 1431.6945 | BD31: =BD11*Annual!$O50/100 -> 1542.356 | BE31: =BE11*Annual!$O50/100 -> 1469.316 | BF31: =BF11*Annual!P50/100 -> 1324.3397 | BG31: =BG11*Annual!P50/100 -> 1380.3027 | BH31: =BH11*Annual!P50/100 -> 1454.9159 | BI31: =BI11*Annual!P50/100 -> 1442.7535 | BJ31: =BJ11*Annual!Q50/100 -> 1346.6391 | BK31: =BK11*Annual!Q50/100 -> 1399.3372 | BL31: =BL11*Annual!Q50/100 -> 1462.3508 | BM31: =BM11*Annual!Q50/100 -> 1460.7185 | BN31: =BN11*Annual!$R50/100 -> 1371.2526 | BO31: =BO11*Annual!$R50/100 -> 1426.4295 | BP31: =BP11*Annual!$R50/100 -> 1474.9601 | BQ31: =BQ11*Annual!$R50/100 -> 1464.1592 | BR31: =BR11*Annual!$S50/100 -> 1341.8475 | BS31: =BS11*Annual!$S50/100 -> 1374.0584 | BT31: =BT11*Annual!$S50/100 -> 1427.9398 | BU31: =BU11*Annual!$S50/100 -> 1403.4587 | BV31: =BV11*Annual!$T50/100 -> 1301.6111 | BW31: =BW11*Annual!$T50/100 -> 1370.8308 | BX31: =BX11*Annual!$T50/100 -> 1436.7048 | BY31: =BY11*Annual!$U50/100 -> 1399.2991
A32: Construction | B32: =B12*Annual!$B51/100 -> 1157.4083 | C32: =C12*Annual!$B51/100 -> 1173.1515 | D32: =D12*Annual!$B51/100 -> 1160.0322 | E32: =E12*Annual!$B51/100 -> 1108.1383 | F32: =F12*Annual!$C51/100 -> 1136.5275 | G32: =G12*Annual!$C51/100 -> 1150.0075 | H32: =H12*Annual!$C51/100 -> 1140.1783 | I32: =I12*Annual!$C51/100 -> 1092.437 | J32: =J12*Annual!$D51/100 -> 1184.2119 | K32: =K12*Annual!$D51/100 -> 1191.3871 | L32: =L12*Annual!$D51/100 -> 1177.3237 | M32: =M12*Annual!$D51/100 -> 1224.6807 | N32: =N12*Annual!$E51/100 -> 1084.2534 | O32: =O12*Annual!$E51/100 -> 1057.0478 | P32: =P12*Annual!$E51/100 -> 1027.7493 | Q32: =Q12*Annual!$E51/100 -> 1070.8598 | R32: =R12*Annual!$F51/100 -> 995.9433 | S32: =S12*Annual!$F51/100 -> 994.74289 | T32: =T12*Annual!$F51/100 -> 979.13747 | U32: =U12*Annual!$F51/100 -> 1028.5546 | V32: =V12*Annual!$G51/100 -> 996.57132 | W32: =W12*Annual!$G51/100 -> 1019.4041 | X32: =X12*Annual!$G51/100 -> 1031.2141 | Y32: =Y12*Annual!$G51/100 -> 1108.7667 | Z32: =Z12*Annual!H51/100 -> 1374.8833 | AA32: =AA12*Annual!H51/100 -> 1386.2044 | AB32: =AB12*Annual!H51/100 -> 1365.8265 | AC32: =AC12*Annual!H51/100 -> 1446.5837 | AD32: =AD12*Annual!$I51/100 -> 1071.3516 | AE32: =AE12*Annual!$I51/100 -> 1072.4026 | AF32: =AF12*Annual!$I51/100 -> 1093.8747 | AG32: =AG12*Annual!$I51/100 -> 1165.0479 | AH32: =AH12*Annual!$J51/100 -> 1127.2784 | AI32: =AI12*Annual!$J51/100 -> 1127.4245 | AJ32: =AJ12*Annual!$J51/100 -> 1148.0187 | AK32: =AK12*Annual!$J51/100 -> 1209.0711 | AL32: =AL12*Annual!$K51/100 -> 1201.1586 | AM32: =AM12*Annual!$K51/100 -> 1228.6873 | AN32: =AN12*Annual!$K51/100 -> 1275.2518 | AO32: =AO12*Annual!$K51/100 -> 1339.5342 | AP32: =AP12*Annual!$L51/100 -> 1362.2351 | AQ32: =AQ12*Annual!$L51/100 -> 1400.566 | AR32: =AR12*Annual!$L51/100 -> 1449.2969 | AS32: =AS12*Annual!$L51/100 -> 1516.4504 | AT32: =AT12*Annual!$M51/100 -> 1469.0794 | AU32: =AU12*Annual!$M51/100 -> 1505.8462 | AV32: =AV12*Annual!$M51/100 -> 1558.9699 | AW32: =AW12*Annual!$M51/100 -> 1629.898 | AX32: =AX12*Annual!$N51/100 -> 1685.922 | AY32: =AY12*Annual!$N51/100 -> 1704.5008 | AZ32: =AZ12*Annual!$N51/100 -> 1744.2509 | BA32: =BA12*Annual!$N51/100 -> 1918.2295 | BB32: =BB12*Annual!$O51/100 -> 1852.6748 | BC32: =BC12*Annual!$O51/100 -> 1875.3072 | BD32: =BD12*Annual!$O51/100 -> 1922.3988 | BE32: =BE12*Annual!$O51/100 -> 2005.9442 | BF32: =BF12*Annual!P51/100 -> 2032.0266 | BG32: =BG12*Annual!P51/100 -> 2035.2142 | BH32: =BH12*Annual!P51/100 -> 2071.8706 | BI32: =BI12*Annual!P51/100 -> 2159.8172 | BJ32: =BJ12*Annual!Q51/100 -> 2107.6739 | BK32: =BK12*Annual!Q51/100 -> 2084.7231 | BL32: =BL12*Annual!Q51/100 -> 2081.7994 | BM32: =BM12*Annual!Q51/100 -> 2161.601 | BN32: =BN12*Annual!$R51/100 -> 2105.2908 | BO32: =BO12*Annual!$R51/100 -> 2095.3368 | BP32: =BP12*Annual!$R51/100 -> 2096.5079 | BQ32: =BQ12*Annual!$R51/100 -> 2173.9531 | BR32: =BR12*Annual!$S51/100 -> 2136.7587 | BS32: =BS12*Annual!$S51/100 -> 2134.1183 | BT32: =BT12*Annual!$S51/100 -> 2157.4411 | BU32: =BU12*Annual!$S51/100 -> 2256.3001 | BV32: =BV12*Annual!$T51/100 -> 2183.4169 | BW32: =BW12*Annual!$T51/100 -> 2185.0326 | BX32: =BX12*Annual!$T51/100 -> 2212.7935 | BY32: =BY12*Annual!$U51/100 -> 2360.8516
A33: Tertiary industries | B33: =SUM(B34:B38) -> 24027.14 | C33: =SUM(C34:C38) -> 24303.535 | D33: =SUM(D34:D38) -> 25223.143 | E33: =SUM(E34:E38) -> 26219.137 | F33: =SUM(F34:F38) -> 25140.849 | G33: =SUM(G34:G38) -> 25397.185 | H33: =SUM(H34:H38) -> 26219.141 | I33: =SUM(I34:I38) -> 27205.437 | ... BY33: =SUM(BY34:BY38) -> 51586.112
A34: Wholesale & retail trade; hotels & restaurants | B34: =B14*Annual!$B53/100 -> 4878.3885 | C34: =C14*Annual!$B53/100 -> 5004.5376 | D34: =D14*Annual!$B53/100 -> 5337.5679 | E34: =E14*Annual!$B53/100 -> 6135.3481 | F34: =F14*Annual!$C53/100 -> 5082.5905 | G34: =G14*Annual!$C53/100 -> 5164.5759 | H34: =H14*Annual!$C53/100 -> 5414.8875 | I34: =I14*Annual!$C53/100 -> 6173.6595 | J34: =J14*Annual!$D53/100 -> 5198.1192 | K34: =K14*Annual!$D53/100 -> 5231.9191 | L34: =L14*Annual!$D53/100 -> 5432.7964 | M34: =M14*Annual!$D53/100 -> 6093.8972 | N34: =N14*Annual!$E53/100 -> 5179.0878 | O34: =O14*Annual!$E53/100 -> 5292.9308 | P34: =P14*Annual!$E53/100 -> 5488.3508 | Q34: =Q14*Annual!$E53/100 -> 6189.7889 | R34: =R14*Annual!$F53/100 -> 5385.4926 | S34: =S14*Annual!$F53/100 -> 5593.4589 | T34: =T14*Annual!$F53/100 -> 5915.3183 | U34: =U14*Annual!$F53/100 -> 6840.3861 | V34: =V14*Annual!$G53/100 -> 5905.0989 | W34: =W14*Annual!$G53/100 -> 6126.3743 | X34: =X14*Annual!$G53/100 -> 6385.3603 | Y34: =Y14*Annual!$G53/100 -> 7274.5658 | Z34: =Z14*Annual!H53/100 -> 6501.3526 | AA34: =AA14*Annual!H53/100 -> 6634.8189 | AB34: =AB14*Annual!H53/100 -> 6817.4305 | AC34: =AC14*Annual!H53/100 -> 7744.7943 | AD34: =AD14*Annual!$I53/100 -> 6592.528 | AE34: =AE14*Annual!$I53/100 -> 6755.3489 | AF34: =AF14*Annual!$I53/100 -> 7013.4015 | AG34: =AG14*Annual!$I53/100 -> 8015.6098 | AH34: =AH14*Annual!$J53/100 -> 6753.6927 | AI34: =AI14*Annual!$J53/100 -> 6934.0942 | AJ34: =AJ14*Annual!$J53/100 -> 7314.0755 | AK34: =AK14*Annual!$J53/100 -> 8359.2832 | AL34: =AL14*Annual!$K53/100 -> 7062.2196 | AM34: =AM14*Annual!$K53/100 -> 7271.7462 | AN34: =AN14*Annual!$K53/100 -> 7602.6045 | AO34: =AO14*Annual!$K53/100 -> 9020.8601 | AP34: =AP14*Annual!$L53/100 -> 7557.199 | AQ34: =AQ14*Annual!$L53/100 -> 7730.7758 | AR34: =AR14*Annual!$L53/100 -> 8095.2364 | AS34: =AS14*Annual!$L53/100 -> 9576.4701 | AT34: =AT14*Annual!$M53/100 -> 7997.4898 | AU34: =AU14*Annual!$M53/100 -> 8230.6835 | AV34: =AV14*Annual!$M53/100 -> 8640.8938 | AW34: =AW14*Annual!$M53/100 -> 10200.949 | AX34: =AX14*Annual!$N53/100 -> 8518.7708 | AY34: =AY14*Annual!$N53/100 -> 8732.1698 | AZ34: =AZ14*Annual!$N53/100 -> 9138.5468 | BA34: =BA14*Annual!$N53/100 -> 10641.699 | BB34: =BB14*Annual!$O53/100 -> 8882.2255 | BC34: =BC14*Annual!$O53/100 -> 8909.7305 | BD34: =BD14*Annual!$O53/100 -> 9047.0648 | BE34: =BE14*Annual!$O53/100 -> 10584.068 | BF34: =BF14*Annual!P53/100 -> 8885.2035 | BG34: =BG14*Annual!P53/100 -> 8836.4314 | BH34: =BH14*Annual!P53/100 -> 9153.0749 | BI34: =BI14*Annual!P53/100 -> 10572.153 | BJ34: =BJ14*Annual!Q53/100 -> 9008.1704 | BK34: =BK14*Annual!Q53/100 -> 9195.6502 | BL34: =BL14*Annual!Q53/100 -> 9611.4093 | BM34: =BM14*Annual!Q53/100 -> 11193.015 | BN34: =BN14*Annual!$R53/100 -> 9446.7716 | BO34: =BO14*Annual!$R53/100 -> 9616.8067 | BP34: =BP14*Annual!$R53/100 -> 10098.883 | BQ34: =BQ14*Annual!$R53/100 -> 11829.768 | BR34: =BR14*Annual!$S53/100 -> 9884.819 | BS34: =BS14*Annual!$S53/100 -> 10008.588 | BT34: =BT14*Annual!$S53/100 -> 10441.371 | BU34: =BU14*Annual!$S53/100 -> 12189.788 | BV34: =BV14*Annual!$T53/100 -> 10170.581 | BW34: =BW14*Annual!$T53/100 -> 10316.926 | BX34: =BX14*Annual!$T53/100 -> 10720.466 | BY34: =BY14*Annual!$U53/100 -> 12520.381
A35: Transport , storage and communication | B35: =B15*Annual!$B54/100 -> 4164.588 | C35: =C15*Annual!$B54/100 -> 4174.3852 | D35: =D15*Annual!$B54/100 -> 4517.1938 | E35: =E15*Annual!$B54/100 -> 4610.8554 | F35: =F15*Annual!$C54/100 -> 4420.1489 | G35: =G15*Annual!$C54/100 -> 4400.1908 | H35: =H15*Annual!$C54/100 -> 4700.5673 | I35: =I15*Annual!$C54/100 -> 4726.4028 | J35: =J15*Annual!$D54/100 -> 4592.9037 | K35: =K15*Annual!$D54/100 -> 4636.0241 | L35: =L15*Annual!$D54/100 -> 4956.141 | M35: =M15*Annual!$D54/100 -> 5076.77 | N35: =N15*Annual!$E54/100 -> 4916.9311 | O35: =O15*Annual!$E54/100 -> 4936.8211 | P35: =P15*Annual!$E54/100 -> 5110.7738 | Q35: =Q15*Annual!$E54/100 -> 5169.6142 | R35: =R15*Annual!$F54/100 -> 4948.354 | S35: =S15*Annual!$F54/100 -> 5061.0829 | T35: =T15*Annual!$F54/100 -> 5358.2805 | U35: =U15*Annual!$F54/100 -> 5481.49 | V35: =V15*Annual!$G54/100 -> 5294.2293 | W35: =W15*Annual!$G54/100 -> 5429.6325 | X35: =X15*Annual!$G54/100 -> 5698.29 | Y35: =Y15*Annual!$G54/100 -> 5772.7574 | Z35: =Z15*Annual!H54/100 -> 5508.6365 | AA35: =AA15*Annual!H54/100 -> 5613.3984 | AB35: =AB15*Annual!H54/100 -> 5922.3967 | AC35: =AC15*Annual!H54/100 -> 6107.9231 | AD35: =AD15*Annual!$I54/100 -> 6016.5291 | AE35: =AE15*Annual!$I54/100 -> 6178.0558 | AF35: =AF15*Annual!$I54/100 -> 6486.9948 | AG35: =AG15*Annual!$I54/100 -> 6636.7098 | AH35: =AH15*Annual!$J54/100 -> 6494.9979 | AI35: =AI15*Annual!$J54/100 -> 6621.9807 | AJ35: =AJ15*Annual!$J54/100 -> 6881.0942 | AK35: =AK15*Annual!$J54/100 -> 7090.2297 | AL35: =AL15*Annual!$K54/100 -> 6738.0703 | AM35: =AM15*Annual!$K54/100 -> 6880.5834 | AN35: =AN15*Annual!$K54/100 -> 7256.6299 | AO35: =AO15*Annual!$K54/100 -> 7426.2782 | AP35: =AP15*Annual!$L54/100 -> 7162.3031 | AQ35: =AQ15*Annual!$L54/100 -> 7314.8988 | AR35: =AR15*Annual!$L54/100 -> 7669.9738 | AS35: =AS15*Annual!$L54/100 -> 7828.5874 | AT35: =AT15*Annual!$M54/100 -> 7498.2444 | AU35: =AU15*Annual!$M54/100 -> 7680.8609 | AV35: =AV15*Annual!$M54/100 -> 8128.4755 | AW35: =AW15*Annual!$M54/100 -> 8226.9895 | AX35: =AX15*Annual!$N54/100 -> 8082.2879 | AY35: =AY15*Annual!$N54/100 -> 8263.4315 | AZ35: =AZ15*Annual!$N54/100 -> 8646.9024 | BA35: =BA15*Annual!$N54/100 -> 8791.0823 | BB35: =BB15*Annual!$O54/100 -> 8450.3112 | BC35: =BC15*Annual!$O54/100 -> 8615.1064 | BD35: =BD15*Annual!$O54/100 -> 8997.8519 | BE35: =BE15*Annual!$O54/100 -> 9135.5633 | BF35: =BF15*Annual!P54/100 -> 8696.0081 | BG35: =BG15*Annual!P54/100 -> 8739.6309 | BH35: =BH15*Annual!P54/100 -> 9090.7981 | BI35: =BI15*Annual!P54/100 -> 9232.8683 | BJ35: =BJ15*Annual!Q54/100 -> 8808.7405 | BK35: =BK15*Annual!Q54/100 -> 8973.8098 | BL35: =BL15*Annual!Q54/100 -> 9382.7173 | BM35: =BM15*Annual!Q54/100 -> 9550.6122 | BN35: =BN15*Annual!$R54/100 -> 9055.8208 | BO35: =BO15*Annual!$R54/100 -> 9248.5368 | BP35: =BP15*Annual!$R54/100 -> 9642.4869 | BQ35: =BQ15*Annual!$R54/100 -> 9834.4978 | BR35: =BR15*Annual!$S54/100 -> 9338.8921 | BS35: =BS15*Annual!$S54/100 -> 9507.9678 | BT35: =BT15*Annual!$S54/100 -> 9867.3631 | BU35: =BU15*Annual!$S54/100 -> 10035.523 | BV35: =BV15*Annual!$T54/100 -> 9490.8743 | BW35: =BW15*Annual!$T54/100 -> 9656.0244 | BX35: =BX15*Annual!$T54/100 -> 10050.516 | BY35: =BY15*Annual!$U54/100 -> 10217.123
A36: Finance, real estate and business services | B36: =B16*Annual!$B55/100 -> 5942.3934 | C36: =C16*Annual!$B55/100 -> 6000.6079 | D36: =D16*Annual!$B55/100 -> 6177.5695 | E36: =E16*Annual!$B55/100 -> 6276.7534 | F36: =F16*Annual!$C55/100 -> 6206.85 | G36: =G16*Annual!$C55/100 -> 6403.5831 | H36: =H16*Annual!$C55/100 -> 6636.5163 | I36: =I16*Annual!$C55/100 -> 6820.4794 | J36: =J16*Annual!$D55/100 -> 6692.4327 | K36: =K16*Annual!$D55/100 -> 6799.8125 | L36: =L16*Annual!$D55/100 -> 6839.454 | M36: =M16*Annual!$D55/100 -> 6840.9284 | N36: =N16*Annual!$E55/100 -> 6759.339 | O36: =O16*Annual!$E55/100 -> 6952.3154 | P36: =P16*Annual!$E55/100 -> 7051.6097 | Q36: =Q16*Annual!$E55/100 -> 7068.8086 | R36: =R16*Annual!$F55/100 -> 7175.6127 | S36: =S16*Annual!$F55/100 -> 7349.7247 | T36: =T16*Annual!$F55/100 -> 7473.9137 | U36: =U16*Annual!$F55/100 -> 7525.3827 | V36: =V16*Annual!$G55/100 -> 7290.224 | W36: =W16*Annual!$G55/100 -> 7402.0831 | X36: =X16*Annual!$G55/100 -> 7529.2289 | Y36: =Y16*Annual!$G55/100 -> 7655.4237 | Z36: =Z16*Annual!H55/100 -> 7572.5351 | AA36: =AA16*Annual!H55/100 -> 7824.407 | AB36: =AB16*Annual!H55/100 -> 8009.5899 | AC36: =AC16*Annual!H55/100 -> 8173.4366 | AD36: =AD16*Annual!$I55/100 -> 8306.2849 | AE36: =AE16*Annual!$I55/100 -> 8285.2473 | AF36: =AF16*Annual!$I55/100 -> 8245.3023 | AG36: =AG16*Annual!$I55/100 -> 8339.4393 | AH36: =AH16*Annual!$J55/100 -> 8745.9011 | AI36: =AI16*Annual!$J55/100 -> 8696.3982 | AJ36: =AJ16*Annual!$J55/100 -> 8736.242 | AK36: =AK16*Annual!$J55/100 -> 8852.151 | AL36: =AL16*Annual!$K55/100 -> 9306.4419 | AM36: =AM16*Annual!$K55/100 -> 9318.9381 | AN36: =AN16*Annual!$K55/100 -> 9368.251 | AO36: =AO16*Annual!$K55/100 -> 9568.0558 | AP36: =AP16*Annual!$L55/100 -> 10284.193 | AQ36: =AQ16*Annual!$L55/100 -> 10300.905 | AR36: =AR16*Annual!$L55/100 -> 10394.795 | AS36: =AS16*Annual!$L55/100 -> 10554.323 | AT36: =AT16*Annual!$M55/100 -> 10948.45 | AU36: =AU16*Annual!$M55/100 -> 11079.465 | AV36: =AV16*Annual!$M55/100 -> 11234.086 | AW36: =AW16*Annual!$M55/100 -> 11468.089 | AX36: =AX16*Annual!$N55/100 -> 11873.179 | AY36: =AY16*Annual!$N55/100 -> 11821.185 | AZ36: =AZ16*Annual!$N55/100 -> 12024.057 | BA36: =BA16*Annual!$N55/100 -> 12482.76 | BB36: =BB16*Annual!$O55/100 -> 12630.069 | BC36: =BC16*Annual!$O55/100 -> 12806.357 | BD36: =BD16*Annual!$O55/100 -> 12992.024 | BE36: =BE16*Annual!$O55/100 -> 13332.322 | BF36: =BF16*Annual!P55/100 -> 13088.054 | BG36: =BG16*Annual!P55/100 -> 13077.091 | BH36: =BH16*Annual!P55/100 -> 13090.566 | BI36: =BI16*Annual!P55/100 -> 13343.997 | BJ36: =BJ16*Annual!Q55/100 -> 13313.017 | BK36: =BK16*Annual!Q55/100 -> 13405.213 | BL36: =BL16*Annual!Q55/100 -> 13451.131 | BM36: =BM16*Annual!Q55/100 -> 13716.533 | BN36: =BN16*Annual!$R55/100 -> 13867.679 | BO36: =BO16*Annual!$R55/100 -> 13978.693 | BP36: =BP16*Annual!$R55/100 -> 14147.085 | BQ36: =BQ16*Annual!$R55/100 -> 14486.116 | BR36: =BR16*Annual!$S55/100 -> 14584.026 | BS36: =BS16*Annual!$S55/100 -> 14522.114 | BT36: =BT16*Annual!$S55/100 -> 14482.969 | BU36: =BU16*Annual!$S55/100 -> 14778.779 | BV36: =BV16*Annual!$T55/100 -> 14837.952 | BW36: =BW16*Annual!$T55/100 -> 15055.522 | BX36: =BX16*Annual!$T55/100 -> 14979.803 | BY36: =BY16*Annual!$U55/100 -> 14951.044
A37: Personal services | B37: =B17*Annual!$B56/100 -> 2539.1359 | C37: =C17*Annual!$B56/100 -> 2610.9905 | D37: =D17*Annual!$B56/100 -> 2657.4344 | E37: =E17*Annual!$B56/100 -> 2654.4713 | F37: =F17*Annual!$C56/100 -> 2684.1387 | G37: =G17*Annual!$C56/100 -> 2673.5092 | H37: =H17*Annual!$C56/100 -> 2687.509 | I37: =I17*Annual!$C56/100 -> 2688.8256 | J37: =J17*Annual!$D56/100 -> 2657.6926 | K37: =K17*Annual!$D56/100 -> 2687.8482 | L37: =L17*Annual!$D56/100 -> 2709.8293 | M37: =M17*Annual!$D56/100 -> 2667.6605 | N37: =N17*Annual!$E56/100 -> 2743.0426 | O37: =O17*Annual!$E56/100 -> 2822.9462 | P37: =P17*Annual!$E56/100 -> 2908.4935 | Q37: =Q17*Annual!$E56/100 -> 2915.5707 | R37: =R17*Annual!$F56/100 -> 2895.8662 | S37: =S17*Annual!$F56/100 -> 2932.922 | T37: =T17*Annual!$F56/100 -> 2996.599 | U37: =U17*Annual!$F56/100 -> 2985.6188 | V37: =V17*Annual!$G56/100 -> 3004.5741 | W37: =W17*Annual!$G56/100 -> 3058.9504 | X37: =X17*Annual!$G56/100 -> 3153.6761 | Y37: =Y17*Annual!$G56/100 -> 3149.7876 | Z37: =Z17*Annual!H56/100 -> 3128.2923 | AA37: =AA17*Annual!H56/100 -> 3143.459 | AB37: =AB17*Annual!H56/100 -> 3205.041 | AC37: =AC17*Annual!H56/100 -> 3178.5153 | AD37: =AD17*Annual!$I56/100 -> 3165.0154 | AE37: =AE17*Annual!$I56/100 -> 3203.8317 | AF37: =AF17*Annual!$I56/100 -> 3292.5164 | AG37: =AG17*Annual!$I56/100 -> 3299.122 | AH37: =AH17*Annual!$J56/100 -> 3326.382 | AI37: =AI17*Annual!$J56/100 -> 3403.8157 | AJ37: =AJ17*Annual!$J56/100 -> 3507.224 | AK37: =AK17*Annual!$J56/100 -> 3445.1464 | AL37: =AL17*Annual!$K56/100 -> 3394.0137 | AM37: =AM17*Annual!$K56/100 -> 3463.0979 | AN37: =AN17*Annual!$K56/100 -> 3537.3781 | AO37: =AO17*Annual!$K56/100 -> 3530.0253 | AP37: =AP17*Annual!$L56/100 -> 3546.5333 | AQ37: =AQ17*Annual!$L56/100 -> 3581.0333 | AR37: =AR17*Annual!$L56/100 -> 3640.92 | AS37: =AS17*Annual!$L56/100 -> 3626.2575 | AT37: =AT17*Annual!$M56/100 -> 3754.2341 | AU37: =AU17*Annual!$M56/100 -> 3774.9181 | AV37: =AV17*Annual!$M56/100 -> 3807.98 | AW37: =AW17*Annual!$M56/100 -> 3821.3351 | AX37: =AX17*Annual!$N56/100 -> 3997.2381 | AY37: =AY17*Annual!$N56/100 -> 4044.1208 | AZ37: =AZ17*Annual!$N56/100 -> 4043.4696 | BA37: =BA17*Annual!$N56/100 -> 3908.5191 | BB37: =BB17*Annual!$O56/100 -> 4162.0857 | BC37: =BC17*Annual!$O56/100 -> 4227.9308 | BD37: =BD17*Annual!$O56/100 -> 4200.2989 | BE37: =BE17*Annual!$O56/100 -> 4005.9903 | BF37: =BF17*Annual!P56/100 -> 4134.3802 | BG37: =BG17*Annual!P56/100 -> 4167.8125 | BH37: =BH17*Annual!P56/100 -> 4171.4043 | BI37: =BI17*Annual!P56/100 -> 4118.8969 | BJ37: =BJ17*Annual!Q56/100 -> 4128.2709 | BK37: =BK17*Annual!Q56/100 -> 4189.817 | BL37: =BL17*Annual!Q56/100 -> 4211.6536 | BM37: =BM17*Annual!Q56/100 -> 4173.2651 | BN37: =BN17*Annual!$R56/100 -> 4283.0729 | BO37: =BO17*Annual!$R56/100 -> 4309.1274 | BP37: =BP17*Annual!$R56/100 -> 4289.9347 | BQ37: =BQ17*Annual!$R56/100 -> 4247.585 | BR37: =BR17*Annual!$S56/100 -> 4359.7831 | BS37: =BS17*Annual!$S56/100 -> 4446.5187 | BT37: =BT17*Annual!$S56/100 -> 4419.8375 | BU37: =BU17*Annual!$S56/100 -> 4290.2866 | BV37: =BV17*Annual!$T56/100 -> 4454.1534 | BW37: =BW17*Annual!$T56/100 -> 4522.3631 | BX37: =BX17*Annual!$T56/100 -> 4508.263 | BY37: =BY17*Annual!$U56/100 -> 4380.5582
