Workbook
Name BB: #REF!
Name BB: #REF!

Sheet SOSC-jb
B1: Undergraduate Majors
B2: Faculty of Social Sciences
B4: Study Year | C4: Major Type | G4: Head Count Enrolments
D5: 1999-00 | E5: 2000-01 | F5: 2001-02 | G5: 2002-03 | H5: 2003-04 | I5: 2004-05 | J5: 2005-06 | K5: 2006-07 | L5: 2007-08 | M5: 2008-09 | N5: 2011-12 | O5: 2012-13 | P5: 2013-14 | Q5: 2014-15 | R5: 2015-16
C6: Single | D6: 566 | E6: 560 | F6: 604 | G6: 739 | H6: 1193 | I6: 1245 | J6: 1268 | K6: 1287 | L6: 1281 | M6: 1347 | N6: 1377 | O6: 1501 | P6: 1466 | Q6: 1507 | R6: 1347
C7: Combined | D7: 23 | E7: 18 | F7: 6 | G7: 8 | H7: 12 | I7: 13 | J7: 18 | K7: 19 | L7: 15 | M7: 21 | N7: 18 | O7: 21 | P7: 14 | Q7: 15 | R7: 7
B8: Year I | C8: Sub-Total: | D8: 589 | E8: 578 | F8: 610 | G8: 747 | H8: 1205 | I8: 1258 | J8: 1286 | K8: 1306 | L8: 1296 | M8: 1368 | N8: 1395 | O8: 1522 | P8: 1480 | Q8: 1522 | R8: 1354
C9: Gen/Integ. Studies | D9: 3 | E9: 2 | F9: 0 | G9: 1 | H9: 0 | I9: 16 | K9: 270 | L9: 389 | M9: 350 | N9: 311 | O9: 300 | P9: 264 | Q9: 220 | R9: 226
C10: Total: | D10: 592 | E10: 580 | F10: 610 | G10: 748 | H10: 1205 | I10: 1274 | J10: 1286 | K10: 1576 | L10: 1685 | M10: 1718 | N10: 1706 | O10: 1822 | P10: 1744 | Q10: 1742 | R10: 1580
C11: Single | D11: 474 | E11: 572 | F11: 618 | G11: 693 | H11: 827 | I11: 1219 | J11: 1235 | K11: 1161 | L11: 1102 | M11: 1026 | N11: 1046 | O11: 1079 | P11: 1192 | Q11: 1207 | R11: 1158
C12: Combined | D12: 127 | E12: 78 | F12: 52 | G12: 65 | H12: 48 | I12: 78 | J12: 68 | K12: 68 | L12: 48 | M12: 47 | N12: 61 | O12: 56 | P12: 64 | Q12: 54 | R12: 46
B13: Year II | C13: Sub-Total: | D13: 601 | E13: 650 | F13: 670 | G13: 758 | H13: 875 | I13: 1297 | J13: 1303 | K13: 1229 | L13: 1150 | M13: 1073 | N13: 1107 | O13: 1135 | P13: 1256 | Q13: 1261 | R13: 1204
C14: Gen/Integ. Studies | D14: 1 | E14: 1 | F14: 1 | G14: 1 | H14: 0 | I14: 11 | J14: 1 | K14: 101 | L14: 144 | M14: 167 | N14: 130 | O14: 121 | P14: 126 | Q14: 104 | R14: 89
C15: Total: | D15: 602 | E15: 651 | F15: 671 | G15: 759 | H15: 875 | I15: 1308 | J15: 1304 | K15: 1330 | L15: 1294 | M15: 1240 | N15: 1237 | O15: 1256 | P15: 1382 | Q15: 1365 | R15: 1293
C16: Single | D16: 747 | E16: 685 | F16: 762 | G16: 785 | H16: 876 | I16: 806 | J16: 1128 | K16: 1132 | L16: 1023 | M16: 891 | N16: 917 | O16: 956 | P16: 922 | Q16: 1037 | R16: 1031
C17: Combined | D17: 208 | E17: 164 | F17: 161 | G17: 118 | H17: 71 | I17: 77 | J17: 88 | K17: 64 | L17: 79 | M17: 67 | N17: 69 | O17: 76 | P17: 60 | Q17: 56 | R17: 54
B18: Year III | C18: Sub-Total: | D18: 955 | E18: 849 | F18: 923 | G18: 903 | H18: 947 | I18: 883 | J18: 1216 | K18: 1196 | L18: 1102 | M18: 958 | N18: 986 | O18: 1032 | P18: 982 | Q18: 1093 | R18: 1085
C19: Gen/Integ. Studies | D19: 23 | E19: 15 | F19: 9 | G19: 6 | H19: 2 | I19: 2 | J19: 1 | K19: 92 | L19: 105 | M19: 93 | N19: 117 | O19: 88 | P19: 89 | Q19: 95 | R19: 95
C20: Total: | D20: 978 | E20: 864 | F20: 932 | G20: 909 | H20: 949 | I20: 885 | J20: 1217 | K20: 1288 | L20: 1207 | M20: 1051 | N20: 1103 | O20: 1120 | P20: 1071 | Q20: 1188 | R20: 1180
C21: Single | D21: 225 | E21: 378 | F21: 446 | G21: 440 | H21: 513 | I21: 387 | J21: 507 | K21: 767 | L21: 673 | M21: 620 | N21: 669 | O21: 584 | P21: 624 | Q21: 690 | R21: 775
C22: Combined | D22: 83 | E22: 74 | F22: 73 | G22: 84 | H22: 50 | I22: 27 | J22: 42 | K22: 74 | L22: 45 | M22: 52 | N22: 52 | O22: 39 | P22: 53 | Q22: 59 | R22: 56
B23: Year IV | C23: Sub-Total: | D23: 308 | E23: 452 | F23: 519 | G23: 524 | H23: 563 | I23: 414 | J23: 549 | K23: 841 | L23: 718 | M23: 672 | N23: 721 | O23: 623 | P23: 677 | Q23: 749 | R23: 831
C24: Gen/Integ. Studies | D24: 2 | E24: 3 | F24: 3 | G24: 1 | H24: 4 | I24: 1 | J24: 1 | K24: 3 | L24: 5 | M24: 10 | N24: 7 | O24: 9 | P24: 1 | Q24: 8 | R24: 22
C25: Total: | D25: 310 | E25: 455 | F25: 522 | G25: 525 | H25: 567 | I25: 415 | J25: 550 | K25: 844 | L25: 723 | M25: 682 | N25: 728 | O25: 632 | P25: 678 | Q25: 757 | R25: 853
C26: Single | D26: 2012 | E26: 2195 | F26: 2430 | G26: 2657 | H26: 3409 | I26: 3657 | J26: 4138 | K26: 4347 | L26: 4079 | M26: 3884 | N26: 4009 | O26: 4120 | P26: 4204 | Q26: 4441 | R26: 4311
C27: Combined | D27: 441 | E27: 334 | F27: 292 | G27: 275 | H27: 181 | I27: 195 | J27: 216 | K27: 225 | L27: 187 | M27: 187 | N27: 200 | O27: 192 | P27: 191 | Q27: 184 | R27: 163
B28: TOTAL: | C28: Sub-Total: | D28: 2453 | E28: 2529 | F28: 2722 | G28: 2932 | H28: 3590 | I28: 3852 | J28: 4354 | K28: 4572 | L28: 4266 | M28: 4071 | N28: 4209 | O28: 4312 | P28: 4395 | Q28: 4625 | R28: 4474
C29: Gen/Integ. Studies | D29: 29 | E29: 21 | F29: 13 | G29: 9 | H29: 6 | I29: 30 | J29: 3 | K29: 466 | L29: 643 | M29: 620 | N29: 565 | O29: 518 | P29: 480 | Q29: 427 | R29: 432
C30: Total: | D30: 2482 | E30: 2550 | F30: 2735 | G30: 2941 | H30: 3596 | I30: 3882 | J30: 4357 | K30: 5038 | L30: 4909 | M30: 4691 | N30: 4774 | O30: 4830 | P30: 4875 | Q30: 5052 | R30: 4906 | U30: =5052-4830 -> 222
C31: Adjusted Total: | D31: 2375 | E31: 2382 | F31: 2578 | G31: 2824 | H31: 3596 | I31: 3882 | J31: 4357 | K31: 5038 | L31: 4909 | M31: 4691
B32: Male | H32: 988 | I32: 1123 | J32: 1383 | K32: 1718 | L32: 1641 | M32: 1625 | N32: 1743 | O32: 1765 | P32: 1813 | Q32: 1809 | R32: 1768 | S32: =R32/R30 -> 0.36037505
B33: Female | H33: 2608 | I33: 2759 | J33: 2974 | K33: 3320 | L33: 3268 | M33: 3066 | N33: 3031 | O33: 3065 | P33: 3062 | Q33: 3243 | R33: 3138 | S33: =R33/R30 -> 0.63962495
B34: Full-Time | H34: 3258 | I34: 3497 | J34: 3905 | K34: 4382 | L34: 4220 | M34: 4049 | N34: 4195 | O34: 4249 | P34: 4389 | Q34: 4561 | R34: 4359 | S34: =R34/R30 -> 0.88850387
B35: Part-Time | H35: 338 | I35: 385 | J35: 452 | K35: 656 | L35: 689 | M35: 642 | N35: 579 | O35: 581 | P35: 486 | Q35: 491 | R35: 547 | S35: =R35/R30 -> 0.11149613
B61: CODES: All plus NEUR, minus ARTS

Sheet sosc sum-jb 
A1: Undergraduate Majors
A2: Faculty of Social Sciences
A3: Summary
A4: Major | B4: Head Count Enrolments (Including Coop) | U4: Data for chart:
B5: 2003-04 | C5: 2004-05 | D5: 2005-06 | E5: 2006-07 | F5: 2007-08 | G5: 2008-09 | H5: 2011-12 | I5: 2012-13 | J5: 2013-14 | K5: 2014-15 | L5: 2015-16 | U5: Year
A6: Applied Linguistics | H6: Reported under Faculty of Humanities | K6: 238 | L6: 211 | U6: APLS | Z6: 238
A7: Business Economics | B7: 114 | C7: 113 | D7: 120 | E7: 144 | F7: 154 | G7: 131 | H7: 166 | I7: 180 | J7: 182 | K7: 233 | L7: 194 | U7: BECO
A8: Child and Youth Studies | B8: 883 | C8: 751 | D8: 798 | E8: 787 | F8: 786 | G8: 768 | H8: 803 | I8: 880 | J8: 907 | K8: 882 | L8: 912 | U8: CHYS
A9: Communications, Popular Culture & Film | B9: 618 | C9: 703 | D9: 741 | E9: 675 | F9: 593 | G9: 559 | H9: 609 | I9: 668 | J9: 688 | K9: 715 | L9: 727 | U9: CPCF
A10: Economics | B10: 137 | C10: 159 | D10: 214 | E10: 217 | F10: 161 | G10: 190 | H10: 227 | I10: 227 | J10: 239 | K10: 257 | L10: 292 | U10: ECON
A11: Geography | B11: 196 | C11: 250 | D11: 330 | E11: 378 | F11: 367 | G11: 310 | H11: 255 | I11: 216 | J11: 227 | K11: 180 | L11: 172 | U11: GEOG
A12: Labour Studies | B12: 15 | C12: 22 | D12: 29 | E12: 28 | F12: 25 | G12: 23 | H12: 46 | I12: 80 | J12: 110 | K12: 118 | L12: 128 | U12: LABR
A13: Neuroscience | B13: 72 | C13: 71 | D13: 73 | E13: 73 | F13: 66 | G13: 57 | H13: 85 | I13: 91 | J13: 115 | K13: 131 | L13: 138 | U13: NEUR
A14: Political Science | B14: 325 | C14: 418 | D14: 506 | E14: 499 | F14: 495 | G14: 458 | H14: 477 | I14: 469 | J14: 419 | K14: 395 | L14: 362 | U14: POLI
A15: Psychology | B15: 696 | C15: 827 | D15: 874 | E15: 867 | F15: 799 | G15: 787 | H15: 829 | I15: 837 | J15: 839 | K15: 849 | L15: 766 | U15: PSYC
A16: Sociology | B16: 549 | C16: 619 | D16: 679 | E16: 761 | F16: 717 | G16: 703 | H16: 610 | I16: 596 | J16: 640 | K16: 601 | L16: 553 | U16: SOCI
A17: Tourism and Environment | B17: 37 | C17: 46 | D17: 47 | E17: 199 | F17: 157 | G17: 157 | H17: 167 | I17: 119 | J17: 83 | K17: 81 | L17: 76 | U17: TREN
A18: Women's Studies | B18: 27 | C18: 36 | D18: 34 | E18: 39 | F18: 31 | G18: 28 | H18: 36 | I18: 44 | J18: 46 | K18: 48 | L18: 39 | U18: WISE
A19: General Studies (Social Science) | E19: 464 | F19: 644 | G19: 617 | H19: 562 | I19: 518 | J19: 468 | K19: 418 | L19: 424 | U19: GENL
A20: Faculty Total: | E20: 5038 | F20: 4909 | G20: 4691 | H20: 4774 | I20: 4830 | J20: 4875 | K20: 5052 | L20: 4906
A21: *Combined Majors and General/Integrated Majors are counted in full in each unit if the majors are offered by two different units. In the Faculty Total, the student is counted only once if the units belong to the same Faculty.

Sheet sosc sum (COOP)
A1: Undergraduate Majors
A2: Faculty of Social Sciences
A3: Summary - COOP only
A4: Major | B4: Head Count Enrollments (Coop Only) | U4: Data for chart:
B5: 2003-04 | C5: 2004-05 | D5: 2005-06 | E5: 2006-07 | F5: 2007-08 | G5: 2008-09 | H5: 2011-12 | I5: 2012-13 | J5: 2013-14 | K5: 2014-15 | L5: 2015-16
A6: Applied Linguistics | H6: Reported under Faculty of Humanities | K6: 2 | L6: 0
A7: Business Economics | B7: Coop data not available | C7: 17 | D7: 15 | E7: 21 | F7: 31 | G7: 19 | H7: 28 | I7: 30 | J7: 55 | K7: 88 | L7: 68 | U7: BECO
A8: Child and Youth Studies | U8: CHYS
A9: Communications, Popular Culture & Film | C9: 88 | D9: 81 | E9: 61 | F9: 23 | G9: 11 | U9: CPCF
A10: Economics | C10: 1 | D10: 4 | E10: 3 | F10: 2 | G10: 4 | H10: 8 | I10: 17 | J10: 22 | K10: 19 | L10: 14 | U10: ECON
A11: Geography | F11: 9 | G11: 13 | H11: 19 | I11: 14 | J11: 24 | K11: 17 | L11: 18 | U11: GEOG
A12: Labour Studies | K12: 7 | U12: LABR
A13: Neuroscience | F13: 24 | G13: 20 | H13: 27 | I13: 33 | J13: 39 | K13: 46 | L13: 54 | U13: NEUR
A14: Political Science | C14: 16 | D14: 15 | E14: 20 | F14: 37 | G14: 43 | H14: 52 | I14: 53 | J14: 46 | K14: 56 | L14: 55 | U14: POLI
A15: Psychology | C15: 69 | D15: 61 | E15: 79 | F15: 72 | G15: 79 | H15: 119 | I15: 138 | J15: 136 | K15: 132 | L15: 131 | U15: PSYC
A16: Sociology | U16: SOCI
A17: Tourism and Environment | K17: 10 | L17: 39 | U17: TREN
A18: Women's Studies | U18: WISE
A19: General Studies (Social Science) | U19: GENL
A20: Faculty Total: | D20: 202 | E20: 184 | F20: 198 | G20: 189 | H20: 253 | I20: 285 | J20: 322 | K20: 377 | L20: 379
A21: *Combined Majors and General/Integrated Majors are counted in full in each unit if the majors are offered by two different units. In the Faculty Total, the student is counted only once if the units belong to the same Faculty.

Sheet APLS-jb
B1: Undergraduate Majors
B2: Applied Linguistics
B3: TOTAL
B4: Study Year | C4: Major Type | H4: Head Count Enrolments (Including Coop)
D5: 1999-00 | E5: 2000-01 | F5: 2001-02 | G5: 2002-03 | H5: 2003-04 | J5: 2004-05 | L5: 2005-06 | M5: 2006-07 | N5: 2007-08 | O5: 2008-09 | P5: 2011-12 | Q5: 2012-13 | R5: 2013-14 | S5: 2014-15 | T5: 2015-16
C6: Single | D6: 34 | E6: 37 | F6: 45 | G6: 57 | H6: 72 | I6: Coop data not available | J6: 73 | K6: 0 | L6: 87 | M6: 77 | N6: 77 | O6: 70 | P6: 80 | Q6: 82 | R6: 104 | S6: 75 | T6: 60
C7: Combined | D7: 0 | E7: 0 | F7: 0 | G7: 0 | H7: 1 | J7: 0 | K7: 0 | P7: 1 | S7: 1
B8: Year I | C8: Sub-Total: | D8: =D6+D7 -> 34 | E8: =E6+E7 -> 37 | F8: =F6+F7 -> 45 | G8: =G6+G7 -> 57 | H8: =H6+H7 -> 73 | J8: =J6+J7 -> 73 | K8: 0 | L8: =L6+L7 -> 87 | M8: =M6+M7 -> 77 | N8: =SUM(N6:N7) -> 77 | O8: 70 | P8: 81 | Q8: 82 | R8: 104 | S8: 76 | T8: 60
C9: Gen./Integ. Studies | D9: 0 | E9: 0 | F9: 0 | G9: 0 | H9: 0 | J9: 0 | K9: 0
C10: Total: | D10: =D8+D9 -> 34 | E10: =E8+E9 -> 37 | F10: =F8+F9 -> 45 | G10: =G8+G9 -> 57 | H10: =H8+H9 -> 73 | J10: =J8+J9 -> 73 | K10: 0 | L10: =L8+L9 -> 87 | M10: =M8+M9 -> 77 | N10: =SUM(N8:N9) -> 77 | O10: 70 | P10: 81 | Q10: 82 | R10: 104 | S10: 76 | T10: 60
C11: Single | D11: 37 | E11: 30 | F11: 35 | G11: 49 | H11: 52 | J11: 78 | K11: 0 | L11: 55 | M11: 62 | N11: 67 | O11: =54-2 -> 52 | P11: 57 | Q11: 72 | R11: 55 | S11: 65 | T11: 41
C12: Combined | D12: 8 | E12: 4 | F12: 2 | G12: 2 | H12: 3 | J12: 4 | K12: 0 | L12: 5 | M12: 1 | N12: 2 | O12: 2 | P12: 1 | Q12: 4 | R12: 6 | S12: 2 | T12: 3
B13: Year II | C13: Sub-Total: | D13: =D11+D12 -> 45 | E13: =E11+E12 -> 34 | F13: =F11+F12 -> 37 | G13: =G11+G12 -> 51 | H13: =H11+H12 -> 55 | J13: =J11+J12 -> 82 | K13: 0 | L13: =L11+L12 -> 60 | M13: =M11+M12 -> 63 | N13: =SUM(N11:N12) -> 69 | O13: 54 | P13: 58 | Q13: 76 | R13: 61 | S13: 67 | T13: 44
C14: Gen./Integ. Studies | D14: 0 | E14: 0 | F14: 0 | G14: 0 | H14: 0 | J14: 0 | K14: 0 | Q14: 1
C15: Total: | D15: =D13+D14 -> 45 | E15: =E13+E14 -> 34 | F15: =F13+F14 -> 37 | G15: =G13+G14 -> 51 | H15: =H13+H14 -> 55 | J15: =J13+J14 -> 82 | K15: 0 | L15: =L13+L14 -> 60 | M15: =M13+M14 -> 63 | N15: =SUM(N13:N14) -> 69 | O15: 54 | P15: 58 | Q15: 77 | R15: 61 | S15: 67 | T15: 44
C16: Single | D16: 52 | E16: 42 | F16: 40 | G16: =52-9 -> 43 | H16: 48 | J16: 42 | K16: 0 | L16: 67 | M16: 51 | N16: 51 | O16: =68-1-1-1-1-1 -> 63 | P16: 60 | Q16: 39 | R16: 53 | S16: 50 | T16: 61
C17: Combined | D17: 7 | E17: 9 | F17: 11 | G17: 9 | H17: 4 | J17: 4 | K17: 0 | L17: 3 | M17: 6 | N17: 4 | O17: 5 | P17: 9 | Q17: 5 | R17: 3 | S17: 6 | T17: 1
B18: Year III | C18: Sub-Total: | D18: =D16+D17 -> 59 | E18: =E16+E17 -> 51 | F18: =F16+F17 -> 51 | G18: =G16+G17 -> 52 | H18: =H16+H17 -> 52 | J18: =J16+J17 -> 46 | K18: 0 | L18: =L16+L17 -> 70 | M18: =M16+M17 -> 57 | N18: =N16+N17 -> 55 | O18: 68 | P18: 69 | Q18: 44 | R18: 56 | S18: 56 | T18: 62
C19: Gen./Integ. Studies | D19: 0 | E19: 0 | F19: 0 | G19: 0 | H19: 0 | J19: 0 | K19: 0 | R19: 1
C20: Total: | D20: =D18+D19 -> 59 | E20: =E18+E19 -> 51 | F20: =F18+F19 -> 51 | G20: =G18+G19 -> 52 | H20: =H18+H19 -> 52 | J20: =J18+J19 -> 46 | K20: 0 | L20: =L18+L19 -> 70 | M20: =M18+M19 -> 57 | N20: =N18+N19 -> 55 | O20: 68 | P20: 69 | Q20: 44 | R20: 57 | S20: 56 | T20: 62
C21: Single | D21: 21 | E21: 35 | F21: 43 | G21: =54-8 -> 46 | H21: 55 | J21: 37 | K21: 0 | L21: 34 | M21: 51 | N21: 40 | O21: =45-2 -> 43 | P21: 52 | Q21: 56 | R21: 39 | S21: 38 | T21: 42
C22: Combined | D22: 7 | E22: 3 | F22: 3 | G22: 8 | H22: 4 | J22: 1 | K22: 0 | L22: 2 | M22: 4 | N22: 3 | O22: 2 | P22: 4 | Q22: 2 | R22: 5 | S22: 1 | T22: 3
B23: Year IV | C23: Sub-Total: | D23: =D21+D22 -> 28 | E23: =E21+E22 -> 38 | F23: =F21+F22 -> 46 | G23: =G21+G22 -> 54 | H23: =H21+H22 -> 59 | J23: =J21+J22 -> 38 | K23: 0 | L23: =L21+L22 -> 36 | M23: =M21+M22 -> 55 | N23: =N21+N22 -> 43 | O23: 45 | P23: 56 | Q23: 58 | R23: 44 | S23: 39 | T23: 45
C24: Gen./Integ. Studies | D24: 0 | E24: 0 | F24: 0 | G24: 0 | H24: 0 | J24: 0 | K24: 0
C25: Total: | D25: =D23+D24 -> 28 | E25: =E23+E24 -> 38 | F25: =F23+F24 -> 46 | G25: =G23+G24 -> 54 | H25: =H23+H24 -> 59 | J25: =J23+J24 -> 38 | K25: 0 | L25: =L23+L24 -> 36 | M25: =M23+M24 -> 55 | N25: =N23+N24 -> 43 | O25: 45 | P25: 56 | Q25: 58 | R25: 44 | S25: 39 | T25: 45
C26: Single | D26: =SUM(D6,D11,D16,D21) -> 144 | E26: =SUM(E6,E11,E16,E21) -> 144 | F26: =SUM(F6,F11,F16,F21) -> 163 | G26: =SUM(G6,G11,G16,G21) -> 195 | H26: =SUM(H6,H11,H16,H21) -> 227 | J26: =SUM(J6,J11,J16,J21) -> 230 | K26: 0 | L26: =SUM(L6,L11,L16,L21) -> 243 | M26: =SUM(M6,M11,M16,M21) -> 241 | N26: =SUM(N6,N11,N16,N21) -> 235 | O26: =SUM(O6,O11,O16,O21) -> 228 | P26: 249 | Q26: 249 | R26: 251 | S26: 228 | T26: 204
C27: Combined | D27: =SUM(D7,D12,D17,D22) -> 22 | E27: =SUM(E7,E12,E17,E22) -> 16 | F27: =SUM(F7,F12,F17,F22) -> 16 | G27: =SUM(G7,G12,G17,G22) -> 19 | H27: =SUM(H7,H12,H17,H22) -> 12 | J27: =SUM(J7,J12,J17,J22) -> 9 | K27: 0 | L27: =SUM(L7,L12,L17,L22) -> 10 | M27: =SUM(M7,M12,M17,M22) -> 11 | N27: =SUM(N7,N12,N17,N22) -> 9 | O27: =SUM(O7,O12,O17,O22) -> 9 | P27: 15 | Q27: 11 | R27: 14 | S27: 10 | T27: 7
B28: TOTAL: | C28: Sub-Total: | D28: =D26+D27 -> 166 | E28: =E26+E27 -> 160 | F28: =F26+F27 -> 179 | G28: =G26+G27 -> 214 | H28: =H26+H27 -> 239 | J28: =J26+J27 -> 239 | K28: 0 | L28: =L26+L27 -> 253 | M28: =M26+M27 -> 252 | N28: =N26+N27 -> 244 | O28: =SUM(O26:O27) -> 237 | P28: 264 | Q28: 260 | R28: 265 | S28: 238 | T28: 211
C29: Gen./Integ. Studies | D29: =SUM(D9,D14,D19,D24) -> 0 | E29: =SUM(E9,E14,E19,E24) -> 0 | F29: =SUM(F9,F14,F19,F24) -> 0 | G29: =SUM(G9,G14,G19,G24) -> 0 | H29: =SUM(H9,H14,H19,H24) -> 0 | J29: =SUM(J9,J14,J19,J24) -> 0 | K29: 0 | Q29: 1 | R29: 1
C30: Total: | D30: =D28+D29 -> 166 | E30: =E28+E29 -> 160 | F30: =F28+F29 -> 179 | G30: =G28+G29 -> 214 | H30: =H28+H29 -> 239 | J30: =J28+J29 -> 239 | K30: 0 | L30: =L28+L29 -> 253 | M30: =M28+M29 -> 252 | N30: =N28+N29 -> 244 | O30: =SUM(O10,O15,O20,O25) -> 237 | P30: 264 | Q30: 261 | R30: 266 | S30: 238 | T30: 211
B31: Male | D31: 6 | E31: 8 | F31: 8 | G31: 15 | H31: 13 | J31: 14 | K31: 0 | L31: 19 | M31: 22 | N31: 19 | O31: 21 | P31: 17 | Q31: 15 | R31: 15 | S31: 17 | T31: 16
B32: Female | D32: 160 | E32: 152 | F32: 171 | G32: 199 | H32: 226 | J32: 225 | K32: 0 | L32: 234 | M32: 230 | N32: 225 | O32: 216 | P32: 247 | Q32: 246 | R32: 251 | S32: 221 | T32: 195
B33: Full-Time | D33: 152 | E33: 142 | F33: 164 | G33: 184 | H33: 222 | J33: 222 | K33: 0 | L33: 231 | M33: 232 | N33: 222 | O33: 212 | P33: 247 | Q33: 245 | R33: 248 | S33: 224 | T33: 194
B34: Part-Time | D34: 14 | E34: 18 | F34: 15 | G34: 30 | H34: 17 | J34: 17 | K34: 0 | L34: 22 | M34: 20 | N34: 22 | O34: 25 | P34: 17 | Q34: 16 | R34: 18 | S34: 14 | T34: 17
B55: Codes:
B56: ALTS
B57: APLI
B58: CODC
B59: HEAR
B60: HESC
...

Sheet APLS (COOP)-jb
B1: Undergraduate Majors
B2: Applied Linguistics
B3: COOP
B4: Study Year | C4: Major Type | D4: Head Count Enrolments
D5: 2005-06 | E5: 2006-07 | F5: 2007-08 | G5: 2008-09 | H5: 2011-12 | I5: 2012-13 | J5: 2013-14 | K5: 2014-15 | L5: 2015-16
C6: Single
C7: Combined
B8: Year I | C8: Sub-Total:
C9: Gen./Integ. Studies
C10: Total:
C11: Single | F11: 1 | G11: =1 -> 1 | I11: 1 | K11: 1
C12: Combined
B13: Year II | C13: Sub-Total: | F13: =SUM(F11:F12) -> 1 | G13: 1 | I13: 1 | K13: 1
C14: Gen./Integ. Studies
C15: Total: | F15: =SUM(F13:F14) -> 1 | G15: 1 | I15: 1 | K15: 1
C16: Single | J16: 1
C17: Combined
B18: Year III | C18: Sub-Total: | J18: 1
C19: Gen./Integ. Studies
C20: Total: | J20: 1
C21: Single | K21: 1
C22: Combined
B23: Year IV | C23: Sub-Total: | K23: 1
C24: Gen./Integ. Studies
C25: Total: | K25: 1
C26: Single | F26: =SUM(F6,F11,F16,F21) -> 1 | G26: =SUM(G6,G11,G16,G21) -> 1 | I26: 1 | K26: 2
C27: Combined
B28: TOTAL: | C28: Sub-Total: | F28: =F26+F27 -> 1 | G28: =G26+G27 -> 1 | I28: 1 | K28: 2
C29: Gen./Integ. Studies
C30: Total: | D30: 0 | E30: 0 | F30: =F28+F29 -> 1 | G30: =G28+G29 -> 1 | H30: 0 | I30: 1 | J30: 1 | K30: 2 | L30: 0
B31: Male
B32: Female | F32: 1 | G32: 1 | I32: 1 | J32: 1 | K32: 2
B33: Full-Time | F33: 1 | G33: 1 | I33: 1 | J33: 1 | K33: 1
B34: Part-Time | K34: 1
B35: Note: Prior to 2014-15 APLS enrolment was reported under the Faculty of Humanities.
B64: Codes:
B65: ALTS
B66: APLI
B67: CODC
B68: HEAR
...

Sheet BECO-jb
B1: Undergraduate Majors
B2: Business Economics
B3: TOTAL
B4: Study Year | C4: Major Type | D4: Head Count Enrolments (Including Coop)
D5: 2003-04 | E5: 2004-05 | F5: 2005-06 | G5: 2006-07 | H5: 2007-08 | I5: 2008-09 | J5: 2011-12 | K5: 2012-13 | L5: 2013-14 | M5: 2014-15 | N5: 2015-16
C6: Single | D6: 49 | E6: 54 | F6: 49 | G6: 74 | H6: 84 | I6: 78 | J6: 100 | K6: 96 | L6: 102 | M6: 138 | N6: 101
C7: Combined | D7: 0 | E7: 0
B8: Year I | C8: Sub-Total: | D8: =D6+D7 -> 49 | E8: =E6+E7 -> 54 | F8: =F6+F7 -> 49 | G8: =G6+G7 -> 74 | H8: =H6+H7 -> 84 | I8: =I6+I7 -> 78 | J8: 100 | K8: 96 | L8: 102 | M8: 138 | N8: 101
C9: Gen/Integ. Studies | D9: 0 | E9: 0
C10: Total: | D10: =D8+D9 -> 49 | E10: =E8+E9 -> 54 | F10: =F8+F9 -> 49 | G10: =G8+G9 -> 74 | H10: =H8+H9 -> 84 | I10: =I8+I9 -> 78 | J10: 100 | K10: 96 | L10: 102 | M10: 138 | N10: 101
C11: Single | D11: 20 | E11: 35 | F11: 31 | G11: 19 | H11: 31 | I11: 17 | J11: 36 | K11: 32 | L11: 26 | M11: 35 | N11: 36
C12: Combined | D12: 0 | E12: 0
B13: Year II | C13: Sub-Total: | D13: =D11+D12 -> 20 | E13: =E11+E12 -> 35 | F13: =F11+F12 -> 31 | G13: =G11+G12 -> 19 | H13: =H11+H12 -> 31 | I13: =I11+I12 -> 17 | J13: 36 | K13: 32 | L13: 26 | M13: 35 | N13: 36
C14: Gen/Integ. Studies | D14: 0 | E14: 0
C15: Total: | D15: =D13+D14 -> 20 | E15: =E13+E14 -> 35 | F15: =F13+F14 -> 31 | G15: =G13+G14 -> 19 | H15: =H13+H14 -> 31 | I15: =I13+I14 -> 17 | J15: 36 | K15: 32 | L15: 26 | M15: 35 | N15: 36
C16: Single | D16: 18 | E16: 11 | F16: 29 | G16: 24 | H16: 17 | I16: 23 | J16: 14 | K16: 32 | L16: 30 | M16: 30 | N16: 30
C17: Combined | D17: 0 | E17: 0
B18: Year III | C18: Sub-Total: | D18: =D16+D17 -> 18 | E18: =E16+E17 -> 11 | F18: =F16+F17 -> 29 | G18: =G16+G17 -> 24 | H18: =H16+H17 -> 17 | I18: =I16+I17 -> 23 | J18: 14 | K18: 32 | L18: 30 | M18: 30 | N18: 30
C19: Gen/Integ. Studies | D19: 0 | E19: 0
C20: Total: | D20: =D18+D19 -> 18 | E20: =E18+E19 -> 11 | F20: =F18+F19 -> 29 | G20: =G18+G19 -> 24 | H20: =H18+H19 -> 17 | I20: =I18+I19 -> 23 | J20: 14 | K20: 32 | L20: 30 | M20: 30 | N20: 30
C21: Single | D21: 27 | E21: 13 | F21: 11 | G21: 27 | H21: 22 | I21: 13 | J21: 16 | K21: 20 | L21: 24 | M21: 30 | N21: 27
C22: Combined | D22: 0 | E22: 0
B23: Year IV | C23: Sub-Total: | D23: =D21+D22 -> 27 | E23: =E21+E22 -> 13 | F23: =F21+F22 -> 11 | G23: =G21+G22 -> 27 | H23: =H21+H22 -> 22 | I23: =I21+I22 -> 13 | J23: 16 | K23: 20 | L23: 24 | M23: 30 | N23: 27
C24: Gen/Integ. Studies | D24: 0 | E24: 0
C25: Total: | D25: =D23+D24 -> 27 | E25: =E23+E24 -> 13 | F25: =F23+F24 -> 11 | G25: =G23+G24 -> 27 | H25: =H23+H24 -> 22 | I25: =I23+I24 -> 13 | J25: 16 | K25: 20 | L25: 24 | M25: 30 | N25: 27
C26: Single | D26: =SUM(D6,D11,D16,D21) -> 114 | E26: =SUM(E6,E11,E16,E21) -> 113 | F26: =SUM(F6,F11,F16,F21) -> 120 | G26: =SUM(G6,G11,G16,G21) -> 144 | H26: =SUM(H6,H11,H16,H21) -> 154 | I26: =SUM(I6,I11,I16,I21) -> 131 | J26: 166 | K26: 180 | L26: 182 | M26: 233 | N26: 194
C27: Combined | D27: =SUM(D7,D12,D17,D22) -> 0 | E27: =SUM(E7,E12,E17,E22) -> 0
B28: TOTAL: | C28: Sub-Total: | D28: =D26+D27 -> 114 | E28: =E26+E27 -> 113 | F28: =F26+F27 -> 120 | G28: =G26+G27 -> 144 | H28: =H26+H27 -> 154 | I28: =I26+I27 -> 131 | J28: 166 | K28: 180 | L28: 182 | M28: 233 | N28: 194
C29: Gen/Integ. Studies | D29: =SUM(D9,D14,D19,D24) -> 0 | E29: =SUM(E9,E14,E19,E24) -> 0
C30: Total: | D30: =D28+D29 -> 114 | E30: =E28+E29 -> 113 | F30: =F28+F29 -> 120 | G30: =G28+G29 -> 144 | H30: =H28+H29 -> 154 | I30: =I28+I29 -> 131 | J30: 166 | K30: 180 | L30: 182 | M30: 233 | N30: 194
B31: Male | D31: 79 | E31: 76 | F31: 81 | G31: 104 | H31: 111 | I31: 91 | J31: 114 | K31: 129 | L31: 138 | M31: 163 | N31: 135 | O31: =N31/N30 -> 0.69587629
B32: Female | D32: 35 | E32: 37 | F32: 39 | G32: 40 | H32: 43 | I32: 40 | J32: 52 | K32: 51 | L32: 44 | M32: 70 | N32: 59 | O32: =N32/N30 -> 0.30412371
B33: Full-Time | D33: 99 | E33: 99 | F33: 105 | G33: 127 | H33: 135 | I33: 108 | J33: 153 | K33: 161 | L33: 160 | M33: 212 | N33: 179 | O33: =N33/N30 -> 0.92268041
B34: Part-Time | D34: 15 | E34: 14 | F34: 15 | G34: 17 | H34: 19 | I34: 23 | J34: 13 | K34: 19 | L34: 22 | M34: 21 | N34: 15 | O34: =N34/N30 -> 0.077319588
B54: Codes: | C54: BECE, BECH, BEFE

Sheet BECO (COOP)-jb
B1: Undergraduate Majors
B2: Business Economics
B3: COOP
B4: Study Year | C4: Major Type | D4: Head Count Enrollments (Coop Only)
D5: 2003-04- | E5: 2004-05 | F5: 2005-06 | G5: 2006-07 | H5: 2007-08 | I5: 2008-09 | J5: 2011-12 | K5: 2012-13 | L5: 2013-14 | M5: 2014-15 | N5: 2015-16
C6: Single | D6: Coop data not available | E6: 5 | F6: 4 | G6: 10 | H6: 16 | I6: 5 | J6: 13 | K6: 19 | L6: 40 | M6: 69 | N6: 42
C7: Combined | E7: 0
B8: Year I | C8: Sub-Total: | E8: 5 | F8: 4 | G8: 10 | H8: =H6+H7 -> 16 | I8: =I6+I7 -> 5 | J8: 13 | K8: 19 | L8: 40 | M8: 69 | N8: 42
C9: Gen/Integ. Studies | E9: 0
C10: Total: | E10: 5 | F10: 4 | G10: 10 | H10: =H8+H9 -> 16 | I10: =I8+I9 -> 5 | J10: 13 | K10: 19 | L10: 40 | M10: 69 | N10: 42
C11: Single | E11: 7 | F11: 4 | G11: 2 | H11: 7 | I11: 4 | J11: 7 | K11: 4 | L11: 7 | M11: 7 | N11: 16
C12: Combined | E12: 0
B13: Year II | C13: Sub-Total: | E13: 7 | F13: 4 | G13: 2 | H13: =H11+H12 -> 7 | I13: =I11+I12 -> 4 | J13: 7 | K13: 4 | L13: 7 | M13: 7 | N13: 16
C14: Gen/Integ. Studies | E14: 0
C15: Total: | E15: 7 | F15: 4 | G15: 2 | H15: =H13+H14 -> 7 | I15: =I13+I14 -> 4 | J15: 7 | K15: 4 | L15: 7 | M15: 7 | N15: 16
C16: Single | E16: 3 | F16: 5 | G16: 4 | H16: 4 | I16: 6 | J16: 2 | K16: 4 | L16: 5 | M16: 9 | N16: 7
C17: Combined | E17: 0
B18: Year III | C18: Sub-Total: | E18: 3 | F18: 5 | G18: 4 | H18: =H16+H17 -> 4 | I18: =I16+I17 -> 6 | J18: 2 | K18: 4 | L18: 5 | M18: 9 | N18: 7
C19: Gen/Integ. Studies | E19: 0
C20: Total: | E20: 3 | F20: 5 | G20: 4 | H20: =H18+H19 -> 4 | I20: =I18+I19 -> 6 | J20: 2 | K20: 4 | L20: 5 | M20: 9 | N20: 7
C21: Single | E21: 2 | F21: 2 | G21: 5 | H21: 4 | I21: 4 | J21: 6 | K21: 3 | L21: 3 | M21: 3 | N21: 3
C22: Combined | E22: 0
B23: Year IV | C23: Sub-Total: | E23: 2 | F23: 2 | G23: 5 | H23: =H21+H22 -> 4 | I23: =I21+I22 -> 4 | J23: 6 | K23: 3 | L23: 3 | M23: 3 | N23: 3
C24: Gen/Integ. Studies | E24: 0
C25: Total: | E25: 2 | F25: 2 | G25: 5 | H25: =H23+H24 -> 4 | I25: =I23+I24 -> 4 | J25: 6 | K25: 3 | L25: 3 | M25: 3 | N25: 3
C26: Single | E26: =SUM(E6,E11,E16,E21) -> 17 | F26: =SUM(F6,F11,F16,F21) -> 15 | G26: =SUM(G6,G11,G16,G21) -> 21 | H26: =SUM(H6,H11,H16,H21) -> 31 | I26: =SUM(I6,I11,I16,I21) -> 19 | J26: 28 | K26: 30 | L26: 55 | M26: 88 | N26: 68
C27: Combined | E27: 0
B28: TOTAL: | C28: Sub-Total: | E28: =SUM(E8,E13,E18,E23) -> 17 | F28: =SUM(F8,F13,F18,F23) -> 15 | G28: =SUM(G8,G13,G18,G23) -> 21 | H28: =SUM(H8,H13,H18,H23) -> 31 | I28: =SUM(I8,I13,I18,I23) -> 19 | J28: 28 | K28: 30 | L28: 55 | M28: 88 | N28: 68
C29: Gen/Integ. Studies | E29: 0
C30: Total: | E30: =SUM(E10,E15,E20,E25) -> 17 | F30: =SUM(F10,F15,F20,F25) -> 15 | G30: =SUM(G10,G15,G20,G25) -> 21 | H30: =SUM(H10,H15,H20,H25) -> 31 | I30: =SUM(I10,I15,I20,I25) -> 19 | J30: 28 | K30: 30 | L30: 55 | M30: 88 | N30: 68
B31: Male | E31: 14 | F31: 13 | G31: 18 | H31: 24 | I31: 14 | J31: 22 | K31: 20 | L31: 44 | M31: 63 | N31: 51 | O31: =N31/N30 -> 0.75
B32: Female | E32: 3 | F32: 2 | G32: 3 | H32: 7 | I32: 5 | J32: 6 | K32: 10 | L32: 11 | M32: 25 | N32: 17 | O32: =N32/N30 -> 0.25
B33: Full-Time | E33: 14 | F33: 13 | G33: 14 | H33: 25 | I33: 11 | J33: 25 | K33: 26 | L33: 52 | M33: 83 | N33: 66 | O33: =N33/N30 -> 0.97058824
B34: Part-Time | E34: 3 | F34: 2 | G34: 7 | H34: 6 | I34: 8 | J34: 3 | K34: 4 | L34: 3 | M34: 5 | N34: 2 | O34: =N34/N30 -> 0.029411765
B54: Codes: | C54: BECE, BECH, BEFE

Sheet CHYS-jb
B1: Undergraduate Majors
B2: Child and Youth Studies
B4: Study Year | C4: Major Type | H4: Head Count Enrolments
D5: 1999-00 | E5: 2000-01 | F5: 2001-02 | G5: 2002-03 | H5: 2003-04 | I5: 2004-05 | J5: 2005-06 | K5: 2006-07 | L5: 2007-08 | M5: 2008-09 | N5: 2011-12 | O5: 2012-13 | P5: 2013-14 | Q5: 2014-15 | R5: 2015-16
C6: Single | D6: 152 | E6: 181 | F6: 171 | G6: 186 | H6: 262 | I6: 174 | J6: 204 | K6: 184 | L6: 186 | M6: =96+91 -> 187 | N6: 217 | O6: 274 | P6: 226 | Q6: 216 | R6: 251
C7: Combined | D7: 1 | E7: 0 | F7: 0 | G7: 0 | H7: 2 | I7: 0 | M7: 1 | N7: 3 | O7: 2 | P7: 1 | Q7: 2 | R7: 1
B8: Year I | C8: Sub-Total: | D8: =D6+D7 -> 153 | E8: =E6+E7 -> 181 | F8: =F6+F7 -> 171 | G8: =G6+G7 -> 186 | H8: =H6+H7 -> 264 | I8: =I6+I7 -> 174 | J8: =J6+J7 -> 204 | K8: =K6+K7 -> 184 | ... M8: =M6+M7 -> 188 | N8: 220 | O8: 276 | P8: 227 | Q8: 218 | R8: 252
C9: Gen/Integ. Studies | D9: 0 | E9: 0 | F9: 0 | G9: 0 | H9: 0 | I9: 0
C10: Total: | D10: =D8+D9 -> 153 | E10: =E8+E9 -> 181 | F10: =F8+F9 -> 171 | G10: =G8+G9 -> 186 | H10: =H8+H9 -> 264 | I10: =I8+I9 -> 174 | J10: =J8+J9 -> 204 | K10: =K8+K9 -> 184 | ... M10: =M8+M9 -> 188 | N10: 220 | O10: 276 | P10: 227 | Q10: 218 | R10: 252
C11: Single | D11: 83 | E11: 114 | F11: 139 | G11: =140+61 -> 201 | H11: =61+143 -> 204 | I11: 197 | J11: 189 | K11: 211 | L11: 202 | M11: =3+150+37 -> 190 | N11: 238 | O11: 232 | P11: 243 | Q11: 220 | R11: 228
C12: Combined | D12: 17 | E12: 7 | F12: 7 | G12: 9 | H12: 12 | I12: 21 | J12: 9 | K12: 11 | L12: 17 | M12: =1+1+1+4+9 -> 16 | N12: 11 | O12: 6 | P12: 19 | Q12: 15 | R12: 8
B13: Year II | C13: Sub-Total: | D13: =D11+D12 -> 100 | E13: =E11+E12 -> 121 | F13: =F11+F12 -> 146 | G13: =G11+G12 -> 210 | H13: =H11+H12 -> 216 | I13: =I11+I12 -> 218 | J13: =J11+J12 -> 198 | K13: =K11+K12 -> 222 | ... M13: =M11+M12 -> 206 | N13: 249 | O13: 238 | P13: 262 | Q13: 235 | R13: 236
C14: Gen/Integ. Studies | D14: 0 | E14: 0 | F14: 0 | G14: 0 | H14: 0 | I14: 0 | J14: 1 | P14: 1
C15: Total: | D15: =D13+D14 -> 100 | E15: =E13+E14 -> 121 | F15: =F13+F14 -> 146 | G15: =G13+G14 -> 210 | H15: =H13+H14 -> 216 | I15: =I13+I14 -> 218 | J15: =J13+J14 -> 199 | K15: =K13+K14 -> 222 | ... M15: =M13+M14 -> 206 | N15: 249 | O15: 238 | P15: 263 | Q15: 235 | R15: 236
C16: Single | D16: 95 | E16: 161 | F16: 192 | G16: =165+65 -> 230 | H16: 231 | I16: 195 | J16: 212 | K16: 173 | L16: 194 | M16: =40+125 -> 165 | N16: 159 | O16: 198 | P16: 206 | Q16: 215 | R16: 187
C17: Combined | D17: 24 | E17: 29 | F17: 27 | G17: =7+13 -> 20 | H17: 18 | I17: 17 | J17: 25 | K17: 12 | L17: 18 | M17: =1+1+16+5 -> 23 | N17: 14 | O17: 13 | P17: 7 | Q17: 15 | R17: 14
B18: Year III | C18: Sub-Total: | D18: =D16+D17 -> 119 | E18: =E16+E17 -> 190 | F18: =F16+F17 -> 219 | G18: =G16+G17 -> 250 | H18: =H16+H17 -> 249 | I18: =I16+I17 -> 212 | J18: =J16+J17 -> 237 | K18: =K16+K17 -> 185 | ... M18: =M16+M17 -> 188 | N18: 173 | O18: 211 | P18: 213 | Q18: 230 | R18: 201
C19: Gen/Integ. Studies | D19: 1 | E19: 0 | F19: 0 | G19: 0 | H19: 0 | I19: 0 | K19: 1 | N19: 1 | P19: 1 | Q19: 2
C20: Total: | D20: =D18+D19 -> 120 | E20: =E18+E19 -> 190 | F20: =F18+F19 -> 219 | G20: =G18+G19 -> 250 | H20: =H18+H19 -> 249 | I20: =I18+I19 -> 212 | J20: =J18+J19 -> 237 | K20: =K18+K19 -> 186 | ... M20: =M18+M19 -> 188 | N20: 174 | O20: 211 | P20: 214 | Q20: 232 | R20: 201
C21: Single | D21: 39 | E21: 129 | F21: 148 | G21: =54+53 -> 107 | H21: =60+87 -> 147 | I21: 142 | J21: 153 | K21: 182 | L21: 161 | M21: =48+123 -> 171 | N21: 149 | O21: 146 | P21: 194 | Q21: 188 | R21: 210
C22: Combined | D22: 13 | E22: 13 | F22: 11 | G22: 9 | H22: 7 | I22: 5 | J22: 5 | K22: 13 | L22: 8 | M22: =1+1+1+6+5 -> 14 | N22: 11 | O22: 9 | P22: 9 | Q22: 8 | R22: 12
B23: Year IV | C23: Sub-Total: | D23: =D21+D22 -> 52 | E23: =E21+E22 -> 142 | F23: =F21+F22 -> 159 | G23: =G21+G22 -> 116 | H23: =H21+H22 -> 154 | I23: =I21+I22 -> 147 | J23: =J21+J22 -> 158 | K23: =K21+K22 -> 195 | ... M23: =M21+M22 -> 185 | N23: 160 | O23: 155 | P23: 203 | Q23: 196 | R23: 222
C24: Gen/Integ. Studies | D24: 0 | E24: 0 | F24: 0 | G24: 0 | H24: 0 | I24: 0 | M24: 1 | Q24: 1 | R24: 1
C25: Total: | D25: =D23+D24 -> 52 | E25: =E23+E24 -> 142 | F25: =F23+F24 -> 159 | G25: =G23+G24 -> 116 | H25: =H23+H24 -> 154 | I25: =I23+I24 -> 147 | J25: =J23+J24 -> 158 | K25: =K23+K24 -> 195 | ... M25: =M23+M24 -> 186 | N25: 160 | O25: 155 | P25: 203 | Q25: 197 | R25: 223
C26: Single | D26: =SUM(D6,D11,D16,D21) -> 369 | E26: =SUM(E6,E11,E16,E21) -> 585 | F26: =SUM(F6,F11,F16,F21) -> 650 | G26: =SUM(G6,G11,G16,G21) -> 724 | H26: =SUM(H6,H11,H16,H21) -> 844 | I26: =SUM(I6,I11,I16,I21) -> 708 | J26: =SUM(J6,J11,J16,J21) -> 758 | K26: =SUM(K6,K11,K16,K21) -> 750 | ... M26: =SUM(M6,M11,M16,M21) -> 713 | N26: 763 | O26: 850 | P26: 869 | Q26: 839 | R26: 876
C27: Combined | D27: =SUM(D7,D12,D17,D22) -> 55 | E27: =SUM(E7,E12,E17,E22) -> 49 | F27: =SUM(F7,F12,F17,F22) -> 45 | G27: =SUM(G7,G12,G17,G22) -> 38 | H27: =SUM(H7,H12,H17,H22) -> 39 | I27: =SUM(I7,I12,I17,I22) -> 43 | J27: =SUM(J7,J12,J17,J22) -> 39 | K27: =SUM(K7,K12,K17,K22) -> 36 | ... M27: =SUM(M7,M12,M17,M22) -> 54 | N27: 39 | O27: 30 | P27: 36 | Q27: 40 | R27: 35
B28: TOTAL: | C28: Sub-Total: | D28: =D26+D27 -> 424 | E28: =E26+E27 -> 634 | F28: =F26+F27 -> 695 | G28: =G26+G27 -> 762 | H28: =H26+H27 -> 883 | I28: =I26+I27 -> 751 | J28: =J26+J27 -> 797 | K28: =K26+K27 -> 786 | ... M28: =M26+M27 -> 767 | N28: 802 | O28: 880 | P28: 905 | Q28: 879 | R28: 911
C29: Gen/Integ. Studies | D29: =SUM(D9,D14,D19,D24) -> 1 | E29: =SUM(E9,E14,E19,E24) -> 0 | F29: =SUM(F9,F14,F19,F24) -> 0 | G29: =SUM(G9,G14,G19,G24) -> 0 | H29: =SUM(H9,H14,H19,H24) -> 0 | I29: =SUM(I9,I14,I19,I24) -> 0 | J29: =SUM(J9,J14,J19,J24) -> 1 | K29: =SUM(K9,K14,K19,K24) -> 1 | M29: =SUM(M9,M14,M19,M24) -> 1 | N29: 1 | P29: 2 | Q29: 3 | R29: 1
C30: Total: | D30: =D28+D29 -> 425 | E30: =E28+E29 -> 634 | F30: =F28+F29 -> 695 | G30: =G28+G29 -> 762 | H30: =H28+H29 -> 883 | I30: =I28+I29 -> 751 | J30: =J28+J29 -> 798 | K30: =K28+K29 -> 787 | ... M30: =M28+M29 -> 768 | N30: 803 | O30: 880 | P30: 907 | Q30: 882 | R30: 912
B31: Male | D31: 13 | E31: 18 | F31: 19 | G31: 17 | H31: 19 | I31: 16 | J31: 13 | K31: 19 | L31: 21 | M31: 18 | N31: 23 | O31: 34 | P31: 48 | Q31: 49 | R31: 49 | S31: =R31/R30 -> 0.05372807
B32: Female | D32: 412 | E32: 616 | F32: 676 | G32: 745 | H32: 864 | I32: 735 | J32: 785 | K32: 768 | L32: 765 | M32: 750 | N32: 780 | O32: 846 | P32: 859 | Q32: 833 | R32: 863 | S32: =R32/R30 -> 0.94627193
B33: Full-Time | D33: 413 | E33: 614 | F33: 677 | G33: 736 | H33: 851 | I33: 712 | J33: 757 | K33: 754 | L33: 733 | M33: 717 | N33: 770 | O33: 846 | P33: 876 | Q33: 853 | R33: 880 | S33: =R33/R30 -> 0.96491228
B34: Part-Time | D34: 12 | E34: 20 | F34: 18 | G34: 26 | H34: 32 | I34: 39 | J34: 41 | K34: 33 | L34: 53 | M34: 51 | N34: 33 | O34: 34 | P34: 31 | Q34: 29 | R34: 32 | S34: =R34/R30 -> 0.035087719
B54: Codes: | C54: CHED
C55: CHLD
C56: CHYN
C57: CHYS
C58: CYED

Sheet CPCF-jb
B1: Undergraduate Majors
B2: Communications, Popular Culture and Film
B4: Study Year | C4: Major Type | D4: Head Count Enrolments (Including Coop)
D5: 2003-04 | E5: 2004-05 | F5: 2005-06 | G5: 2006-07 | H5: 2007-08 | I5: 2008-09 | J5: 2011-12 | K5: 2012-13 | L5: 2013-14 | M5: 2014-15 | N5: 2015-16
C6: Single | D6: =SUM('COMM-jb'!H6,'FILM-jb'!H6,'PCUL-jb'!H6) -> 203 | E6: =SUM('COMM-jb'!I6,'FILM-jb'!I6,'PCUL-jb'!I6) -> 250 | F6: 238 | G6: 213 | H6: 194 | I6: 209 | J6: 217 | K6: 295 | L6: 307 | M6: 303 | N6: 268
C7: Combined | D7: =SUM('COMM-jb'!H7,'FILM-jb'!H7,'PCUL-jb'!H7) -> 1 | E7: =SUM('COMM-jb'!I7,'FILM-jb'!I7,'PCUL-jb'!I7) -> 1 | G7: 1 | H7: 1 | N7: 1
B8: Year I | C8: Sub-Total: | D8: =D6+D7 -> 204 | E8: =E6+E7 -> 251 | F8: =F6+F7 -> 238 | G8: =G6+G7 -> 214 | H8: =H6+H7 -> 195 | I8: =I6+I7 -> 209 | J8: 217 | K8: 295 | L8: 307 | M8: 303 | N8: 269
C9: Gen/Integ. Studies | D9: =SUM('COMM-jb'!H9,'FILM-jb'!H9,'PCUL-jb'!H9) -> 0 | E9: =SUM('COMM-jb'!I9,'FILM-jb'!I9,'PCUL-jb'!I9) -> 0
C10: Total: | D10: =D8+D9 -> 204 | E10: =E8+E9 -> 251 | F10: =F8+F9 -> 238 | G10: =G8+G9 -> 214 | H10: =H8+H9 -> 195 | I10: =I8+I9 -> 209 | J10: 217 | K10: 295 | L10: 307 | M10: 303 | N10: 269
C11: Single | D11: =SUM('COMM-jb'!H11,'FILM-jb'!H11,'PCUL-jb'!H11) -> 158 | E11: =SUM('COMM-jb'!I11,'FILM-jb'!I11,'PCUL-jb'!I11) -> 244 | F11: 200 | G11: 193 | H11: 166 | I11: 153 | J11: 172 | K11: 150 | L11: 199 | M11: 183 | N11: 206
C12: Combined | D12: 6 | E12: ='COMM-jb'!I12+'FILM-jb'!I12+'PCUL-jb'!I12 -> 9 | F12: 6 | G12: 2 | H12: 2 | I12: 1 | J12: 1 | K12: 2 | L12: 1 | M12: 1 | N12: 1
B13: Year II | C13: Sub-Total: | D13: =D11+D12 -> 164 | E13: =E11+E12 -> 253 | F13: =F11+F12 -> 206 | G13: =G11+G12 -> 195 | H13: =H11+H12 -> 168 | I13: =I11+I12 -> 154 | J13: 173 | K13: 152 | L13: 200 | M13: 184 | N13: 207
C14: Gen/Integ. Studies | D14: =SUM('COMM-jb'!H14,'FILM-jb'!H14,'PCUL-jb'!H14) -> 0 | E14: =SUM('COMM-jb'!I14,'FILM-jb'!I14,'PCUL-jb'!I14) -> 0
C15: Total: | D15: =D13+D14 -> 164 | E15: =E13+E14 -> 253 | F15: =F13+F14 -> 206 | G15: =G13+G14 -> 195 | H15: =H13+H14 -> 168 | I15: =I13+I14 -> 154 | J15: 173 | K15: 152 | L15: 200 | M15: 184 | N15: 207
C16: Single | D16: =SUM('COMM-jb'!H16,'FILM-jb'!H16,'PCUL-jb'!H16) -> 141 | E16: =SUM('COMM-jb'!I16,'FILM-jb'!I16,'PCUL-jb'!I16) -> 140 | F16: 193 | G16: 168 | H16: 153 | I16: 125 | J16: 140 | K16: 150 | L16: 119 | M16: 153 | N16: 147
C17: Combined | D17: =SUM('COMM-jb'!H17,'FILM-jb'!H17,'PCUL-jb'!H17) -> 6 | E17: =SUM('COMM-jb'!I17,'FILM-jb'!I17,'PCUL-jb'!I17) -> 11 | F17: 6 | G17: 5 | H17: 2 | I17: 1 | J17: 2 | K17: 2 | L17: 2 | M17: 1
B18: Year III | C18: Sub-Total: | D18: =D16+D17 -> 147 | E18: =E16+E17 -> 151 | F18: =F16+F17 -> 199 | G18: =G16+G17 -> 173 | H18: =H16+H17 -> 155 | I18: =I16+I17 -> 126 | J18: 142 | K18: 152 | L18: 121 | M18: 154 | N18: 147
C19: Gen/Integ. Studies | D19: =SUM('COMM-jb'!H19,'FILM-jb'!H19,'PCUL-jb'!H19) -> 0 | E19: =SUM('COMM-jb'!I19,'FILM-jb'!I19,'PCUL-jb'!I19) -> 1
C20: Total: | D20: =D18+D19 -> 147 | E20: =E18+E19 -> 152 | F20: =F18+F19 -> 199 | G20: =G18+G19 -> 173 | H20: =H18+H19 -> 155 | I20: =I18+I19 -> 126 | J20: 142 | K20: 152 | L20: 121 | M20: 154 | N20: 147
C21: Single | D21: =SUM('COMM-jb'!H21,'FILM-jb'!H21,'PCUL-jb'!H21) -> 93 | E21: =SUM('COMM-jb'!I21,'FILM-jb'!I21,'PCUL-jb'!I21) -> 45 | F21: 89 | G21: 87 | H21: 72 | I21: 68 | J21: 76 | K21: 66 | L21: 60 | M21: 72 | N21: 103
C22: Combined | D22: =SUM('COMM-jb'!H22,'FILM-jb'!H22,'PCUL-jb'!H22) -> 10 | E22: =SUM('COMM-jb'!I22,'FILM-jb'!I22,'PCUL-jb'!I22) -> 2 | F22: 9 | G22: 6 | H22: 3 | I22: 2 | J22: 1 | K22: 3 | M22: 2 | N22: 1
B23: Year IV | C23: Sub-Total: | D23: =D21+D22 -> 103 | E23: =E21+E22 -> 47 | F23: =F21+F22 -> 98 | G23: =G21+G22 -> 93 | H23: =H21+H22 -> 75 | I23: =I21+I22 -> 70 | J23: 77 | K23: 69 | L23: 60 | M23: 74 | N23: 104
C24: Gen/Integ. Studies | D24: =SUM('COMM-jb'!H24,'FILM-jb'!H24,'PCUL-jb'!H24) -> 0 | E24: =SUM('COMM-jb'!I24,'FILM-jb'!I24,'PCUL-jb'!I24) -> 0
C25: Total: | D25: =D23+D24 -> 103 | E25: =E23+E24 -> 47 | F25: =F23+F24 -> 98 | G25: =G23+G24 -> 93 | H25: =H23+H24 -> 75 | I25: =I23+I24 -> 70 | J25: 77 | K25: 69 | L25: 60 | M25: 74 | N25: 104
C26: Single | D26: =SUM(D6,D11,D16,D21) -> 595 | E26: =SUM(E6,E11,E16,E21) -> 679 | F26: =SUM(F6,F11,F16,F21) -> 720 | G26: =SUM(G6,G11,G16,G21) -> 661 | H26: =SUM(H6,H11,H16,H21) -> 585 | I26: =SUM(I6,I11,I16,I21) -> 555 | J26: 605 | K26: 661 | L26: 685 | M26: 711 | N26: 724
C27: Combined | D27: =SUM(D7,D12,D17,D22) -> 23 | E27: =SUM(E7,E12,E17,E22) -> 23 | F27: =SUM(F7,F12,F17,F22) -> 21 | G27: =SUM(G7,G12,G17,G22) -> 14 | H27: =SUM(H7,H12,H17,H22) -> 8 | I27: =SUM(I7,I12,I17,I22) -> 4 | J27: 4 | K27: 7 | L27: 3 | M27: 4 | N27: 3
B28: TOTAL: | C28: Sub-Total: | D28: =SUM(D8,D13,D18,D23) -> 618 | E28: =SUM(E8,E13,E18,E23) -> 702 | F28: =SUM(F8,F13,F18,F23) -> 741 | G28: =SUM(G8,G13,G18,G23) -> 675 | H28: =SUM(H8,H13,H18,H23) -> 593 | I28: =SUM(I8,I13,I18,I23) -> 559 | J28: 609 | K28: 668 | L28: 688 | M28: 715 | N28: 727
C29: Gen/Integ. Studies | D29: =SUM(D9,D14,D19,D24) -> 0 | E29: =SUM(E9,E14,E19,E24) -> 1
C30: Total: | D30: =SUM(D10,D15,D20,D25) -> 618 | E30: =SUM(E10,E15,E20,E25) -> 703 | F30: =SUM(F10,F15,F20,F25) -> 741 | G30: =SUM(G10,G15,G20,G25) -> 675 | H30: =SUM(H10,H15,H20,H25) -> 593 | I30: =SUM(I10,I15,I20,I25) -> 559 | J30: 609 | K30: 668 | L30: 688 | M30: 715 | N30: 727
B31: Male | D31: 222 | E31: 274 | F31: 305 | G31: 288 | H31: 220 | I31: 231 | J31: 286 | K31: 313 | L31: 328 | M31: 349 | N31: 342 | O31: =N31/N30 -> 0.47042641
B32: Female | D32: 396 | E32: 429 | F32: 436 | G32: 387 | H32: 373 | I32: 328 | J32: 323 | K32: 355 | L32: 360 | M32: 366 | N32: 385 | O32: =N32/N30 -> 0.52957359
B33: Full-Time | D33: 560 | E33: 643 | F33: 675 | G33: 616 | H33: 537 | I33: 514 | J33: 552 | K33: 599 | L33: 641 | M33: 667 | N33: 685 | O33: =N33/N30 -> 0.94222834
B34: Part-Time | D34: 58 | E34: 60 | F34: 66 | G34: 59 | H34: 56 | I34: 45 | J34: 57 | K34: 69 | L34: 47 | M34: 48 | N34: 42 | O34: =N34/N30 -> 0.057771664
B35: *Coop not offered to new students starting in 2007-08. No students were registered in the coop option starting in 2011-12.

Sheet CPCF (COOP)-jb
B1: Undergraduate Majors
B2: Communications, Popular Culture and Film
B3: COOP
B4: Study Year | C4: Major Type | D4: Head Count Enrollments (Coop Only)
D5: 2003-04 | E5: 2004-05 | F5: 2005-06 | G5: 2006-07 | H5: 2007-08 | I5: 2008-09 | J5: 2011-12 | K5: 2012-13 | L5: 2013-14 | M5: 2014-15 | N5: 2015-16
C6: Single | D6: Coop data not available | E6: 41 | F6: 46 | G6: 34 | H6: 1
C7: Combined | E7: 0
B8: Year I | C8: Sub-Total: | E8: 41 | F8: 46 | G8: 34 | H8: =H6+H7 -> 1
C9: Gen/Integ. Studies | E9: 0
C10: Total: | E10: 41 | F10: 46 | G10: 34 | H10: =H8+H9 -> 1
C11: Single | E11: 18 | F11: 15 | G11: 12 | H11: 7 | I11: 1
C12: Combined | E12: 0
B13: Year II | C13: Sub-Total: | E13: 18 | F13: 15 | G13: 12 | H13: =H11+H12 -> 7 | I13: =I11+I12 -> 1
C14: Gen/Integ. Studies | E14: 0
C15: Total: | E15: 18 | F15: 15 | G15: 12 | H15: =H13+H14 -> 7 | I15: =I13+I14 -> 1
C16: Single | E16: 18 | F16: 7 | G16: 13 | H16: 12 | I16: 6
C17: Combined | E17: 0
B18: Year III | C18: Sub-Total: | E18: 18 | F18: 7 | G18: 13 | H18: =H16+H17 -> 12 | I18: =I16+I17 -> 6
C19: Gen/Integ. Studies | E19: 0
C20: Total: | E20: 18 | F20: 7 | G20: 13 | H20: =H18+H19 -> 12 | I20: =I18+I19 -> 6
C21: Single | E21: 11 | F21: 13 | G21: 2 | H21: 3 | I21: 4
C22: Combined | E22: 0
B23: Year IV | C23: Sub-Total: | E23: 11 | F23: 13 | G23: 2 | H23: =H21+H22 -> 3 | I23: =I21+I22 -> 4
C24: Gen/Integ. Studies | E24: 0
C25: Total: | E25: 11 | F25: 13 | G25: 2 | H25: =H23+H24 -> 3 | I25: =I23+I24 -> 4
C26: Single | E26: =SUM(E6,E11,E16,E21) -> 88 | F26: =SUM(F6,F11,F16,F21) -> 81 | G26: =SUM(G6,G11,G16,G21) -> 61 | H26: =SUM(H6,H11,H16,H21) -> 23 | I26: =SUM(I6,I11,I16,I21) -> 11
C27: Combined | E27: 0
B28: TOTAL: | C28: Sub-Total: | E28: =SUM(E8,E13,E18,E23) -> 88 | F28: =SUM(F8,F13,F18,F23) -> 81 | G28: =SUM(G8,G13,G18,G23) -> 61 | H28: =SUM(H8,H13,H18,H23) -> 23 | I28: =SUM(I8,I13,I18,I23) -> 11
C29: Gen/Integ. Studies | E29: 0
C30: Total: | E30: =SUM(E10,E15,E20,E25) -> 88 | F30: =SUM(F10,F15,F20,F25) -> 81 | G30: =SUM(G10,G15,G20,G25) -> 61 | H30: =SUM(H10,H15,H20,H25) -> 23 | I30: =SUM(I10,I15,I20,I25) -> 11
B31: Male | E31: 17 | F31: 22 | G31: 14 | H31: 8 | I31: 5
B32: Female | E32: 71 | F32: 59 | G32: 47 | H32: 15 | I32: 6
B33: Full-Time | E33: 74 | F33: 73 | G33: 52 | H33: 15 | I33: 7
B34: Part-Time | E34: 14 | F34: 8 | G34: 9 | H34: 8 | I34: 4
B35: *Coop not offered to new students starting in 2007-08. No students were registered in the coop option starting in 2011-12.

Sheet COMM-jb
B1: Undergraduate Majors
B2: [Communication Studies]
B4: Study Year | C4: Major Type | H4: Head Count Enrolments
D5: 1999-00 | E5: 2000-01 | F5: 2001-02 | G5: 2002-03 | H5: 2003-04 | I5: 2004-05 | J5: 2005-06 | K5: 2006-07 | L5: 2007-08 | M5: 2008-09 | N5: 2011-12 | O5: 2012-13 | P5: 2013-14 | Q5: 2014-15 | R5: 2015-16
C6: Single | D6: =81+2 -> 83 | E6: =1+65 -> 66 | F6: =53+13+28 -> 94 | G6: =43+48 -> 91 | H6: =49+46+7 -> 102 | I6: 162 | J6: 146 | K6: 137 | L6: 132 | M6: =72+4+53 -> 129 | N6: 142 | O6: 211 | P6: 242 | Q6: 261 | R6: 228
C7: Combined | D7: 0 | E7: 1 | F7: 1 | G7: 1 | H7: 0 | I7: 0
B8: Year I | C8: Sub-Total: | D8: =D6+D7 -> 83 | E8: =E6+E7 -> 67 | F8: =F6+F7 -> 95 | G8: =G6+G7 -> 92 | H8: =H6+H7 -> 102 | I8: =I6+I7 -> 162 | J8: =J6+J7 -> 146 | K8: =K6+K7 -> 137 | ... M8: =M6+M7 -> 129 | N8: 142 | O8: 211 | P8: 242 | Q8: 261 | R8: 228
C9: Gen/Integ. Studies | D9: 0 | E9: 0 | F9: 0 | G9: 0 | H9: 0 | I9: 0
C10: Total: | D10: =D8+D9 -> 83 | E10: =E8+E9 -> 67 | F10: =F8+F9 -> 95 | G10: =G8+G9 -> 92 | H10: =H8+H9 -> 102 | I10: =I8+I9 -> 162 | J10: =J8+J9 -> 146 | K10: =K8+K9 -> 137 | ... M10: =M8+M9 -> 129 | N10: 142 | O10: 211 | P10: 242 | Q10: 261 | R10: 228
C11: Single | D11: =94+0 -> 94 | E11: =1+100 -> 101 | F11: =76+40 -> 116 | G11: =56+37+5 -> 98 | H11: =67+42+1 -> 110 | I11: 146 | J11: 118 | K11: 125 | L11: 104 | M11: =60+3+37 -> 100 | N11: 131 | O11: 106 | P11: 143 | Q11: 144 | R11: 172
C12: Combined | D12: 3 | E12: 8 | F12: 5 | G12: 4 | H12: 3 | I12: 0
B13: Year II | C13: Sub-Total: | D13: =D11+D12 -> 97 | E13: =E11+E12 -> 109 | F13: =F11+F12 -> 121 | G13: =G11+G12 -> 102 | H13: =H11+H12 -> 113 | I13: =I11+I12 -> 146 | J13: =J11+J12 -> 118 | K13: =K11+K12 -> 125 | ... M13: =M11+M12 -> 100 | N13: 131 | O13: 106 | P13: 143 | Q13: 144 | R13: 172
C14: Gen/Integ. Studies | D14: 0 | E14: 0 | F14: 0 | G14: 0 | H14: 0 | I14: 0
C15: Total: | D15: =D13+D14 -> 97 | E15: =E13+E14 -> 109 | F15: =F13+F14 -> 121 | G15: =G13+G14 -> 102 | H15: =H13+H14 -> 113 | I15: =I13+I14 -> 146 | J15: =J13+J14 -> 118 | K15: =K13+K14 -> 125 | ... M15: =M13+M14 -> 100 | N15: 131 | O15: 106 | P15: 143 | Q15: 144 | R15: 172
C16: Single | D16: 131 | E16: =0+107 -> 107 | F16: =75+48 -> 123 | G16: =68+47+4 -> 119 | H16: =66+48 -> 114 | I16: 109 | J16: 118 | K16: 104 | L16: 99 | M16: =47+5+27 -> 79 | N16: 93 | O16: 115 | P16: 87 | Q16: 109 | R16: 118
C17: Combined | D17: 12 | E17: 3 | F17: 8 | G17: 4 | H17: 4 | I17: 7 | J17: 3
B18: Year III | C18: Sub-Total: | D18: =D16+D17 -> 143 | E18: =E16+E17 -> 110 | F18: =F16+F17 -> 131 | G18: =G16+G17 -> 123 | H18: =H16+H17 -> 118 | I18: =I16+I17 -> 116 | J18: =J16+J17 -> 121 | K18: =K16+K17 -> 104 | ... M18: =M16+M17 -> 79 | N18: 93 | O18: 115 | P18: 87 | Q18: 109 | R18: 118
C19: Gen/Integ. Studies | D19: 0 | E19: 0 | F19: 0 | G19: 0 | H19: 0 | I19: 0
C20: Total: | D20: =D18+D19 -> 143 | E20: =E18+E19 -> 110 | F20: =F18+F19 -> 131 | G20: =G18+G19 -> 123 | H20: =H18+H19 -> 118 | I20: =I18+I19 -> 116 | J20: =J18+J19 -> 121 | K20: =K18+K19 -> 104 | ... M20: =M18+M19 -> 79 | N20: 93 | O20: 115 | P20: 87 | Q20: 109 | R20: 118
C21: Single | D21: 32 | E21: =0+49 -> 49 | F21: =42+26 -> 68 | G21: =49+19+8 -> 76 | H21: =51+24 -> 75 | I21: 37 | J21: 73 | K21: 59 | L21: 51 | M21: =31+2+13 -> 46 | N21: 54 | O21: 44 | P21: 45 | Q21: 46 | R21: 72
C22: Combined | D22: 4 | E22: 6 | F22: 3 | G22: 7 | H22: 6 | I22: 1 | J22: 6 | K22: 3 | L22: 1 | M22: 1
B23: Year IV | C23: Sub-Total: | D23: =D21+D22 -> 36 | E23: =E21+E22 -> 55 | F23: =F21+F22 -> 71 | G23: =G21+G22 -> 83 | H23: =H21+H22 -> 81 | I23: =I21+I22 -> 38 | J23: =J21+J22 -> 79 | K23: =K21+K22 -> 62 | ... M23: =M21+M22 -> 47 | N23: 54 | O23: 44 | P23: 45 | Q23: 46 | R23: 72
C24: Gen/Integ. Studies | D24: 0 | E24: 0 | F24: 0 | G24: 0 | H24: 0 | I24: 0
C25: Total: | D25: =D23+D24 -> 36 | E25: =E23+E24 -> 55 | F25: =F23+F24 -> 71 | G25: =G23+G24 -> 83 | H25: =H23+H24 -> 81 | I25: =I23+I24 -> 38 | J25: =J23+J24 -> 79 | K25: =K23+K24 -> 62 | ... M25: =M23+M24 -> 47 | N25: 54 | O25: 44 | P25: 45 | Q25: 46 | R25: 72
C26: Single | D26: =SUM(D6,D11,D16,D21) -> 340 | E26: =SUM(E6,E11,E16,E21) -> 323 | F26: =SUM(F6,F11,F16,F21) -> 401 | G26: =SUM(G6,G11,G16,G21) -> 384 | H26: =SUM(H6,H11,H16,H21) -> 401 | I26: =SUM(I6,I11,I16,I21) -> 454 | J26: =SUM(J6,J11,J16,J21) -> 455 | K26: =SUM(K6,K11,K16,K21) -> 425 | ... M26: =SUM(M6,M11,M16,M21) -> 354 | N26: 420 | O26: 476 | P26: 517 | Q26: 560 | R26: 590
C27: Combined | D27: =SUM(D7,D12,D17,D22) -> 19 | E27: =SUM(E7,E12,E17,E22) -> 18 | F27: =SUM(F7,F12,F17,F22) -> 17 | G27: =SUM(G7,G12,G17,G22) -> 16 | H27: =SUM(H7,H12,H17,H22) -> 13 | I27: =SUM(I7,I12,I17,I22) -> 8 | J27: =SUM(J7,J12,J17,J22) -> 9 | K27: =SUM(K7,K12,K17,K22) -> 3 | ... M27: =SUM(M7,M12,M17,M22) -> 1
B28: TOTAL: | C28: Sub-Total: | D28: =D26+D27 -> 359 | E28: =E26+E27 -> 341 | F28: =SUM(F8,F13,F18,F23) -> 418 | G28: =SUM(G8,G13,G18,G23) -> 400 | H28: =SUM(H8,H13,H18,H23) -> 414 | I28: =SUM(I8,I13,I18,I23) -> 462 | J28: =SUM(J8,J13,J18,J23) -> 464 | K28: =SUM(K8,K13,K18,K23) -> 428 | L28: =SUM(L8,L13,L18,L23) -> 387 | M28: =SUM(M8,M13,M18,M23) -> 355 | N28: 420 | O28: 476 | P28: 517 | Q28: 560 | R28: 590
C29: Gen/Integ. Studies | D29: =SUM(D9,D14,D19,D24) -> 0 | E29: =SUM(E9,E14,E19,E24) -> 0 | F29: =SUM(F9,F14,F19,F24) -> 0 | G29: =SUM(G9,G14,G19,G24) -> 0 | H29: =SUM(H9,H14,H19,H24) -> 0 | I29: =SUM(I9,I14,I19,I24) -> 0
C30: Total: | D30: =D28+D29 -> 359 | E30: =E28+E29 -> 341 | F30: =SUM(F10,F15,F20,F25) -> 418 | G30: =SUM(G10,G15,G20,G25) -> 400 | H30: =SUM(H10,H15,H20,H25) -> 414 | I30: =SUM(I10,I15,I20,I25) -> 462 | J30: =SUM(J10,J15,J20,J25) -> 464 | K30: =SUM(K10,K15,K20,K25) -> 428 | L30: =SUM(L10,L15,L20,L25) -> 387 | M30: =SUM(M10,M15,M20,M25) -> 355 | N30: 420 | O30: 476 | P30: 517 | Q30: 560 | R30: 590
B31: Male | D31: =150+9 -> 159 | E31: =10+131 -> 141 | F31: =157+9 -> 166 | G31: 142 | H31: =78+43+5 -> 126 | I31: 157 | J31: 178 | K31: 175 | L31: 129 | M31: =94+11+32+1 -> 138 | N31: 181 | O31: 218 | P31: 242 | Q31: 267 | R31: 270 | S31: =R31/R30 -> 0.45762712
B32: Female | D32: =188+12 -> 200 | E32: =10+190 -> 200 | F32: =244+8 -> 252 | G32: 258 | H32: =414-126 -> 288 | I32: 305 | J32: 286 | K32: 253 | L32: 258 | M32: =116+3+98 -> 217 | N32: 239 | O32: 258 | P32: 275 | Q32: 293 | R32: 320 | S32: =R32/R30 -> 0.54237288
B33: Full-Time | D33: =311+19 -> 330 | E33: =18+301 -> 319 | F33: =207+18+119+17+11 -> 372 | G33: =400-55 -> 345 | H33: =414-51 -> 363 | I33: 417 | J33: 419 | K33: 392 | L33: 349 | M33: =193+11+124+1 -> 329 | N33: 385 | O33: 426 | P33: 480 | Q33: 526 | R33: 559 | S33: =R33/R30 -> 0.94745763
B34: Part-Time | D34: 19 | E34: 22 | F34: 46 | G34: 55 | H34: =32+18+1 -> 51 | I34: 45 | J34: 45 | K34: 36 | L34: 38 | M34: =17+3+6 -> 26 | N34: 35 | O34: 50 | P34: 37 | Q34: 34 | R34: 31 | S34: =R34/R30 -> 0.052542373
B54: Codes: | C54: BCMN
C55: CJCM
C56: COMM
C57: COMS
C58: CSBC
C59: CSCL
C60: CSIN
...

Sheet FILM-jb
B1: Undergraduate Majors
B2: [Film Studies]
B4: Study Year | C4: Major Type | H4: Head Count Enrolments
D5: 1999-00 | E5: 2000-01 | F5: 2001-02 | G5: 2002-03 | H5: 2003-04 | I5: 2004-05 | J5: 2005-06 | K5: 2006-07 | L5: 2007-08 | M5: 2008-09 | N5: 2011-12 | O5: 2012-13 | P5: 2013-14 | Q5: 2014-15 | R5: 2015-16
C6: Single | D6: 34 | E6: 28 | F6: 26 | G6: 40 | H6: 61 | I6: 56 | J6: 58 | K6: 40 | L6: 32 | M6: 48 | N6: 58 | O6: 64 | P6: 54 | Q6: 34 | R6: 36
C7: Combined | D7: 0 | E7: 1 | F7: 1 | G7: 1 | H7: 1 | I7: 1 | K7: 1 | L7: 1 | R7: 1
B8: Year I | C8: Sub-Total: | D8: =D6+D7 -> 34 | E8: =E6+E7 -> 29 | F8: =F6+F7 -> 27 | G8: =G6+G7 -> 41 | H8: =H6+H7 -> 62 | I8: =I6+I7 -> 57 | J8: =J6+J7 -> 58 | K8: =K6+K7 -> 41 | ... M8: =M6+M7 -> 48 | N8: 58 | O8: 64 | P8: 54 | Q8: 34 | R8: 37
C9: Gen/Integ. Studies | D9: 0 | E9: 0 | F9: 0 | G9: 0 | H9: 0 | I9: 0
C10: Total: | D10: =D8+D9 -> 34 | E10: =E8+E9 -> 29 | F10: =F8+F9 -> 27 | G10: =G8+G9 -> 41 | H10: =H8+H9 -> 62 | I10: =I8+I9 -> 57 | J10: =J8+J9 -> 58 | K10: =K8+K9 -> 41 | ... M10: =M8+M9 -> 48 | N10: 58 | O10: 64 | P10: 54 | Q10: 34 | R10: 37
C11: Single | D11: 12 | E11: 20 | F11: 17 | G11: 20 | H11: 33 | I11: 59 | J11: 42 | K11: 30 | L11: 29 | M11: 22 | N11: 33 | O11: 28 | P11: 41 | Q11: 28 | R11: 23
C12: Combined | D12: 2 | E12: 7 | F12: 2 | G12: 4 | H12: 4 | I12: 7 | J12: 5 | K12: 2 | L12: 2 | M12: 1 | N12: 1 | O12: 2 | P12: 1 | Q12: 1 | R12: 1
B13: Year II | C13: Sub-Total: | D13: =D11+D12 -> 14 | E13: =E11+E12 -> 27 | F13: =F11+F12 -> 19 | G13: =G11+G12 -> 24 | H13: =H11+H12 -> 37 | I13: =I11+I12 -> 66 | J13: =J11+J12 -> 47 | K13: =K11+K12 -> 32 | ... M13: =M11+M12 -> 23 | N13: 34 | O13: 30 | P13: 42 | Q13: 29 | R13: 24
C14: Gen/Integ. Studies | D14: 0 | E14: 0 | F14: 0 | G14: 0 | H14: 0 | I14: 0
C15: Total: | D15: =D13+D14 -> 14 | E15: =E13+E14 -> 27 | F15: =F13+F14 -> 19 | G15: =G13+G14 -> 24 | H15: =H13+H14 -> 37 | I15: =I13+I14 -> 66 | J15: =J13+J14 -> 47 | K15: =K13+K14 -> 32 | ... M15: =M13+M14 -> 23 | N15: 34 | O15: 30 | P15: 42 | Q15: 29 | R15: 24
C16: Single | D16: 19 | E16: 11 | F16: 17 | G16: 16 | H16: 19 | I16: 21 | J16: 47 | K16: 37 | L16: 29 | M16: 24 | N16: 30 | O16: 27 | P16: 19 | Q16: 30 | R16: 21
C17: Combined | D17: 1 | E17: 5 | F17: 7 | G17: 4 | H17: 2 | I17: 3 | J17: 3 | K17: 4 | L17: 1 | M17: 1 | N17: 2 | O17: 2 | P17: 2 | Q17: 1
B18: Year III | C18: Sub-Total: | D18: =D16+D17 -> 20 | E18: =E16+E17 -> 16 | F18: =F16+F17 -> 24 | G18: =G16+G17 -> 20 | H18: =H16+H17 -> 21 | I18: =I16+I17 -> 24 | J18: =J16+J17 -> 50 | K18: =K16+K17 -> 41 | ... M18: =M16+M17 -> 25 | N18: 32 | O18: 29 | P18: 21 | Q18: 31 | R18: 21
C19: Gen/Integ. Studies | D19: 0 | E19: 0 | F19: 0 | G19: 0 | H19: 0 | I19: 1
C20: Total: | D20: =D18+D19 -> 20 | E20: =E18+E19 -> 16 | F20: =F18+F19 -> 24 | G20: =G18+G19 -> 20 | H20: =H18+H19 -> 21 | I20: =I18+I19 -> 25 | J20: =J18+J19 -> 50 | K20: =K18+K19 -> 41 | ... M20: =M18+M19 -> 25 | N20: 32 | O20: 29 | P20: 21 | Q20: 31 | R20: 21
C21: Single | D21: 0 | E21: 6 | F21: 11 | G21: 12 | H21: 10 | I21: 5 | J21: 10 | K21: 14 | L21: 16 | M21: 12 | N21: 12 | O21: 17 | P21: 8 | Q21: 15 | R21: 20
C22: Combined | D22: 2 | E22: 3 | F22: 5 | G22: 4 | H22: 4 | I22: 1 | J22: 4 | K22: 3 | L22: 2 | M22: 1 | N22: 1 | O22: 3 | Q22: 2 | R22: 1
B23: Year IV | C23: Sub-Total: | D23: =D21+D22 -> 2 | E23: =E21+E22 -> 9 | F23: =F21+F22 -> 16 | G23: =G21+G22 -> 16 | H23: =H21+H22 -> 14 | I23: =I21+I22 -> 6 | J23: =J21+J22 -> 14 | K23: =K21+K22 -> 17 | ... M23: =M21+M22 -> 13 | N23: 13 | O23: 20 | P23: 8 | Q23: 17 | R23: 21
C24: Gen/Integ. Studies | D24: 0 | E24: 0 | F24: 0 | G24: 0 | H24: 0 | I24: 0
C25: Total: | D25: =D23+D24 -> 2 | E25: =E23+E24 -> 9 | F25: =F23+F24 -> 16 | G25: =G23+G24 -> 16 | H25: =H23+H24 -> 14 | I25: =I23+I24 -> 6 | J25: =J23+J24 -> 14 | K25: =K23+K24 -> 17 | ... M25: =M23+M24 -> 13 | N25: 13 | O25: 20 | P25: 8 | Q25: 17 | R25: 21
C26: Single | D26: =SUM(D6,D11,D16,D21) -> 65 | E26: =SUM(E6,E11,E16,E21) -> 65 | F26: =SUM(F6,F11,F16,F21) -> 71 | G26: =SUM(G6,G11,G16,G21) -> 88 | H26: =SUM(H6,H11,H16,H21) -> 123 | I26: =SUM(I6,I11,I16,I21) -> 141 | J26: =SUM(J6,J11,J16,J21) -> 157 | K26: =SUM(K6,K11,K16,K21) -> 121 | ... M26: =SUM(M6,M11,M16,M21) -> 106 | N26: 133 | O26: 136 | P26: 122 | Q26: 107 | R26: 103
C27: Combined | D27: =SUM(D7,D12,D17,D22) -> 5 | E27: =SUM(E7,E12,E17,E22) -> 16 | F27: =SUM(F7,F12,F17,F22) -> 15 | G27: =SUM(G7,G12,G17,G22) -> 13 | H27: =SUM(H7,H12,H17,H22) -> 11 | I27: =SUM(I7,I12,I17,I22) -> 12 | J27: =SUM(J7,J12,J17,J22) -> 12 | K27: =SUM(K7,K12,K17,K22) -> 10 | ... M27: =SUM(M7,M12,M17,M22) -> 3 | N27: 4 | O27: 7 | P27: 3 | Q27: 4
B28: TOTAL: | C28: Sub-Total: | D28: =D26+D27 -> 70 | E28: =E26+E27 -> 81 | F28: =SUM(F8,F13,F18,F23) -> 86 | G28: =SUM(G8,G13,G18,G23) -> 101 | H28: =SUM(H8,H13,H18,H23) -> 134 | I28: =SUM(I8,I13,I18,I23) -> 153 | J28: =SUM(J8,J13,J18,J23) -> 169 | K28: =SUM(K8,K13,K18,K23) -> 131 | L28: =SUM(L8,L13,L18,L23) -> 112 | M28: =SUM(M8,M13,M18,M23) -> 109 | N28: 137 | O28: 143 | P28: 125 | Q28: 111 | R28: 103
C29: Gen/Integ. Studies | D29: =SUM(D9,D14,D19,D24) -> 0 | E29: =SUM(E9,E14,E19,E24) -> 0 | F29: =SUM(F9,F14,F19,F24) -> 0 | G29: =SUM(G9,G14,G19,G24) -> 0 | H29: =SUM(H9,H14,H19,H24) -> 0 | I29: =SUM(I9,I14,I19,I24) -> 1
C30: Total: | D30: =D28+D29 -> 70 | E30: =E28+E29 -> 81 | F30: =SUM(F10,F15,F20,F25) -> 86 | G30: =SUM(G10,G15,G20,G25) -> 101 | H30: =SUM(H10,H15,H20,H25) -> 134 | I30: =SUM(I10,I15,I20,I25) -> 154 | J30: =SUM(J10,J15,J20,J25) -> 169 | K30: =SUM(K10,K15,K20,K25) -> 131 | L30: =SUM(L10,L15,L20,L25) -> 112 | M30: =SUM(M10,M15,M20,M25) -> 109 | N30: 137 | O30: 143 | P30: 125 | Q30: 111 | R30: 103
B31: Male | D31: 45 | E31: 50 | F31: =49+9 -> 58 | G31: 62 | H31: =70+7 -> 77 | I31: 92 | J31: 102 | K31: 85 | L31: 72 | M31: =67+1 -> 68 | N31: 89 | O31: 81 | P31: 71 | Q31: 68 | R31: 59 | S31: =R31/R30 -> 0.57281553
B32: Female | D32: 25 | E32: 31 | F32: =24+4 -> 28 | G32: 39 | H32: =134-77 -> 57 | I32: 62 | J32: 67 | K32: 46 | L32: 40 | M32: =39+2 -> 41 | N32: 48 | O32: 62 | P32: 54 | Q32: 43 | R32: 44 | S32: =R32/R30 -> 0.42718447
B33: Full-Time | D33: 64 | E33: =56+8+7 -> 71 | F33: =68+14 -> 82 | G33: 90 | H33: =134-5 -> 129 | I33: 145 | J33: 159 | K33: 118 | L33: 100 | M33: =95+3 -> 98 | N33: 124 | O33: 128 | P33: 116 | Q33: 102 | R33: 97 | S33: =R33/R30 -> 0.94174757
B34: Part-Time | D34: 6 | E34: 10 | F34: 4 | G34: 11 | H34: =4+1 -> 5 | I34: 9 | J34: 10 | K34: 13 | L34: 12 | M34: 11 | N34: 13 | O34: 15 | P34: 9 | Q34: 9 | R34: 6 | S34: =R34/R30 -> 0.058252427
B54: Codes:
B55: FILM
B56: FILN

Sheet PCUL-jb
B1: Undergraduate Majors
B2: [Popular Culture]
B4: Study Year | C4: Major Type | H4: Head Count Enrolments
D5: 1999-00 | E5: 2000-01 | F5: 2001-02 | G5: 2002-03 | H5: 2003-04 | I5: 2004-05 | J5: 2005-06 | K5: 2006-07 | L5: 2007-08 | M5: 2008-09 | N5: 2011-12 | O5: 2012-13 | P5: 2013-14 | Q5: 2014-15 | R5: 2015-16
C6: Single | D6: 0 | E6: 5 | F6: 16 | G6: 24 | H6: 40 | I6: 32 | J6: 34 | K6: 36 | L6: 30 | M6: 32 | N6: 17 | O6: 20 | P6: 11 | Q6: 8 | R6: 4
C7: Combined | D7: 0 | E7: 0 | F7: 0 | G7: 0 | H7: 0 | I7: 0
B8: Year I | C8: Sub-Total: | D8: =D6+D7 -> 0 | E8: =E6+E7 -> 5 | F8: =F6+F7 -> 16 | G8: =G6+G7 -> 24 | H8: =H6+H7 -> 40 | I8: =I6+I7 -> 32 | J8: =J6+J7 -> 34 | K8: =K6+K7 -> 36 | ... M8: =M6+M7 -> 32 | N8: 17 | O8: 20 | P8: 11 | Q8: 8 | R8: 4
C9: Gen/Integ. Studies | D9: 0 | E9: 0 | F9: 0 | G9: 0 | H9: 0 | I9: 0
C10: Total: | D10: =D8+D9 -> 0 | E10: =E8+E9 -> 5 | F10: =F8+F9 -> 16 | G10: =G8+G9 -> 24 | H10: =H8+H9 -> 40 | I10: =I8+I9 -> 32 | J10: =J8+J9 -> 34 | K10: =K8+K9 -> 36 | ... M10: =M8+M9 -> 32 | N10: 17 | O10: 20 | P10: 11 | Q10: 8 | R10: 4
C11: Single | D11: 1 | E11: 3 | F11: 7 | G11: 8 | H11: 15 | I11: 39 | J11: 40 | K11: 38 | L11: 33 | M11: 31 | N11: 8 | O11: 16 | P11: 15 | Q11: 11 | R11: 11
C12: Combined | D12: 0 | E12: 0 | F12: 0 | G12: 0 | H12: 1 | I12: 2 | J12: 1
B13: Year II | C13: Sub-Total: | D13: =D11+D12 -> 1 | E13: =E11+E12 -> 3 | F13: =F11+F12 -> 7 | G13: =G11+G12 -> 8 | H13: =H11+H12 -> 16 | I13: =I11+I12 -> 41 | J13: =J11+J12 -> 41 | K13: =K11+K12 -> 38 | ... M13: =M11+M12 -> 31 | N13: 8 | O13: 16 | P13: 15 | Q13: 11 | R13: 11
C14: Gen/Integ. Studies | D14: 0 | E14: 0 | F14: 0 | G14: 0 | H14: 0 | I14: 0
C15: Total: | D15: =D13+D14 -> 1 | E15: =E13+E14 -> 3 | F15: =F13+F14 -> 7 | G15: =G13+G14 -> 8 | H15: =H13+H14 -> 16 | I15: =I13+I14 -> 41 | J15: =J13+J14 -> 41 | K15: =K13+K14 -> 38 | ... M15: =M13+M14 -> 31 | N15: 8 | O15: 16 | P15: 15 | Q15: 11 | R15: 11
C16: Single | D16: 3 | E16: 4 | F16: 2 | G16: 7 | H16: 8 | I16: 10 | J16: 28 | K16: 27 | L16: 25 | M16: 22 | N16: 17 | O16: 8 | P16: 13 | Q16: 14 | R16: 8
C17: Combined | D17: 1 | E17: 0 | F17: 0 | G17: 1 | H17: 0 | I17: 1 | J17: 2 | K17: 1 | L17: 1
B18: Year III | C18: Sub-Total: | D18: =D16+D17 -> 4 | E18: =E16+E17 -> 4 | F18: =F16+F17 -> 2 | G18: =G16+G17 -> 8 | H18: =H16+H17 -> 8 | I18: =I16+I17 -> 11 | J18: =J16+J17 -> 30 | K18: =K16+K17 -> 28 | ... M18: =M16+M17 -> 22 | N18: 17 | O18: 8 | P18: 13 | Q18: 14 | R18: 8
C19: Gen/Integ. Studies | D19: 0 | E19: 0 | F19: 0 | G19: 0 | H19: 0 | I19: 0
C20: Total: | D20: =D18+D19 -> 4 | E20: =E18+E19 -> 4 | F20: =F18+F19 -> 2 | G20: =G18+G19 -> 8 | H20: =H18+H19 -> 8 | I20: =I18+I19 -> 11 | J20: =J18+J19 -> 30 | K20: =K18+K19 -> 28 | ... M20: =M18+M19 -> 22 | N20: 17 | O20: 8 | P20: 13 | Q20: 14 | R20: 8
C21: Single | D21: 0 | E21: 2 | F21: 0 | G21: 1 | H21: 8 | I21: 3 | J21: 6 | K21: 14 | L21: 5 | M21: 10 | N21: 10 | O21: 5 | P21: 7 | Q21: 11 | R21: 11
C22: Combined | D22: 0 | E22: 1 | F22: 1 | G22: 1 | H22: 0 | I22: 0 | J22: 1
B23: Year IV | C23: Sub-Total: | D23: =D21+D22 -> 0 | E23: =E21+E22 -> 3 | F23: =F21+F22 -> 1 | G23: =G21+G22 -> 2 | H23: =H21+H22 -> 8 | I23: =I21+I22 -> 3 | J23: =J21+J22 -> 7 | K23: =K21+K22 -> 14 | ... M23: =M21+M22 -> 10 | N23: 10 | O23: 5 | P23: 7 | Q23: 11 | R23: 11
C24: Gen/Integ. Studies | D24: 0 | E24: 0 | F24: 0 | G24: 0 | H24: 0 | I24: 0
C25: Total: | D25: =D23+D24 -> 0 | E25: =E23+E24 -> 3 | F25: =F23+F24 -> 1 | G25: =G23+G24 -> 2 | H25: =H23+H24 -> 8 | I25: =I23+I24 -> 3 | J25: =J23+J24 -> 7 | K25: =K23+K24 -> 14 | ... M25: =M23+M24 -> 10 | N25: 10 | O25: 5 | P25: 7 | Q25: 11 | R25: 11
C26: Single | D26: =SUM(D6,D11,D16,D21) -> 4 | E26: =SUM(E6,E11,E16,E21) -> 14 | F26: =SUM(F6,F11,F16,F21) -> 25 | G26: =SUM(G6,G11,G16,G21) -> 40 | H26: =SUM(H6,H11,H16,H21) -> 71 | I26: =SUM(I6,I11,I16,I21) -> 84 | J26: =SUM(J6,J11,J16,J21) -> 108 | K26: =SUM(K6,K11,K16,K21) -> 115 | ... M26: =SUM(M6,M11,M16,M21) -> 95 | N26: 52 | O26: 49 | P26: 46 | Q26: 44 | R26: 34
C27: Combined | D27: =SUM(D7,D12,D17,D22) -> 1 | E27: =SUM(E7,E12,E17,E22) -> 1 | F27: =SUM(F7,F12,F17,F22) -> 1 | G27: =SUM(G7,G12,G17,G22) -> 2 | H27: =SUM(H7,H12,H17,H22) -> 1 | I27: =SUM(I7,I12,I17,I22) -> 3 | J27: =SUM(J7,J12,J17,J22) -> 4 | K27: =SUM(K7,K12,K17,K22) -> 1 | L27: =SUM(L7,L12,L17,L22) -> 1
