Workbook
Name current_period: [1]Schedule!$F$3

Sheet Cover Sheet
B2: SC Germany Auto 10-1 | D2: Reporting Date | F2: 41191
B3: Monthly Investor Report | D3: Payment Date | F3: 41197
D4: Period No | F4: 27
B5: Cover Sheet Monthly Investor Report | D5: Monthly Period | F5: 41197
D6: Interest Period | E6: from | F6: 41164 | G6: to | H6: =F3 -> 41197 | I6: = | J6: =H6-F6&" days" -> 33 days
D7: Collection Period | E7: from | F7: ="01."&TEXT(F6,"MM.jjjj") -> 01.09.2012 | G7: to | H7: =_xll.MONATSENDE(F6,0) -> 41182
B13: Index | C13: Page
B15: 1. Portfolio Information | C15: 1
B16: 2. Reserve Accounts | C16: 2
B17: 3. Delinquency Data | C17: 3
B18: 4. Default Data | C18: 4
B19: 4.1 Default Data per Quarter | C19: 5
B20: 5. Outstanding Notes | C20: 6
B21: 6. Original Principal Balance | C21: 7
B22: 6.1 Original PB (Graph) | C22: 8
B23: 7. Current Principal Balance | C23: 9
B24: 7.1 Current PB (Graph) | C24: 10
B25: 8. Borrower Concentration | C25: 11
B26: 9. Geographical Distribution | C26: 12
... B46: 24. Disclaimer | C46: 32

Sheet 1. Portfolio Information
B2: ='Cover Sheet'!B2 -> SC Germany Auto 10-1 | D2: Reporting Date | F2: ='Cover Sheet'!F2 -> 41191
B3: ='Cover Sheet'!B3 -> Monthly Investor Report | D3: Payment Date | F3: ='Cover Sheet'!F3 -> 41197
D4: Period No | F4: ='Cover Sheet'!F4 -> 27
B5: 1. Portfolio Information | D5: Monthly Period | F5: ='Cover Sheet'!F5 -> 41197
D6: ='Cover Sheet'!D6 -> Interest Period | E6: from | F6: ='Cover Sheet'!F6 -> 41164 | G6: to | H6: ='Cover Sheet'!H6 -> 41197 | I6: = | J6: ='Cover Sheet'!J6 -> 33 days
D7: ='Cover Sheet'!D7 -> Collection Period | E7: from | F7: ='Cover Sheet'!F7 -> 01.09.2012 | G7: to | H7: ='Cover Sheet'!H7 -> 41182
F11: current period | J11: previous period
B13: Outstanding Receivables | C13: No. of Contracts | F13: Aggregate Outstanding Principal Amount | J13: Aggregate Outstanding Principal Amount
B15: Beginning of Period | C15: 44093 | F15: 2.2884412e+08 | J15: 2.4075656e+08
B17: Scheduled Principal Payments | F17: 7378325.6
B18: Prepayment Principal | F18: 3694466.8
B19: Others | F19: 70332.99
B20: Total Principal Collections | F20: 11143125 | J20: 11843340
B22: Total Interest Collections | F22: 1404158.5 | J22: 1508203.9
B24: Defaults | F24: 147457.31 | J24: 69108.08
B26: End of Period | C26: ='10. Object Type'!G16 -> 42113 | F26: 2.1755353e+08 | J26: 2.2884412e+08
B30: Current Prepayment Rate (annualised) | F30: =IF(F15=0,0,(F18)/F15*12) -> 0.19372839

Sheet 2. Reserve Accounts
B2: ='Cover Sheet'!B2 -> SC Germany Auto 10-1 | D2: Reporting Date | F2: ='Cover Sheet'!F2 -> 41191
B3: ='Cover Sheet'!B3 -> Monthly Investor Report | D3: Payment Date | F3: ='Cover Sheet'!F3 -> 41197
D4: Period No | F4: ='Cover Sheet'!F4 -> 27
B5: 2. Reserve Accounts | D5: Monthly Period | F5: ='Cover Sheet'!F5 -> 41197
D6: ='Cover Sheet'!D6 -> Interest Period | E6: from | F6: ='Cover Sheet'!F6 -> 41164 | G6: to | H6: ='Cover Sheet'!H6 -> 41197 | I6: = | J6: ='Cover Sheet'!J6 -> 33 days
D7: ='Cover Sheet'!D7 -> Collection Period | E7: from | F7: ='Cover Sheet'!F7 -> 01.09.2012 | G7: to | H7: ='Cover Sheet'!H7 -> 41182
B13: Note Balance
B14: Beginning of Period | D14: 2.2884418e+08
B15: End of Period | D15: 2.1755362e+08
B17: Reserve Accounts
B18: Reserve Account | C18: in % | F18: Trigger Event y/n
B19: Beginning of Period | C19: =IF(ISNUMBER(D14),D19/D14,"") -> 0.06 | D19: 13730651
B20: Cash Outflow | D20: -677433.45
B21: Cash Inflow | D21: 0
B22: End of Period | C22: =IF(ISNUMBER(D22),D22/D15,"") -> 0.06 | D22: 13053217
B23: Required Reserve Fund | C23: =IF(ISNUMBER(D23),D23/D15,"") -> 0.06 | D23: 13053217
B25: Commingling Reserve | C25: in %
B26: Beginning of Period | C26: =IF(AND(ISNUMBER(D15),ISNUMBER(D26)),D26/D14,"") -> 0.10539609 | D26: 24119283 | F26: yes
B27: Cash Outflow | D27: 1362940.3
B28: Cash Inflow | D28: 0
B29: End of Period | C29: =IF(AND(ISNUMBER(D15),ISNUMBER(D29)),D29/D15,"") -> 0.10460107 | D29: 22756342
B30: Required Commingling Reserve Fund | D30: 22756342
B32: Set-Off Reserve | C32: in %
B33: Beginning of Period | C33: =IF(AND(ISNUMBER(D15),ISNUMBER(D33)),D33/D14,"") -> 0.00065118107 | D33: 149019 | F33: yes
B34: Cash Outflow | D34: 0
B35: Cash Inflow | D35: 488854.63
B36: End of Period | C36: =IF(AND(ISNUMBER(D15),ISNUMBER(D36)),D36/D15,"") -> 0.0029320294 | D36: 637873.63
B37: Required Set-Off Reserve Fund | D37: 637873.63
B39: Current Set-Off Amount | D39: 637873.63
B40: Set-Off Amount (per Loan) | D40: =D39/'1. Portfolio Information'!C26 -> 15.146716
B41: Set-Off Amount (in % of Outstanding Balance) | D41: =D39/'1. Portfolio Information'!F26 -> 0.0029320307

Sheet 3. Delinquency Data
B2: ='Cover Sheet'!B2 -> SC Germany Auto 10-1 | D2: Reporting Date | F2: ='Cover Sheet'!F2 -> 41191
B3: ='Cover Sheet'!B3 -> Monthly Investor Report | D3: Payment Date | F3: ='Cover Sheet'!F3 -> 41197
D4: Period No | F4: ='Cover Sheet'!F4 -> 27
B5: 3. Delinquency Data | D5: Monthly Period | F5: ='Cover Sheet'!F5 -> 41197
D6: Interest Period | E6: from | F6: ='Cover Sheet'!F6 -> 41164 | G6: to | H6: ='Cover Sheet'!H6 -> 41197 | I6: = | J6: ='Cover Sheet'!J6 -> 33 days
D7: Collection Period | E7: from | F7: ='Cover Sheet'!F7 -> 01.09.2012 | G7: to | H7: ='Cover Sheet'!H7 -> 41182
B13: Note Balance
B14: Beginning of Period | D14: ='2. Reserve Accounts'!D14 -> 2.2884418e+08
B15: End of Period | D15: ='2. Reserve Accounts'!D15 -> 2.1755362e+08
B17: Delinquency Data and Ratios | D17: 3-MRA* / current ratio | F17: Amount at risk | H17: Overdue amount | J17: Number of Loans
B20: 3-MRA* 1- 30 days past due | D20: =IF(ISERROR((SUM(F21:F23)/3)/$D$14),"n/a",(SUM(F21:F23)/3)/$D$14) -> 0.0067529224
B21: 1- 30 days past due period before previous period | F21: 1650031.7 | H21: 143585.17 | J21: 228
B22: 1- 30 days past due previous period | F22: 1739281.4 | H22: 133166.84 | J22: 229
B23: 1- 30 days past due current period | D23: =IF(ISERROR(F23/$D$14),"n/a",F23/$D$14) -> 0.0054481959 | F23: 1246787.9 | H23: 79535.29 | J23: 176
B25: 3-MRA* 31- 60 days past due | D25: =IF(ISERROR((SUM($F$26:$F$28)/3)/$D$14),"n/a",(SUM($F$26:$F$28)/3)/$D$14) -> 0.0023999076
B26: 31- 60 days past due period before previous period | F26: 561993.8 | H26: 40227.12 | J26: 69
B27: 31- 60 days past due previous period | F27: 580115.79 | H27: 49489.14 | J27: 88
B28: 31- 60 days past due current period | D28: =IF(ISERROR($F$28/$D$14),"n/a",$F$28/$D$14) -> 0.0022089488 | F28: 505505.08 | H28: 63778.17 | J28: 69
B30: 3-MRA* 61-90 days past due | D30: =IF(ISERROR((SUM($F$31:$F$33)/3)/$D$14),"n/a",(SUM($F$31:$F$33)/3)/$D$14) -> 0.0011430822
B31: 61- 90 days past due period before previous period | F31: 340394.59 | H31: 52034.39 | J31: 42
B32: 61- 90 days past due previous period | F32: 201611.6 | H32: 17155.15 | J32: 35
B33: 61- 90 days past due current period | D33: =IF(ISERROR($F$33/$D$14),"n/a",$F$33/$D$14) -> 0.0010607958 | F33: 242756.95 | H33: 19790.74 | J33: 40
B35: 3-MRA* 91-120 days past due | D35: =IF(ISERROR((SUM($F$36:$F$38)/3)/$D$14),"n/a",(SUM($F$36:$F$38)/3)/$D$14) -> 0.00082886133
B36: 91- 120 days past due period before previous period | F36: 216082.55 | H36: 25420.61 | J36: 28
B37: 91- 120 days past due previous period | F37: 216154.83 | H37: 26411.1 | J37: 25
B38: 91- 120 days past due current period | D38: =IF(ISERROR(F38/$D$14),"n/a",F38/$D$14) -> 0.00059779934 | F38: 136802.9 | H38: 17706.04 | J38: 23
B40: 3-MRA* 121-150 days past due | D40: =IF(ISERROR((SUM(F41:F43)/3)/$D$14),"n/a",(SUM(F41:F43)/3)/$D$14) -> 0.0004708914
B41: 121- 150 days past due period before previous period | F41: 120803.01 | H41: 13748.87 | J41: 13
B42: 121- 150 days past due previous period | F42: 68124.92 | H42: 6883.14 | J42: 10
B43: 121- 150 days past due current period | D43: =IF(ISERROR(F43/$D$14),"n/a",F43/$D$14) -> 0.00058709966 | F43: 134354.34 | H43: 20307.46 | J43: 14
B45: 3-MRA* 151-180 days past due | D45: =IF(ISERROR((SUM(F46:F48)/3)/$D$14),"n/a",(SUM(F46:F48)/3)/$D$14) -> 0.00089438627
B46: 151- 180 days past due period before previous period | F46: 194093.3 | H46: 36440.71 | J46: 26
B47: 151- 180 days past due previous period | F47: 252645.69 | H47: 41846.15 | J47: 28
B48: 151- 180 days past due current period | D48: =IF(ISERROR(F48/$D$14),"n/a",F48/$D$14) -> 0.00073100521 | F48: 167286.29 | H48: 34830.92 | J48: 18
B50: * 3-MRA stands for three months rolling average

Sheet 4. Default Data
B2: ='Cover Sheet'!B2 -> SC Germany Auto 10-1 | D2: Reporting Date | F2: ='Cover Sheet'!F2 -> 41191
B3: ='Cover Sheet'!B3 -> Monthly Investor Report | D3: Payment Date | F3: ='Cover Sheet'!F3 -> 41197
D4: Period No | F4: ='Cover Sheet'!F4 -> 27
B5: 4. Default Data | D5: Monthly Period | F5: ='Cover Sheet'!F5 -> 41197
D6: Interest Period | E6: from | F6: ='Cover Sheet'!F6 -> 41164 | G6: to | H6: ='Cover Sheet'!H6 -> 41197 | I6: = | J6: ='Cover Sheet'!J6 -> 33 days
D7: Collection Period | E7: from | F7: ='Cover Sheet'!F7 -> 01.09.2012 | G7: to | H7: ='Cover Sheet'!H7 -> 41182
B13: Note Balance
B14: Beginning of Period | D14: ='2. Reserve Accounts'!D14 -> 2.2884418e+08
B15: End of Period | D15: ='2. Reserve Accounts'!D15 -> 2.1755362e+08
B17: Default Data and Ratios | F17: Amount | H17: Number of Loans
B19: Current Default
B20: Current Period Gross Default | F20: 147457.31
B21: Current Period Recoveries | F21: 23551.24
B22: Current Period Net Default | F22: =F20-F21 -> 123906.07
B23: New Number of Defaulted Contracts | H23: 26
B25: Cumulative Default
B26: Cumulative Gross Default | F26: 2028188.2
B27: Cumulative Recoveries | F27: 211534.02
B28: Cumulative Net Default | F28: =F26-F27 -> 1816654.2
B29: Total Number of Defaulted Contracts | H29: 310
D30: 3-MRA* / current ratio | F30: Ratio
B32: 3-MRA* Annualised Net Default Ratio (New Default) | D32: =IF(ISERROR(SUM($F$33:$F$35)/3),"n/a",(SUM($F$33:$F$35)/3)) -> 0.0045836297
B33: Annualised Loss Ratio period before previous period | F33: 0.0037928207
B34: Annualised Loss Ratio previous period | F34: 0.0031235537
B35: Annualised Loss Ratio current period | D35: =F35 -> 0.0068345148 | F35: 0.0068345148
B37: Principal Deficiency | H37: Trigger Event y/n
B38: Principal Deficiency period before previous period | F38: 0 | H38: no
B39: Principal Deficiency previous period | F39: 0
B40: Principal Deficiency current period | F40: 0
B41: PDL Trigger | F41: 7500000
B43: Repurchased Assets
B44: Current Repurchased Asset Amount through breach of warranty or voluntary buyback | F44: 0
B45: Cumulative Repurchased Asset Amount through breach of warranty or voluntary buyback | F45: 0
B47: * 3-MRA stands for three months rolling average

Sheet 4.1 Default Data per Quarter
B2: ='Cover Sheet'!B2 -> SC Germany Auto 10-1 | D2: Reporting Date | F2: ='Cover Sheet'!F2 -> 41191
B3: ='Cover Sheet'!B3 -> Monthly Investor Report | D3: Payment Date | F3: ='Cover Sheet'!F3 -> 41197
D4: Period No | F4: ='Cover Sheet'!F4 -> 27
B5: 4.1 Default Data per Quarter | D5: Monthly Period | F5: ='Cover Sheet'!F5 -> 41197
D6: Interest Period | E6: from | F6: ='Cover Sheet'!F6 -> 41164 | G6: to | H6: ='Cover Sheet'!H6 -> 41197 | I6: = | J6: ='Cover Sheet'!J6 -> 33 days
D7: Collection Period | E7: from | F7: ='Cover Sheet'!F7 -> 01.09.2012 | G7: to | H7: ='Cover Sheet'!H7 -> 41182
G12: Recoveries in Quarter
C13: Quarter of Default | D13: Periods | E13: New Defaults | F13: Recoveries | G13: Q3 2010 | H13: Q4 2010 | I13: Q1 2011 | J13: Q2 2011 | K13: Q3 2011 | L13: Q4 2011 | M13: Q1 2012 | N13: Q2 2012 | O13: Q3 2012
C14: Q3 2010 | D14: 1-3 | E14: 18080.13 | F14: 9649.25 | G14: 0 | H14: 6674.65 | I14: 1240.29 | J14: 1734.31 | K14: 0 | L14: 0 | M14: 0 | N14: 0 | O14: 0
C15: Q4 2010 | D15: 4-6 | E15: 39130.82 | F15: 5578.65 | G15: 0 | H15: 0 | I15: 216.8 | J15: 1386.65 | K15: 1288.22 | L15: 1060.13 | M15: 275.13 | N15: 676.59 | O15: 675.13
C16: Q1 2011 | D16: 7-9 | E16: 132388.14 | F16: 25920.33 | G16: 0 | H16: 0 | I16: 0 | J16: 486.39 | K16: 907.78 | L16: 8671.14 | M16: 8228.91 | N16: 4851.37 | O16: 2774.74
C17: Q2 2011 | D17: 10-12 | E17: 259054.98 | F17: 40447.54 | G17: 0 | H17: 0 | I17: 0 | J17: 9429.4 | K17: 7140.33 | L17: 3204.08 | M17: 15942.07 | N17: 2200 | O17: 2531.66
C18: Q3 2011 | D18: 13-15 | E18: 287265.59 | F18: 29156.35 | G18: 0 | H18: 0 | I18: 0 | J18: 0 | K18: 2213.54 | L18: 7381.58 | M18: 3425.02 | N18: 13524.49 | O18: 2611.72
C19: Q4 2011 | D19: 16-18 | E19: 434542.57 | F19: 24415.02 | G19: 0 | H19: 0 | I19: 0 | J19: 0 | K19: 0 | L19: 457.78 | M19: 10964.16 | N19: 4493.8 | O19: 8499.28
C20: Q1 2012 | D20: 19-21 | E20: 272500.21 | F20: 35950.03 | G20: 0 | H20: 0 | I20: 0 | J20: 0 | K20: 0 | L20: 0 | M20: 17360.15 | N20: 7633.8 | O20: 10956.08
C21: Q2 2012 | D21: 22-24 | E21: 264365.3 | F21: 39328.86 | G21: 0 | H21: 0 | I21: 0 | J21: 0 | K21: 0 | L21: 0 | M21: 0 | N21: 7173.88 | O21: 32154.98
C22: Q3 2012 | D22: 25-27 | E22: 320860.43 | F22: 1087.99 | G22: 0 | H22: 0 | I22: 0 | J22: 0 | K22: 0 | L22: 0 | M22: 0 | N22: 0 | O22: 1087.99
C23: Total | E23: 2028188.2 | F23: 211534.02 | G23: 0 | H23: 6674.65 | I23: 1457.09 | J23: 13036.75 | K23: 11549.87 | L23: 20774.71 | M23: 56195.44 | N23: 40553.93 | O23: 61291.58

Sheet 5. Outstanding Notes
B2: ='Cover Sheet'!B2 -> SC Germany Auto 10-1 | D2: Reporting Date | F2: ='Cover Sheet'!F2 -> 41191
B3: ='Cover Sheet'!B3 -> Monthly Investor Report | D3: Payment Date | F3: ='Cover Sheet'!F3 -> 41197
D4: Period No | F4: ='Cover Sheet'!F4 -> 27
B5: 5. Outstanding Notes | D5: Monthly Period | F5: ='Cover Sheet'!F5 -> 41197
D6: ='Cover Sheet'!D6 -> Interest Period | E6: from | F6: ='Cover Sheet'!F6 -> 41164 | G6: to | H6: ='Cover Sheet'!H6 -> 41197 | I6: = | J6: ='Cover Sheet'!J6 -> 33 days
D7: ='Cover Sheet'!D7 -> Collection Period | E7: from | F7: ='Cover Sheet'!F7 -> 01.09.2012 | G7: to | H7: ='Cover Sheet'!H7 -> 41182
B13: 1. Note Balance | C13: All notes | D13: Class A | F13: Class B
B14: General Note Information
B15: ISIN Code | D15: XS0525278304 | F15: XS0525278486
B16: Currency | D16: EUR | F16: EUR
B17: Initial Tranching | C17: in % | D17: 0.945 | F17: 0.055
B18: Legal Maturity | D18: 43678 | F18: 43678
B19: Expected Maturity | D19: 41821 | F19: 41821
B20: Original Rating (Fitch / Moody's / S&P) | D20: AAA/Aaa/AAA | F20: A/A3/A
B21: Current Rating (Fitch / Moody's / S&P)* | D21: AAA/Aaa/AAA | F21: A+/A3/A
B22: Initial Notes Aggregate Principal Outstanding Balance | C22: 600000000 | D22: 567000000 | F22: 33000000
B23: Initial Nominal per Note | D23: 50000 | F23: =D23 -> 50000
B24: Initial Number of Notes per Class | D24: =D22/D23 -> 11340 | F24: =F22/F23 -> 660
B26: Current Note Information
B27: Class Principal Outstanding Balance Beginning of Period | C27: 2.2884418e+08 | D27: 1.9584418e+08 | F27: 33000000
B28: Available Distribution Amount | C28: 26449008
B29: Amortisation | C29: 11290558
B30: Redemption per Class | C30: 11290558 | D30: 11290558 | F30: 0
B31: Redemption per Note | D31: =IF(ISNUMBER(D30),D30/D24,"") -> 995.64 | F31: =IF(ISNUMBER(F30),F30/F24,"") -> 0
B32: Class Principal Outstanding Balance End of Period | C32: =+C27-C30 -> 2.1755362e+08 | D32: =D27-D30 -> 1.8455362e+08 | F32: =F27-F30 -> 33000000
B33: Current Tranching | D33: =+D32/$C$32 -> 0.84831326 | F33: =+F32/$C$32 -> 0.15168674
B34: Current Pool Factor | D34: =D32/D22 -> 0.3254914 | F34: =F32/F22 -> 1
B36: 2. Payments to Investors per Note | C36: All notes | D36: Class A | F36: Class B
B37: Interest Rate Basis: 1-M Euribor / Spread | C37: 0.0012 | D37: 105 | F37: 150
B38: DayCount Convention | D38: act/360 | F38: act/360
B39: Interest Days | C39: 33
B40: Principal Outstanding per Note Beginning of Period | D40: =D27/D24 -> 17270.21 | F40: =F27/F24 -> 50000
B41: > Principal Repayment per Note | D41: =+D31 -> 995.64 | F41: =+F31 -> 0
B42: Principal Outstanding per Note End of Period | D42: =D40-D41 -> 16274.57 | F42: =F40-F41 -> 50000
B43: > Interest accrued for the period | D43: =-'19. PoP + Transaction Costs'!D35 -> 210016.8 | F43: =-'19. PoP + Transaction Costs'!F35 -> 49005
B44: Interest Payment | D44: 210016.8 | F44: 49005
B45: Interest Payment per Note | D45: 18.52 | F45: 74.25
B48: 3. Credit Enhancements | D48: Class A | F48: Class B
B49: Initial total CE (Subordination, Reserve) | D49: 0.085 | F49: =D49-F17 -> 0.03
B50: Current CE (incl. Excess Spread) | D50: ='2. Reserve Accounts'!C22+'5. Outstanding Notes'!F33+('14. Customer Yield'!E31-'20. Swap Counterparty Data'!C32) -> 0.26537203 | F50: =D50-F33 -> 0.11368529
...

Sheet 6. Original Principal Balance
B2: ='Cover Sheet'!B2 -> SC Germany Auto 10-1 | D2: Reporting Date | F2: ='Cover Sheet'!F2 -> 41191
B3: ='Cover Sheet'!B3 -> Monthly Investor Report | D3: Payment Date | F3: ='Cover Sheet'!F3 -> 41197
D4: Period No | F4: ='Cover Sheet'!F4 -> 27
B5: 6. Original Principal Balance | D5: Monthly Period | F5: ='Cover Sheet'!F5 -> 41197
D6: ='Cover Sheet'!D6 -> Interest Period | E6: from | F6: ='Cover Sheet'!F6 -> 41164 | G6: to | H6: ='Cover Sheet'!H6 -> 41197 | I6: = | J6: ='Cover Sheet'!J6 -> 33 days
D7: ='Cover Sheet'!D7 -> Collection Period | E7: from | F7: ='Cover Sheet'!F7 -> 01.09.2012 | G7: to | H7: ='Cover Sheet'!H7 -> 41182
D13: Original Principal Balance (Ranges in EUR) | E13: Original Principal Balance in EUR | F13: Percentage of Balance | G13: Number of Loans | H13: Percentage of Loans
D14: 0: 999 | E14: 6298.56 | F14: 1.4173782e-05 | G14: 7 | H14: 0.00016621946
D15: 1000: 1999 | E15: 296520.07 | F15: 0.00066726533 | G15: 176 | H15: 0.0041792321
D16: 2000: 2999 | E16: 2007950.4 | F16: 0.0045185328 | G16: 764 | H16: 0.018141666
D17: 3000: 3999 | E17: 5825918.6 | F17: 0.013110187 | G17: 1639 | H17: 0.038919099
D18: 4000: 4999 | E18: 10872160 | F18: 0.024465849 | G18: 2395 | H18: 0.0568708
D19: 5000: 5999 | E19: 17617796 | F19: 0.039645695 | G19: 3199 | H19: 0.075962292
D20: 6000: 6999 | E20: 22082005 | F20: 0.049691599 | G20: 3398 | H20: 0.080687674
D21: 7000: 7999 | E21: 26963319 | F21: 0.060676122 | G21: 3596 | H21: 0.08538931
D22: 8000: 8999 | E22: 27917363 | F22: 0.062823028 | G22: 3289 | H22: 0.078099399
D23: 9000: 9999 | E23: 28029332 | F23: 0.063074993 | G23: 2950 | H23: 0.070049628
D24: 10000:10999 | E24: 29632194 | F24: 0.066681946 | G24: 2836 | H24: 0.067342626
D25: 11000:11999 | E25: 29958618 | F25: 0.067416505 | G25: 2601 | H25: 0.061762401
... D50: 35001: | E50: 2498384.4 | F50: 0.0056221668 | G50: 60 | H50: 0.0014247382
D51: Total | E51: =SUM(E14:E50) -> 4.4438106e+08 | F51: =SUM(F14:F50) -> 1 | G51: =SUM(G14:G50) -> 42113 | H51: =SUM(H14:H50) -> 1
D54: Statistics | E54: in EUR
D55: Average Amount | E55: 10552.111

Sheet 6.1 Original PB (Graph)
B2: ='Cover Sheet'!B2 -> SC Germany Auto 10-1 | D2: Reporting Date | F2: ='Cover Sheet'!F2 -> 41191
B3: ='Cover Sheet'!B3 -> Monthly Investor Report | D3: Payment Date | F3: ='Cover Sheet'!F3 -> 41197
D4: Period No | F4: ='Cover Sheet'!F4 -> 27
B5: 6.1 Original PB (Graph) | D5: Monthly Period | F5: ='Cover Sheet'!F5 -> 41197
D6: ='Cover Sheet'!D6 -> Interest Period | E6: from | F6: ='Cover Sheet'!F6 -> 41164 | G6: to | H6: ='Cover Sheet'!H6 -> 41197 | I6: = | J6: ='Cover Sheet'!J6 -> 33 days
D7: ='Cover Sheet'!D7 -> Collection Period | E7: from | F7: ='Cover Sheet'!F7 -> 01.09.2012 | G7: to | H7: ='Cover Sheet'!H7 -> 41182

Sheet 7. Current Principal Balance
B2: ='Cover Sheet'!B2 -> SC Germany Auto 10-1 | D2: Reporting Date | F2: ='Cover Sheet'!F2 -> 41191
B3: ='Cover Sheet'!B3 -> Monthly Investor Report | D3: Payment Date | F3: ='Cover Sheet'!F3 -> 41197
D4: Period No | F4: ='Cover Sheet'!F4 -> 27
B5: 7. Current Principal Balance | D5: Monthly Period | F5: ='Cover Sheet'!F5 -> 41197
D6: ='Cover Sheet'!D6 -> Interest Period | E6: from | F6: ='Cover Sheet'!F6 -> 41164 | G6: to | H6: ='Cover Sheet'!H6 -> 41197 | I6: = | J6: ='Cover Sheet'!J6 -> 33 days
D7: ='Cover Sheet'!D7 -> Collection Period | E7: from | F7: ='Cover Sheet'!F7 -> 01.09.2012 | G7: to | H7: ='Cover Sheet'!H7 -> 41182
D13: Current Principal Balance (Ranges in EUR) | E13: Current Principal Balance in EUR | F13: Percentage of Balance | G13: Number of Loans | H13: Percentage of Loans
D14: 0: 999 | E14: 1723098.7 | F14: 0.0079203436 | G14: 7425 | H14: 0.17631135
D15: 1000: 1999 | E15: 5805912.6 | F15: 0.026687282 | G15: 3856 | H15: 0.091563175
D16: 2000: 2999 | E16: 10165088 | F16: 0.046724538 | G16: 4052 | H16: 0.09621732
D17: 3000: 3999 | E17: 13996739 | F17: 0.064336987 | G17: 4022 | H17: 0.095504951
D18: 4000: 4999 | E18: 16510213 | F18: 0.075890348 | G18: 3677 | H18: 0.087312706
D19: 5000: 5999 | E19: 18444662 | F19: 0.084782174 | G19: 3363 | H19: 0.079856576
D20: 6000: 6999 | E20: 19373431 | F20: 0.089051329 | G20: 2982 | H20: 0.070809489
D21: 7000: 7999 | E21: 20852582 | F21: 0.095850347 | G21: 2780 | H21: 0.06601287
D22: 8000: 8999 | E22: 23051192 | F22: 0.10595641 | G22: 2716 | H22: 0.064493149
D23: 9000: 9999 | E23: 19241495 | F23: 0.088444874 | G23: 2028 | H23: 0.048156151
D24: 10000:10999 | E24: 14700698 | F24: 0.067572784 | G24: 1404 | H24: 0.033338874
D25: 11000:11999 | E25: 12103097 | F25: 0.055632728 | G25: 1056 | H25: 0.025075392
... D49: 35001: | E49: 270791.11 | F49: 0.0012447102 | G49: 6 | H49: 0.00014247382
D50: Total | E50: =SUM(E14:E49) -> 2.1755353e+08 | F50: =SUM(F14:F49) -> 1 | G50: =SUM(G14:G49) -> 42113 | H50: =SUM(H14:H49) -> 1
D53: Statistics | E53: in EUR
D54: Average Amount | E54: 5165.9472

Sheet 7.1 Current PB (Graph)
B2: ='Cover Sheet'!B2 -> SC Germany Auto 10-1 | D2: Reporting Date | F2: ='Cover Sheet'!F2 -> 41191
B3: ='Cover Sheet'!B3 -> Monthly Investor Report | D3: Payment Date | F3: ='Cover Sheet'!F3 -> 41197
D4: Period No | F4: ='Cover Sheet'!F4 -> 27
B5: 7.1 Current PB (Graph) | D5: Monthly Period | F5: ='Cover Sheet'!F5 -> 41197
D6: ='Cover Sheet'!D6 -> Interest Period | E6: from | F6: ='Cover Sheet'!F6 -> 41164 | G6: to | H6: ='Cover Sheet'!H6 -> 41197 | I6: = | J6: ='Cover Sheet'!J6 -> 33 days
D7: ='Cover Sheet'!D7 -> Collection Period | E7: from | F7: ='Cover Sheet'!F7 -> 01.09.2012 | G7: to | H7: ='Cover Sheet'!H7 -> 41182

Sheet 8. Borrower Concentration
B2: ='Cover Sheet'!B2 -> SC Germany Auto 10-1 | D2: Reporting Date | F2: ='Cover Sheet'!F2 -> 41191
B3: ='Cover Sheet'!B3 -> Monthly Investor Report | D3: Payment Date | F3: ='Cover Sheet'!F3 -> 41197
D4: Period No | F4: ='Cover Sheet'!F4 -> 27
B5: 8. Borrower Concentration | D5: Monthly Period | F5: ='Cover Sheet'!F5 -> 41197
D6: ='Cover Sheet'!D6 -> Interest Period | E6: from | F6: ='Cover Sheet'!F6 -> 41164 | G6: to | H6: ='Cover Sheet'!H6 -> 41197 | I6: = | J6: ='Cover Sheet'!J6 -> 33 days
D7: ='Cover Sheet'!D7 -> Collection Period | E7: from | F7: ='Cover Sheet'!F7 -> 01.09.2012 | G7: to | H7: ='Cover Sheet'!H7 -> 41182
D13: No | E13: Current Principal Balance in EUR | F13: Percentage of Balance | G13: Number of Loans
D14: 1 | E14: 68576.51 | F14: 0.00031521671 | G14: 1
D15: =+D14+1 -> 2 | E15: 43386.68 | F15: 0.0001994299 | G15: 1
D16: =+D15+1 -> 3 | E16: 42780.79 | F16: 0.00019664489 | G16: 1
D17: =+D16+1 -> 4 | E17: 42210.74 | F17: 0.00019402461 | G17: 1
D18: =+D17+1 -> 5 | E18: 38211.86 | F18: 0.00017564348 | G18: 1
D19: =+D18+1 -> 6 | E19: 37047.87 | F19: 0.00017029312 | G19: 2
D20: =+D19+1 -> 7 | E20: 35624.53 | F20: 0.00016375064 | G20: 1
D21: =+D20+1 -> 8 | E21: 34294.01 | F21: 0.00015763481 | G21: 1
D22: =+D21+1 -> 9 | E22: 33959.41 | F22: 0.0001560968 | G22: 1
D23: =+D22+1 -> 10 | E23: 32808.72 | F23: 0.00015080757 | G23: 1
D24: =+D23+1 -> 11 | E24: 32115.09 | F24: 0.00014761925 | G24: 1
D25: =+D24+1 -> 12 | E25: 31069.37 | F25: 0.00014281253 | G25: 1
D26: =+D25+1 -> 13 | E26: 31040.15 | F26: 0.00014267822 | G26: 1
... D38: =+D37+1 -> 25 | E38: 28549.67 | F38: 0.00013123055 | G38: 1
E39: =SUM(E14:E38) -> 860097.79 | F39: =SUM(F14:F38) -> 0.0039534995 | G39: =SUM(G14:G38) -> 26

Sheet 9. Geographical Distribution
B2: ='Cover Sheet'!B2 -> SC Germany Auto 10-1 | D2: Reporting Date | F2: ='Cover Sheet'!F2 -> 41191
B3: ='Cover Sheet'!B3 -> Monthly Investor Report | D3: Payment Date | F3: ='Cover Sheet'!F3 -> 41197
D4: Period No | F4: ='Cover Sheet'!F4 -> 27
B5: 9. Geographical Distribution | D5: Monthly Period | F5: ='Cover Sheet'!F5 -> 41197
D6: ='Cover Sheet'!D6 -> Interest Period | E6: from | F6: ='Cover Sheet'!F6 -> 41164 | G6: to | H6: ='Cover Sheet'!H6 -> 41197 | I6: = | J6: ='Cover Sheet'!J6 -> 33 days
D7: ='Cover Sheet'!D7 -> Collection Period | E7: from | F7: ='Cover Sheet'!F7 -> 01.09.2012 | G7: to | H7: ='Cover Sheet'!H7 -> 41182
D13: State | E13: Current Principal Balance in EUR | F13: Percentage of Balance | G13: Number of Loans | H13: Percentage of Loans
D14: Baden-Württemberg | E14: 16939938 | F14: 0.077865605 | G14: 3341 | H14: 0.079334172
D15: Bayern | E15: 19855347 | F15: 0.091266487 | G15: 3789 | H15: 0.089972218
D16: Berlin | E16: 5662739.5 | F16: 0.026029177 | G16: 1144 | H16: 0.027165008
D17: Brandenburg | E17: 14540375 | F17: 0.06683585 | G17: 2847 | H17: 0.067603828
D18: Bremen | E18: 1250942.6 | F18: 0.0057500451 | G18: 266 | H18: 0.0063163394
D19: Hamburg | E19: 3106904 | F19: 0.014281101 | G19: 625 | H19: 0.014841023
D20: Hessen | E20: 13518248 | F20: 0.062137571 | G20: 2451 | H20: 0.058200556
D21: Mecklenburg-Vorpommern | E21: 10872019 | F21: 0.049973995 | G21: 2189 | H21: 0.051979199
D22: Niedersachsen | E22: 22271359 | F22: 0.10237186 | G22: 4188 | H22: 0.099446727
D23: Nordrhein-Westfalen | E23: 38669899 | F23: 0.17774889 | G23: 7654 | H23: 0.1817491
D24: Rheinland-Pfalz | E24: 9083024.5 | F24: 0.041750756 | G24: 1716 | H24: 0.040747513
D25: Saarland | E25: 2615645.7 | F25: 0.012022998 | G25: 483 | H25: 0.011469143
... D30: n/a | E30: 954982.78 | F30: 0.004389645 | G30: 185 | H30: 0.0043929428
D31: Total | E31: 2.1755353e+08 | F31: =SUM(F14:F30) -> 1 | G31: 42113 | H31: =SUM(H14:H30) -> 1

Sheet 9.1 Geographical (Graph)
B2: ='Cover Sheet'!B2 -> SC Germany Auto 10-1 | D2: Reporting Date | F2: ='Cover Sheet'!F2 -> 41191
B3: ='Cover Sheet'!B3 -> Monthly Investor Report | D3: Payment Date | F3: ='Cover Sheet'!F3 -> 41197
D4: Period No | F4: ='Cover Sheet'!F4 -> 27
B5: 9.1 Geographical Distribution (Graph) | D5: Monthly Period | F5: ='Cover Sheet'!F5 -> 41197
D6: ='Cover Sheet'!D6 -> Interest Period | E6: from | F6: ='Cover Sheet'!F6 -> 41164 | G6: to | H6: ='Cover Sheet'!H6 -> 41197 | I6: = | J6: ='Cover Sheet'!J6 -> 33 days
D7: ='Cover Sheet'!D7 -> Collection Period | E7: from | F7: ='Cover Sheet'!F7 -> 01.09.2012 | G7: to | H7: ='Cover Sheet'!H7 -> 41182

Sheet 10. Object Type
B2: ='Cover Sheet'!B2 -> SC Germany Auto 10-1 | D2: Reporting Date | F2: ='Cover Sheet'!F2 -> 41191
B3: ='Cover Sheet'!B3 -> Monthly Investor Report | D3: Payment Date | F3: ='Cover Sheet'!F3 -> 41197
D4: Period No | F4: ='Cover Sheet'!F4 -> 27
B5: 10. Object Type | D5: Monthly Period | F5: ='Cover Sheet'!F5 -> 41197
D6: ='Cover Sheet'!D6 -> Interest Period | E6: from | F6: ='Cover Sheet'!F6 -> 41164 | G6: to | H6: ='Cover Sheet'!H6 -> 41197 | I6: = | J6: ='Cover Sheet'!J6 -> 33 days
D7: ='Cover Sheet'!D7 -> Collection Period | E7: from | F7: ='Cover Sheet'!F7 -> 01.09.2012 | G7: to | H7: ='Cover Sheet'!H7 -> 41182
D13: Car Type | E13: Current Principal Balance in EUR | F13: Percentage of Balance | G13: Number of Loans | H13: Percentage of Loans
D14: New Vehicle | E14: 87339759 | F14: 0.4014633 | G14: 17116 | H14: 0.40643032
D15: Used Vehicle | E15: 1.3021377e+08 | F15: 0.5985367 | G15: 24997 | H15: 0.59356968
D16: Total | E16: =SUM(E14:E15) -> 2.1755353e+08 | F16: =SUM(F14:F15) -> 1 | G16: =SUM(G14:G15) -> 42113 | H16: =SUM(H14:H15) -> 1
D21: Object Type | E21: Current Principal Balance in EUR | F21: Percentage of Balance | G21: Number of Loans | H21: Percentage of Loans
D22: Car | E22: 2.1318702e+08 | F22: 0.97992902 | G22: 40462 | H22: 0.96079595
D23: Motorbike | E23: 3550506.7 | F23: 0.016320152 | G23: 1566 | H23: 0.037185667
D24: Trailer | E24: 816006.65 | F24: 0.0037508315 | G24: 85 | H24: 0.0020183791
D25: Total | E25: =SUM(E22:E24) -> 2.1755353e+08 | F25: =SUM(F22:F24) -> 1 | G25: =SUM(G22:G24) -> 42113 | H25: =SUM(H22:H24) -> 1

Sheet 11. Insurances
B2: ='Cover Sheet'!B2 -> SC Germany Auto 10-1 | D2: Reporting Date | F2: ='Cover Sheet'!F2 -> 41191
B3: ='Cover Sheet'!B3 -> Monthly Investor Report | D3: Payment Date | F3: ='Cover Sheet'!F3 -> 41197
D4: Period No | F4: ='Cover Sheet'!F4 -> 27
B5: 11. Insurances | D5: Monthly Period | F5: ='Cover Sheet'!F5 -> 41197
D6: ='Cover Sheet'!D6 -> Interest Period | E6: from | F6: ='Cover Sheet'!F6 -> 41164 | G6: to | H6: ='Cover Sheet'!H6 -> 41197 | I6: = | J6: ='Cover Sheet'!J6 -> 33 days
D7: ='Cover Sheet'!D7 -> Collection Period | E7: from | F7: ='Cover Sheet'!F7 -> 01.09.2012 | G7: to | H7: ='Cover Sheet'!H7 -> 41182
D13: Payment Protection Insurance | E13: Current Principal Balance in EUR | F13: Percentage of Balance | G13: Number of Loans | H13: Percentage of Loans
D14: No | E14: 63801195 | F14: 0.29326664 | G14: 12314 | H14: 0.29240377
D15: Yes | E15: 1.5375234e+08 | F15: 0.70673336 | G15: 29799 | H15: 0.70759623
D16: Total | E16: =SUM(E14:E15) -> 2.1755353e+08 | F16: =SUM(F14:F15) -> 1 | G16: =SUM(G14:G15) -> 42113 | H16: =SUM(H14:H15) -> 1
D19: Gap Insurance | E19: Current Principal Balance in EUR | F19: Percentage of Balance | G19: Number of Loans | H19: Percentage of Loans
D20: No | E20: 1.5550295e+08 | F20: 0.71478016 | G20: 31176 | H20: 0.74029397
D21: Yes | E21: 62050584 | F21: 0.28521984 | G21: 10937 | H21: 0.25970603
D22: Total | E22: =SUM(E20:E21) -> 2.1755353e+08 | F22: =SUM(F20:F21) -> 1 | G22: =SUM(G20:G21) -> 42113 | H22: =SUM(H20:H21) -> 1

Sheet 12. Type of Contract
B2: ='Cover Sheet'!B2 -> SC Germany Auto 10-1 | D2: Reporting Date | F2: ='Cover Sheet'!F2 -> 41191
B3: ='Cover Sheet'!B3 -> Monthly Investor Report | D3: Payment Date | F3: ='Cover Sheet'!F3 -> 41197
D4: Period No | F4: ='Cover Sheet'!F4 -> 27
B5: 12. Type of Contract | D5: Monthly Period | F5: ='Cover Sheet'!F5 -> 41197
D6: ='Cover Sheet'!D6 -> Interest Period | E6: from | F6: ='Cover Sheet'!F6 -> 41164 | G6: to | H6: ='Cover Sheet'!H6 -> 41197 | I6: = | J6: ='Cover Sheet'!J6 -> 33 days
D7: ='Cover Sheet'!D7 -> Collection Period | E7: from | F7: ='Cover Sheet'!F7 -> 01.09.2012 | G7: to | H7: ='Cover Sheet'!H7 -> 41182
D13: Contracts w/Balloon Payments | E13: Current Principal Balance in EUR | F13: Percentage of Balance | G13: Number of Loans | H13: Percentage of Loans
D14: No | E14: 1.454049e+08 | F14: 0.66836376 | G14: 33075 | H14: 0.78538694
D15: Yes | E15: 72148637 | F15: 0.33163624 | G15: 9038 | H15: 0.21461306
D16: - of which ballon rates | E16: =E29 -> 51126495 | F16: =E16/E18 -> 0.2350065
D17: - of which regular installments | E17: =F17*E18 -> 21022142 | F17: =F15-F16 -> 0.096629743
D18: Total | E18: =SUM(E14:E15) -> 2.1755353e+08 | F18: =SUM(F14:F15) -> 1 | G18: =SUM(G14:G15) -> 42113 | H18: =SUM(H14:H15) -> 1
D23: Balloon Loans - Original Term in months | E23: Balloon Amounts in EUR | F23: Balloon Amounts in % | G23: Number of Balloon Loans | H23: Balloon Loans in %
D24: 26:38 | E24: 7385128.8 | F24: 0.14444817 | G24: 1572 | H24: 0.17393229
D25: 39:51 | E25: 23268961 | F25: 0.4551253 | G25: 4048 | H25: 0.4478867
D26: 52:64 | E26: 20387057 | F26: 0.39875719 | G26: 3409 | H26: 0.37718522
D27: 65:72 | E27: 50686.86 | F27: 0.00099140104 | G27: 5 | H27: 0.00055321974
D28: 73: | E28: 34660.25 | F28: 0.00067793128 | G28: 4 | H28: 0.00044257579
D29: Total | E29: =SUM(E24:E28) -> 51126495 | F29: =SUM(F24:F28) -> 1 | G29: =SUM(G24:G28) -> 9038 | H29: =SUM(H24:H28) -> 1
D34: Balloon Loans - Remaining Term in months | E34: Balloon Amounts in EUR | F34: Balloon Amounts in % | G34: Number of Balloon Loans | H34: Balloon Loans in %
D35: 0:12 | E35: 17234374 | F35: 0.33709282 | G35: 3512 | H35: 0.38858154
D36: 13:25 | E36: 24911387 | F36: 0.48725005 | G36: 4164 | H36: 0.4607214
D37: 26:38 | E37: 8968781.2 | F37: 0.17542336 | G37: 1360 | H37: 0.15047577
D38: 39:51 | E38: 3996 | F38: 7.8159084e-05 | G38: 1 | H38: 0.00011064395
D39: 73: | E39: 7956 | F39: 0.00015561403 | G39: 1 | H39: 0.00011064395
D40: Total | E40: =SUM(E35:E39) -> 51126495 | F40: =SUM(F35:F39) -> 1 | G40: =SUM(G35:G39) -> 9038 | H40: =SUM(H35:H39) -> 1

Sheet 13. Payment Methods
B2: ='Cover Sheet'!B2 -> SC Germany Auto 10-1 | D2: Reporting Date | F2: ='Cover Sheet'!F2 -> 41191
B3: ='Cover Sheet'!B3 -> Monthly Investor Report | D3: Payment Date | F3: ='Cover Sheet'!F3 -> 41197
D4: Period No | F4: ='Cover Sheet'!F4 -> 27
B5: 13. Payment Methods | D5: Monthly Period | F5: ='Cover Sheet'!F5 -> 41197
D6: ='Cover Sheet'!D6 -> Interest Period | E6: from | F6: ='Cover Sheet'!F6 -> 41164 | G6: to | H6: ='Cover Sheet'!H6 -> 41197 | I6: = | J6: ='Cover Sheet'!J6 -> 33 days
D7: ='Cover Sheet'!D7 -> Collection Period | E7: from | F7: ='Cover Sheet'!F7 -> 01.09.2012 | G7: to | H7: ='Cover Sheet'!H7 -> 41182
D13: Payment Method | E13: Current Principal Balance in EUR | F13: Percentage of Balance | G13: Number of Loans | H13: Percentage of Loans
D14: Direct Debit | E14: 2.1121382e+08 | F14: 0.97085907 | G14: 40388 | H14: 0.95903878
D15: Other | E15: 6339713.3 | F15: 0.029140935 | G15: 1725 | H15: 0.040961223
D16: Total | E16: =SUM(E14:E15) -> 2.1755353e+08 | F16: =SUM(F14:F15) -> 1 | G16: =SUM(G14:G15) -> 42113 | H16: =SUM(H14:H15) -> 1
D20: Cycle of Payment | E20: Current Principal Balance in EUR | F20: Percentage of Balance | G20: Number of Loans | H20: Percentage of Loans
D21: 15th of month | E21: 1.0627947e+08 | F21: 0.48852102 | G21: 20500 | H21: 0.48678555
D22: 1st of month | E22: 1.1127406e+08 | F22: 0.51147898 | G22: 21613 | H22: 0.51321445
D23: Total | E23: =SUM(E21:E22) -> 2.1755353e+08 | F23: =SUM(F21:F22) -> 1 | G23: =SUM(G21:G22) -> 42113 | H23: =SUM(H21:H22) -> 1
D27: Downpayment | E27: Current Principal Balance in EUR | F27: Percentage of Balance | G27: Number of Loans | H27: Percentage of Loans
D28: with initial downpayment | E28: 1.5363001e+08 | F28: 0.70617108 | G28: 31438 | H28: 0.74651533
D29: without initial downpayment | E29: 63923521 | F29: 0.29382892 | G29: 10675 | H29: 0.25348467
D30: Total | E30: =SUM(E28:E29) -> 2.1755353e+08 | F30: =SUM(F28:F29) -> 1 | G30: =SUM(G28:G29) -> 42113 | H30: =SUM(H28:H29) -> 1
D34: Downpayment and Purchase Price in EUR | E34: All contracts | F34: Contracts with initial downpayment
D35: Weighted average downpayment | E35: 3345.3494 | F35: 4481.287
D36: Average purchase price | E36: 13750.087 | F36: 14606.891
D37: Downpayment in % | E37: =E35/E36 -> 0.24329659 | F37: =F35/F36 -> 0.30679265

Sheet 14. Customer Yield
B2: ='Cover Sheet'!B2 -> SC Germany Auto 10-1 | D2: Reporting Date | F2: ='Cover Sheet'!F2 -> 41191
B3: ='Cover Sheet'!B3 -> Monthly Investor Report | D3: Payment Date | F3: ='Cover Sheet'!F3 -> 41197
D4: Period No | F4: ='Cover Sheet'!F4 -> 27
B5: 14. Customer Yield | D5: Monthly Period | F5: ='Cover Sheet'!F5 -> 41197
D6: ='Cover Sheet'!D6 -> Interest Period | E6: from | F6: ='Cover Sheet'!F6 -> 41164 | G6: to | H6: ='Cover Sheet'!H6 -> 41197 | I6: = | J6: ='Cover Sheet'!J6 -> 33 days
D7: ='Cover Sheet'!D7 -> Collection Period | E7: from | F7: ='Cover Sheet'!F7 -> 01.09.2012 | G7: to | H7: ='Cover Sheet'!H7 -> 41182
D13: Yield Range* | E13: Current Principal Balance in EUR | F13: Percentage of Balance | G13: Number of Loans | H13: Percentage of Loans
D14: 1: 1 | E14: 2535.22 | F14: 1.1653316e-05 | G14: 1 | H14: 2.3745637e-05
D15: 4: 4 | E15: 20674985 | F15: 0.09503401 | G15: 3200 | H15: 0.075986038
D16: 5: 5 | E16: 43490089 | F16: 0.19990523 | G16: 6842 | H16: 0.16246765
D17: 6: 6 | E17: 60038156 | F17: 0.27596957 | G17: 11457 | H17: 0.27205376
D18: 7: 7 | E18: 45501491 | F18: 0.20915078 | G18: 8928 | H18: 0.21200104
D19: 8: 8 | E19: 25420516 | F19: 0.11684718 | G19: 5483 | H19: 0.13019733
D20: 9: 9 | E20: 15514263 | F20: 0.071312393 | G20: 4069 | H20: 0.096620996
D21: 10:10 | E21: 6249179.9 | F21: 0.028724792 | G21: 1976 | H21: 0.046921378
D22: 11:11 | E22: 340298.77 | F22: 0.001564207 | G22: 78 | H22: 0.0018521597
D23: 12:12 | E23: 101168.56 | F23: 0.00046502835 | G23: 28 | H23: 0.00066487783
D24: 13:13 | E24: 193649.58 | F24: 0.00089012381 | G24: 45 | H24: 0.0010685537
D25: 14:14 | E25: 1003.14 | F25: 4.611003e-06 | G25: 1 | H25: 2.3745637e-05
D26: 15:15 | E26: 26197.89 | F26: 0.00012042043 | G26: 5 | H26: 0.00011872818
D27: Total | E27: =SUM(E14:E26) -> 2.1755353e+08 | F27: =SUM(F14:F26) -> 1 | G27: =SUM(G14:G26) -> 42113 | H27: =SUM(H14:H26) -> 1
D30: Statistics | E30: in %
D31: WA Interest | E31: 0.064685286
D33: *runs from .00 to .99

Sheet 14.1 Customer Yield (Graph)
B2: ='Cover Sheet'!B2 -> SC Germany Auto 10-1 | D2: Reporting Date | F2: ='Cover Sheet'!F2 -> 41191
B3: ='Cover Sheet'!B3 -> Monthly Investor Report | D3: Payment Date | F3: ='Cover Sheet'!F3 -> 41197
D4: Period No | F4: ='Cover Sheet'!F4 -> 27
B5: 14.1 Customer Yield (Graph) | D5: Monthly Period | F5: ='Cover Sheet'!F5 -> 41197
D6: ='Cover Sheet'!D6 -> Interest Period | E6: from | F6: ='Cover Sheet'!F6 -> 41164 | G6: to | H6: ='Cover Sheet'!H6 -> 41197 | I6: = | J6: ='Cover Sheet'!J6 -> 33 days
D7: ='Cover Sheet'!D7 -> Collection Period | E7: from | F7: ='Cover Sheet'!F7 -> 01.09.2012 | G7: to | H7: ='Cover Sheet'!H7 -> 41182
H45: *runs from .00 to .99

Sheet 15. Seasoning
B2: ='Cover Sheet'!B2 -> SC Germany Auto 10-1 | D2: Reporting Date | F2: ='Cover Sheet'!F2 -> 41191
B3: ='Cover Sheet'!B3 -> Monthly Investor Report | D3: Payment Date | F3: ='Cover Sheet'!F3 -> 41197
D4: Period No | F4: ='Cover Sheet'!F4 -> 27
B5: 15. Seasoning | D5: Monthly Period | F5: ='Cover Sheet'!F5 -> 41197
D6: ='Cover Sheet'!D6 -> Interest Period | E6: from | F6: ='Cover Sheet'!F6 -> 41164 | G6: to | H6: ='Cover Sheet'!H6 -> 41197 | I6: = | J6: ='Cover Sheet'!J6 -> 33 days
D7: ='Cover Sheet'!D7 -> Collection Period | E7: from | F7: ='Cover Sheet'!F7 -> 01.09.2012 | G7: to | H7: ='Cover Sheet'!H7 -> 41182
D13: Seasoning in Months | E13: Current Principal Balance in EUR | F13: Percentage of Balance | G13: Number of Loans | H13: Percentage of Loans
D14: 27:29 | E14: 746825.95 | F14: 0.0034328376 | G14: 97 | H14: 0.0023033268
D15: 30:32 | E15: 78197840 | F15: 0.35944183 | G15: 11720 | H15: 0.27829886
D16: 33:35 | E16: 47543770 | F16: 0.21853826 | G16: 8332 | H16: 0.19784865
D17: 36:38 | E17: 38345105 | F17: 0.17625595 | G17: 8429 | H17: 0.20015197
D18: 39:41 | E18: 18802013 | F18: 0.086424767 | G18: 4641 | H18: 0.1102035
D19: 42:44 | E19: 16231388 | F19: 0.074608708 | G19: 3925 | H19: 0.093201624
D20: 45:47 | E20: 7709468.4 | F20: 0.03543711 | G20: 1814 | H20: 0.043074585
D21: 48:50 | E21: 5253138 | F21: 0.024146416 | G21: 1563 | H21: 0.03711443
D22: 51:53 | E22: 3210298.4 | F22: 0.014756361 | G22: 1027 | H22: 0.024386769
D23: 54:56 | E23: 725102.61 | F23: 0.0033329847 | G23: 239 | H23: 0.0056752072
D24: 57:59 | E24: 363231.59 | F24: 0.0016696193 | G24: 114 | H24: 0.0027070026
D25: 60:62 | E25: 207155.85 | F25: 0.00095220632 | G25: 100 | H25: 0.0023745637
... D32: 81: | E32: 5764.79 | F32: 2.6498259e-05 | G32: 11 | H32: 0.000261202
D33: Total | E33: =SUM(E14:E32) -> 2.1755353e+08 | F33: =SUM(F14:F32) -> 1 | G33: =SUM(G14:G32) -> 42113 | H33: =SUM(H14:H32) -> 1
D36: Statistics
D37: WA Seasoning | E37: 35.792734

Sheet 15.1 Seasoning (Graph)
B2: ='Cover Sheet'!B2 -> SC Germany Auto 10-1 | D2: Reporting Date | F2: ='Cover Sheet'!F2 -> 41191
B3: ='Cover Sheet'!B3 -> Monthly Investor Report | D3: Payment Date | F3: ='Cover Sheet'!F3 -> 41197
D4: Period No | F4: ='Cover Sheet'!F4 -> 27
B5: 15.1 Seasoning (Graph) | D5: Monthly Period | F5: ='Cover Sheet'!F5 -> 41197
D6: ='Cover Sheet'!D6 -> Interest Period | E6: from | F6: ='Cover Sheet'!F6 -> 41164 | G6: to | H6: ='Cover Sheet'!H6 -> 41197 | I6: = | J6: ='Cover Sheet'!J6 -> 33 days
D7: ='Cover Sheet'!D7 -> Collection Period | E7: from | F7: ='Cover Sheet'!F7 -> 01.09.2012 | G7: to | H7: ='Cover Sheet'!H7 -> 41182

Sheet 16. Remaining Term
B2: ='Cover Sheet'!B2 -> SC Germany Auto 10-1 | D2: Reporting Date | F2: ='Cover Sheet'!F2 -> 41191
B3: ='Cover Sheet'!B3 -> Monthly Investor Report | D3: Payment Date | F3: ='Cover Sheet'!F3 -> 41197
D4: Period No | F4: ='Cover Sheet'!F4 -> 27
B5: 16. Remaining Term | D5: Monthly Period | F5: ='Cover Sheet'!F5 -> 41197
D6: ='Cover Sheet'!D6 -> Interest Period | E6: from | F6: ='Cover Sheet'!F6 -> 41164 | G6: to | H6: ='Cover Sheet'!H6 -> 41197 | I6: = | J6: ='Cover Sheet'!J6 -> 33 days
D7: ='Cover Sheet'!D7 -> Collection Period | E7: from | F7: ='Cover Sheet'!F7 -> 01.09.2012 | G7: to | H7: ='Cover Sheet'!H7 -> 41182
D13: Remaining Term in Months | E13: Current Principal Balance in EUR | F13: Percentage of Balance | G13: Number of Loans | H13: Percentage of Loans
D14: 0: 6 | E14: 14960673 | F14: 0.068767777 | G14: 7883 | H14: 0.18718685
D15: 7:13 | E15: 18444532 | F15: 0.08478158 | G15: 5456 | H15: 0.12955619
D16: 14:20 | E16: 39467787 | F16: 0.18141644 | G16: 7569 | H16: 0.17973072
D17: 21:27 | E17: 36572787 | F17: 0.16810937 | G17: 6644 | H17: 0.15776601
D18: 28:34 | E18: 37558209 | F18: 0.17263893 | G18: 5760 | H18: 0.13677487
D19: 35:41 | E19: 31031340 | F19: 0.14263772 | G19: 4353 | H19: 0.10336476
D20: 42:48 | E20: 18002255 | F20: 0.082748621 | G20: 2262 | H20: 0.05371263
D21: 49:55 | E21: 20274630 | F21: 0.093193753 | G21: 2077 | H21: 0.049319688
D22: 56:62 | E22: 1053818.8 | F22: 0.0048439514 | G22: 94 | H22: 0.0022320899
D23: 63:69 | E23: 180486.51 | F23: 0.00082961884 | G23: 14 | H23: 0.00033243891
D24: 77:83 | E24: 7014.99 | F24: 3.2244891e-05 | G24: 1 | H24: 2.3745637e-05
D25: Total | E25: =SUM(E14:E24) -> 2.1755353e+08 | F25: =SUM(F14:F24) -> 1 | G25: =SUM(G14:G24) -> 42113 | H25: =SUM(H14:H24) -> 1
D29: Statistics
D30: WA Remaining Term | E30: 27.823743

Sheet 16.1 Remaining Term (Graph)
B2: ='Cover Sheet'!B2 -> SC Germany Auto 10-1 | D2: Reporting Date | F2: ='Cover Sheet'!F2 -> 41191
B3: ='Cover Sheet'!B3 -> Monthly Investor Report | D3: Payment Date | F3: ='Cover Sheet'!F3 -> 41197
D4: Period No | F4: ='Cover Sheet'!F4 -> 27
B5: 16.1 Remaining Term (Graph) | D5: Monthly Period | F5: ='Cover Sheet'!F5 -> 41197
D6: ='Cover Sheet'!D6 -> Interest Period | E6: from | F6: ='Cover Sheet'!F6 -> 41164 | G6: to | H6: ='Cover Sheet'!H6 -> 41197 | I6: = | J6: ='Cover Sheet'!J6 -> 33 days
D7: ='Cover Sheet'!D7 -> Collection Period | E7: from | F7: ='Cover Sheet'!F7 -> 01.09.2012 | G7: to | H7: ='Cover Sheet'!H7 -> 41182

Sheet 17. Original Term
B2: ='Cover Sheet'!B2 -> SC Germany Auto 10-1 | D2: Reporting Date | F2: ='Cover Sheet'!F2 -> 41191
B3: ='Cover Sheet'!B3 -> Monthly Investor Report | D3: Payment Date | F3: ='Cover Sheet'!F3 -> 41197
D4: Period No | F4: ='Cover Sheet'!F4 -> 27
B5: 17. Original Term | D5: Monthly Period | F5: ='Cover Sheet'!F5 -> 41197
D6: ='Cover Sheet'!D6 -> Interest Period | E6: from | F6: ='Cover Sheet'!F6 -> 41164 | G6: to | H6: ='Cover Sheet'!H6 -> 41197 | I6: = | J6: ='Cover Sheet'!J6 -> 33 days
D7: ='Cover Sheet'!D7 -> Collection Period | E7: from | F7: ='Cover Sheet'!F7 -> 01.09.2012 | G7: to | H7: ='Cover Sheet'!H7 -> 41182
D13: Original Term in Months | E13: Current Principal Balance in EUR | F13: Percentage of Balance | G13: Number of Loans | H13: Percentage of Loans
D14: 13:25 | E14: 0 | F14: 0 | G14: 1 | H14: 2.3745637e-05
D15: 26:38 | E15: 9979329 | F15: 0.045870682 | G15: 5182 | H15: 0.12304989
D16: 39:51 | E16: 45989955 | F16: 0.21139604 | G16: 11251 | H16: 0.26716216
D17: 52:64 | E17: 73845174 | F17: 0.3394345 | G17: 13287 | H17: 0.31550828
D18: 65:77 | E18: 49276590 | F18: 0.22650328 | G18: 7840 | H18: 0.18616579
D19: 78: | E19: 38462486 | F19: 0.1767955 | G19: 4552 | H19: 0.10809014
D20: Total | E20: =SUM(E14:E19) -> 2.1755353e+08 | F20: =SUM(F14:F19) -> 1 | G20: =SUM(G14:G19) -> 42113 | H20: =SUM(H14:H19) -> 1
D24: Statistics
D25: WA Original Term | E25: 63.616476

Sheet 17.1 Original Term (Graph)
B2: ='Cover Sheet'!B2 -> SC Germany Auto 10-1 | D2: Reporting Date | F2: ='Cover Sheet'!F2 -> 41191
B3: ='Cover Sheet'!B3 -> Monthly Investor Report | D3: Payment Date | F3: ='Cover Sheet'!F3 -> 41197
D4: Period No | F4: ='Cover Sheet'!F4 -> 27
B5: 17.1 Original Term (Graph) | D5: Monthly Period | F5: ='Cover Sheet'!F5 -> 41197
D6: ='Cover Sheet'!D6 -> Interest Period | E6: from | F6: ='Cover Sheet'!F6 -> 41164 | G6: to | H6: ='Cover Sheet'!H6 -> 41197 | I6: = | J6: ='Cover Sheet'!J6 -> 33 days
D7: ='Cover Sheet'!D7 -> Collection Period | E7: from | F7: ='Cover Sheet'!F7 -> 01.09.2012 | G7: to | H7: ='Cover Sheet'!H7 -> 41182

Sheet 18. Manufacturer
B2: ='Cover Sheet'!B2 -> SC Germany Auto 10-1 | D2: Reporting Date | F2: ='Cover Sheet'!F2 -> 41191
B3: ='Cover Sheet'!B3 -> Monthly Investor Report | D3: Payment Date | F3: ='Cover Sheet'!F3 -> 41197
D4: Period No | F4: ='Cover Sheet'!F4 -> 27
B5: 18. Manufacturer | D5: Monthly Period | F5: ='Cover Sheet'!F5 -> 41197
D6: ='Cover Sheet'!D6 -> Interest Period | E6: from | F6: ='Cover Sheet'!F6 -> 41164 | G6: to | H6: ='Cover Sheet'!H6 -> 41197 | I6: = | J6: ='Cover Sheet'!J6 -> 33 days
D7: ='Cover Sheet'!D7 -> Collection Period | E7: from | F7: ='Cover Sheet'!F7 -> 01.09.2012 | G7: to | H7: ='Cover Sheet'!H7 -> 41182
D13: Manufacturer | E13: Current Principal Balance in EUR | F13: Percentage of Balance | G13: Number of Loans | H13: Percentage of Loans
D14: 1 | E14: 26526153 | F14: 0.12192931 | G14: 5325 | H14: 0.12644552
D15: =+D14+1 -> 2 | E15: 21723827 | F15: 0.099855084 | G15: 3753 | H15: 0.089117375
D16: =+D15+1 -> 3 | E16: 17825659 | F16: 0.081936885 | G16: 3134 | H16: 0.074418826
D17: =+D16+1 -> 4 | E17: 17736350 | F17: 0.08152637 | G17: 3491 | H17: 0.082896018
D18: =+D17+1 -> 5 | E18: 14795040 | F18: 0.068006435 | G18: 2491 | H18: 0.059150381
D19: =+D18+1 -> 6 | E19: 9762324.5 | F19: 0.044873206 | G19: 2033 | H19: 0.048274879
D20: =+D19+1 -> 7 | E20: 9318107.6 | F20: 0.042831332 | G20: 1810 | H20: 0.042979602
D21: =+D20+1 -> 8 | E21: 9103753.6 | F21: 0.041846038 | G21: 1466 | H21: 0.034811103
D22: =+D21+1 -> 9 | E22: 8949719.4 | F22: 0.04113801 | G22: 1330 | H22: 0.031581697
D23: =+D22+1 -> 10 | E23: 8913454.4 | F23: 0.040971315 | G23: 1311 | H23: 0.03113053
D24: =+D23+1 -> 11 | E24: 8764356.8 | F24: 0.040285978 | G24: 1862 | H24: 0.044214376
D25: =+D24+1 -> 12 | E25: 7959510.2 | F25: 0.036586444 | G25: 1421 | H25: 0.03374255
D26: =+D25+1 -> 13 | E26: 7083765.4 | F26: 0.032561022 | G26: 1811 | H26: 0.043003348
... D28: =+D27+1 -> 15 | E28: 5489142.5 | F28: 0.025231227 | G28: 1025 | H28: 0.024339278
E29: =SUM(E14:E28) -> 1.8044606e+08 | F29: =SUM(F14:F28) -> 0.8294329 | G29: =SUM(G14:G28) -> 33613 | H29: =SUM(H14:H28) -> 0.79816209
D31: TOP 15 manufacturer brands in alphabetical order:
D32: Audi, BMW, Citroen, Ford, Honda, Hyundai, Kia, Mazda, Mercedes, Nissan, Opel, Peugeot, Renault, Suzuki, VW

Sheet 19. PoP + Transaction Costs
B2: ='Cover Sheet'!B2 -> SC Germany Auto 10-1 | D2: Reporting Date | F2: ='Cover Sheet'!F2 -> 41191
B3: ='Cover Sheet'!B3 -> Monthly Investor Report | D3: Payment Date | F3: ='Cover Sheet'!F3 -> 41197
D4: Period No | F4: ='Cover Sheet'!F4 -> 27
B5: 19. Priority of Payments + Transaction Costs | D5: Monthly Period | F5: ='Cover Sheet'!F5 -> 41197
D6: ='Cover Sheet'!D6 -> Interest Period | E6: from | F6: ='Cover Sheet'!F6 -> 41164 | G6: to | H6: ='Cover Sheet'!H6 -> 41197 | I6: = | J6: ='Cover Sheet'!J6 -> 33 days
D7: ='Cover Sheet'!D7 -> Collection Period | E7: from | F7: ='Cover Sheet'!F7 -> 01.09.2012 | G7: to | H7: ='Cover Sheet'!H7 -> 41182
B13: Priority of Payments
B15: Available Distribution Amount | D15: 26449008
B16: Senior Expenses | C16: - | D16: 34450.2
B17: Net Swap Payments | C17: - | D17: 205578.36
B18: Interest Notes Class A | C18: - | D18: 210016.8
B19: Interest Notes Class B | C19: - | D19: 49005
B20: Principal Payments Class A | C20: - | D20: 11290558
B21: Principal Payments Class B | C21: - | D21: 0
B22: Payment due to rounding differences | C22: - | D22: 89.73
B23: Payments to Reserve Fund | C23: - | D23: 13053217
B24: Payments to Commingling Reserve Ledger | C24: - | D24: n/a
B25: Payments to Set-Off Reserve Ledger | C25: - | D25: n/a
B26: Swap Termination Payments | C26: - | D26: n/a
B27: Interest Subordinated Loan | C27: - | D27: 32976.45
B28: Principal Payments Subordinated Loan | C28: - | D28: 677433.45
B29: Payments to Seller | C29: = | D29: =D15-D16-D17-D18-D19-D20-D21-D22-IF(ISNUMBER(D23),D23,0)-IF(ISNUMBER(D24),D24,0)-IF(ISNUMBER(D25),D25,0)-IF(ISNUMBER(D26),D26,0)-D27-D28 -> 895682.92
B33: Transaction Costs | C33: All notes | D33: Class A | F33: Class B
B34: Senior Expenses | C34: -34450.2
B35: Interest accrued for the Period | C35: =SUM(D35:F35) -> -259021.8 | D35: -210016.8 | F35: -49005
B36: Cumulative Interest accrued | C36: =SUM(D36:F36) -> -17651683 | D36: -15931453 | F36: -1720230.6
B37: Interest Payments | C37: =SUM(D37:F37) -> -259021.8 | D37: -210016.8 | F37: -49005
B38: Cumulative Interest Payments | C38: =SUM(D38:F38) -> -17651683 | D38: -15931453 | F38: -1720230.6
B39: Interest accrued on Subordinated Loan for the Period | C39: -32976.45
B40: Cumulative Interest accrued on Subordinated Loan | C40: -1308729.4
B41: Interest Payments on Subordinated Loan | C41: -32976.45
B42: Cumulative Interest Payments on Subordinated Loan | C42: -1308729.4
B43: Unpaid Interest for the Period | C43: =C35-C37+C39-C41 -> 0
B44: Cumulative Unpaid Interest | C44: =C36-C38+C40-C42 -> 0

Sheet 20. Swap Counterparty Data
B2: ='Cover Sheet'!B2 -> SC Germany Auto 10-1 | D2: Reporting Date | G2: ='Cover Sheet'!F2 -> 41191
B3: ='Cover Sheet'!B3 -> Monthly Investor Report | D3: Payment Date | G3: ='Cover Sheet'!F3 -> 41197
D4: Period No | G4: ='Cover Sheet'!F4 -> 27
B5: 20. Swap Counterparty | D5: Monthly Period | G5: ='Cover Sheet'!F5 -> 41197
D6: ='Cover Sheet'!D6 -> Interest Period | F6: from | G6: ='Cover Sheet'!F6 -> 41164 | H6: to | I6: ='Cover Sheet'!H6 -> 41197 | J6: = | K6: ='Cover Sheet'!J6 -> 33 days
D7: ='Cover Sheet'!D7 -> Collection Period | F7: from | G7: ='Cover Sheet'!F7 -> 01.09.2012 | H7: to | I7: ='Cover Sheet'!H7 -> 41182
B13: Swap Counterparty
B14: Swap Counterparty | C14: Natixis
B15: Swap Rating Trigger Breach | C15: no
D17: Moody's | G17: Fitch | J17: S & P
B18: Rating Trigger & Current Ratings | C18: Consequenses | D18: Long Term | E18: Short Term | G18: Long Term | H18: Short Term | J18: Long Term | K18: Short Term | M18: Trigger breach
B20: 1st Rating Trigger | C20: Collateral, Guarantee or Replacement | D20: A2 | E20: P-1 | G20: A | H20: F1 | J20: --- | K20: A1 | M20: no
B22: 2nd Rating Trigger | C22: Guarantee or Replacement | D22: A3 | E22: P-2 | G22: BBB+ | H22: F2 | J22: --- | K22: A2 | M22: no
B24: 3rd Rating Trigger | C24: Guarantee or Replacement | D24: --- | E24: --- | G24: BBB- | H24: F3 | J24: --- | K24: --- | M24: no
B26: Current Counterparty Ratings | D26: A2 | E26: P-1 | F26: Stable | G26: A+ | H26: F1+ | I26: Negative | J26: A | K26: A-1 | L26: Stable
B29: Current Swap Data | E29: Swap Counterparty Details | I29: Counterparty Replacement
B30: Swap Type | C30: Fixed Floating Interest Rate Swap | E30: Natixis - OTC Collateral Management | I30: Old Counterparty | L30: =C14 -> Natixis
B31: Notional Amount | C31: 2.2884418e+08 | E31: 90 Avenue de Terroirs de France | I31: Current Counterparty | L31: =C14 -> Natixis
B32: Fixed Rate | C32: 0.011 | E32: 75012 Paris
B33: Floating Rate (Euribor) | C33: 0.0012 | E33: France
B34: Net Swap Payments | C34: -205578.36 | E34: eMail: collateral-management@natixis.com
E35: Phone: +33 158 55 99 48
B38: Ratings as of 30.09.2012

Sheet 21. Counterparties
B2: SC Germany Auto 10-1 | E2: Reporting Date | H2: ='Cover Sheet'!F2 -> 41191
B3: ='Cover Sheet'!B3 -> Monthly Investor Report | E3: Payment Date | H3: ='Cover Sheet'!F3 -> 41197
E4: Period No | H4: ='Cover Sheet'!F4 -> 27
B5: 21. Counterparties | E5: Monthly Period | H5: ='Cover Sheet'!F5 -> 41197
E6: ='Cover Sheet'!D6 -> Interest Period | G6: from | H6: ='Cover Sheet'!F6 -> 41164 | I6: to | J6: ='Cover Sheet'!H6 -> 41197 | K6: = | L6: ='Cover Sheet'!$J$6 -> 33 days
E7: ='Cover Sheet'!D7 -> Collection Period | G7: from | H7: ='Cover Sheet'!F7 -> 01.09.2012 | I7: to | J7: ='Cover Sheet'!H7 -> 41182
D12: Moody's | G12: Fitch | J12: S & P
D13: Long Term | E13: Short Term | F13: Outlook | G13: Long Term | H13: Short Term | I13: Outlook | J13: Long Term | K13: Short Term | L13: Outlook | N13: Counterparty status
B14: Joint Lead Managers: | C14: Portigon AG (ex WestLB AG)
C15: Asset Based Finance | D15: NR | E15: NR | G15: A+ | H15: F1+ | I15: Stable | J15: NR | K15: NR | N15: performing
C16: Herzogstraße 15
B17: eMail: abs@portigon.com | C17: 40217 Düsseldorf
B18: Phone: +49 211 826 01 | C18: Germany
C20: Natixis | D20: A2 | E20: P-1 | F20: Stable | G20: A+ | H20: F1+ | I20: Negative | J20: A | K20: A-1 | L20: Stable | N20: performing
C21: BP 4
B22: eMail: legal.bonds@natixis.com | C22: 75060 Paris Cedex 02
B23: Phone: +33 158 55 99 48 | C23: France
B25: Paying Agent: | C25: Bank of New York Mellon | D25: Aa1 | E25: P-1 | F25: Stable | G25: AA- | H25: F1+ | I25: Stable | J25: AA- | K25: A-1+ | L25: Negative | N25: performing
C26: Corporate Trust Administration
C27: One Canada Square
B28: eMail: BNYM.Structured.Finance.Team.8@bnymellon.com | C28: London E14 5AL
B29: Fax: +44 20 7964 4637 | C29: England
B31: Transaction Account: | C31: Bank of New York Mellon | D31: Aa1 | E31: P-1 | F31: Stable | G31: AA- | H31: F1+ | I31: Stable | J31: AA- | K31: A-1+ | L31: Negative | N31: performing
C32: Corporate Trust Administration
C33: Messe Turm
C34: Friedrich-Ebert-Anlage 49
B35: eMail: tsampikos.trigenis@bnymellon.com | C35: 60327 Frankfurt am Main
B36: Fax: +49 69 12014 1687 | C36: Germany
B38: Transaction Security Trustee: | C38: Bank of New York Mellon | D38: Aa1 | E38: P-1 | F38: Stable | G38: AA- | H38: F1+ | I38: Stable | J38: AA- | K38: A-1+ | L38: Negative | N38: performing
C39: Corporate Trust Administration
C40: One Canada Square
B41: eMail: BNYM.Structured.Finance.Team.8@bnymellon.com | C41: London E14 5AL
B42: Fax: +44 20 7964 4637 | C42: England
B44: Data Trustee: | C44: Portigon AG (ex WestLB AG) | N44: performing
C45: Asset Based Finance | D45: NR | E45: NR | G45: A+ | H45: F1+ | I45: Stable | J45: NR | K45: NR
C46: Herzogstraße 15
B47: eMail: abs@portigon.com | C47: 40217 Düsseldorf
B48: Phone: +49 211 826 01 | C48: Germany
B52: Rating Agencies: | C52: Moody's Deutschland GmbH | E52: Fitch Ratings Limited | I52: Standard & Poor's Ratings Services
C53: Strutured Finance Monitoring | E53: Strutured Finance Monitoring | I53: Structured Finance
...

Sheet 22. Issuer Information
B2: SC Germany Auto 10-1 | D2: Reporting Date | F2: ='Cover Sheet'!F2 -> 41191
B3: ='Cover Sheet'!B3 -> Monthly Investor Report | D3: Payment Date | F3: ='Cover Sheet'!F3 -> 41197
D4: Period No | F4: ='Cover Sheet'!F4 -> 27
B5: 22. Issuer Information | D5: Monthly Period | F5: ='Cover Sheet'!F5 -> 41197
D6: ='Cover Sheet'!D6 -> Interest Period | E6: from | F6: ='Cover Sheet'!F6 -> 41164 | G6: to | H6: ='Cover Sheet'!H6 -> 41197 | I6: = | J6: ='Cover Sheet'!$J$6 -> 33 days
D7: ='Cover Sheet'!D7 -> Collection Period | E7: from | F7: ='Cover Sheet'!F7 -> 01.09.2012 | G7: to | H7: ='Cover Sheet'!H7 -> 41182
B13: Deal Name: | D13: SC Germany Auto 2010-1
B15: Issuer: | D15: SC Germany Auto 2010-1 UG (haftungsbeschränkt)
D16: The Managing Directors
D17: Steinweg 3-5
D18: 60313 Frankfurt am Main
D19: Germany
D20: eMail fradirectors@wilmingtontrust.com
D21: fax +49 (0) 69 2992 5387
B23: Seller of the Receivables: | D23: Santander Consumer Bank AG
B25: Servicer Name: | D25: Santander Consumer Bank AG
B27: Reporting Entity: | D27: Santander Consumer Bank AG
D28: Capital Markets
D29: Santander-Platz 1
D30: 41061 Mönchengladbach
D31: Germany
D32: fax +49 (0) 2161 690 7077
D33: abs_ger@santander.de
B35: SPV-Administrator: | D35: Wilmington Trust SP Services (Frankfurt) GmbH
D36: Steinweg 3-5
D37: 60313 Frankfurt am Main
D38: Germany
D39: eMail fradirectors@wilmingtontrust.com
D40: fax +49 (0) 69 2992 5387

Sheet 23. Santander Consumer Bank
B2: SC Germany Auto 10-1 | E2: Reporting Date | H2: ='Cover Sheet'!F2 -> 41191
B3: ='Cover Sheet'!B3 -> Monthly Investor Report | E3: Payment Date | H3: ='Cover Sheet'!F3 -> 41197
E4: Period No | H4: ='Cover Sheet'!F4 -> 27
B5: 23. Santander Consumer Bank | E5: Monthly Period | H5: ='Cover Sheet'!F5 -> 41197
E6: ='Cover Sheet'!D6 -> Interest Period | G6: from | H6: ='Cover Sheet'!F6 -> 41164 | I6: ='Cover Sheet'!G6 -> to | J6: ='Cover Sheet'!H6 -> 41197 | K6: = | L6: ='Cover Sheet'!$J$6 -> 33 days
E7: ='Cover Sheet'!D7 -> Collection Period | G7: from | H7: ='Cover Sheet'!F7 -> 01.09.2012 | I7: to | J7: ='Cover Sheet'!H7 -> 41182
B13: Contact Details
B14: Capital Markets
B15: Peter Rene Müller | C15: +49-2161-690-7337 | D15: peterrene.mueller@santander.de
B16: Ralf Schüring | C16: +49-2161-690-5464 | D16: ralf.schuering@santander.de
B17: Bastian Menges | C17: +49-2161-690-7085 | D17: bastian.menges@santander.de
B18: Michael Schuh | C18: +49-2161-690-5877 | D18: michael.schuh@santander.de
B19: Tobias Daners | C19: +49-2161-690-7410 | D19: tobias.daners@santander.de
B21: Accounting & Taxes
B22: Ralph Cüppers | C22: +49-2161-690-7569 | D22: ralph.cueppers@santander.gesban.de
B23: Heidemarie Gillaux | C23: +49-2161-690-5207 | D23: heidemarie.gillaux@santander.gesban.de
B26: Ratings Santander | D26: Moody's | G26: Fitch | J26: S & P
D27: Long Term | E27: Short Term | F27: Outlook | G27: Long Term | H27: Short Term | I27: Outlook | J27: Long Term | K27: Short Term | L27: Outlook
B29: Banco Santander S.A. | D29: Baa2 | E29: P-2 | F29: Negative | G29: BBB+ | H29: F2 | I29: Negative | J29: A- | K29: A-2 | L29: Negative
B31: Santander Consumer Finance S.A. | D31: Baa2 | E31: P-2 | F31: Negative | G31: BBB+ | H31: F2 | I31: Negative | J31: BBB+ | K31: A-2 | L31: Negative
B35: Ratings as of 30.09.2012

Sheet 24. Disclaimer
B2: SC Germany Auto 10-1 | E2: Reporting Date | G2: ='Cover Sheet'!F2 -> 41191
B3: ='Cover Sheet'!B3 -> Monthly Investor Report | E3: Payment Date | G3: ='Cover Sheet'!F3 -> 41197
E4: Period No | G4: ='Cover Sheet'!F4 -> 27
B5: 24. Disclaimer | E5: Monthly Period | G5: ='Cover Sheet'!F5 -> 41197
E6: ='Cover Sheet'!D6 -> Interest Period | F6: from | G6: ='Cover Sheet'!F6 -> 41164 | H6: to | I6: ='Cover Sheet'!H6 -> 41197 | J6: ='Cover Sheet'!I6 -> = | K6: ='Cover Sheet'!J6 -> 33 days
E7: ='Cover Sheet'!D7 -> Collection Period | F7: from | G7: ='Cover Sheet'!F7 -> 01.09.2012 | H7: to | I7: ='Cover Sheet'!H7 -> 41182
B13: The on page 4 "Outstanding Notes" mentioned indicators should be considered as valuations.They were determined on the basis of the following assumptions: - data relating to the market used for such determination is that of the immediately preceding business day; - the prices may contain terms of issue which were prevalent during the time of issue of the Notes and consequently may differ from current prevalent terms; - the prices do not or only partially reflect any illiquidity which may be predominant in the market; - the prices take into account the increased premiums relating to liquidity of the underlying assets (collateral).
B15: Disclaimer:
B17: The valuation prices (Bewertungskurse) mentioned on page 4 ”Outstanding Notes” reflect Portigon AG (ex WestLB AG) and NATIXIS's assessment of market conditions as of the on page4 "Outstanding Notes" mentioned date of determination. The valuation prices were determined using recognised methods and on the basis of publicly available data relating to the market, however, such data is subject to continuous adjustments.
B19: The valuation prices are non-binding and are provided to investors solely for information purposes. These are not to be considered as an offer on the part of Portigon AG (ex WestLB AG) or NATIXIS to amend or terminate the concluded transaction(s) or to conclude any transactions. The presented valuation prices do not necessarily reflect to the internal valuation approach of Portigon AG (ex WestLB AG)'s or NATIXIS's risk management, accounting department or any other (based upon a theoretical model) valuations of Portigon AG (ex WestLB AG) or of NATIXIS.
