Workbook
Name OLE_LINK4: 'SHIP DATA'!$G$1

Sheet Low load SFOC
C2: 6S80ME-C8.2 | H2: 6S80MC-C8.2 | J2: 6S80ME-C8.2
A3: % MCR | B3: Low load tuning (EGB) | D3: Normal tuning | F3: Low load tuning (EGB) | H3: Normal tuning | J3: Low load tuning (VT)
A4: 25 | B4: 170 | C4: =(B4/B$14-1)*100 -> 3.8485034 | D4: 175 | E4: =(D4/D$14-1)*100 -> 6.6422913 | F4: 176 | G4: =(F4/F$14-1)*100 -> 5.0119332 | H4: 179 | I4: =(H4/H$14-1)*100 -> 6.4842356 | J4: 169.9 | K4: =(J4/J$14-1)*100 -> 3.787416 | L4: 172.4 | M4: =(L4/L$14-1)*100 -> 5.3789731
A5: 30 | B5: 168.3 | C5: =(B5/B$14-1)*100 -> 2.8100183 | D5: 173 | E5: =(D5/D$14-1)*100 -> 5.4235222 | F5: 174.1 | G5: =(F5/F$14-1)*100 -> 3.8782816 | H5: 177 | I5: =(H5/H$14-1)*100 -> 5.2944676 | J5: 168 | K5: =(J5/J$14-1)*100 -> 2.6267563 | L5: 170.5 | M5: =(L5/L$14-1)*100 -> 4.2176039
A6: 35 | B6: 166.6 | C6: =(B6/B$14-1)*100 -> 1.7715333 | D6: 171.3 | E6: =(D6/D$14-1)*100 -> 4.3875686 | F6: 172.2 | G6: =(F6/F$14-1)*100 -> 2.7446301 | H6: 175.1 | I6: =(H6/H$14-1)*100 -> 4.164188 | J6: 166.2 | K6: =(J6/J$14-1)*100 -> 1.5271839 | L6: 168.8 | M6: =(L6/L$14-1)*100 -> 3.1784841
A7: 40 | B7: 165 | C7: =(B7/B$14-1)*100 -> 0.79413561 | D7: 169.8 | E7: =(D7/D$14-1)*100 -> 3.4734918 | F7: 170.5 | G7: =(F7/F$14-1)*100 -> 1.7303103 | H7: 173.4 | I7: =(H7/H$14-1)*100 -> 3.1528852 | J7: 164.8 | K7: =(J7/J$14-1)*100 -> 0.6719609 | L7: 167.1 | M7: =(L7/L$14-1)*100 -> 2.1393643
A8: 45 | B8: 163.4 | C8: =(B8/B$14-1)*100 -> -0.18326206 | D8: 168.2 | E8: =(D8/D$14-1)*100 -> 2.4984765 | F8: 169.1 | G8: =(F8/F$14-1)*100 -> 0.89498807 | H8: 172.2 | I8: =(H8/H$14-1)*100 -> 2.4390244 | J8: 163.2 | K8: =(J8/J$14-1)*100 -> -0.30543677 | L8: 165.7 | M8: =(L8/L$14-1)*100 -> 1.2836186
A9: 50 | B9: 162 | C9: =(B9/B$14-1)*100 -> -1.038485 | D9: 167 | E9: =(D9/D$14-1)*100 -> 1.7672151 | F9: 168 | G9: =(F9/F$14-1)*100 -> 0.23866348 | H9: 171 | I9: =(H9/H$14-1)*100 -> 1.7251636 | J9: 162 | K9: =(J9/J$14-1)*100 -> -1.038485 | L9: 164.3 | M9: =(L9/L$14-1)*100 -> 0.42787286
A10: 55 | B10: 161 | C10: =(B10/B$14-1)*100 -> -1.6493586 | D10: 165.8 | E10: =(D10/D$14-1)*100 -> 1.0359537 | F10: 167 | G10: =(F10/F$14-1)*100 -> -0.35799523 | H10: 170.1 | I10: =(H10/H$14-1)*100 -> 1.189768 | J10: 160.8 | K10: =(J10/J$14-1)*100 -> -1.7715333 | L10: 163.2 | M10: =(L10/L$14-1)*100 -> -0.24449878
A11: 60 | B11: 160 | C11: =(B11/B$14-1)*100 -> -2.2602321 | D11: 164.8 | E11: =(D11/D$14-1)*100 -> 0.42656917 | F11: 166.3 | G11: =(F11/F$14-1)*100 -> -0.77565632 | H11: 169.3 | I11: =(H11/H$14-1)*100 -> 0.7138608 | J11: 159.9 | K11: =(J11/J$14-1)*100 -> -2.3213195 | L11: 162.3 | M11: =(L11/L$14-1)*100 -> -0.79462103
A12: 65 | B12: 159.4 | C12: =(B12/B$14-1)*100 -> -2.6267563 | D12: 164.2 | E12: =(D12/D$14-1)*100 -> 0.060938452 | F12: 165.8 | G12: =(F12/F$14-1)*100 -> -1.0739857 | H12: 168.7 | I12: =(H12/H$14-1)*100 -> 0.3569304 | J12: 159.25 | K12: =(J12/J$14-1)*100 -> -2.7183873 | L12: 161.9 | M12: =(L12/L$14-1)*100 -> -1.0391198
A13: 70 | B13: 161.5 | C13: =(B13/B$14-1)*100 -> -1.3439218 | D13: 164 | E13: =(D13/D$14-1)*100 -> -0.060938452 | F13: 166.6 | G13: =(F13/F$14-1)*100 -> -0.59665871 | H13: 168.3 | I13: =(H13/H$14-1)*100 -> 0.1189768 | J13: 161.3 | K13: =(J13/J$14-1)*100 -> -1.4660965 | L13: 162.4 | M13: =(L13/L$14-1)*100 -> -0.73349633
A14: 75 | B14: 163.7 | C14: =(B14/B$14-1)*100 -> 0 | D14: 164.1 | E14: =(D14/D$14-1)*100 -> 0 | F14: 167.6 | G14: =(F14/F$14-1)*100 -> 0 | H14: 168.1 | I14: =(H14/H$14-1)*100 -> 0 | J14: 163.7 | K14: =(J14/J$14-1)*100 -> 0 | L14: 163.6 | M14: =(L14/L$14-1)*100 -> 0
A15: 80 | B15: 164.6 | C15: =(B15/B$14-1)*100 -> 0.54978619 | D15: 164.3 | E15: =(D15/D$14-1)*100 -> 0.1218769 | F15: 168.1 | G15: =(F15/F$14-1)*100 -> 0.29832936 | H15: 168 | I15: =(H15/H$14-1)*100 -> -0.0594884 | J15: 164.3 | K15: =(J15/J$14-1)*100 -> 0.36652413 | L15: 164.4 | M15: =(L15/L$14-1)*100 -> 0.48899756
... A19: 100 | B19: 169.5 | C19: =(B19/B$14-1)*100 -> 3.5430666 | D19: 168 | E19: =(D19/D$14-1)*100 -> 2.3765996 | F19: 173 | G19: =(F19/F$14-1)*100 -> 3.221957 | H19: 171 | I19: =(H19/H$14-1)*100 -> 1.7251636 | J19: 168.4 | K19: =(J19/J$14-1)*100 -> 2.8711057 | L19: 169.3 | M19: =(L19/L$14-1)*100 -> 3.4841076
A20: 25 | C20: 5.0119332
A21: 30 | C21: 3.8782816
A22: 35 | C22: 2.7446301
A23: 40 | C23: 1.7303103
A24: 45 | C24: 0.89498807
A25: 50 | C25: 0.23866348
A26: 55 | C26: -0.35799523
A27: 60 | C27: -0.77565632
A28: 65 | C28: -1.0739857
A29: 70 | C29: -0.59665871
A30: 75 | C30: 0
A31: 80 | C31: 0.29832936
... A51: 100 | C51: 2.8711057
A52: 25 | B52: =0.0000000020194*A52^6-0.0000007555*A52^5+0.00011181*A52^4-0.00832*A52^3+0.33*A52^2-6.851*A52+62.9 -> 4.6658691 | C52: 5.3789731
A53: 30 | B53: =0.0000000020194*A53^6-0.0000007555*A53^5+0.00011181*A53^4-0.00832*A53^3+0.33*A53^2-6.851*A53+62.9 -> 3.4095926 | C53: 4.2176039
A54: 35 | B54: =0.0000000020194*A54^6-0.0000007555*A54^5+0.00011181*A54^4-0.00832*A54^3+0.33*A54^2-6.851*A54+62.9 -> 2.4617983 | C54: 3.1784841
A55: 40 | B55: =0.0000000020194*A55^6-0.0000007555*A55^5+0.00011181*A55^4-0.00832*A55^3+0.33*A55^2-6.851*A55+62.9 -> 1.5218624 | C55: 2.1393643
A56: 45 | B56: =0.0000000020194*A56^6-0.0000007555*A56^5+0.00011181*A56^4-0.00832*A56^3+0.33*A56^2-6.851*A56+62.9 -> 0.54350712 | C56: 1.2836186
A57: 50 | B57: =0.0000000020194*A57^6-0.0000007555*A57^5+0.00011181*A57^4-0.00832*A57^3+0.33*A57^2-6.851*A57+62.9 -> -0.378125 | C57: 0.42787286
A58: 55 | B58: =0.0000000020194*A58^6-0.0000007555*A58^5+0.00011181*A58^4-0.00832*A58^3+0.33*A58^2-6.851*A58+62.9 -> -1.0966784 | C58: -0.24449878
A59: 60 | B59: =0.0000000020194*A59^6-0.0000007555*A59^5+0.00011181*A59^4-0.00832*A59^3+0.33*A59^2-6.851*A59+62.9 -> -1.4820736 | C59: -0.79462103
A60: 65 | B60: =0.0000000020194*A60^6-0.0000007555*A60^5+0.00011181*A60^4-0.00832*A60^3+0.33*A60^2-6.851*A60+62.9 -> -1.4652782 | C60: -1.0391198
A61: 70 | B61: =0.0000000020194*A61^6-0.0000007555*A61^5+0.00011181*A61^4-0.00832*A61^3+0.33*A61^2-6.851*A61+62.9 -> -1.0603594 | C61: -0.73349633
A62: 75 | B62: =0.0000000020194*A62^6-0.0000007555*A62^5+0.00011181*A62^4-0.00832*A62^3+0.33*A62^2-6.851*A62+62.9 -> -0.36381836 | C62: 0
A63: 80 | B63: =0.0000000020194*A63^6-0.0000007555*A63^5+0.00011181*A63^4-0.00832*A63^3+0.33*A63^2-6.851*A63+62.9 -> 0.4687936 | C63: 0.48899756
...

Sheet Normal SFOC
B2: % MCR | C2: 6S80ME-C8.2 | E2: 6S80MC-C8.2
B3: 25 | C3: 175 | D3: =(C3/C$12-1)*100 -> 6.7073171 | E3: 179 | F3: =(E3/E$14-1)*100 -> 6.547619
B4: 30 | C4: 173 | D4: =(C4/C$12-1)*100 -> 5.4878049 | E4: 177 | F4: =(E4/E$14-1)*100 -> 5.3571429
B5: 35 | C5: 171.3 | D5: =(C5/C$12-1)*100 -> 4.4512195 | E5: 175.1 | F5: =(E5/E$14-1)*100 -> 4.2261905
B6: 40 | C6: 169.8 | D6: =(C6/C$12-1)*100 -> 3.5365854 | E6: 173.4 | F6: =(E6/E$14-1)*100 -> 3.2142857
B7: 45 | C7: 168.2 | D7: =(C7/C$12-1)*100 -> 2.5609756 | E7: 172.2 | F7: =(E7/E$14-1)*100 -> 2.5
B8: 50 | C8: 167 | D8: =(C8/C$12-1)*100 -> 1.8292683 | E8: 171 | F8: =(E8/E$14-1)*100 -> 1.7857143
B9: 55 | C9: 165.8 | D9: =(C9/C$12-1)*100 -> 1.097561 | E9: 170.1 | F9: =(E9/E$14-1)*100 -> 1.25
B10: 60 | C10: 164.8 | D10: =(C10/C$12-1)*100 -> 0.48780488 | E10: 169.3 | F10: =(E10/E$14-1)*100 -> 0.77380952
B11: 65 | C11: 164.2 | D11: =(C11/C$12-1)*100 -> 0.12195122 | E11: 168.7 | F11: =(E11/E$14-1)*100 -> 0.41666667
B12: 70 | C12: 164 | D12: =(C12/C$12-1)*100 -> 0 | E12: 168.3 | F12: =(E12/E$14-1)*100 -> 0.17857143
B13: 75 | C13: 164.1 | D13: =(C13/C$12-1)*100 -> 0.06097561 | E13: 168.1 | F13: =(E13/E$14-1)*100 -> 0.05952381
B14: 80 | C14: 164.3 | D14: =(C14/C$12-1)*100 -> 0.18292683 | E14: 168 | F14: =(E14/E$14-1)*100 -> 0
... B18: 100 | C18: 168 | D18: =(C18/C$12-1)*100 -> 2.4390244 | E18: 171 | F18: =(E18/E$14-1)*100 -> 1.7857143
B19: 25 | D19: 6.547619
B20: 30 | D20: 5.3571429
B21: 35 | D21: 4.2261905
B22: 40 | D22: 3.2142857
B23: 45 | D23: 2.5
B24: 50 | D24: 1.7857143
B25: 55 | D25: 1.25
B26: 60 | D26: 0.77380952
B27: 65 | D27: 0.41666667
B28: 70 | D28: 0.17857143
B29: 75 | D29: 0.05952381
B30: 80 | D30: 0
... B34: 100 | D34: 1.7857143
B36: 25 | D36: =0.0028*B36^2-0.41*B36+15 -> 6.5
B37: 30 | D37: =0.0028*B37^2-0.41*B37+15 -> 5.22
B38: 35 | D38: =0.0028*B38^2-0.41*B38+15 -> 4.08
B39: 40 | D39: =0.0028*B39^2-0.41*B39+15 -> 3.08
B40: 45 | D40: =0.0028*B40^2-0.41*B40+15 -> 2.22
B41: 50 | D41: =0.0028*B41^2-0.41*B41+15 -> 1.5
B42: 55 | D42: =0.0028*B42^2-0.41*B42+15 -> 0.92
B43: 60 | D43: =0.0028*B43^2-0.41*B43+15 -> 0.48
B44: 65 | D44: =0.0028*B44^2-0.41*B44+15 -> 0.18
B45: 70 | D45: =0.0028*B45^2-0.41*B45+15 -> 0.02
B46: 75 | D46: =0.0028*B46^2-0.41*B46+15 -> 0
B47: 80 | D47: =0.0028*B47^2-0.41*B47+15 -> 0.12
... B51: 100 | D51: =0.0028*B51^2-0.41*B51+15 -> 2

Sheet Up date log
A2: Date | B2: Update
A3: 140
A45: 41319 | B45: Cr correction due to bulbous has been modified, to be max. - 50 % of Cr
A46: 42049 | B46: Correction of SFOC as function of engine load (%MCR)
A47: 42049 | B47: Possibility of specification of normal loading or low loading SFOC

Sheet Truck data
A1: Truck engine data | B1: EU 1996 | C1: EU 2001 | D1: EU 2006 | E1: EU 2011 | F1: EU 2015
A2: Version: 16th November 2009 | B2: EURO 2 | C2: EURO 3 | D2: EURO 4 | E2: EURO 5 | F2: EURO 6
A3: Specific oil consumption (kg/kWh) | B3: 0.2 | C3: 0.2 | D3: 0.2 | E3: 0.2 | F3: 0.2
A4: NOx emission (g/kWh) | B4: 7 | C4: 5 | D4: 3.5 | E4: 2 | F4: 0.4
A5: CO emission (g/kWh) | B5: 1.2 | C5: 1.2 | D5: 0.1 | E5: 0.1 | F5: 0.1
A6: HC emission (g/kWh) | B6: 0.3 | C6: 0.25 | D6: 0.015 | E6: 0.015 | F6: 0.004
A7: Particulate emission (g/kWh) | B7: 0.15 | C7: 0.1 | D7: 0.02 | E7: 0.02 | F7: 0.01
A8: Sulphur content in oil (pct.) | B8: 0.001 | C8: =B8 -> 0.001 | D8: =C8 -> 0.001 | E8: =D8 -> 0.001 | F8: =E8 -> 0.001
A9: SO2 emission (g/kWh) | B9: =B3*20*B8 -> 0.004 | C9: =C3*20*C8 -> 0.004 | D9: =D3*20*D8 -> 0.004 | E9: =E3*20*E8 -> 0.004 | F9: =F3*20*F8 -> 0.004
A10: CO2 emission (g/kg) | B10: 3206 | C10: 3206 | D10: 3206 | E10: 3206 | F10: 3206 | G10: IMO MEPC 1 - Circ. 681
A11: NOx emission (g/kg) | B11: =B4/B3 -> 35 | C11: =C4/C3 -> 25 | D11: =D4/D3 -> 17.5 | E11: =E4/E3 -> 10 | F11: =F4/F3 -> 2
A12: CO emission (g/kg) | B12: =B5/B3 -> 6 | C12: =C5/C3 -> 6 | D12: =D5/D3 -> 0.5 | E12: =E5/E3 -> 0.5 | F12: =F5/F3 -> 0.5
A13: HC emission (g/kg) | B13: =B6/B3 -> 1.5 | C13: =C6/C3 -> 1.25 | D13: =D6/D3 -> 0.075 | E13: =E6/E3 -> 0.075 | F13: =F6/F3 -> 0.02
A14: Particulate emission (g/kg) | B14: =B7/B3 -> 0.75 | C14: =C7/C3 -> 0.5 | D14: =D7/D3 -> 0.1 | E14: =E7/E3 -> 0.1 | F14: =F7/F3 -> 0.05
A15: SO2 emission (g/kg) | B15: =B9/B3 -> 0.02 | C15: =C9/C3 -> 0.02 | D15: =D9/D3 -> 0.02 | E15: =E9/E3 -> 0.02 | F15: =F9/F3 -> 0.02
A16: NOx emission (g/MJ) | B16: =B4/B3/B21 -> 0.81775701 | C16: =C4/C3/B21 -> 0.58411215 | D16: =D4/D3/B21 -> 0.4088785 | E16: =E4/E3/B21 -> 0.23364486 | F16: =F4/F3/B21 -> 0.046728972
A17: CO emission (g/MJ) | B17: =B5/B3/B21 -> 0.14018692 | C17: =C5/C3/B21 -> 0.14018692 | D17: =D5/D3/B21 -> 0.011682243 | E17: =E5/E3/B21 -> 0.011682243 | F17: =F5/F3/B21 -> 0.011682243
A18: HC emission (g/MJ) | B18: =B6/B3/B21 -> 0.035046729 | C18: =C6/C3/B21 -> 0.029205607 | D18: =D6/D3/B21 -> 0.0017523364 | E18: =E6/E3/B21 -> 0.0017523364 | F18: =F6/F3/B21 -> 0.00046728972
A19: Particulate emission (g/MJ) | B19: =B7/B3/B21 -> 0.017523364 | C19: =C7/C3/B21 -> 0.011682243 | D19: =D7/D3/B21 -> 0.0023364486 | E19: =E7/E3/B21 -> 0.0023364486 | F19: =F7/F3/B21 -> 0.0011682243
A20: SO2 emission (g/MJ) | B20: =B9/B3/B21 -> 0.00046728972 | C20: =C9/C3/B21 -> 0.00046728972 | D20: =D9/D3/B21 -> 0.00046728972 | E20: =E9/E3/B21 -> 0.00046728972 | F20: =F9/F3/B21 -> 0.00046728972
A21: Calorific value for diesel oil (MJ/kg) | B21: 42.8
A22: EURO NORM (2 - 6) | D22: 5 | I22: Cargo handling per container
A23: TEU per truck | C23: TEU/truck | D23: 2 | I23: Handling time | J23: minutes | K23: 30
A24: Average weight of a container (TEU) | C24: t/TEU | D24: 10 | I24: Average diesel engine load during handling | J24: kW | K24: 50
A25: Length of truck - total | C25: m | D25: 16 | I25: Energy consumption per TEU | J25: MJ/TEU | K25: =K23/60*D3*B21 -> 4.28
A26: Driving distance | C26: km | D26: 400 | I26: Oil consumption per TEU | J26: g/TEU | K26: =K23/60*D3*1000 -> 100
A27: Weight of truck load | C27: t/truck | D27: =D23*D24 -> 20 | I27: CO2 emissions per TEU | J27: g/TEU | K27: =K26*B10/1000 -> 320.6
A28: Fuel consumption ratio - driving distance | C28: (-) | D28: =MAX(1,(IF(D26<20,140-D26*1.4,IF(D26<55,112-(D26-20)*0.25,IF(D26<205,103.25-(D26-55)*0.015,100.7-(D26-225)*0.005))))/100) -> 1 | I28: NOx emissions per TEU | J28: g/TEU | K28: =K25*IF(D22=2,B16,IF(D22=3,C16,IF(D22=4,D16,IF(D22=5,E16,F16)))) -> 1
A29: Energy consumption per TEU per km | C29: MJ/TEU/km | D29: =(7.5+0.27*D27-0.001*D27^2)/D23 -> 6.25 | I29: HC emissions per TEU | J29: g/TEU | K29: =K25*IF(D22=2,B18,IF(D22=3,C18,IF(D22=4,D18,IF(D22=5,E18,F18)))) -> 0.0075
A30: Energy consumption per lanemeter per km | C30: MJ/lm/km | D30: =D29*D23/D25 -> 0.78125 | I30: CO emissions per TEU | J30: g/TEU | K30: =K25*IF(D22=2,B17,IF(D22=3,C17,IF(D22=4,D17,IF(D22=5,E17,F17)))) -> 0.05
A31: Energy consumption per ton load per km | C31: MJ/t/km | D31: =D29/D24 -> 0.625 | I31: SOx emissions per TEU | J31: g/TEU | K31: =K25*IF(D22=2,B20,IF(D22=3,C20,IF(D22=4,D20,IF(D22=5,E20,F20)))) -> 0.002
A32: Oil consumption per TEU per km | C32: g/TEU/km | D32: =1000*D29/B21 -> 146.02804 | I32: Particulate emissions per TEU | J32: g/TEU | K32: =K25*IF(D22=2,B19,IF(D22=3,C19,IF(D22=4,D19,IF(D22=5,E19,F19)))) -> 0.01
A33: Oil consumption per lanemeter per km | C33: g/lm/km | D33: =D32*D23/D25 -> 18.253505
A34: Oil consumption per ton load per km | C34: g/t/km | D34: =D32/D24 -> 14.602804
A35: CO2 emissions per TEU per km | C35: g/TEU/km | D35: =D32*B10/1000 -> 468.16589
A36: CO2 emissions per lanemeter per km | C36: g/lm/km | D36: =D35*D23/D25 -> 58.520736
A37: CO2 emissions per ton load per km | C37: g/t/km | D37: =D35/D24 -> 46.816589
A38: NOx emissions per TEU per km | C38: g/TEU/km | D38: =D29*IF(D22=2,B16,IF(D22=3,C16,IF(D22=4,D16,IF(D22=5,E16,F16)))) -> 1.4602804
A39: NOx emissions per lanemeter per km | C39: g/lm/km | D39: =D38*D23/D25 -> 0.18253505
A40: NOx emissions per ton load per km | C40: g/t/km | D40: =D38/D24 -> 0.14602804
...

Sheet SHIP DATA
A1: Ship data (container ship) | B1: Units | C1: Default values | D1: Alternative 1 | E1: Alternative 2
A2: Container capacity | B2: TEU | C2: 18000 | D2: =C2 -> 18000 | E2: =D2 -> 18000
A3: Feeder ship - type 1 (<2900 TEU) - Panamax - type 2 (1900 - 5300 TEU) or Post Panamax - type 3 (>4000 TEU) | B3: (-) | C3: =IF(C2<2500,1,IF(C2<=5000,2,3)) -> 3 | D3: =IF(D2<2500,1,IF(D2<=5000,2,3)) -> 3 | E3: =IF(E2<2500,1,IF(E2<=5000,2,3)) -> 3
A4: Elongation in percent | B4: % | C4: 0 | D4: 0 | E4: 0
A5: Length between pp | B5: m | C5: =(1+C4/100)*IF(C3=1,10.14*C2^0.378,IF(C3=2,IF(C2<3800,2.494*C2^0.555,241.92+(C2-3800)*0.037),IF(C2<8000,131.31+0.03012*C2-0.00000099556*C2^2,14.66*C2^0.339))) -> 406.13587 | D5: =(1+D4/100)*IF(D3=1,10.14*D2^0.378,IF(D3=2,IF(D2<3800,2.494*D2^0.555,241.92+(D2-3800)*0.037),IF(D2<8000,131.31+0.03012*D2-0.00000099556*D2^2,14.66*D2^0.339))) -> 406.13587 | E5: =(1+E4/100)*IF(E3=1,10.14*E2^0.378,IF(E3=2,IF(E2<3800,2.494*E2^0.555,241.92+(E2-3800)*0.037),IF(E2<8000,131.31+0.03012*E2-0.00000099556*E2^2,14.66*E2^0.339))) -> 406.13587
A6: Length in waterline incl. bulbous bow (= 1.01 Lpp) | B6: m | C6: =C5*1.01 -> 410.19723 | D6: =D5*1.01 -> 410.19723 | E6: =E5*1.01 -> 410.19723
A7: Length over all | B7: m | C7: =IF(C3<3,MIN(294.1,1.2*C5^0.977),1.2*C5^0.977) -> 424.47601 | D7: =IF(D3<3,MIN(294.1,1.2*D5^0.977),1.2*D5^0.977) -> 424.47601 | E7: =IF(E3<31,MIN(294.1,1.2*E5^0.977),1.2*E5^0.977) -> 294.1
A8: Breadth mld. | B8: m | C8: =IF(C3=1,2.9*C2^0.3,IF(C3=2,32.22,32.51+0.0013*C2)) -> 55.91 | D8: =C8 -> 55.91 | E8: =C8 -> 55.91
A9: Depth | B9: m | C9: =IF(C3=1,0.767*C2^0.394,IF(C3=2,14.77+0.0013*C2,MIN(30.2,16.5+0.0011*C2))) -> 30.2 | D9: =C9 -> 30.2 | E9: =C9 -> 30.2
A10: Design draught | B10: m | C10: =IF(C3<3,MIN(C11,12,1.188*C2^0.279),4.83*C2^0.11) -> 14.191461 | D10: =C10 -> 14.191461 | E10: =D10 -> 14.191461
A11: Maximum draught | B11: m | C11: =IF(C3=1,0.827*C2^0.336,IF(C3=2,IF(C2<3300,2.19*C2^0.211,12.1+(C2-3300)*0.00082),12.73+0.0002*C2)) -> 16.33 | D11: =C11 -> 16.33 | E11: =D11 -> 16.33
A12: Maximum draught - design draught | B12: m | C12: =C11-C10 -> 2.1385391 | D12: =D11-D10 -> 2.1385391 | E12: =E11-E10 -> 2.1385391
A13: Design deadweight/Maximum deadweight | B13: % | C13: =C14/C15*100 -> 78.723597 | D13: =D14/D15*100 -> 78.723597 | E13: =E14/E15*100 -> 78.723597
A14: Design deadweight | B14: tons | C14: =C15-(C11-C10)*C5*C8*C32*1.025 -> 158706.77 | D14: =D15-(D11-D10)*D5*D8*D32*1.025 -> 158706.77 | E14: =E15-(E11-E10)*E5*E8*E32*1.025 -> 158706.77
A15: Maximum deadweight | B15: tons | C15: =C16*C2 -> 201600 | D15: =D16*D2 -> 201600 | E15: =E16*E2 -> 201600
A16: Maximum deadweight/TEU | B16: tons/TEU | C16: =IF(C3=1,13.65,IF(C3=2,14.6-0.00038*C2,MAX(11.2,50.43*C2^-0.16))) -> 11.2 | D16: =C16 -> 11.2 | E16: =D16 -> 11.2
A17: Lightweight coefficient | B17: t/m3 | C17: =IF(C3=1,0.659*C2^-0.23,IF(C3=2,0.105,MAX(0.09,0.104-0.00000115*C2))) -> 0.09 | D17: =IF(D3=1,0.659*D2^-0.23,IF(D3=2,0.105,MAX(0.09,0.104-0.00000115*D2))) -> 0.09 | E17: =IF(E3=1,0.659*E2^-0.23,IF(E3=2,0.105,MAX(0.09,0.104-0.00000115*E2))) -> 0.09
A18: Steel weight correction | B18: % | C18: 0 | D18: 0 | E18: 0
A19: Calculated machinery weight change due to engine change | B19: tons | C19: 0 | D19: =WEIGHT!J31+D47*D65/10*IF(D58=1,0.03,0.01) -> -869.80502 | E19: =WEIGHT!Q31+E47*E65/10*IF(E58=1,0.03,0.01) -> -385.93393
A20: Specified machinery weight change ( = the calculated value) | B20: tons | C20: 0 | D20: 0 | E20: 0
A21: Lightweight | B21: tons | C21: =C5*C8*C9*C17+C18/100*WEIGHT!C24 -> 61717.78 | D21: =C5*C8*C9*C17+WEIGHT!J30+WEIGHT!J32+D20+'SHIP DATA'!D18/100*WEIGHT!J66 -> 61717.78 | E21: =C5*C8*C9*C17+WEIGHT!Q30+WEIGHT!Q32+E20+'SHIP DATA'!E18/100*WEIGHT!Q66 -> 61717.78
A22: Steel weight | B22: tons | C22: =WEIGHT!C24 -> 54731.157 | D22: =WEIGHT!J24 -> 54731.157 | E22: =WEIGHT!Q24 -> 54731.157
A23: Displacement at design draught | B23: tons | C23: =C14+C21 -> 220424.55 | D23: =D14+D21 -> 220424.55 | E23: =E14+E21 -> 220424.55
A24: Displacement at maximum draught | B24: tons | C24: =C15+C21 -> 263317.78 | D24: =D15+D21 -> 263317.78 | E24: =E15+E21 -> 263317.78
A25: Block coefficient (based on Lpp) at design draught | B25: - | C25: =C23/C5/C8/C10/1.025 -> 0.66734153 | D25: =D23/D5/D8/D10/1.025 -> 0.66734153 | E25: =E23/E5/E8/E10/1.025 -> 0.66734153
A26: Block coefficient (based on Lpp) at maximum draught | B26: - | C26: =C24/1.025/C5/C8/C11 -> 0.69280226 | D26: =D24/1.025/D5/D8/D11 -> 0.69280226 | E26: =E24/1.025/E5/E8/E11 -> 0.69280226
A27: Lpp/Displ.vol.1/3 at design draught | B27: - | C27: =C5/(C23/1.025)^(1/3) -> 6.7789014 | D27: =D5/(D23/1.025)^(1/3) -> 6.7789014 | E27: =E5/(E23/1.025)^(1/3) -> 6.7789014
A28: Lpp/Displ.vol.1/3 at maximum draught | B28: - | C28: =C5/(C24/1.025)^(1/3) -> 6.3887993 | D28: =D5/(D24/1.025)^(1/3) -> 6.3887993 | E28: =E5/(E24/1.025)^(1/3) -> 6.3887993
A29: Midship section coefficient | B29: - | C29: 0.98 | D29: 0.98 | E29: 0.98
A30: Prismatic coefficient at design draught | B30: - | C30: =C25/C29 -> 0.68096074 | D30: =D25/D29 -> 0.68096074 | E30: =E25/E29 -> 0.68096074
A31: Prismatic coefficient at maximum draught | B31: - | C31: =C26/C29 -> 0.70694108 | D31: =D26/D29 -> 0.70694108 | E31: =E26/E29 -> 0.70694108
A32: Waterplane area coefficient based on Lpp | B32: - | C32: =0.55+0.45*C26 -> 0.86176101 | D32: =0.55+0.45*D26 -> 0.86176101 | E32: =0.55+0.45*E26 -> 0.86176101
A33: Wetted surface at design draught | B33: m2 | C33: =C34-2.4*(C11-C10)*(C6+C8) -> 25924.104 | D33: =D34-2.4*(D11-D10)*(D6+D8) -> 25924.104 | E33: =E34-2.4*(E11-E10)*(E6+E8) -> 27864.745
A34: Wetted surface at maximum draught | B34: m2 | C34: =IF(C50=1,0.995*(C24/C11/1.025+1.9*C11*C6),IF(C51=1,1.21*(C24/C11/1.025+1.3*C11*C6)*(1.2-0.34*C26*C5/C6),1.13*(C24/C11/1.025+1.7*C11*C6)*(1.2-0.31*C26*C5/C6))) -> 28316.396 | D34: =IF(D50=1,0.995*(D24/D11/1.025+1.9*D11*D6),IF(D51=1,1.21*(D24/D11/1.025+1.3*D11*D6)*(1.2-0.34*D26*D5/D6),1.13*(D24/D11/1.025+1.7*D11*D6)*(1.2-0.31*D26*D5/D6))) -> 28316.396 | E34: =IF(E50=1,0.995*(E24/E11/1.025+1.9*E11*E6),IF(E51=1,1.21*(E24/E11/1.025+1.3*E11*E6)*(1.2-0.34*E26*E5/E6),1.13*(E24/E11/1.025+1.7*E11*E6)*(1.2-0.31*E26*E5/E6))) -> 30257.038
A35: Service speed at design draught | B35: knots | C35: =IF(C5<95,14.02+(C5-95)*0.16,IF(C5<350,MIN(25.7,4+0.1216*C5-0.00017*C5^2),25.7)) -> 25.7 | D35: 23 | E35: 23
A36: Froude Number at service speed | B36: - | C36: =C35*0.5144/(9.81*C6)^0.5 -> 0.20840264 | D36: =D35*0.5144/(9.81*D6)^0.5 -> 0.1865082 | E36: =E35*0.5144/(9.81*E6)^0.5 -> 0.1865082
A37: Scantling trial speed at 100 % deadweight at 75 % MCR | B37: knots | C37: ='PT1-1'!V33 -> 25.013806 | D37: ='PT2-1'!V33 -> 22.438168 | E37: ='PT3-1'!V33 -> 22.454957
A38: Froude Number at 'reference speed' | B38: - | C38: =C37*0.5144/(9.81*C6)^0.5 -> 0.20283826 | D38: =D37*0.5144/(9.81*D6)^0.5 -> 0.18195227 | E38: =E37*0.5144/(9.81*E6)^0.5 -> 0.18208842
A39: Service allowance on resistance | B39: pct. | C39: 15 | D39: 15 | E39: 15
A40: Beaufort No. | B40: - | C40: 0 | D40: 0 | E40: 0
...

Sheet Emission factors
A1: Engine and emission reduction technologies | B1: Main engine | C1: Auxiliary engines | D1: Main engine | E1: Auxiliary engines | F1: Main engine | G1: Auxiliary engines
A2: Main engine type (2-stroke = 1, 4-stroke = 2) | B2: ='SHIP DATA'!C58 -> 1 | C2: 2 | D2: ='SHIP DATA'!D58 -> 1 | E2: 2 | F2: ='SHIP DATA'!E58 -> 1 | G2: 2
A3: Derated main engine - only for 2 stroke engines (NO = 0, YES = 1) | B3: ='SHIP DATA'!C65 -> 0 | C3: - | D3: ='SHIP DATA'!D65 -> 0 | E3: - | F3: ='SHIP DATA'!E65 -> 0 | G3: -
A4: Fuel for main engine (HFO = 1, MDO/GO = 2, LNG = 3 (only for 4 stroke), Dual fuel = 4) | B4: ='SHIP DATA'!C60 -> 2 | C4: =IF(B4=1,2,B4) -> 2 | D4: ='SHIP DATA'!D60 -> 2 | E4: =IF(D4=1,2,D4) -> 2 | F4: ='SHIP DATA'!E60 -> 2 | G4: =IF(F4=1,2,F4) -> 2
A5: Specific Fuel Oil Consumption (SFOC) at 75 % MCR for main engine in g/kW/hour. If not specified (1) a default value will be used | B5: ='SHIP DATA'!C61 -> 1 | C5: - | D5: ='SHIP DATA'!D61 -> 1 | E5: - | F5: ='SHIP DATA'!E61 -> 1 | G5: -
A6: Fuel optimised main engine? (0 = NO, 1 = YES) | B6: ='SHIP DATA'!C66 -> 0 | C6: - | D6: ='SHIP DATA'!D66 -> 0 | E6: - | F6: ='SHIP DATA'!E66 -> 0 | G6: -
A7: TIER 1, 2 or 3 engine (If individual NOx reduction technology is selected then press 0) | B7: ='SHIP DATA'!C67 -> 3 | C7: =B7 -> 3 | D7: ='SHIP DATA'!D67 -> 3 | E7: =D7 -> 3 | F7: ='SHIP DATA'!E67 -> 3 | G7: =F7 -> 3
A8: Specify NOx reduction technology: EGR (Exhaust Gas Recirculation) =1, SCR (Selective Catalyic Reduction) = 2 or other technology = 3 | B8: ='SHIP DATA'!C68 -> 1 | C8: =B8 -> 1 | D8: ='SHIP DATA'!D68 -> 1 | E8: =D8 -> 1 | F8: ='SHIP DATA'!E68 -> 1 | G8: =F8 -> 1
A9: Sulphur content in % in heavy fuel oil (HFO) | B9: ='SHIP DATA'!C63 -> 1 | C9: - | D9: ='SHIP DATA'!D63 -> 1 | E9: - | F9: ='SHIP DATA'!E63 -> 1 | G9: -
A10: Sulphur content in % in diesel/gas oil (DO/GO) | B10: ='SHIP DATA'!C64 -> 1 | C10: =B10 -> 1 | D10: ='SHIP DATA'!D64 -> 1 | E10: =D10 -> 1 | F10: ='SHIP DATA'!E64 -> 1 | G10: =F10 -> 1
A11: Use of scrubbers (NO = 0, YES=1) | B11: ='SHIP DATA'!C69 -> 0 | C11: =B11 -> 0 | D11: ='SHIP DATA'!D69 -> 0 | E11: =D11 -> 0 | F11: ='SHIP DATA'!E69 -> 0 | G11: =F11 -> 0
A12: Emission factors
A13: Fuel consumption (kg/kW/hour) | B13: =IF(B5>1,B5/1000,IF(B4=4,IF(B2=1,0.15,0.16),IF(B4=3,0.155,IF(B2=1,0.17,0.19)*(1+B39/100)*42.7/B33))) -> 0.1751 | C13: =IF(C4=3,0.155,IF(C4=4,0.16,0.19*42.7/C33*(1+C39/100))) -> 0.1957 | D13: =IF(D5>1,D5/1000,IF(D4=4,IF(D2=1,0.15,0.16),IF(D4=3,0.155,IF(D2=1,0.17,0.19)*(1+D39/100)*42.7/D33))) -> 0.1751 | E13: =IF(E4=3,0.155,IF(E4=4,0.16,0.19*42.7/E33*(1+E39/100))) -> 0.1957 | F13: =IF(F5>1,F5/1000,IF(F4=4,IF(F2=1,0.15,0.16),IF(F4=3,0.155,IF(F2=1,0.17,0.19)*(1+F39/100)*42.7/F33))) -> 0.1751 | G13: =IF(G4=3,0.155,IF(G4=4,0.16,0.19*42.7/G33*(1+G39/100))) -> 0.1957
A14: CO2 emission (g/kW/hour) | B14: =B13*B21 -> 561.3706 | C14: =C21*C13 -> 627.4142 | D14: =D13*D21 -> 561.3706 | E14: =E21*E13 -> 627.4142 | F14: =F13*F21 -> 561.3706 | G14: =G21*G13 -> 627.4142
A15: NOx emission (g/kW/hour) | B15: =IF(AND(B2=1,B4=4),IF(B7<3,12,3.4),IF(AND(B2=2,B4=4),IF(B7<3,9.6,2.4),IF(AND(B2=2,B4=3),1.3,IF(OR(B4=1,B4=2),IF(B2=1,17,12)*(1-B40/100))))) -> 3.4 | C15: =IF(AND(C2=1,C4=4),IF(C7<3,12,3.4),IF(AND(C2=2,C4=4),IF(C7<3,9.6,2.4),IF(AND(C2=2,C4=3),1.3,IF(OR(C4=1,C4=2),IF(C2=1,17,12)*(1-C40/100))))) -> 2.4 | D15: =IF(AND(D2=1,D4=4),IF(D7<3,12,3.4),IF(AND(D2=2,D4=4),IF(D7<3,9.6,2.4),IF(AND(D2=2,D4=3),1.3,IF(OR(D4=1,D4=2),IF(D2=1,17,12)*(1-D40/100))))) -> 3.4 | E15: =IF(AND(E2=1,E4=4),IF(E7<3,12,3.4),IF(AND(E2=2,E4=4),IF(E7<3,9.6,2.4),IF(AND(E2=2,E4=3),1.3,IF(OR(E4=1,E4=2),IF(E2=1,17,12)*(1-E40/100))))) -> 2.4 | F15: =IF(AND(F2=1,F4=4),IF(F7<3,12,3.4),IF(AND(F2=2,F4=4),IF(F7<3,9.6,2.4),IF(AND(F2=2,F4=3),1.3,IF(OR(F4=1,F4=2),IF(F2=1,17,12)*(1-F40/100))))) -> 3.4 | G15: =IF(AND(G2=1,G4=4),IF(G7<3,12,3.4),IF(AND(G2=2,G4=4),IF(G7<3,9.6,2.4),IF(AND(G2=2,G4=3),1.3,IF(OR(G4=1,G4=2),IF(G2=1,17,12)*(1-G40/100))))) -> 2.4
A16: CO emission (g/kW(hour) | B16: =IF(B4<3,IF(B2=1,0.35,0.5),IF(B2=1,0.3,1.3)) -> 0.35 | C16: =IF(C4<3,IF(C2=1,0.35,0.5),IF(C2=1,0.3,1.3)) -> 0.5 | D16: =IF(D4<3,IF(D2=1,0.35,0.5),IF(D2=1,0.3,1.3)) -> 0.35 | E16: =IF(E4<3,IF(E2=1,0.35,0.5),IF(E2=1,0.3,1.3)) -> 0.5 | F16: =IF(F4<3,IF(F2=1,0.35,0.5),IF(F2=1,0.3,1.3)) -> 0.35 | G16: =IF(G4<3,IF(G2=1,0.35,0.5),IF(G2=1,0.3,1.3)) -> 0.5
A17: HC emission (g/kW/hour) | B17: 0.5 | C17: 0.5 | D17: 0.5 | E17: 0.5 | F17: 0.5 | G17: 0.5
A18: Particulates (g/kW/hour) | B18: =IF(B4>2,IF(B4=3,0.03,0.1),(0.26+0.081*B19+0.103*B19^2)*(1-B41/100)) -> 0.444 | C18: =IF(C4>2,IF(C4=3,0.03,0.1),(0.26+0.081*C19+0.103*C19^2)*(1-C41/100)) -> 0.444 | D18: =IF(D4>2,IF(D4=3,0.03,0.1),(0.26+0.081*D19+0.103*D19^2)*(1-D41/100)) -> 0.444 | E18: =IF(E4>2,IF(E4=3,0.03,0.1),(0.26+0.081*E19+0.103*E19^2)*(1-E41/100)) -> 0.444 | F18: =IF(F4>2,IF(F4=3,0.03,0.1),(0.26+0.081*F19+0.103*F19^2)*(1-F41/100)) -> 0.444 | G18: =IF(G4>2,IF(G4=3,0.03,0.1),(0.26+0.081*G19+0.103*G19^2)*(1-G41/100)) -> 0.444
A19: S content in oil (pct.) | B19: =IF(B4=1,B9,B10) -> 1 | C19: =B10 -> 1 | D19: =IF(D4=1,D9,D10) -> 1 | E19: =D10 -> 1 | F19: =IF(F4=1,F9,F10) -> 1 | G19: =F10 -> 1
A20: SO2 emission (g/kW/hour) | B20: =IF(B4<3,B13*21*B19*(1-B42/100),(IF(B4=3,0,0.19*21*B19*$B45/100))) -> 3.6771 | C20: =IF(C4<3,C13*21*C19*(1-C42/100),(IF(C4=3,0,0.19*21*C19*$B45/100))) -> 4.1097 | D20: =IF(D4<3,D13*21*D19*(1-D42/100),(IF(D4=3,0,0.19*21*D19*$B45/100))) -> 3.6771 | E20: =IF(E4<3,E13*21*E19*(1-E42/100),(IF(E4=3,0,0.19*21*E19*$B45/100))) -> 4.1097 | F20: =IF(F4<3,F13*21*F19*(1-F42/100),(IF(F4=3,0,0.19*21*F19*$B45/100))) -> 3.6771 | G20: =IF(G4<3,G13*21*G19*(1-G42/100),(IF(G4=3,0,0.19*21*G19*$B45/100))) -> 4.1097
A21: CO2 emission (g/kg fuel) | B21: =IF(B4=4,2780,(IF(AND(B4=3,B2=2),2750,IF(B4<3,IF(B4=1,3114,3206))))) -> 3206 | C21: =IF(C4=3,2750,IF(C4=4,2780,IF(C4=1,3114,3206))) -> 3206 | D21: =IF(D4=4,2780,(IF(AND(D4=3,D2=2),2750,IF(D4<3,IF(D4=1,3114,3206))))) -> 3206 | E21: =IF(E4=3,2750,IF(E4=4,2780,IF(E4=1,3114,3206))) -> 3206 | F21: =IF(F4=4,2780,(IF(AND(F4=3,F2=2),2750,IF(F4<3,IF(F4=1,3114,3206))))) -> 3206 | G21: =IF(G4=3,2750,IF(G4=4,2780,IF(G4=1,3114,3206))) -> 3206
A22: NOx emission (g/kg fuel) | B22: =B15/B$13 -> 19.417476 | C22: =C15/C$13 -> 12.263669 | D22: =D15/D$13 -> 19.417476 | E22: =E15/E$13 -> 12.263669 | F22: =F15/F$13 -> 19.417476 | G22: =G15/G$13 -> 12.263669
A23: CO emission (g/kg fuel) | B23: =B16/B$13 -> 1.9988578 | C23: =C16/C$13 -> 2.554931 | D23: =D16/D$13 -> 1.9988578 | E23: =E16/E$13 -> 2.554931 | F23: =F16/F$13 -> 1.9988578 | G23: =G16/G$13 -> 2.554931
A24: HC emission (g/kg fuel) | B24: =B17/B$13 -> 2.8555111 | C24: =C17/C$13 -> 2.554931 | D24: =D17/D$13 -> 2.8555111 | E24: =E17/E$13 -> 2.554931 | F24: =F17/F$13 -> 2.8555111 | G24: =G17/G$13 -> 2.554931
A25: Particulates (g/kg fuel) | B25: =B18/B13 -> 2.5356939 | C25: =C18/C13 -> 2.2687787 | D25: =D18/D13 -> 2.5356939 | E25: =E18/E13 -> 2.2687787 | F25: =F18/F13 -> 2.5356939 | G25: =G18/G13 -> 2.2687787
A26: SO2 emission (g/kg fuel) | B26: =B20/B$13 -> 21 | C26: =C20/C$13 -> 21 | D26: =D20/D$13 -> 21 | E26: =E20/E$13 -> 21 | F26: =F20/F$13 -> 21 | G26: =G20/G$13 -> 21
A27: CO2 emission (g/MJ) | B27: =B21/B33 -> 75.081967 | C27: =C21/C33 -> 75.081967 | D27: =D21/D33 -> 75.081967 | E27: =E21/E33 -> 75.081967 | F27: =F21/F33 -> 75.081967 | G27: =G21/G33 -> 75.081967
A28: NOx emission (g/MJ) | B28: =B22/B33 -> 0.45474182 | C28: =C22/C33 -> 0.28720536 | D28: =D22/D33 -> 0.45474182 | E28: =E22/E33 -> 0.28720536 | F28: =F22/F33 -> 0.45474182 | G28: =G22/G33 -> 0.28720536
A29: CO emission (g/MJ) | B29: =B23/B33 -> 0.046811658 | C29: =C23/C33 -> 0.05983445 | D29: =D23/D33 -> 0.046811658 | E29: =E23/E33 -> 0.05983445 | F29: =F23/F33 -> 0.046811658 | G29: =G23/G33 -> 0.05983445
A30: HC emission (g/MJ) | B30: =B24/B33 -> 0.066873797 | C30: =C24/C33 -> 0.05983445 | D30: =D24/D33 -> 0.066873797 | E30: =E24/E33 -> 0.05983445 | F30: =F24/F33 -> 0.066873797 | G30: =G24/G33 -> 0.05983445
A31: Particulates (g/MJ) | B31: =B25/B33 -> 0.059383932 | C31: =C25/C33 -> 0.053132992 | D31: =D25/D33 -> 0.059383932 | E31: =E25/E33 -> 0.053132992 | F31: =F25/F33 -> 0.059383932 | G31: =G25/G33 -> 0.053132992
A32: SO2 emission (g/MJ) | B32: =B26/B33 -> 0.49180328 | C32: =C26/C33 -> 0.49180328 | D32: =D26/D33 -> 0.49180328 | E32: =E26/E33 -> 0.49180328 | F32: =F26/F33 -> 0.49180328 | G32: =G26/G33 -> 0.49180328
A33: Calorific value (MJ/kg fuel) | B33: =IF(B4=4,B35*B46/100+B34*B45/100,IF(B4=3,B35,B34)) -> 42.7 | C33: =IF(C4=4,C35*B46/100+B45/100*C34,IF(C4=3,C35,C34)) -> 42.7 | D33: =IF(D4=4,D35*B46/100+D34*B45/100,IF(D4=3,D35,D34)) -> 42.7 | E33: =IF(E4=4,E35*B46/100+B45/100*E34,IF(E4=3,E35,E34)) -> 42.7 | F33: =IF(F4=4,F35*B46/100+F34*B45/100,IF(F4=3,F35,F34)) -> 42.7 | G33: =IF(G4=4,G35*B46/100+B45/100*G34,IF(G4=3,G35,G34)) -> 42.7
A34: Calorific value (MJ/kg oil) | B34: =IF(B4=1,40.5,42.7) -> 42.7 | C34: =IF(C4=1,40.5,42.7) -> 42.7 | D34: =IF(D4=1,40.5,42.7) -> 42.7 | E34: =IF(E4=1,40.5,42.7) -> 42.7 | F34: =IF(F4=1,40.5,42.7) -> 42.7 | G34: =IF(G4=1,40.5,42.7) -> 42.7
A35: Calorific value (MJ/kg LNG) | B35: 50 | C35: 50 | D35: 50 | E35: 50 | F35: 50 | G35: 50
A36: SFOC change due to engine type (pct.) derated versus normal engine | B36: =IF(B2=1,-B3*4,0) -> 0 | C36: 0 | D36: =IF(D2=1,-D3*4,0) -> 0 | E36: 0 | F36: =IF(F2=1,-F3*4,0) -> 0 | G36: 0
A37: Extra energy demand due to scrubber (pct.) | B37: =IF(B11=1,3,0) -> 0 | C37: =B37 -> 0 | D37: =IF(D11=1,3,0) -> 0 | E37: =D37 -> 0 | F37: =IF(F11=1,3,0) -> 0 | G37: =F37 -> 0
A38: Extra energy demand due to NOx reducing EGR technology (pct.) | B38: =IF(OR(B7=1,B8=2,B8=3),0,IF(B8=1,(IF(B7=2,IF(B6=0,2,0.5),IF(B7=3,IF(B6=0,3,1.3)))))) -> 3 | C38: =B38 -> 3 | D38: =IF(OR(D7=1,D8=2,D8=3),0,IF(D8=1,(IF(D7=2,IF(D6=0,2,0.5),IF(D7=3,IF(D6=0,3,1.3)))))) -> 3 | E38: =D38 -> 3 | F38: =IF(OR(F7=1,F8=2,F8=3),0,IF(F8=1,(IF(F7=2,IF(F6=0,2,0.5),IF(F7=3,IF(F6=0,3,1.3)))))) -> 3 | G38: =F38 -> 3
A39: Total change of SFOC (pct.) | B39: =SUM(B36:B38) -> 3 | C39: =SUM(C36:C38) -> 3 | D39: =SUM(D36:D38) -> 3 | E39: =SUM(E36:E38) -> 3 | F39: =SUM(F36:F38) -> 3 | G39: =SUM(G36:G38) -> 3
A40: NOx reduction compared to Tier 1 (pct.) | B40: =IF(B7=1,0,IF(B7=2,20,IF(B7=3,80))) -> 80 | C40: =IF(C7=1,0,IF(C7=2,20,IF(C7=3,80))) -> 80 | D40: =IF(D7=1,0,IF(D7=2,20,IF(D7=3,80))) -> 80 | E40: =IF(E7=1,0,IF(E7=2,20,IF(E7=3,80))) -> 80 | F40: =IF(F7=1,0,IF(F7=2,20,IF(F7=3,80))) -> 80 | G40: =IF(G7=1,0,IF(G7=2,20,IF(G7=3,80))) -> 80
...

Sheet Emissions in harbor
A1: Emissions and energy demand in harbor (Container ship)
C2: Default | D2: Alternative 1 | E2: Alternative 2
A3: Maximum number of containers | B3: TEU | C3: ='SHIP DATA'!C2 -> 18000 | D3: ='SHIP DATA'!D2 -> 18000 | E3: ='SHIP DATA'!E2 -> 18000
A4: Capacity utilization (100 % ~ design condition) | B4: % | C4: ='SHIP DATA'!C72 -> 88.408683 | D4: ='SHIP DATA'!D72 -> 88.408683 | E4: ='SHIP DATA'!E72 -> 88.408683
A5: Utilized number of containers | B5: TEU | C5: ='SHIP DATA'!C72*'SHIP DATA'!C2/100 -> 15913.563 | D5: ='SHIP DATA'!D72*'SHIP DATA'!D2/100 -> 15913.563 | E5: ='SHIP DATA'!E72*'SHIP DATA'!E2/100 -> 15913.563
A6: Deadweight (cargo + consumerables + ballast water etc.) | B6: tons | C6: ='SHIP DATA'!C73 -> 141120 | D6: ='SHIP DATA'!D73 -> 141120 | E6: ='SHIP DATA'!E73 -> 141120
A7: Deadwight per container | B7: dwt/TEU | C7: =C6/C5 -> 8.8679072 | D7: =D6/D5 -> 8.8679072 | E7: =E6/E5 -> 8.8679072
A8: Draught | B8: m | C8: ='SHIP DATA'!C77 -> 13.280646 | D8: ='SHIP DATA'!D77 -> 13.280646 | E8: ='SHIP DATA'!E77 -> 13.280646
A10: Auxiliary power in harbor | B10: kW | C10: ='SHIP DATA'!$C$49 -> 6980.679 | D10: ='SHIP DATA'!$D$49 -> 6980.679 | E10: ='SHIP DATA'!$E$49 -> 6980.679
A11: Energy demand per hour | B11: GJ/hour | C11: ='SHIP DATA'!C86*'Emission factors'!C33 -> 58.333276 | D11: ='SHIP DATA'!D86*'Emission factors'!E33 -> 58.333276 | E11: ='SHIP DATA'!E85*'Emission factors'!G33 -> 18.690726
A12: Oil consumption per hour | B12: t/hour | C12: ='SHIP DATA'!C86 -> 1.3661189 | D12: ='SHIP DATA'!D86 -> 1.3661189 | E12: ='SHIP DATA'!E86 -> 1.3661189
A13: CO2 emissions per hour | B13: t/hour | C13: ='SHIP DATA'!C86*'Emission factors'!D21/1000 -> 4.3797771 | D13: ='SHIP DATA'!D86*'Emission factors'!E21/1000 -> 4.3797771 | E13: ='SHIP DATA'!E86*'Emission factors'!G21/1000 -> 4.3797771
A14: NOx emissions per hour | B14: kg/hour | C14: ='SHIP DATA'!C86*'Emission factors'!C22 -> 16.75363 | D14: ='SHIP DATA'!D86*'Emission factors'!E22 -> 16.75363 | E14: ='SHIP DATA'!E86*'Emission factors'!G22 -> 16.75363
A15: SOx emissions per hour | B15: kg/hour | C15: ='SHIP DATA'!C86*'Emission factors'!C26 -> 28.688497 | D15: ='SHIP DATA'!D86*'Emission factors'!E26 -> 28.688497 | E15: ='SHIP DATA'!E86*'Emission factors'!G26 -> 28.688497
A16: CO emissions per hour | B16: kg/hour | C16: ='SHIP DATA'!C86*'Emission factors'!C23 -> 3.4903395 | D16: ='SHIP DATA'!D86*'Emission factors'!E23 -> 3.4903395 | E16: ='SHIP DATA'!E86*'Emission factors'!G23 -> 3.4903395
A17: HC emissions per hour | B17: kg/hour | C17: ='SHIP DATA'!C86*'Emission factors'!C24 -> 3.4903395 | D17: ='SHIP DATA'!D86*'Emission factors'!E24 -> 3.4903395 | E17: ='SHIP DATA'!E86*'Emission factors'!G24 -> 3.4903395
A18: Particulate emissions per hour | B18: kg/hour | C18: ='SHIP DATA'!C86*'Emission factors'!$C25 -> 3.0994215 | D18: ='SHIP DATA'!D86*'Emission factors'!$E25 -> 3.0994215 | E18: ='SHIP DATA'!E86*'Emission factors'!$G25 -> 3.0994215

Sheet Emissions-TEU
A1: Emissions and energy demand (Container ship) | K1: Road | L1: Road | N1: Road | O1: Road
C2: Default | D2: Alternative 1 | E2: Alternative 2 | G2: Emissions and energy demand (Truck) | K2: km | L2: nm | N2: km | O2: nm
A3: Capacity utilization (100 % ~ design condition) | B3: % | C3: ='SHIP DATA'!C72 -> 88.408683 | D3: ='SHIP DATA'!D72 -> 88.408683 | E3: ='SHIP DATA'!E72 -> 88.408683 | G3: EURO NORM 2, 3, 4, 5 or 6 | H3: (-) | I3: 5 | K3: 1207 | L3: =K3/1.852 -> 651.72786 | N3: 179 | O3: =N3/1.852 -> 96.652268
A4: Utilized number of containers | B4: TEU | C4: ='SHIP DATA'!C72*'SHIP DATA'!C2/100 -> 15913.563 | D4: ='SHIP DATA'!D72*'SHIP DATA'!D2/100 -> 15913.563 | E4: ='SHIP DATA'!E72*'SHIP DATA'!E2/100 -> 15913.563 | G4: TEU per truck | H4: (-) | I4: ='Truck data'!D23 -> 2
A5: Deadweight (cargo + consumerables + ballast water etc.) | B5: tons | C5: ='SHIP DATA'!C73 -> 141120 | D5: ='SHIP DATA'!D73 -> 141120 | E5: ='SHIP DATA'!E73 -> 141120 | G5: Average weight of a container | H5: (tons/TEU) | I5: ='Truck data'!D24 -> 10
A6: Deadwight per container | B6: dwt/TEU | C6: =C5/C4 -> 8.8679072 | D6: =D5/D4 -> 8.8679072 | E6: =E5/E4 -> 8.8679072 | G6: Length of truck - total | H6: m | I6: ='Truck data'!D25 -> 16
A7: Draught | B7: m | C7: ='SHIP DATA'!C77 -> 13.280646 | D7: ='SHIP DATA'!D77 -> 13.280646 | E7: ='SHIP DATA'!E77 -> 13.280646 | G7: Weight of truck load | H7: (tons/truck) | I7: =I4*I5 -> 20
A8: Ship speed | B8: knots | C8: ='SHIP DATA'!C79 -> 25.7 | D8: ='SHIP DATA'!D79 -> 18.5 | E8: ='SHIP DATA'!E79 -> 18.5
A10: Energy demand
A11: Energy demand per hour | B11: GJ/hour | C11: ='SHIP DATA'!C85*'Emission factors'!C33+'SHIP DATA'!C87*'Emission factors'!B33 -> 549.85744 | D11: ='SHIP DATA'!D85*'Emission factors'!E33+'SHIP DATA'!D87*'Emission factors'!D33 -> 204.26216 | E11: ='SHIP DATA'!E85*'Emission factors'!G33+'SHIP DATA'!E87*'Emission factors'!F33 -> 268.07378 | G11: Energy consumption per TEU per naitical mile | H11: (MJ/TEU/nm) | I11: =1.852*(7.5+0.27*I7-0.001*I7^2)/I4 -> 11.575
A12: Energy demand per nautical mile | B12: GJ/nm | C12: =C11/C8 -> 21.395231 | D12: =D11/D8 -> 11.041198 | E12: =E11/E8 -> 14.490475 | G12: Energy consumption per ton cargo per naitical mile | H12: (MJ/t/nm) | I12: =I11/I5 -> 1.1575
A13: Energy demand per TEU per nautical mile | B13: MJ/TEU/nm | C13: =C12*1000/C4 -> 1.3444652 | D13: =D12*1000/D4 -> 0.6938231 | E13: =E12*1000/E4 -> 0.91057387 | G13: Energy consumption per lanemeter per nautical mile | H13: (MJ/lm/nm) | I13: =I11*I4/I6 -> 1.446875
A15: Oil consumption
A16: Oil consumption per hour | B16: t/hour | C16: ='SHIP DATA'!C88 -> 12.877224 | D16: ='SHIP DATA'!D88 -> 4.783657 | E16: ='SHIP DATA'!E88 -> 6.2780745 | G16: Oil consumption per TEU per nautical mile | H16: (g/TEU/nm) | I16: ='Truck data'!D32*1.852 -> 270.44393
A17: Oil consumption demand per nautical mile | B17: kg/nm | C17: =C16*1000/C8 -> 501.05928 | D17: =D16*1000/D8 -> 258.57606 | E17: =E16*1000/E8 -> 339.35538 | G17: Oil consumption per ton cargo per nautical mile | H17: (g/t/nm) | I17: =I16/I5 -> 27.044393
A18: Oil consumption per TEU per nautical mile | B18: g/TEU/nm | C18: =C17*1000/C4 -> 31.486304 | D18: =D17*1000/D4 -> 16.248785 | E18: =E17*1000/E4 -> 21.324915 | G18: Oil consumption per lanemeter per nautical mile | H18: (g/lm/nm) | I18: =I16*I4/I6 -> 33.805491
A20: CO2 emissions
A21: CO2 emissions per hour | B21: t/hour | C21: =('SHIP DATA'!C85*'Emission factors'!C21+'SHIP DATA'!C87*'Emission factors'!B21)/1000 -> 41.284379 | D21: =('SHIP DATA'!D85*'Emission factors'!E21+'SHIP DATA'!D87*'Emission factors'!D21)/1000 -> 15.336404 | E21: =('SHIP DATA'!E85*'Emission factors'!G21+'SHIP DATA'!E87*'Emission factors'!F21)/1000 -> 20.127507 | G21: CO2 emissions per TEU per nautical mile | H21: (g/TEU/nm) | I21: ='Truck data'!D35*1.852 -> 867.04322 | L21: =L3*I21/1000 -> 565.07623 | O21: =N3*I21/1000 -> 155.20074
A22: CO2 emissions per nautical mile | B22: kg/nm | C22: =C21*1000/C8 -> 1606.3961 | D22: =D21*1000/D8 -> 828.99484 | E22: =E21*1000/E8 -> 1087.9733 | G22: CO2 emissions per ton cargo per nautical mile | H22: (g/t/nm) | I22: =I21/I5 -> 86.704322
A23: CO2 emissions per TEU per nautical mile | B23: g/TEU/nm | C23: =C22*1000/C4 -> 100.94509 | D23: =D22*1000/D4 -> 52.093603 | E23: =E22*1000/E4 -> 68.367677 | G23: CO2 emissions per lanemeter per nautical mile | H23: (g/lm/nm) | I23: =I21*I4/I6 -> 108.3804
A25: NOx emissions
A26: NOx emissions per hour | B26: kg/hour | C26: ='SHIP DATA'!C85*'Emission factors'!C22+'SHIP DATA'!C87*'Emission factors'!B22 -> 246.34882 | D26: ='SHIP DATA'!D85*'Emission factors'!E22+'SHIP DATA'!D87*'Emission factors'!D22 -> 90.257242 | E26: ='SHIP DATA'!E85*'Emission factors'!G22+'SHIP DATA'!E87*'Emission factors'!F22 -> 118.77298 | G26: NOx emissions per TEU per naitical mile | H26: (g/TEU/nm) | I26: ='Truck data'!D38*1.852 -> 2.7044393
A27: NOx emissions per nautical mile | B27: kg/nm | C27: =C26/C8 -> 9.5855572 | D27: =D26/D8 -> 4.8787699 | E27: =E26/E8 -> 6.4201611 | G27: NOx emissions per ton cargo per naitical mile | H27: (g/t/nm) | I27: =I26/I5 -> 0.27044393
A28: NOx emissions per TEU per nautical mile | B28: g/TEU/nm | C28: =C27*1000/C4 -> 0.60235141 | D28: =D27*1000/D4 -> 0.30657935 | E28: =E27*1000/E4 -> 0.40343958 | G28: NOx emissions per lanemeter per nautical mile | H28: (g/lm/nm) | I28: =I26*I4/I6 -> 0.33805491
A30: SOx emissions
A31: SOx emissions per hour | B31: kg/hour | C31: ='SHIP DATA'!C85*'Emission factors'!C26+'SHIP DATA'!C87*'Emission factors'!B26 -> 270.42169 | D31: ='SHIP DATA'!D85*'Emission factors'!E26+'SHIP DATA'!D87*'Emission factors'!D26 -> 100.4568 | E31: ='SHIP DATA'!E85*'Emission factors'!G26+'SHIP DATA'!E87*'Emission factors'!F26 -> 131.83956 | G31: SOx emissions per TEU per nautical mile | H31: (g/TEU/km) | I31: ='Truck data'!D47*1.852 -> 0.0054088785
A32: SOx emissions per nautical mile | B32: kg/nm | C32: =C31/C8 -> 10.522245 | D32: =D31/D8 -> 5.4300972 | E32: =E31/E8 -> 7.1264629 | G32: SOx emissions per ton cargo per nautical mile | H32: (g/t/km) | I32: =I31/I5 -> 0.00054088785
A33: SOx emissions per TEU per nautical mile | B33: g/TEU/nm | C33: =C32*1000/C4 -> 0.66121238 | D33: =D32*1000/D4 -> 0.34122447 | E33: =E32*1000/E4 -> 0.44782321 | G33: SOx emissions per lanemeter per nautical mile | H33: (g/lm/nm) | I33: =I31*I4/I6 -> 0.00067610981
A35: CO emissions
A36: CO emissions per hour | B36: kg/hour | C36: ='SHIP DATA'!C85*'Emission factors'!C23+'SHIP DATA'!C87*'Emission factors'!B23 -> 26.026905 | D36: ='SHIP DATA'!D85*'Emission factors'!E23+'SHIP DATA'!D87*'Emission factors'!D23 -> 9.7662287 | E36: ='SHIP DATA'!E85*'Emission factors'!G23+'SHIP DATA'!E87*'Emission factors'!F23 -> 12.792384 | G36: CO emissions per TEU per nautical mile | H36: (g/TEU/nm) | I36: ='Truck data'!D44*1.852 -> 0.13522196
A37: CO emissions per nautical mile | B37: kg/nm | C37: =C36/C8 -> 1.01272 | D37: =D36/D8 -> 0.52790425 | E37: =E36/E8 -> 0.69148019 | G37: CO emissions per ton cargo per nautical mile | H37: (g/t/nm) | I37: =I36/I5 -> 0.013522196
A38: CO emissions per TEU per nautical mile | B38: g/TEU/nm | C38: =C37*1000/C4 -> 0.063638799 | D38: =D37*1000/D4 -> 0.033173228 | E38: =E37*1000/E4 -> 0.043452255 | G38: CO emissions per lanemeter per nautical mile | H38: (g/lm/nm) | I38: =I36*I4/I6 -> 0.016902745
A40: HC emissions
A41: HC emissions per hour | B41: kg/hour | C41: ='SHIP DATA'!C85*'Emission factors'!C24+'SHIP DATA'!C87*'Emission factors'!B24 -> 36.61583 | D41: ='SHIP DATA'!D85*'Emission factors'!E24+'SHIP DATA'!D87*'Emission factors'!D24 -> 13.549311 | E41: ='SHIP DATA'!E85*'Emission factors'!G24+'SHIP DATA'!E87*'Emission factors'!F24 -> 17.795541 | G41: HC emissions per TEU per nautical mile | H41: (g/TEU/nm) | I41: ='Truck data'!D41*1.852 -> 0.020283294
A42: HC emissions per nautical mile | B42: kg/nm | C42: =C41/C8 -> 1.4247405 | D42: =D41/D8 -> 0.73239519 | E42: =E41/E8 -> 0.96192114 | G42: HC emissions per ton cargo per nautical mile | H42: (g/t/nm) | I42: =I41/I5 -> 0.0020283294
A43: HC emissions per TEU per nautical mile | B43: g/TEU/nm | C43: =C42*1000/C4 -> 0.089529948 | D43: =D42*1000/D4 -> 0.046023332 | E43: =E42*1000/E4 -> 0.060446623 | G43: HC emissions per lanemeter per naitical mile | H43: (g/lm/nm) | I43: =I41*I4/I6 -> 0.0025354118
A45: Particulate emissions
A46: Particulate emissions per hour | B46: kg/hour | C46: ='SHIP DATA'!C85*'Emission factors'!$C25+'SHIP DATA'!C87*'Emission factors'!B25 -> 32.514857 | D46: ='SHIP DATA'!D85*'Emission factors'!$E25+'SHIP DATA'!D87*'Emission factors'!D25 -> 12.031788 | E46: ='SHIP DATA'!E85*'Emission factors'!$G25+'SHIP DATA'!E87*'Emission factors'!F25 -> 15.80244 | G46: Particulate emissions per TEU per nautical mile | H46: (g/TEU/nm) | I46: ='Truck data'!D50*1.852 -> 0.027044393
A47: Particalate emissions per nautical mile | B47: kg/nm | C47: =C46/C8 -> 1.2651695 | D47: =D46/D8 -> 0.65036693 | E47: =E46/E8 -> 0.85418597 | G47: Particulate emissions per ton cargo per nautical mile | H47: (g/t/nm) | I47: =I46/I5 -> 0.0027044393
A48: Particulate emissions per TEU per nautical mile | B48: g/TEU/nm | C48: =C47*1000/C4 -> 0.079502594 | D48: =D47*1000/D4 -> 0.040868719 | E48: =E47*1000/E4 -> 0.053676601 | G48: Particulate emissions per lanemeter per nautical mile | H48: (g/lm/nm) | I48: =I46*I4/I6 -> 0.0033805491

Sheet Emissions-ton
A1: Emissions and energy demand | C1: ='SHIP DATA'!C2 -> 18000 | D1: TEU
A2: Condition data
A3: Capacity utilization (100 % ~ design condition) | B3: % | C3: ='SHIP DATA'!C72 -> 88.408683 | D3: ='SHIP DATA'!D72 -> 88.408683 | E3: ='SHIP DATA'!E72 -> 88.408683
A4: Deadweight (cargo + consumerables + ballast water etc.) | B4: tons | C4: ='SHIP DATA'!C73 -> 141120 | D4: ='SHIP DATA'!D73 -> 141120 | E4: ='SHIP DATA'!E73 -> 141120
A5: Payload i.e. cargo only | B5: tons | C5: ='SHIP DATA'!C74 -> 134136.9 | D5: ='SHIP DATA'!D74 -> 134136.9 | E5: ='SHIP DATA'!E74 -> 134136.9
A6: Deadweight/TEU | B6: dwt/TEU | C6: =C4/'Emissions-TEU'!C4 -> 8.8679072 | D6: =D4/'Emissions-TEU'!D4 -> 8.8679072 | E6: =E4/'Emissions-TEU'!E4 -> 8.8679072
A7: Payload/TEU | B7: t/TEU | C7: =C5/'Emissions-TEU'!C4 -> 8.429093 | D7: =D5/'Emissions-TEU'!D4 -> 8.429093 | E7: =E5/'Emissions-TEU'!E4 -> 8.429093
A8: Draught | B8: m | C8: ='SHIP DATA'!C77 -> 13.280646 | D8: ='SHIP DATA'!D77 -> 13.280646 | E8: ='SHIP DATA'!E77 -> 13.280646
A9: Ship speed | B9: knots | C9: ='SHIP DATA'!C79 -> 25.7 | D9: ='SHIP DATA'!D79 -> 18.5 | E9: ='SHIP DATA'!E79 -> 18.5
A10: Speed dependency exponent N (Power = constant VN) | C10: ='SHIP DATA'!C81 -> 3.5098067 | D10: ='SHIP DATA'!D81 -> 2.9567346 | E10: ='SHIP DATA'!E81 -> 2.8045177
A12: Energy demand
A13: Energy demand per hour | B13: GJ/hour | C13: ='SHIP DATA'!C85*'Emission factors'!C33+'SHIP DATA'!C87*'Emission factors'!B33 -> 549.85744 | D13: ='SHIP DATA'!D85*'Emission factors'!E33+'SHIP DATA'!D87*'Emission factors'!D33 -> 204.26216 | E13: ='SHIP DATA'!E85*'Emission factors'!G33+'SHIP DATA'!E87*'Emission factors'!F33 -> 268.07378
A14: Energy demand per nautiacal mile | B14: GJ/nm | C14: =C13/C9 -> 21.395231 | D14: =D13/D9 -> 11.041198 | E14: =E13/E9 -> 14.490475
A15: Energy demand per ton payload per nautical mile | B15: MJ/t/nm | C15: =C16*C4/C5 -> 0.15950295 | D15: =D16*D4/D5 -> 0.082312901 | E15: =E16*E4/E5 -> 0.1080275
A16: Energy demand per ton deadweight per nautical mile | B16: MJ/dwt/nm | C16: =C14*1000/C4 -> 0.1516102 | D16: =D14*1000/D4 -> 0.078239779 | E16: =E14*1000/E4 -> 0.10268193
A17: Energy demand per ton payload per km | B17: g/t/km | C17: =C15/1.852 -> 0.086124702 | D17: =D15/1.852 -> 0.044445411 | E17: =E15/1.852 -> 0.058330185 | F17: Useful for comparison with transportation with truck or train
A18: Oil consumption
A19: Oil consumption per hour | B19: t/hour | C19: ='SHIP DATA'!C88 -> 12.877224 | D19: ='SHIP DATA'!D88 -> 4.783657 | E19: ='SHIP DATA'!E88 -> 6.2780745
A20: Oil consumption demand per nautical mile | B20: kg/nm | C20: =C19*1000/C9 -> 501.05928 | D20: =D19*1000/D9 -> 258.57606 | E20: =E19*1000/E9 -> 339.35538
A21: Oil consumption per ton payload per nautical mile | B21: g/t/nm | C21: =C22*C4/C5 -> 3.735432 | D21: =D22*D4/D5 -> 1.9277026 | E21: =E22*E4/E5 -> 2.5299181
A22: Oil consumption per ton deadweight per nautical mile | B22: g/dwt/nm | C22: =C20*1000/C4 -> 3.5505901 | D22: =D20*1000/D4 -> 1.8323133 | E22: =E20*1000/E4 -> 2.4047291
A23: CO2 emissions
A24: CO2 emissions per hour | B24: t/hour | C24: =('SHIP DATA'!C85*'Emission factors'!C21+'SHIP DATA'!C87*'Emission factors'!B21)/1000 -> 41.284379 | D24: =('SHIP DATA'!D85*'Emission factors'!E21+'SHIP DATA'!D87*'Emission factors'!D21)/1000 -> 15.336404 | E24: =('SHIP DATA'!E85*'Emission factors'!G21+'SHIP DATA'!E87*'Emission factors'!F21)/1000 -> 20.127507
A25: CO2 emissions per nautical mile | B25: kg/nm | C25: =C24*1000/C9 -> 1606.3961 | D25: =D24*1000/D9 -> 828.99484 | E25: =E24*1000/E9 -> 1087.9733
A26: CO2 emissions per ton payload per nautical mile | B26: g/t/nm | C26: =C27*C4/C5 -> 11.975795 | D26: =D27*D4/D5 -> 6.1802146 | E26: =E27*E4/E5 -> 8.1109174
A27: CO2 emissions per ton deadweight per nautical mile | B27: g/dwt/nm | C27: =C25*1000/C4 -> 11.383192 | D27: =D25*1000/D4 -> 5.8743965 | E27: =E25*1000/E4 -> 7.7095616
A28: CO2 emissions per ton payload per km | B28: g/t/km | C28: =C26/1.852 -> 6.466412 | D28: =D26/1.852 -> 3.3370489 | E28: =E26/1.852 -> 4.3795451 | F28: Useful for comparison with transportation with truck or train
A29: NOx emissions
A30: NOx emissions per hour | B30: kg/hour | C30: ='SHIP DATA'!C85*'Emission factors'!C22+'SHIP DATA'!C87*'Emission factors'!B22 -> 246.34882 | D30: ='SHIP DATA'!D85*'Emission factors'!E22+'SHIP DATA'!D87*'Emission factors'!D22 -> 90.257242 | E30: ='SHIP DATA'!E85*'Emission factors'!G22+'SHIP DATA'!E87*'Emission factors'!F22 -> 118.77298
A31: NOx emissions per nautical mile | B31: kg/nm | C31: =C30/C9 -> 9.5855572 | D31: =D30/D9 -> 4.8787699 | E31: =E30/E9 -> 6.4201611
A32: NOx emissions per ton payload per nautical mile | B32: g/t/nm | C32: =C33*C4/C5 -> 0.071461 | D32: =D33*D4/D5 -> 0.036371571 | E32: =E33*E4/E5 -> 0.047862751
A33: NOx emissions per ton deadweight per nautical mile | B33: g/dwt/nm | C33: =C31*1000/C4 -> 0.067924867 | D33: =D31*1000/D4 -> 0.034571782 | E33: =E31*1000/E4 -> 0.045494339
A34: SOx emissions
A35: SOx emissions per hour | B35: kg/hour | C35: ='SHIP DATA'!C85*'Emission factors'!C26+'SHIP DATA'!C87*'Emission factors'!B26 -> 270.42169 | D35: ='SHIP DATA'!D85*'Emission factors'!E26+'SHIP DATA'!D87*'Emission factors'!D26 -> 100.4568 | E35: ='SHIP DATA'!E85*'Emission factors'!G26+'SHIP DATA'!E87*'Emission factors'!F26 -> 131.83956
A36: SOx emissions per nautical mile | B36: kg/nm | C36: =C35/C9 -> 10.522245 | D36: =D35/D9 -> 5.4300972 | E36: =E35/E9 -> 7.1264629
A37: SOx emissions per ton payload per nautical mile | B37: g/t/nm | C37: =C38*C4/C5 -> 0.078444073 | D37: =D38*D4/D5 -> 0.040481755 | E37: =E38*E4/E5 -> 0.05312828
A38: SOx emissions per ton deadweight per nautical mile | B38: g/dwt/nm | C38: =C36*1000/C4 -> 0.074562393 | D38: =D36*1000/D4 -> 0.03847858 | E38: =E36*1000/E4 -> 0.050499312
A39: CO emissions
A40: CO emissions per hour | B40: kg/hour | C40: ='SHIP DATA'!C85*'Emission factors'!C23+'SHIP DATA'!C87*'Emission factors'!B23 -> 26.026905 | D40: ='SHIP DATA'!D85*'Emission factors'!E23+'SHIP DATA'!D87*'Emission factors'!D23 -> 9.7662287 | E40: ='SHIP DATA'!E85*'Emission factors'!G23+'SHIP DATA'!E87*'Emission factors'!F23 -> 12.792384
A41: CO emissions per nautical mile | B41: kg/nm | C41: =C40/C9 -> 1.01272 | D41: =D40/D9 -> 0.52790425 | E41: =E40/E9 -> 0.69148019
...

Sheet WEIGHT
A1: Weight according to Watson and Gilfillan | E1: Default | H1: Alternative 1 | O1: Alternative 2
A3: Main dimensions | H3: Main dimensions | O3: Main dimensions
A4: Length between perpendiculars | B4: m | C4: ='SHIP DATA'!C5 -> 406.13587 | D4: Block coefficient at design draught | G4: =C8/1.025/C4/C5/C7 -> 0.69280226 | H4: Length between perpendiculars | I4: m | J4: ='SHIP DATA'!D5 -> 406.13587 | K4: Block coefficient at design draught | N4: =J8/1.025/J4/J5/J7 -> 0.69280226 | O4: Length between perpendiculars | P4: m | Q4: ='SHIP DATA'!E5 -> 406.13587 | R4: Block coefficient at design draught | U4: =Q8/1.025/Q4/Q5/Q7 -> 0.69280226
A5: Breadth | B5: m | C5: ='SHIP DATA'!C8 -> 55.91 | D5: Block coefficient at upper deck D | G5: =G4+(1-G4)*(C6-C7)/3/C7 -> 0.77977577 | H5: Breadth | I5: m | J5: ='SHIP DATA'!D8 -> 55.91 | K5: Block coefficient at upper deck D | N5: =N4+(1-N4)*(J6-J7)/3/J7 -> 0.77977577 | O5: Breadth | P5: m | Q5: ='SHIP DATA'!E8 -> 55.91 | R5: Block coefficient at upper deck D | U5: =U4+(1-U4)*(Q6-Q7)/3/Q7 -> 0.77977577
A6: Depth to upper deck | B6: m | C6: ='SHIP DATA'!C9 -> 30.2 | D6: Block coefficient at 0,8 x D | G6: =G4+(1-G4)*(0.8*C6-C7)/3/C7 -> 0.74190122 | H6: Depth to upper deck | I6: m | J6: ='SHIP DATA'!D9 -> 30.2 | K6: Block coefficient at 0,8 x D | N6: =N4+(1-N4)*(0.8*J6-J7)/3/J7 -> 0.74190122 | O6: Depth to upper deck | P6: m | Q6: ='SHIP DATA'!E9 -> 30.2 | R6: Block coefficient at 0,8 x D | U6: =U4+(1-U4)*(0.8*Q6-Q7)/3/Q7 -> 0.74190122
A7: Draught | B7: m | C7: ='SHIP DATA'!C11 -> 16.33 | H7: Draught | I7: m | J7: ='SHIP DATA'!D11 -> 16.33 | O7: Draught | P7: m | Q7: ='SHIP DATA'!E11 -> 16.33
A8: Displacement | B8: tons | C8: ='SHIP DATA'!C15+'SHIP DATA'!C17*WEIGHT!C4*WEIGHT!C5*WEIGHT!C6 -> 263317.78 | H8: Displacement | I8: tons | J8: ='SHIP DATA'!D15+'SHIP DATA'!D17*WEIGHT!J4*WEIGHT!J5*WEIGHT!J6 -> 263317.78 | O8: Displacement | P8: tons | Q8: ='SHIP DATA'!E15+'SHIP DATA'!E17*WEIGHT!Q4*WEIGHT!Q5*WEIGHT!Q6 -> 263317.78
A9: Full width erections | B9: Length | C9: Breadth | D9: Height | E9: Area | F9: Volume | G9: L X H | H9: Full width erections | I9: Length | J9: Breadth | K9: Height | L9: Area | M9: Volume | N9: L X H | O9: Full width erections | P9: Length | Q9: Breadth | R9: Height | S9: Area | T9: Volume | U9: L X H
B10: m | C10: m | D10: m | E10: m2 | F10: m3 | G10: m2 | I10: m | J10: m | K10: m | L10: m2 | M10: m3 | N10: m2 | P10: m | Q10: m | R10: m | S10: m2 | T10: m3 | U10: m2
A12: Sum1 | E12: =SUM(E11:E11) -> 0 | F12: =SUM(F11:F11) -> 0 | G12: =SUM(G11:G11) -> 0 | H12: Sum1 | L12: =SUM(L11:L11) -> 0 | M12: =SUM(M11:M11) -> 0 | N12: =SUM(N11:N11) -> 0 | O12: Sum1 | S12: =SUM(S11:S11) -> 0 | T12: =SUM(T11:T11) -> 0 | U12: =SUM(U11:U11) -> 0
A13: Deck houses | B13: Length | C13: Breadth | D13: Height | E13: Area | F13: Volume | G13: L X H | H13: Deck houses | I13: Length | J13: Breadth | K13: Height | L13: Area | M13: Volume | N13: L X H | O13: Deck houses | P13: Length | Q13: Breadth | R13: Height | S13: Area | T13: Volume | U13: L X H
B14: m | C14: m | D14: m | E14: m2 | F14: m3 | G14: m2 | I14: m | J14: m | K14: m | L14: m2 | M14: m3 | N14: m2 | P14: m | Q14: m | R14: m | S14: m2 | T14: m3 | U14: m2
B15: =C4*0.05 -> 20.306794 | C15: =0.9*C5 -> 50.319 | D15: =C6 -> 30.2 | E15: =B15*C15 -> 1021.8175 | F15: =D15*E15 -> 30858.89 | G15: =B15*D15 -> 613.26517 | I15: =J4*0.05 -> 20.306794 | J15: =0.9*J5 -> 50.319 | K15: =J6 -> 30.2 | L15: =I15*J15 -> 1021.8175 | M15: =K15*L15 -> 30858.89 | N15: =I15*K15 -> 613.26517 | P15: =Q4*0.05 -> 20.306794 | Q15: =0.9*Q5 -> 50.319 | R15: =Q6 -> 30.2 | S15: =P15*Q15 -> 1021.8175 | T15: =R15*S15 -> 30858.89 | U15: =P15*R15 -> 613.26517
A16: Sum2 | E16: =SUM(E15:E15) -> 1021.8175 | F16: =SUM(F15:F15) -> 30858.89 | G16: =SUM(G15:G15) -> 613.26517 | H16: Sum2 | L16: =SUM(L15:L15) -> 1021.8175 | M16: =SUM(M15:M15) -> 30858.89 | N16: =SUM(N15:N15) -> 613.26517 | O16: Sum2 | S16: =SUM(S15:S15) -> 1021.8175 | T16: =SUM(T15:T15) -> 30858.89 | U16: =SUM(U15:U15) -> 613.26517
A17: E - steel factor (normal 0.036) | C17: 0.036 | H17: E - steel factor (normal 0.036) | J17: =C17 -> 0.036 | O17: E - steel factor (normal 0.036) | Q17: =C17 -> 0.036
A18: Volumetric outfit weight factor | C18: 0.015 | H18: Volumetric outfit weight factor | J18: 0.015 | O18: Volumetric outfit weight factor | Q18: 0.015
A19: Calculated volumes and weights | H19: Calculated volumes and weights | O19: Calculated volumes and weights
A20: Hull volume | B20: m3 | C20: =G5*C4*C5*C6 -> 534733.66 | D20: = Vs | H20: Hull volume | I20: m3 | J20: =N5*J4*J5*J6 -> 534733.66 | K20: = Vs | O20: Hull volume | P20: m3 | Q20: =U5*Q4*Q5*Q6 -> 534733.66 | R20: = Vs
A21: Volume of erections & houses | B21: m3 | C21: =F12+F16 -> 30858.89 | D21: =Vo | H21: Volume of erections & houses | I21: m3 | J21: =M12+M16 -> 30858.89 | K21: =Vo | O21: Volume of erections & houses | P21: m3 | Q21: =T12+T16 -> 30858.89 | R21: =Vo
A22: Total volume | B22: m3 | C22: =C20+C21 -> 565592.55 | D22: =Vtot | H22: Total volume | I22: m3 | J22: =J20+J21 -> 565592.55 | K22: =Vtot | O22: Total volume | P22: m3 | Q22: =Q20+Q21 -> 565592.55 | R22: =Vtot
A23: Hull Numeral, E | B23: m2 | C23: =C4*(C5+C7)+0.85*C4*(C6-C7)+0.85*G12+0.75*G16 -> 34587.343 | H23: Hull Numeral, E | I23: m2 | J23: =J4*(J5+J7)+0.85*J4*(J6-J7)+0.85*N12+0.75*N16 -> 34587.343 | O23: Hull Numeral, E | P23: m2 | Q23: =Q4*(Q5+Q7)+0.85*Q4*(Q6-Q7)+0.85*U12+0.75*U16 -> 34587.343
A24: Steel weight (Watson) | B24: tons | C24: =C17*C23^1.36*(1+0.5*(G6-0.7)) -> 54731.157 | E24: =C24/C27*100 -> 89.880345 | H24: Steel weight (Watson) | I24: tons | J24: =J17*J23^1.36*(1+0.5*(N6-0.7)) -> 54731.157 | O24: Steel weight (Watson) | P24: tons | Q24: =Q17*Q23^1.36*(1+0.5*(U6-0.7)) -> 54731.157
A25: Machinery weight | B25: tons | C25: =IF('SHIP DATA'!C58=1,1,0.7)*(0.08*'SHIP DATA'!C47-0.00000032*'SHIP DATA'!C47^2) -> 4722.5202 | E25: =C25/C27*100 -> 7.7553951 | H25: Machinery weight | I25: tons | J25: =IF('SHIP DATA'!D58=1,1,0.7)*(0.08*'SHIP DATA'!D47-0.00000032*'SHIP DATA'!D47^2) -> 3852.7152 | O25: Machinery weight | P25: tons | Q25: =IF('SHIP DATA'!E58=1,1,0.7)*(0.08*'SHIP DATA'!E47-0.00000032*'SHIP DATA'!E47^2) -> 4336.5862
A26: Outfit weight | B26: tons | C26: =49*'SHIP DATA'!C2^0.345 -> 1439.6771 | E26: =C26/C27*100 -> 2.3642598 | H26: Outfit weight | I26: tons | J26: =49*'SHIP DATA'!D2^0.345 -> 1439.6771 | O26: Outfit weight | P26: tons | Q26: =49*'SHIP DATA'!D2^0.345 -> 1439.6771
A27: Total weight | B27: tons | C27: =SUM(C24:C26) -> 60893.354 | E27: 100 | H27: Total weight based on detailed calculation | I27: tons | J27: =J25+J26+J66 -> 60023.549 | O27: Total weight | P27: tons | Q27: =Q25+Q26+Q66 -> 60507.42
A28: Light weight | B28: tons | C28: ='SHIP DATA'!C21 -> 61717.78 | D28: =C28/C27 -> 1.0135388 | H28: Light weight | I28: tons | J28: ='SHIP DATA'!D21 -> 61717.78 | K28: =J28/J27 -> 1.0282261 | O28: Light weight | P28: tons | Q28: ='SHIP DATA'!E21 -> 61717.78 | R28: =Q28/Q27 -> 1.0200035
H29: Light weight without power correction | I29: tons | J29: =J8-'SHIP DATA'!D15 -> 61717.78 | K29: =J29/J27 -> 1.0282261 | O29: Light weight without power correction | P29: tons | Q29: =Q8-'SHIP DATA'!E15 -> 61717.78 | R29: =Q29/Q27 -> 1.0200035
H30: Change of steel weight | I30: tons | J30: =J66-C24 -> 0 | O30: Change of steel weight | P30: tons | Q30: =Q66-C24 -> 0
H31: Change of machinery weight | I31: tons | J31: =J25-C25 -> -869.80502 | O31: Change of machinery weight | P31: tons | Q31: =Q25-C25 -> -385.93393
H32: Change of outfit weight | I32: tons | J32: =J26-C26 -> 0 | O32: Change of outfit weight | P32: tons | Q32: =Q26-C26 -> 0
A33: Weight according to Munro-Smith
A34: Main dimensions | C34: Basis ship | H34: Main dimensions | J34: Actual ship | K34: Difference | O34: Main dimensions | Q34: Actual ship | R34: Difference
A35: Length between perpendiculars | B35: m | C35: ='SHIP DATA'!C5 -> 406.13587 | H35: Length between perpendiculars | I35: m | J35: ='SHIP DATA'!D5 -> 406.13587 | K35: =J35-C35 -> 0 | O35: Length between perpendiculars | P35: m | Q35: ='SHIP DATA'!E5 -> 406.13587 | R35: =Q35-C35 -> 0
A36: Breadth | B36: m | C36: ='SHIP DATA'!C8 -> 55.91 | H36: Breadth | I36: m | J36: ='SHIP DATA'!D8 -> 55.91 | K36: =J36-C36 -> 0 | O36: Breadth | P36: m | Q36: ='SHIP DATA'!E8 -> 55.91 | R36: =Q36-C36 -> 0
A37: Depth to upper deck | B37: m | C37: ='SHIP DATA'!C9 -> 30.2 | H37: Depth to upper deck | I37: m | J37: ='SHIP DATA'!D9 -> 30.2 | K37: =J37-C37 -> 0 | O37: Depth to upper deck | P37: m | Q37: ='SHIP DATA'!E9 -> 30.2 | R37: =Q37-C37 -> 0
A38: Draught | B38: m | C38: ='SHIP DATA'!C11 -> 16.33 | H38: Draught | I38: m | J38: ='SHIP DATA'!D11 -> 16.33 | O38: Draught | P38: m | Q38: ='SHIP DATA'!E11 -> 16.33
A39: Displacement | B39: tons | C39: =C8 -> 263317.78 | H39: Displacement | I39: tons | J39: =J8 -> 263317.78 | O39: Displacement | P39: tons | Q39: =Q8 -> 263317.78
A40: Block coefficient at design draught | B40: (-) | C40: =C39/1.025/C35/C36/C38 -> 0.69280226 | H40: Block coefficient at design draught | I40: (-) | J40: =J39/1.025/J35/J36/J38 -> 0.69280226 | O40: Block coefficient at design draught | P40: (-) | Q40: =Q39/1.025/Q35/Q36/Q38 -> 0.69280226
A41: Block coefficient at upper deck D | B41: (-) | C41: =C40+(1-C40)*(C37-C38)/3/C38 -> 0.77977577 | H41: Block coefficient at upper deck D | I41: (-) | J41: =J40+(1-J40)*(J37-J38)/3/J38 -> 0.77977577 | K41: =J41-C41 -> 0 | O41: Block coefficient at upper deck D | P41: (-) | Q41: =Q40+(1-Q40)*(Q37-Q38)/3/Q38 -> 0.77977577 | R41: =Q41-C41 -> 0
A42: Hull volume | B42: m3 | C42: =C41*C35*C36*C37 -> 534733.66 | H42: Hull volume | I42: m3 | J42: =J41*J35*J36*J37 -> 534733.66 | K42: =J42-C42 -> 0 | O42: Hull volume | P42: m3 | Q42: =Q41*Q35*Q36*Q37 -> 534733.66 | R42: =Q42-C42 -> 0
...

Sheet PS1
